time 0ms: Simulator started for FCFS [Q empty]
time 2ms: Process B4 arrived; added to ready queue [Q B4]
time 4ms: Process B4 started using the CPU for 32ms burst [Q empty]
time 9ms: Process B1 arrived; added to ready queue [Q B1]
time 29ms: Process A6 arrived; added to ready queue [Q B1 A6]
time 30ms: Process B7 arrived; added to ready queue [Q B1 A6 B7]
time 36ms: Process B4 completed a CPU burst; 15 bursts to go [Q B1 A6 B7]
time 36ms: Process B4 switching out of CPU; blocking on I/O until time 159ms [Q B1 A6 B7]
time 40ms: Process B1 started using the CPU for 28ms burst [Q A6 B7]
time 41ms: Process A9 arrived; added to ready queue [Q A6 B7 A9]
time 45ms: Process A0 arrived; added to ready queue [Q A6 B7 A9 A0]
time 45ms: Process B0 arrived; added to ready queue [Q A6 B7 A9 A0 B0]
time 46ms: Process B2 arrived; added to ready queue [Q A6 B7 A9 A0 B0 B2]
time 47ms: Process A1 arrived; added to ready queue [Q A6 B7 A9 A0 B0 B2 A1]
time 54ms: Process A7 arrived; added to ready queue [Q A6 B7 A9 A0 B0 B2 A1 A7]
time 62ms: Process A8 arrived; added to ready queue [Q A6 B7 A9 A0 B0 B2 A1 A7 A8]
time 68ms: Process B1 completed a CPU burst; 16 bursts to go [Q A6 B7 A9 A0 B0 B2 A1 A7 A8]
time 68ms: Process B1 switching out of CPU; blocking on I/O until time 288ms [Q A6 B7 A9 A0 B0 B2 A1 A7 A8]
time 72ms: Process A6 started using the CPU for 280ms burst [Q B7 A9 A0 B0 B2 A1 A7 A8]
time 92ms: Process A2 arrived; added to ready queue [Q B7 A9 A0 B0 B2 A1 A7 A8 A2]
time 95ms: Process B9 arrived; added to ready queue [Q B7 A9 A0 B0 B2 A1 A7 A8 A2 B9]
time 102ms: Process B6 arrived; added to ready queue [Q B7 A9 A0 B0 B2 A1 A7 A8 A2 B9 B6]
time 130ms: Process A5 arrived; added to ready queue [Q B7 A9 A0 B0 B2 A1 A7 A8 A2 B9 B6 A5]
time 140ms: Process B5 arrived; added to ready queue [Q B7 A9 A0 B0 B2 A1 A7 A8 A2 B9 B6 A5 B5]
time 157ms: Process A4 arrived; added to ready queue [Q B7 A9 A0 B0 B2 A1 A7 A8 A2 B9 B6 A5 B5 A4]
time 159ms: Process B4 completed I/O; added to ready queue [Q B7 A9 A0 B0 B2 A1 A7 A8 A2 B9 B6 A5 B5 A4 B4]
time 225ms: Process B8 arrived; added to ready queue [Q B7 A9 A0 B0 B2 A1 A7 A8 A2 B9 B6 A5 B5 A4 B4 B8]
time 271ms: Process B3 arrived; added to ready queue [Q B7 A9 A0 B0 B2 A1 A7 A8 A2 B9 B6 A5 B5 A4 B4 B8 B3]
time 288ms: Process B1 completed I/O; added to ready queue [Q B7 A9 A0 B0 B2 A1 A7 A8 A2 B9 B6 A5 B5 A4 B4 B8 B3 B1]
time 324ms: Process A3 arrived; added to ready queue [Q B7 A9 A0 B0 B2 A1 A7 A8 A2 B9 B6 A5 B5 A4 B4 B8 B3 B1 A3]
time 352ms: Process A6 completed a CPU burst; 17 bursts to go [Q B7 A9 A0 B0 B2 A1 A7 A8 A2 B9 B6 A5 B5 A4 B4 B8 B3 B1 A3]
time 352ms: Process A6 switching out of CPU; blocking on I/O until time 426ms [Q B7 A9 A0 B0 B2 A1 A7 A8 A2 B9 B6 A5 B5 A4 B4 B8 B3 B1 A3]
time 356ms: Process B7 started using the CPU for 71ms burst [Q A9 A0 B0 B2 A1 A7 A8 A2 B9 B6 A5 B5 A4 B4 B8 B3 B1 A3]
time 426ms: Process A6 completed I/O; added to ready queue [Q A9 A0 B0 B2 A1 A7 A8 A2 B9 B6 A5 B5 A4 B4 B8 B3 B1 A3 A6]
time 427ms: Process B7 completed a CPU burst; 25 bursts to go [Q A9 A0 B0 B2 A1 A7 A8 A2 B9 B6 A5 B5 A4 B4 B8 B3 B1 A3 A6]
time 427ms: Process B7 switching out of CPU; blocking on I/O until time 3477ms [Q A9 A0 B0 B2 A1 A7 A8 A2 B9 B6 A5 B5 A4 B4 B8 B3 B1 A3 A6]
time 431ms: Process A9 started using the CPU for 360ms burst [Q A0 B0 B2 A1 A7 A8 A2 B9 B6 A5 B5 A4 B4 B8 B3 B1 A3 A6]
time 791ms: Process A9 completed a CPU burst; 31 bursts to go [Q A0 B0 B2 A1 A7 A8 A2 B9 B6 A5 B5 A4 B4 B8 B3 B1 A3 A6]
time 791ms: Process A9 switching out of CPU; blocking on I/O until time 833ms [Q A0 B0 B2 A1 A7 A8 A2 B9 B6 A5 B5 A4 B4 B8 B3 B1 A3 A6]
time 795ms: Process A0 started using the CPU for 196ms burst [Q B0 B2 A1 A7 A8 A2 B9 B6 A5 B5 A4 B4 B8 B3 B1 A3 A6]
time 833ms: Process A9 completed I/O; added to ready queue [Q B0 B2 A1 A7 A8 A2 B9 B6 A5 B5 A4 B4 B8 B3 B1 A3 A6 A9]
time 991ms: Process A0 completed a CPU burst; 29 bursts to go [Q B0 B2 A1 A7 A8 A2 B9 B6 A5 B5 A4 B4 B8 B3 B1 A3 A6 A9]
time 991ms: Process A0 switching out of CPU; blocking on I/O until time 1072ms [Q B0 B2 A1 A7 A8 A2 B9 B6 A5 B5 A4 B4 B8 B3 B1 A3 A6 A9]
time 995ms: Process B0 started using the CPU for 216ms burst [Q B2 A1 A7 A8 A2 B9 B6 A5 B5 A4 B4 B8 B3 B1 A3 A6 A9]
time 1072ms: Process A0 completed I/O; added to ready queue [Q B2 A1 A7 A8 A2 B9 B6 A5 B5 A4 B4 B8 B3 B1 A3 A6 A9 A0]
time 1211ms: Process B0 completed a CPU burst; 18 bursts to go [Q B2 A1 A7 A8 A2 B9 B6 A5 B5 A4 B4 B8 B3 B1 A3 A6 A9 A0]
time 1211ms: Process B0 switching out of CPU; blocking on I/O until time 1362ms [Q B2 A1 A7 A8 A2 B9 B6 A5 B5 A4 B4 B8 B3 B1 A3 A6 A9 A0]
time 1215ms: Process B2 started using the CPU for 488ms burst [Q A1 A7 A8 A2 B9 B6 A5 B5 A4 B4 B8 B3 B1 A3 A6 A9 A0]
time 1362ms: Process B0 completed I/O; added to ready queue [Q A1 A7 A8 A2 B9 B6 A5 B5 A4 B4 B8 B3 B1 A3 A6 A9 A0 B0]
time 1703ms: Process B2 completed a CPU burst; 14 bursts to go [Q A1 A7 A8 A2 B9 B6 A5 B5 A4 B4 B8 B3 B1 A3 A6 A9 A0 B0]
time 1703ms: Process B2 switching out of CPU; blocking on I/O until time 1770ms [Q A1 A7 A8 A2 B9 B6 A5 B5 A4 B4 B8 B3 B1 A3 A6 A9 A0 B0]
time 1707ms: Process A1 started using the CPU for 632ms burst [Q A7 A8 A2 B9 B6 A5 B5 A4 B4 B8 B3 B1 A3 A6 A9 A0 B0]
time 1770ms: Process B2 completed I/O; added to ready queue [Q A7 A8 A2 B9 B6 A5 B5 A4 B4 B8 B3 B1 A3 A6 A9 A0 B0 B2]
time 2339ms: Process A1 completed a CPU burst; 11 bursts to go [Q A7 A8 A2 B9 B6 A5 B5 A4 B4 B8 B3 B1 A3 A6 A9 A0 B0 B2]
time 2339ms: Process A1 switching out of CPU; blocking on I/O until time 2379ms [Q A7 A8 A2 B9 B6 A5 B5 A4 B4 B8 B3 B1 A3 A6 A9 A0 B0 B2]
time 2343ms: Process A7 started using the CPU for 84ms burst [Q A8 A2 B9 B6 A5 B5 A4 B4 B8 B3 B1 A3 A6 A9 A0 B0 B2]
time 2379ms: Process A1 completed I/O; added to ready queue [Q A8 A2 B9 B6 A5 B5 A4 B4 B8 B3 B1 A3 A6 A9 A0 B0 B2 A1]
time 2427ms: Process A7 completed a CPU burst; 18 bursts to go [Q A8 A2 B9 B6 A5 B5 A4 B4 B8 B3 B1 A3 A6 A9 A0 B0 B2 A1]
time 2427ms: Process A7 switching out of CPU; blocking on I/O until time 2478ms [Q A8 A2 B9 B6 A5 B5 A4 B4 B8 B3 B1 A3 A6 A9 A0 B0 B2 A1]
time 2431ms: Process A8 started using the CPU for 420ms burst [Q A2 B9 B6 A5 B5 A4 B4 B8 B3 B1 A3 A6 A9 A0 B0 B2 A1]
time 2478ms: Process A7 completed I/O; added to ready queue [Q A2 B9 B6 A5 B5 A4 B4 B8 B3 B1 A3 A6 A9 A0 B0 B2 A1 A7]
time 2851ms: Process A8 completed a CPU burst; 7 bursts to go [Q A2 B9 B6 A5 B5 A4 B4 B8 B3 B1 A3 A6 A9 A0 B0 B2 A1 A7]
time 2851ms: Process A8 switching out of CPU; blocking on I/O until time 2907ms [Q A2 B9 B6 A5 B5 A4 B4 B8 B3 B1 A3 A6 A9 A0 B0 B2 A1 A7]
time 2855ms: Process A2 started using the CPU for 28ms burst [Q B9 B6 A5 B5 A4 B4 B8 B3 B1 A3 A6 A9 A0 B0 B2 A1 A7]
time 2883ms: Process A2 completed a CPU burst; 29 bursts to go [Q B9 B6 A5 B5 A4 B4 B8 B3 B1 A3 A6 A9 A0 B0 B2 A1 A7]
time 2883ms: Process A2 switching out of CPU; blocking on I/O until time 2898ms [Q B9 B6 A5 B5 A4 B4 B8 B3 B1 A3 A6 A9 A0 B0 B2 A1 A7]
time 2887ms: Process B9 started using the CPU for 22ms burst [Q B6 A5 B5 A4 B4 B8 B3 B1 A3 A6 A9 A0 B0 B2 A1 A7]
time 2898ms: Process A2 completed I/O; added to ready queue [Q B6 A5 B5 A4 B4 B8 B3 B1 A3 A6 A9 A0 B0 B2 A1 A7 A2]
time 2907ms: Process A8 completed I/O; added to ready queue [Q B6 A5 B5 A4 B4 B8 B3 B1 A3 A6 A9 A0 B0 B2 A1 A7 A2 A8]
time 2909ms: Process B9 completed a CPU burst; 10 bursts to go [Q B6 A5 B5 A4 B4 B8 B3 B1 A3 A6 A9 A0 B0 B2 A1 A7 A2 A8]
time 2909ms: Process B9 switching out of CPU; blocking on I/O until time 3519ms [Q B6 A5 B5 A4 B4 B8 B3 B1 A3 A6 A9 A0 B0 B2 A1 A7 A2 A8]
time 2913ms: Process B6 started using the CPU for 113ms burst [Q A5 B5 A4 B4 B8 B3 B1 A3 A6 A9 A0 B0 B2 A1 A7 A2 A8]
time 3026ms: Process B6 completed a CPU burst; 4 bursts to go [Q A5 B5 A4 B4 B8 B3 B1 A3 A6 A9 A0 B0 B2 A1 A7 A2 A8]
time 3026ms: Process B6 switching out of CPU; blocking on I/O until time 6252ms [Q A5 B5 A4 B4 B8 B3 B1 A3 A6 A9 A0 B0 B2 A1 A7 A2 A8]
time 3030ms: Process A5 started using the CPU for 196ms burst [Q B5 A4 B4 B8 B3 B1 A3 A6 A9 A0 B0 B2 A1 A7 A2 A8]
time 3226ms: Process A5 completed a CPU burst; 4 bursts to go [Q B5 A4 B4 B8 B3 B1 A3 A6 A9 A0 B0 B2 A1 A7 A2 A8]
time 3226ms: Process A5 switching out of CPU; blocking on I/O until time 3245ms [Q B5 A4 B4 B8 B3 B1 A3 A6 A9 A0 B0 B2 A1 A7 A2 A8]
time 3230ms: Process B5 started using the CPU for 80ms burst [Q A4 B4 B8 B3 B1 A3 A6 A9 A0 B0 B2 A1 A7 A2 A8]
time 3245ms: Process A5 completed I/O; added to ready queue [Q A4 B4 B8 B3 B1 A3 A6 A9 A0 B0 B2 A1 A7 A2 A8 A5]
time 3310ms: Process B5 completed a CPU burst; 29 bursts to go [Q A4 B4 B8 B3 B1 A3 A6 A9 A0 B0 B2 A1 A7 A2 A8 A5]
time 3310ms: Process B5 switching out of CPU; blocking on I/O until time 3343ms [Q A4 B4 B8 B3 B1 A3 A6 A9 A0 B0 B2 A1 A7 A2 A8 A5]
time 3314ms: Process A4 started using the CPU for 300ms burst [Q B4 B8 B3 B1 A3 A6 A9 A0 B0 B2 A1 A7 A2 A8 A5]
time 3343ms: Process B5 completed I/O; added to ready queue [Q B4 B8 B3 B1 A3 A6 A9 A0 B0 B2 A1 A7 A2 A8 A5 B5]
time 3477ms: Process B7 completed I/O; added to ready queue [Q B4 B8 B3 B1 A3 A6 A9 A0 B0 B2 A1 A7 A2 A8 A5 B5 B7]
time 3519ms: Process B9 completed I/O; added to ready queue [Q B4 B8 B3 B1 A3 A6 A9 A0 B0 B2 A1 A7 A2 A8 A5 B5 B7 B9]
time 3614ms: Process A4 completed a CPU burst; 3 bursts to go [Q B4 B8 B3 B1 A3 A6 A9 A0 B0 B2 A1 A7 A2 A8 A5 B5 B7 B9]
time 3614ms: Process A4 switching out of CPU; blocking on I/O until time 3705ms [Q B4 B8 B3 B1 A3 A6 A9 A0 B0 B2 A1 A7 A2 A8 A5 B5 B7 B9]
time 3618ms: Process B4 started using the CPU for 12ms burst [Q B8 B3 B1 A3 A6 A9 A0 B0 B2 A1 A7 A2 A8 A5 B5 B7 B9]
time 3630ms: Process B4 completed a CPU burst; 14 bursts to go [Q B8 B3 B1 A3 A6 A9 A0 B0 B2 A1 A7 A2 A8 A5 B5 B7 B9]
time 3630ms: Process B4 switching out of CPU; blocking on I/O until time 3769ms [Q B8 B3 B1 A3 A6 A9 A0 B0 B2 A1 A7 A2 A8 A5 B5 B7 B9]
time 3634ms: Process B8 started using the CPU for 308ms burst [Q B3 B1 A3 A6 A9 A0 B0 B2 A1 A7 A2 A8 A5 B5 B7 B9]
time 3705ms: Process A4 completed I/O; added to ready queue [Q B3 B1 A3 A6 A9 A0 B0 B2 A1 A7 A2 A8 A5 B5 B7 B9 A4]
time 3769ms: Process B4 completed I/O; added to ready queue [Q B3 B1 A3 A6 A9 A0 B0 B2 A1 A7 A2 A8 A5 B5 B7 B9 A4 B4]
time 3942ms: Process B8 completed a CPU burst; 19 bursts to go [Q B3 B1 A3 A6 A9 A0 B0 B2 A1 A7 A2 A8 A5 B5 B7 B9 A4 B4]
time 3942ms: Process B8 switching out of CPU; blocking on I/O until time 6224ms [Q B3 B1 A3 A6 A9 A0 B0 B2 A1 A7 A2 A8 A5 B5 B7 B9 A4 B4]
time 3946ms: Process B3 started using the CPU for 204ms burst [Q B1 A3 A6 A9 A0 B0 B2 A1 A7 A2 A8 A5 B5 B7 B9 A4 B4]
time 4150ms: Process B3 completed a CPU burst; 21 bursts to go [Q B1 A3 A6 A9 A0 B0 B2 A1 A7 A2 A8 A5 B5 B7 B9 A4 B4]
time 4150ms: Process B3 switching out of CPU; blocking on I/O until time 4444ms [Q B1 A3 A6 A9 A0 B0 B2 A1 A7 A2 A8 A5 B5 B7 B9 A4 B4]
time 4154ms: Process B1 started using the CPU for 3004ms burst [Q A3 A6 A9 A0 B0 B2 A1 A7 A2 A8 A5 B5 B7 B9 A4 B4]
time 4444ms: Process B3 completed I/O; added to ready queue [Q A3 A6 A9 A0 B0 B2 A1 A7 A2 A8 A5 B5 B7 B9 A4 B4 B3]
time 6224ms: Process B8 completed I/O; added to ready queue [Q A3 A6 A9 A0 B0 B2 A1 A7 A2 A8 A5 B5 B7 B9 A4 B4 B3 B8]
time 6252ms: Process B6 completed I/O; added to ready queue [Q A3 A6 A9 A0 B0 B2 A1 A7 A2 A8 A5 B5 B7 B9 A4 B4 B3 B8 B6]
time 7158ms: Process B1 completed a CPU burst; 15 bursts to go [Q A3 A6 A9 A0 B0 B2 A1 A7 A2 A8 A5 B5 B7 B9 A4 B4 B3 B8 B6]
time 7158ms: Process B1 switching out of CPU; blocking on I/O until time 7299ms [Q A3 A6 A9 A0 B0 B2 A1 A7 A2 A8 A5 B5 B7 B9 A4 B4 B3 B8 B6]
time 7162ms: Process A3 started using the CPU for 96ms burst [Q A6 A9 A0 B0 B2 A1 A7 A2 A8 A5 B5 B7 B9 A4 B4 B3 B8 B6]
time 7258ms: Process A3 completed a CPU burst; 25 bursts to go [Q A6 A9 A0 B0 B2 A1 A7 A2 A8 A5 B5 B7 B9 A4 B4 B3 B8 B6]
time 7258ms: Process A3 switching out of CPU; blocking on I/O until time 7630ms [Q A6 A9 A0 B0 B2 A1 A7 A2 A8 A5 B5 B7 B9 A4 B4 B3 B8 B6]
time 7262ms: Process A6 started using the CPU for 100ms burst [Q A9 A0 B0 B2 A1 A7 A2 A8 A5 B5 B7 B9 A4 B4 B3 B8 B6]
time 7299ms: Process B1 completed I/O; added to ready queue [Q A9 A0 B0 B2 A1 A7 A2 A8 A5 B5 B7 B9 A4 B4 B3 B8 B6 B1]
time 7362ms: Process A6 completed a CPU burst; 16 bursts to go [Q A9 A0 B0 B2 A1 A7 A2 A8 A5 B5 B7 B9 A4 B4 B3 B8 B6 B1]
time 7362ms: Process A6 switching out of CPU; blocking on I/O until time 7379ms [Q A9 A0 B0 B2 A1 A7 A2 A8 A5 B5 B7 B9 A4 B4 B3 B8 B6 B1]
time 7366ms: Process A9 started using the CPU for 28ms burst [Q A0 B0 B2 A1 A7 A2 A8 A5 B5 B7 B9 A4 B4 B3 B8 B6 B1]
time 7379ms: Process A6 completed I/O; added to ready queue [Q A0 B0 B2 A1 A7 A2 A8 A5 B5 B7 B9 A4 B4 B3 B8 B6 B1 A6]
time 7394ms: Process A9 completed a CPU burst; 30 bursts to go [Q A0 B0 B2 A1 A7 A2 A8 A5 B5 B7 B9 A4 B4 B3 B8 B6 B1 A6]
time 7394ms: Process A9 switching out of CPU; blocking on I/O until time 7424ms [Q A0 B0 B2 A1 A7 A2 A8 A5 B5 B7 B9 A4 B4 B3 B8 B6 B1 A6]
time 7398ms: Process A0 started using the CPU for 1096ms burst [Q B0 B2 A1 A7 A2 A8 A5 B5 B7 B9 A4 B4 B3 B8 B6 B1 A6]
time 7424ms: Process A9 completed I/O; added to ready queue [Q B0 B2 A1 A7 A2 A8 A5 B5 B7 B9 A4 B4 B3 B8 B6 B1 A6 A9]
time 7630ms: Process A3 completed I/O; added to ready queue [Q B0 B2 A1 A7 A2 A8 A5 B5 B7 B9 A4 B4 B3 B8 B6 B1 A6 A9 A3]
time 8494ms: Process A0 completed a CPU burst; 28 bursts to go [Q B0 B2 A1 A7 A2 A8 A5 B5 B7 B9 A4 B4 B3 B8 B6 B1 A6 A9 A3]
time 8494ms: Process A0 switching out of CPU; blocking on I/O until time 8581ms [Q B0 B2 A1 A7 A2 A8 A5 B5 B7 B9 A4 B4 B3 B8 B6 B1 A6 A9 A3]
time 8498ms: Process B0 started using the CPU for 1264ms burst [Q B2 A1 A7 A2 A8 A5 B5 B7 B9 A4 B4 B3 B8 B6 B1 A6 A9 A3]
time 8581ms: Process A0 completed I/O; added to ready queue [Q B2 A1 A7 A2 A8 A5 B5 B7 B9 A4 B4 B3 B8 B6 B1 A6 A9 A3 A0]
time 9762ms: Process B0 completed a CPU burst; 17 bursts to go [Q B2 A1 A7 A2 A8 A5 B5 B7 B9 A4 B4 B3 B8 B6 B1 A6 A9 A3 A0]
time 9762ms: Process B0 switching out of CPU; blocking on I/O until time 9773ms [Q B2 A1 A7 A2 A8 A5 B5 B7 B9 A4 B4 B3 B8 B6 B1 A6 A9 A3 A0]
time 9766ms: Process B2 started using the CPU for 732ms burst [Q A1 A7 A2 A8 A5 B5 B7 B9 A4 B4 B3 B8 B6 B1 A6 A9 A3 A0]
time 9773ms: Process B0 completed I/O; added to ready queue [Q A1 A7 A2 A8 A5 B5 B7 B9 A4 B4 B3 B8 B6 B1 A6 A9 A3 A0 B0]
time 10498ms: Process B2 completed a CPU burst; 13 bursts to go [Q A1 A7 A2 A8 A5 B5 B7 B9 A4 B4 B3 B8 B6 B1 A6 A9 A3 A0 B0]
time 10498ms: Process B2 switching out of CPU; blocking on I/O until time 10539ms [Q A1 A7 A2 A8 A5 B5 B7 B9 A4 B4 B3 B8 B6 B1 A6 A9 A3 A0 B0]
time 10502ms: Process A1 started using the CPU for 200ms burst [Q A7 A2 A8 A5 B5 B7 B9 A4 B4 B3 B8 B6 B1 A6 A9 A3 A0 B0]
time 10539ms: Process B2 completed I/O; added to ready queue [Q A7 A2 A8 A5 B5 B7 B9 A4 B4 B3 B8 B6 B1 A6 A9 A3 A0 B0 B2]
time 10702ms: Process A1 completed a CPU burst; 10 bursts to go [Q A7 A2 A8 A5 B5 B7 B9 A4 B4 B3 B8 B6 B1 A6 A9 A3 A0 B0 B2]
time 10702ms: Process A1 switching out of CPU; blocking on I/O until time 10736ms [Q A7 A2 A8 A5 B5 B7 B9 A4 B4 B3 B8 B6 B1 A6 A9 A3 A0 B0 B2]
time 10706ms: Process A7 started using the CPU for 768ms burst [Q A2 A8 A5 B5 B7 B9 A4 B4 B3 B8 B6 B1 A6 A9 A3 A0 B0 B2]
time 10736ms: Process A1 completed I/O; added to ready queue [Q A2 A8 A5 B5 B7 B9 A4 B4 B3 B8 B6 B1 A6 A9 A3 A0 B0 B2 A1]
time 11474ms: Process A7 completed a CPU burst; 17 bursts to go [Q A2 A8 A5 B5 B7 B9 A4 B4 B3 B8 B6 B1 A6 A9 A3 A0 B0 B2 A1]
time 11474ms: Process A7 switching out of CPU; blocking on I/O until time 11597ms [Q A2 A8 A5 B5 B7 B9 A4 B4 B3 B8 B6 B1 A6 A9 A3 A0 B0 B2 A1]
time 11478ms: Process A2 started using the CPU for 444ms burst [Q A8 A5 B5 B7 B9 A4 B4 B3 B8 B6 B1 A6 A9 A3 A0 B0 B2 A1]
time 11597ms: Process A7 completed I/O; added to ready queue [Q A8 A5 B5 B7 B9 A4 B4 B3 B8 B6 B1 A6 A9 A3 A0 B0 B2 A1 A7]
time 11922ms: Process A2 completed a CPU burst; 28 bursts to go [Q A8 A5 B5 B7 B9 A4 B4 B3 B8 B6 B1 A6 A9 A3 A0 B0 B2 A1 A7]
time 11922ms: Process A2 switching out of CPU; blocking on I/O until time 12383ms [Q A8 A5 B5 B7 B9 A4 B4 B3 B8 B6 B1 A6 A9 A3 A0 B0 B2 A1 A7]
time 11926ms: Process A8 started using the CPU for 176ms burst [Q A5 B5 B7 B9 A4 B4 B3 B8 B6 B1 A6 A9 A3 A0 B0 B2 A1 A7]
time 12102ms: Process A8 completed a CPU burst; 6 bursts to go [Q A5 B5 B7 B9 A4 B4 B3 B8 B6 B1 A6 A9 A3 A0 B0 B2 A1 A7]
time 12102ms: Process A8 switching out of CPU; blocking on I/O until time 12142ms [Q A5 B5 B7 B9 A4 B4 B3 B8 B6 B1 A6 A9 A3 A0 B0 B2 A1 A7]
time 12106ms: Process A5 started using the CPU for 140ms burst [Q B5 B7 B9 A4 B4 B3 B8 B6 B1 A6 A9 A3 A0 B0 B2 A1 A7]
time 12142ms: Process A8 completed I/O; added to ready queue [Q B5 B7 B9 A4 B4 B3 B8 B6 B1 A6 A9 A3 A0 B0 B2 A1 A7 A8]
time 12246ms: Process A5 completed a CPU burst; 3 bursts to go [Q B5 B7 B9 A4 B4 B3 B8 B6 B1 A6 A9 A3 A0 B0 B2 A1 A7 A8]
time 12246ms: Process A5 switching out of CPU; blocking on I/O until time 12360ms [Q B5 B7 B9 A4 B4 B3 B8 B6 B1 A6 A9 A3 A0 B0 B2 A1 A7 A8]
time 12250ms: Process B5 started using the CPU for 340ms burst [Q B7 B9 A4 B4 B3 B8 B6 B1 A6 A9 A3 A0 B0 B2 A1 A7 A8]
time 12360ms: Process A5 completed I/O; added to ready queue [Q B7 B9 A4 B4 B3 B8 B6 B1 A6 A9 A3 A0 B0 B2 A1 A7 A8 A5]
time 12383ms: Process A2 completed I/O; added to ready queue [Q B7 B9 A4 B4 B3 B8 B6 B1 A6 A9 A3 A0 B0 B2 A1 A7 A8 A5 A2]
time 12590ms: Process B5 completed a CPU burst; 28 bursts to go [Q B7 B9 A4 B4 B3 B8 B6 B1 A6 A9 A3 A0 B0 B2 A1 A7 A8 A5 A2]
time 12590ms: Process B5 switching out of CPU; blocking on I/O until time 12622ms [Q B7 B9 A4 B4 B3 B8 B6 B1 A6 A9 A3 A0 B0 B2 A1 A7 A8 A5 A2]
time 12594ms: Process B7 started using the CPU for 20ms burst [Q B9 A4 B4 B3 B8 B6 B1 A6 A9 A3 A0 B0 B2 A1 A7 A8 A5 A2]
time 12614ms: Process B7 completed a CPU burst; 24 bursts to go [Q B9 A4 B4 B3 B8 B6 B1 A6 A9 A3 A0 B0 B2 A1 A7 A8 A5 A2]
time 12614ms: Process B7 switching out of CPU; blocking on I/O until time 12656ms [Q B9 A4 B4 B3 B8 B6 B1 A6 A9 A3 A0 B0 B2 A1 A7 A8 A5 A2]
time 12618ms: Process B9 started using the CPU for 142ms burst [Q A4 B4 B3 B8 B6 B1 A6 A9 A3 A0 B0 B2 A1 A7 A8 A5 A2]
time 12622ms: Process B5 completed I/O; added to ready queue [Q A4 B4 B3 B8 B6 B1 A6 A9 A3 A0 B0 B2 A1 A7 A8 A5 A2 B5]
time 12656ms: Process B7 completed I/O; added to ready queue [Q A4 B4 B3 B8 B6 B1 A6 A9 A3 A0 B0 B2 A1 A7 A8 A5 A2 B5 B7]
time 12760ms: Process B9 completed a CPU burst; 9 bursts to go [Q A4 B4 B3 B8 B6 B1 A6 A9 A3 A0 B0 B2 A1 A7 A8 A5 A2 B5 B7]
time 12760ms: Process B9 switching out of CPU; blocking on I/O until time 12834ms [Q A4 B4 B3 B8 B6 B1 A6 A9 A3 A0 B0 B2 A1 A7 A8 A5 A2 B5 B7]
time 12764ms: Process A4 started using the CPU for 20ms burst [Q B4 B3 B8 B6 B1 A6 A9 A3 A0 B0 B2 A1 A7 A8 A5 A2 B5 B7]
time 12784ms: Process A4 completed a CPU burst; 2 bursts to go [Q B4 B3 B8 B6 B1 A6 A9 A3 A0 B0 B2 A1 A7 A8 A5 A2 B5 B7]
time 12784ms: Process A4 switching out of CPU; blocking on I/O until time 12946ms [Q B4 B3 B8 B6 B1 A6 A9 A3 A0 B0 B2 A1 A7 A8 A5 A2 B5 B7]
time 12788ms: Process B4 started using the CPU for 1140ms burst [Q B3 B8 B6 B1 A6 A9 A3 A0 B0 B2 A1 A7 A8 A5 A2 B5 B7]
time 12834ms: Process B9 completed I/O; added to ready queue [Q B3 B8 B6 B1 A6 A9 A3 A0 B0 B2 A1 A7 A8 A5 A2 B5 B7 B9]
time 12946ms: Process A4 completed I/O; added to ready queue [Q B3 B8 B6 B1 A6 A9 A3 A0 B0 B2 A1 A7 A8 A5 A2 B5 B7 B9 A4]
time 13928ms: Process B4 completed a CPU burst; 13 bursts to go [Q B3 B8 B6 B1 A6 A9 A3 A0 B0 B2 A1 A7 A8 A5 A2 B5 B7 B9 A4]
time 13928ms: Process B4 switching out of CPU; blocking on I/O until time 13958ms [Q B3 B8 B6 B1 A6 A9 A3 A0 B0 B2 A1 A7 A8 A5 A2 B5 B7 B9 A4]
time 13932ms: Process B3 started using the CPU for 516ms burst [Q B8 B6 B1 A6 A9 A3 A0 B0 B2 A1 A7 A8 A5 A2 B5 B7 B9 A4]
time 13958ms: Process B4 completed I/O; added to ready queue [Q B8 B6 B1 A6 A9 A3 A0 B0 B2 A1 A7 A8 A5 A2 B5 B7 B9 A4 B4]
time 14448ms: Process B3 completed a CPU burst; 20 bursts to go [Q B8 B6 B1 A6 A9 A3 A0 B0 B2 A1 A7 A8 A5 A2 B5 B7 B9 A4 B4]
time 14448ms: Process B3 switching out of CPU; blocking on I/O until time 14620ms [Q B8 B6 B1 A6 A9 A3 A0 B0 B2 A1 A7 A8 A5 A2 B5 B7 B9 A4 B4]
time 14452ms: Process B8 started using the CPU for 18ms burst [Q B6 B1 A6 A9 A3 A0 B0 B2 A1 A7 A8 A5 A2 B5 B7 B9 A4 B4]
time 14470ms: Process B8 completed a CPU burst; 18 bursts to go [Q B6 B1 A6 A9 A3 A0 B0 B2 A1 A7 A8 A5 A2 B5 B7 B9 A4 B4]
time 14470ms: Process B8 switching out of CPU; blocking on I/O until time 14600ms [Q B6 B1 A6 A9 A3 A0 B0 B2 A1 A7 A8 A5 A2 B5 B7 B9 A4 B4]
time 14474ms: Process B6 started using the CPU for 142ms burst [Q B1 A6 A9 A3 A0 B0 B2 A1 A7 A8 A5 A2 B5 B7 B9 A4 B4]
time 14600ms: Process B8 completed I/O; added to ready queue [Q B1 A6 A9 A3 A0 B0 B2 A1 A7 A8 A5 A2 B5 B7 B9 A4 B4 B8]
time 14616ms: Process B6 completed a CPU burst; 3 bursts to go [Q B1 A6 A9 A3 A0 B0 B2 A1 A7 A8 A5 A2 B5 B7 B9 A4 B4 B8]
time 14616ms: Process B6 switching out of CPU; blocking on I/O until time 15490ms [Q B1 A6 A9 A3 A0 B0 B2 A1 A7 A8 A5 A2 B5 B7 B9 A4 B4 B8]
time 14620ms: Process B1 started using the CPU for 48ms burst [Q A6 A9 A3 A0 B0 B2 A1 A7 A8 A5 A2 B5 B7 B9 A4 B4 B8]
time 14620ms: Process B3 completed I/O; added to ready queue [Q A6 A9 A3 A0 B0 B2 A1 A7 A8 A5 A2 B5 B7 B9 A4 B4 B8 B3]
time 14668ms: Process B1 completed a CPU burst; 14 bursts to go [Q A6 A9 A3 A0 B0 B2 A1 A7 A8 A5 A2 B5 B7 B9 A4 B4 B8 B3]
time 14668ms: Process B1 switching out of CPU; blocking on I/O until time 14690ms [Q A6 A9 A3 A0 B0 B2 A1 A7 A8 A5 A2 B5 B7 B9 A4 B4 B8 B3]
time 14672ms: Process A6 started using the CPU for 344ms burst [Q A9 A3 A0 B0 B2 A1 A7 A8 A5 A2 B5 B7 B9 A4 B4 B8 B3]
time 14690ms: Process B1 completed I/O; added to ready queue [Q A9 A3 A0 B0 B2 A1 A7 A8 A5 A2 B5 B7 B9 A4 B4 B8 B3 B1]
time 15016ms: Process A6 completed a CPU burst; 15 bursts to go [Q A9 A3 A0 B0 B2 A1 A7 A8 A5 A2 B5 B7 B9 A4 B4 B8 B3 B1]
time 15016ms: Process A6 switching out of CPU; blocking on I/O until time 15059ms [Q A9 A3 A0 B0 B2 A1 A7 A8 A5 A2 B5 B7 B9 A4 B4 B8 B3 B1]
time 15020ms: Process A9 started using the CPU for 308ms burst [Q A3 A0 B0 B2 A1 A7 A8 A5 A2 B5 B7 B9 A4 B4 B8 B3 B1]
time 15059ms: Process A6 completed I/O; added to ready queue [Q A3 A0 B0 B2 A1 A7 A8 A5 A2 B5 B7 B9 A4 B4 B8 B3 B1 A6]
time 15328ms: Process A9 completed a CPU burst; 29 bursts to go [Q A3 A0 B0 B2 A1 A7 A8 A5 A2 B5 B7 B9 A4 B4 B8 B3 B1 A6]
time 15328ms: Process A9 switching out of CPU; blocking on I/O until time 15363ms [Q A3 A0 B0 B2 A1 A7 A8 A5 A2 B5 B7 B9 A4 B4 B8 B3 B1 A6]
time 15332ms: Process A3 started using the CPU for 308ms burst [Q A0 B0 B2 A1 A7 A8 A5 A2 B5 B7 B9 A4 B4 B8 B3 B1 A6]
time 15363ms: Process A9 completed I/O; added to ready queue [Q A0 B0 B2 A1 A7 A8 A5 A2 B5 B7 B9 A4 B4 B8 B3 B1 A6 A9]
time 15490ms: Process B6 completed I/O; added to ready queue [Q A0 B0 B2 A1 A7 A8 A5 A2 B5 B7 B9 A4 B4 B8 B3 B1 A6 A9 B6]
time 15640ms: Process A3 completed a CPU burst; 24 bursts to go [Q A0 B0 B2 A1 A7 A8 A5 A2 B5 B7 B9 A4 B4 B8 B3 B1 A6 A9 B6]
time 15640ms: Process A3 switching out of CPU; blocking on I/O until time 15730ms [Q A0 B0 B2 A1 A7 A8 A5 A2 B5 B7 B9 A4 B4 B8 B3 B1 A6 A9 B6]
time 15644ms: Process A0 started using the CPU for 912ms burst [Q B0 B2 A1 A7 A8 A5 A2 B5 B7 B9 A4 B4 B8 B3 B1 A6 A9 B6]
time 15730ms: Process A3 completed I/O; added to ready queue [Q B0 B2 A1 A7 A8 A5 A2 B5 B7 B9 A4 B4 B8 B3 B1 A6 A9 B6 A3]
time 16556ms: Process A0 completed a CPU burst; 27 bursts to go [Q B0 B2 A1 A7 A8 A5 A2 B5 B7 B9 A4 B4 B8 B3 B1 A6 A9 B6 A3]
time 16556ms: Process A0 switching out of CPU; blocking on I/O until time 16564ms [Q B0 B2 A1 A7 A8 A5 A2 B5 B7 B9 A4 B4 B8 B3 B1 A6 A9 B6 A3]
time 16560ms: Process B0 started using the CPU for 340ms burst [Q B2 A1 A7 A8 A5 A2 B5 B7 B9 A4 B4 B8 B3 B1 A6 A9 B6 A3]
time 16564ms: Process A0 completed I/O; added to ready queue [Q B2 A1 A7 A8 A5 A2 B5 B7 B9 A4 B4 B8 B3 B1 A6 A9 B6 A3 A0]
time 16900ms: Process B0 completed a CPU burst; 16 bursts to go [Q B2 A1 A7 A8 A5 A2 B5 B7 B9 A4 B4 B8 B3 B1 A6 A9 B6 A3 A0]
time 16900ms: Process B0 switching out of CPU; blocking on I/O until time 16994ms [Q B2 A1 A7 A8 A5 A2 B5 B7 B9 A4 B4 B8 B3 B1 A6 A9 B6 A3 A0]
time 16904ms: Process B2 started using the CPU for 876ms burst [Q A1 A7 A8 A5 A2 B5 B7 B9 A4 B4 B8 B3 B1 A6 A9 B6 A3 A0]
time 16994ms: Process B0 completed I/O; added to ready queue [Q A1 A7 A8 A5 A2 B5 B7 B9 A4 B4 B8 B3 B1 A6 A9 B6 A3 A0 B0]
time 17780ms: Process B2 completed a CPU burst; 12 bursts to go [Q A1 A7 A8 A5 A2 B5 B7 B9 A4 B4 B8 B3 B1 A6 A9 B6 A3 A0 B0]
time 17780ms: Process B2 switching out of CPU; blocking on I/O until time 17816ms [Q A1 A7 A8 A5 A2 B5 B7 B9 A4 B4 B8 B3 B1 A6 A9 B6 A3 A0 B0]
time 17784ms: Process A1 started using the CPU for 608ms burst [Q A7 A8 A5 A2 B5 B7 B9 A4 B4 B8 B3 B1 A6 A9 B6 A3 A0 B0]
time 17816ms: Process B2 completed I/O; added to ready queue [Q A7 A8 A5 A2 B5 B7 B9 A4 B4 B8 B3 B1 A6 A9 B6 A3 A0 B0 B2]
time 18392ms: Process A1 completed a CPU burst; 9 bursts to go [Q A7 A8 A5 A2 B5 B7 B9 A4 B4 B8 B3 B1 A6 A9 B6 A3 A0 B0 B2]
time 18392ms: Process A1 switching out of CPU; blocking on I/O until time 18419ms [Q A7 A8 A5 A2 B5 B7 B9 A4 B4 B8 B3 B1 A6 A9 B6 A3 A0 B0 B2]
time 18396ms: Process A7 started using the CPU for 1388ms burst [Q A8 A5 A2 B5 B7 B9 A4 B4 B8 B3 B1 A6 A9 B6 A3 A0 B0 B2]
time 18419ms: Process A1 completed I/O; added to ready queue [Q A8 A5 A2 B5 B7 B9 A4 B4 B8 B3 B1 A6 A9 B6 A3 A0 B0 B2 A1]
time 19784ms: Process A7 completed a CPU burst; 16 bursts to go [Q A8 A5 A2 B5 B7 B9 A4 B4 B8 B3 B1 A6 A9 B6 A3 A0 B0 B2 A1]
time 19784ms: Process A7 switching out of CPU; blocking on I/O until time 19875ms [Q A8 A5 A2 B5 B7 B9 A4 B4 B8 B3 B1 A6 A9 B6 A3 A0 B0 B2 A1]
time 19788ms: Process A8 started using the CPU for 340ms burst [Q A5 A2 B5 B7 B9 A4 B4 B8 B3 B1 A6 A9 B6 A3 A0 B0 B2 A1]
time 19875ms: Process A7 completed I/O; added to ready queue [Q A5 A2 B5 B7 B9 A4 B4 B8 B3 B1 A6 A9 B6 A3 A0 B0 B2 A1 A7]
time 20128ms: Process A8 completed a CPU burst; 5 bursts to go [Q A5 A2 B5 B7 B9 A4 B4 B8 B3 B1 A6 A9 B6 A3 A0 B0 B2 A1 A7]
time 20128ms: Process A8 switching out of CPU; blocking on I/O until time 20195ms [Q A5 A2 B5 B7 B9 A4 B4 B8 B3 B1 A6 A9 B6 A3 A0 B0 B2 A1 A7]
time 20132ms: Process A5 started using the CPU for 200ms burst [Q A2 B5 B7 B9 A4 B4 B8 B3 B1 A6 A9 B6 A3 A0 B0 B2 A1 A7]
time 20195ms: Process A8 completed I/O; added to ready queue [Q A2 B5 B7 B9 A4 B4 B8 B3 B1 A6 A9 B6 A3 A0 B0 B2 A1 A7 A8]
time 20332ms: Process A5 completed a CPU burst; 2 bursts to go [Q A2 B5 B7 B9 A4 B4 B8 B3 B1 A6 A9 B6 A3 A0 B0 B2 A1 A7 A8]
time 20332ms: Process A5 switching out of CPU; blocking on I/O until time 20400ms [Q A2 B5 B7 B9 A4 B4 B8 B3 B1 A6 A9 B6 A3 A0 B0 B2 A1 A7 A8]
time 20336ms: Process A2 started using the CPU for 760ms burst [Q B5 B7 B9 A4 B4 B8 B3 B1 A6 A9 B6 A3 A0 B0 B2 A1 A7 A8]
time 20400ms: Process A5 completed I/O; added to ready queue [Q B5 B7 B9 A4 B4 B8 B3 B1 A6 A9 B6 A3 A0 B0 B2 A1 A7 A8 A5]
time 21096ms: Process A2 completed a CPU burst; 27 bursts to go [Q B5 B7 B9 A4 B4 B8 B3 B1 A6 A9 B6 A3 A0 B0 B2 A1 A7 A8 A5]
time 21096ms: Process A2 switching out of CPU; blocking on I/O until time 21348ms [Q B5 B7 B9 A4 B4 B8 B3 B1 A6 A9 B6 A3 A0 B0 B2 A1 A7 A8 A5]
time 21100ms: Process B5 started using the CPU for 80ms burst [Q B7 B9 A4 B4 B8 B3 B1 A6 A9 B6 A3 A0 B0 B2 A1 A7 A8 A5]
time 21180ms: Process B5 completed a CPU burst; 27 bursts to go [Q B7 B9 A4 B4 B8 B3 B1 A6 A9 B6 A3 A0 B0 B2 A1 A7 A8 A5]
time 21180ms: Process B5 switching out of CPU; blocking on I/O until time 21235ms [Q B7 B9 A4 B4 B8 B3 B1 A6 A9 B6 A3 A0 B0 B2 A1 A7 A8 A5]
time 21184ms: Process B7 started using the CPU for 3ms burst [Q B9 A4 B4 B8 B3 B1 A6 A9 B6 A3 A0 B0 B2 A1 A7 A8 A5]
time 21187ms: Process B7 completed a CPU burst; 23 bursts to go [Q B9 A4 B4 B8 B3 B1 A6 A9 B6 A3 A0 B0 B2 A1 A7 A8 A5]
time 21187ms: Process B7 switching out of CPU; blocking on I/O until time 24149ms [Q B9 A4 B4 B8 B3 B1 A6 A9 B6 A3 A0 B0 B2 A1 A7 A8 A5]
time 21191ms: Process B9 started using the CPU for 64ms burst [Q A4 B4 B8 B3 B1 A6 A9 B6 A3 A0 B0 B2 A1 A7 A8 A5]
time 21235ms: Process B5 completed I/O; added to ready queue [Q A4 B4 B8 B3 B1 A6 A9 B6 A3 A0 B0 B2 A1 A7 A8 A5 B5]
time 21255ms: Process B9 completed a CPU burst; 8 bursts to go [Q A4 B4 B8 B3 B1 A6 A9 B6 A3 A0 B0 B2 A1 A7 A8 A5 B5]
time 21255ms: Process B9 switching out of CPU; blocking on I/O until time 22097ms [Q A4 B4 B8 B3 B1 A6 A9 B6 A3 A0 B0 B2 A1 A7 A8 A5 B5]
time 21259ms: Process A4 started using the CPU for 1248ms burst [Q B4 B8 B3 B1 A6 A9 B6 A3 A0 B0 B2 A1 A7 A8 A5 B5]
time 21348ms: Process A2 completed I/O; added to ready queue [Q B4 B8 B3 B1 A6 A9 B6 A3 A0 B0 B2 A1 A7 A8 A5 B5 A2]
time 22097ms: Process B9 completed I/O; added to ready queue [Q B4 B8 B3 B1 A6 A9 B6 A3 A0 B0 B2 A1 A7 A8 A5 B5 A2 B9]
time 22507ms: Process A4 completed a CPU burst; 1 burst to go [Q B4 B8 B3 B1 A6 A9 B6 A3 A0 B0 B2 A1 A7 A8 A5 B5 A2 B9]
time 22507ms: Process A4 switching out of CPU; blocking on I/O until time 22533ms [Q B4 B8 B3 B1 A6 A9 B6 A3 A0 B0 B2 A1 A7 A8 A5 B5 A2 B9]
time 22511ms: Process B4 started using the CPU for 280ms burst [Q B8 B3 B1 A6 A9 B6 A3 A0 B0 B2 A1 A7 A8 A5 B5 A2 B9]
time 22533ms: Process A4 completed I/O; added to ready queue [Q B8 B3 B1 A6 A9 B6 A3 A0 B0 B2 A1 A7 A8 A5 B5 A2 B9 A4]
time 22791ms: Process B4 completed a CPU burst; 12 bursts to go [Q B8 B3 B1 A6 A9 B6 A3 A0 B0 B2 A1 A7 A8 A5 B5 A2 B9 A4]
time 22791ms: Process B4 switching out of CPU; blocking on I/O until time 22814ms [Q B8 B3 B1 A6 A9 B6 A3 A0 B0 B2 A1 A7 A8 A5 B5 A2 B9 A4]
time 22795ms: Process B8 started using the CPU for 75ms burst [Q B3 B1 A6 A9 B6 A3 A0 B0 B2 A1 A7 A8 A5 B5 A2 B9 A4]
time 22814ms: Process B4 completed I/O; added to ready queue [Q B3 B1 A6 A9 B6 A3 A0 B0 B2 A1 A7 A8 A5 B5 A2 B9 A4 B4]
time 22870ms: Process B8 completed a CPU burst; 17 bursts to go [Q B3 B1 A6 A9 B6 A3 A0 B0 B2 A1 A7 A8 A5 B5 A2 B9 A4 B4]
time 22870ms: Process B8 switching out of CPU; blocking on I/O until time 23136ms [Q B3 B1 A6 A9 B6 A3 A0 B0 B2 A1 A7 A8 A5 B5 A2 B9 A4 B4]
time 22874ms: Process B3 started using the CPU for 16ms burst [Q B1 A6 A9 B6 A3 A0 B0 B2 A1 A7 A8 A5 B5 A2 B9 A4 B4]
time 22890ms: Process B3 completed a CPU burst; 19 bursts to go [Q B1 A6 A9 B6 A3 A0 B0 B2 A1 A7 A8 A5 B5 A2 B9 A4 B4]
time 22890ms: Process B3 switching out of CPU; blocking on I/O until time 22911ms [Q B1 A6 A9 B6 A3 A0 B0 B2 A1 A7 A8 A5 B5 A2 B9 A4 B4]
time 22894ms: Process B1 started using the CPU for 44ms burst [Q A6 A9 B6 A3 A0 B0 B2 A1 A7 A8 A5 B5 A2 B9 A4 B4]
time 22911ms: Process B3 completed I/O; added to ready queue [Q A6 A9 B6 A3 A0 B0 B2 A1 A7 A8 A5 B5 A2 B9 A4 B4 B3]
time 22938ms: Process B1 completed a CPU burst; 13 bursts to go [Q A6 A9 B6 A3 A0 B0 B2 A1 A7 A8 A5 B5 A2 B9 A4 B4 B3]
time 22938ms: Process B1 switching out of CPU; blocking on I/O until time 23016ms [Q A6 A9 B6 A3 A0 B0 B2 A1 A7 A8 A5 B5 A2 B9 A4 B4 B3]
time 22942ms: Process A6 started using the CPU for 756ms burst [Q A9 B6 A3 A0 B0 B2 A1 A7 A8 A5 B5 A2 B9 A4 B4 B3]
time 23016ms: Process B1 completed I/O; added to ready queue [Q A9 B6 A3 A0 B0 B2 A1 A7 A8 A5 B5 A2 B9 A4 B4 B3 B1]
time 23136ms: Process B8 completed I/O; added to ready queue [Q A9 B6 A3 A0 B0 B2 A1 A7 A8 A5 B5 A2 B9 A4 B4 B3 B1 B8]
time 23698ms: Process A6 completed a CPU burst; 14 bursts to go [Q A9 B6 A3 A0 B0 B2 A1 A7 A8 A5 B5 A2 B9 A4 B4 B3 B1 B8]
time 23698ms: Process A6 switching out of CPU; blocking on I/O until time 23818ms [Q A9 B6 A3 A0 B0 B2 A1 A7 A8 A5 B5 A2 B9 A4 B4 B3 B1 B8]
time 23702ms: Process A9 started using the CPU for 16ms burst [Q B6 A3 A0 B0 B2 A1 A7 A8 A5 B5 A2 B9 A4 B4 B3 B1 B8]
time 23718ms: Process A9 completed a CPU burst; 28 bursts to go [Q B6 A3 A0 B0 B2 A1 A7 A8 A5 B5 A2 B9 A4 B4 B3 B1 B8]
time 23718ms: Process A9 switching out of CPU; blocking on I/O until time 23734ms [Q B6 A3 A0 B0 B2 A1 A7 A8 A5 B5 A2 B9 A4 B4 B3 B1 B8]
time 23722ms: Process B6 started using the CPU for 235ms burst [Q A3 A0 B0 B2 A1 A7 A8 A5 B5 A2 B9 A4 B4 B3 B1 B8]
time 23734ms: Process A9 completed I/O; added to ready queue [Q A3 A0 B0 B2 A1 A7 A8 A5 B5 A2 B9 A4 B4 B3 B1 B8 A9]
time 23818ms: Process A6 completed I/O; added to ready queue [Q A3 A0 B0 B2 A1 A7 A8 A5 B5 A2 B9 A4 B4 B3 B1 B8 A9 A6]
time 23957ms: Process B6 completed a CPU burst; 2 bursts to go [Q A3 A0 B0 B2 A1 A7 A8 A5 B5 A2 B9 A4 B4 B3 B1 B8 A9 A6]
time 23957ms: Process B6 switching out of CPU; blocking on I/O until time 24919ms [Q A3 A0 B0 B2 A1 A7 A8 A5 B5 A2 B9 A4 B4 B3 B1 B8 A9 A6]
time 23961ms: Process A3 started using the CPU for 12ms burst [Q A0 B0 B2 A1 A7 A8 A5 B5 A2 B9 A4 B4 B3 B1 B8 A9 A6]
time 23973ms: Process A3 completed a CPU burst; 23 bursts to go [Q A0 B0 B2 A1 A7 A8 A5 B5 A2 B9 A4 B4 B3 B1 B8 A9 A6]
time 23973ms: Process A3 switching out of CPU; blocking on I/O until time 24038ms [Q A0 B0 B2 A1 A7 A8 A5 B5 A2 B9 A4 B4 B3 B1 B8 A9 A6]
time 23977ms: Process A0 started using the CPU for 1024ms burst [Q B0 B2 A1 A7 A8 A5 B5 A2 B9 A4 B4 B3 B1 B8 A9 A6]
time 24038ms: Process A3 completed I/O; added to ready queue [Q B0 B2 A1 A7 A8 A5 B5 A2 B9 A4 B4 B3 B1 B8 A9 A6 A3]
time 24149ms: Process B7 completed I/O; added to ready queue [Q B0 B2 A1 A7 A8 A5 B5 A2 B9 A4 B4 B3 B1 B8 A9 A6 A3 B7]
time 24919ms: Process B6 completed I/O; added to ready queue [Q B0 B2 A1 A7 A8 A5 B5 A2 B9 A4 B4 B3 B1 B8 A9 A6 A3 B7 B6]
time 25001ms: Process A0 completed a CPU burst; 26 bursts to go [Q B0 B2 A1 A7 A8 A5 B5 A2 B9 A4 B4 B3 B1 B8 A9 A6 A3 B7 B6]
time 25001ms: Process A0 switching out of CPU; blocking on I/O until time 25140ms [Q B0 B2 A1 A7 A8 A5 B5 A2 B9 A4 B4 B3 B1 B8 A9 A6 A3 B7 B6]
time 25005ms: Process B0 started using the CPU for 228ms burst [Q B2 A1 A7 A8 A5 B5 A2 B9 A4 B4 B3 B1 B8 A9 A6 A3 B7 B6]
time 25140ms: Process A0 completed I/O; added to ready queue [Q B2 A1 A7 A8 A5 B5 A2 B9 A4 B4 B3 B1 B8 A9 A6 A3 B7 B6 A0]
time 25233ms: Process B0 completed a CPU burst; 15 bursts to go [Q B2 A1 A7 A8 A5 B5 A2 B9 A4 B4 B3 B1 B8 A9 A6 A3 B7 B6 A0]
time 25233ms: Process B0 switching out of CPU; blocking on I/O until time 25352ms [Q B2 A1 A7 A8 A5 B5 A2 B9 A4 B4 B3 B1 B8 A9 A6 A3 B7 B6 A0]
time 25237ms: Process B2 started using the CPU for 492ms burst [Q A1 A7 A8 A5 B5 A2 B9 A4 B4 B3 B1 B8 A9 A6 A3 B7 B6 A0]
time 25352ms: Process B0 completed I/O; added to ready queue [Q A1 A7 A8 A5 B5 A2 B9 A4 B4 B3 B1 B8 A9 A6 A3 B7 B6 A0 B0]
time 25729ms: Process B2 completed a CPU burst; 11 bursts to go [Q A1 A7 A8 A5 B5 A2 B9 A4 B4 B3 B1 B8 A9 A6 A3 B7 B6 A0 B0]
time 25729ms: Process B2 switching out of CPU; blocking on I/O until time 25740ms [Q A1 A7 A8 A5 B5 A2 B9 A4 B4 B3 B1 B8 A9 A6 A3 B7 B6 A0 B0]
time 25733ms: Process A1 started using the CPU for 532ms burst [Q A7 A8 A5 B5 A2 B9 A4 B4 B3 B1 B8 A9 A6 A3 B7 B6 A0 B0]
time 25740ms: Process B2 completed I/O; added to ready queue [Q A7 A8 A5 B5 A2 B9 A4 B4 B3 B1 B8 A9 A6 A3 B7 B6 A0 B0 B2]
time 26265ms: Process A1 completed a CPU burst; 8 bursts to go [Q A7 A8 A5 B5 A2 B9 A4 B4 B3 B1 B8 A9 A6 A3 B7 B6 A0 B0 B2]
time 26265ms: Process A1 switching out of CPU; blocking on I/O until time 26284ms [Q A7 A8 A5 B5 A2 B9 A4 B4 B3 B1 B8 A9 A6 A3 B7 B6 A0 B0 B2]
time 26269ms: Process A7 started using the CPU for 464ms burst [Q A8 A5 B5 A2 B9 A4 B4 B3 B1 B8 A9 A6 A3 B7 B6 A0 B0 B2]
time 26284ms: Process A1 completed I/O; added to ready queue [Q A8 A5 B5 A2 B9 A4 B4 B3 B1 B8 A9 A6 A3 B7 B6 A0 B0 B2 A1]
time 26733ms: Process A7 completed a CPU burst; 15 bursts to go [Q A8 A5 B5 A2 B9 A4 B4 B3 B1 B8 A9 A6 A3 B7 B6 A0 B0 B2 A1]
time 26733ms: Process A7 switching out of CPU; blocking on I/O until time 26737ms [Q A8 A5 B5 A2 B9 A4 B4 B3 B1 B8 A9 A6 A3 B7 B6 A0 B0 B2 A1]
time 26737ms: Process A8 started using the CPU for 820ms burst [Q A5 B5 A2 B9 A4 B4 B3 B1 B8 A9 A6 A3 B7 B6 A0 B0 B2 A1]
time 26737ms: Process A7 completed I/O; added to ready queue [Q A5 B5 A2 B9 A4 B4 B3 B1 B8 A9 A6 A3 B7 B6 A0 B0 B2 A1 A7]
time 27557ms: Process A8 completed a CPU burst; 4 bursts to go [Q A5 B5 A2 B9 A4 B4 B3 B1 B8 A9 A6 A3 B7 B6 A0 B0 B2 A1 A7]
time 27557ms: Process A8 switching out of CPU; blocking on I/O until time 27632ms [Q A5 B5 A2 B9 A4 B4 B3 B1 B8 A9 A6 A3 B7 B6 A0 B0 B2 A1 A7]
time 27561ms: Process A5 started using the CPU for 60ms burst [Q B5 A2 B9 A4 B4 B3 B1 B8 A9 A6 A3 B7 B6 A0 B0 B2 A1 A7]
time 27621ms: Process A5 completed a CPU burst; 1 burst to go [Q B5 A2 B9 A4 B4 B3 B1 B8 A9 A6 A3 B7 B6 A0 B0 B2 A1 A7]
time 27621ms: Process A5 switching out of CPU; blocking on I/O until time 27729ms [Q B5 A2 B9 A4 B4 B3 B1 B8 A9 A6 A3 B7 B6 A0 B0 B2 A1 A7]
time 27625ms: Process B5 started using the CPU for 56ms burst [Q A2 B9 A4 B4 B3 B1 B8 A9 A6 A3 B7 B6 A0 B0 B2 A1 A7]
time 27632ms: Process A8 completed I/O; added to ready queue [Q A2 B9 A4 B4 B3 B1 B8 A9 A6 A3 B7 B6 A0 B0 B2 A1 A7 A8]
time 27681ms: Process B5 completed a CPU burst; 26 bursts to go [Q A2 B9 A4 B4 B3 B1 B8 A9 A6 A3 B7 B6 A0 B0 B2 A1 A7 A8]
time 27681ms: Process B5 switching out of CPU; blocking on I/O until time 27823ms [Q A2 B9 A4 B4 B3 B1 B8 A9 A6 A3 B7 B6 A0 B0 B2 A1 A7 A8]
time 27685ms: Process A2 started using the CPU for 92ms burst [Q B9 A4 B4 B3 B1 B8 A9 A6 A3 B7 B6 A0 B0 B2 A1 A7 A8]
time 27729ms: Process A5 completed I/O; added to ready queue [Q B9 A4 B4 B3 B1 B8 A9 A6 A3 B7 B6 A0 B0 B2 A1 A7 A8 A5]
time 27777ms: Process A2 completed a CPU burst; 26 bursts to go [Q B9 A4 B4 B3 B1 B8 A9 A6 A3 B7 B6 A0 B0 B2 A1 A7 A8 A5]
time 27777ms: Process A2 switching out of CPU; blocking on I/O until time 27838ms [Q B9 A4 B4 B3 B1 B8 A9 A6 A3 B7 B6 A0 B0 B2 A1 A7 A8 A5]
time 27781ms: Process B9 started using the CPU for 181ms burst [Q A4 B4 B3 B1 B8 A9 A6 A3 B7 B6 A0 B0 B2 A1 A7 A8 A5]
time 27823ms: Process B5 completed I/O; added to ready queue [Q A4 B4 B3 B1 B8 A9 A6 A3 B7 B6 A0 B0 B2 A1 A7 A8 A5 B5]
time 27838ms: Process A2 completed I/O; added to ready queue [Q A4 B4 B3 B1 B8 A9 A6 A3 B7 B6 A0 B0 B2 A1 A7 A8 A5 B5 A2]
time 27962ms: Process B9 completed a CPU burst; 7 bursts to go [Q A4 B4 B3 B1 B8 A9 A6 A3 B7 B6 A0 B0 B2 A1 A7 A8 A5 B5 A2]
time 27962ms: Process B9 switching out of CPU; blocking on I/O until time 28156ms [Q A4 B4 B3 B1 B8 A9 A6 A3 B7 B6 A0 B0 B2 A1 A7 A8 A5 B5 A2]
time 27966ms: Process A4 started using the CPU for 276ms burst [Q B4 B3 B1 B8 A9 A6 A3 B7 B6 A0 B0 B2 A1 A7 A8 A5 B5 A2]
time 28156ms: Process B9 completed I/O; added to ready queue [Q B4 B3 B1 B8 A9 A6 A3 B7 B6 A0 B0 B2 A1 A7 A8 A5 B5 A2 B9]
time 28242ms: Process A4 terminated [Q B4 B3 B1 B8 A9 A6 A3 B7 B6 A0 B0 B2 A1 A7 A8 A5 B5 A2 B9]
time 28246ms: Process B4 started using the CPU for 156ms burst [Q B3 B1 B8 A9 A6 A3 B7 B6 A0 B0 B2 A1 A7 A8 A5 B5 A2 B9]
time 28402ms: Process B4 completed a CPU burst; 11 bursts to go [Q B3 B1 B8 A9 A6 A3 B7 B6 A0 B0 B2 A1 A7 A8 A5 B5 A2 B9]
time 28402ms: Process B4 switching out of CPU; blocking on I/O until time 28415ms [Q B3 B1 B8 A9 A6 A3 B7 B6 A0 B0 B2 A1 A7 A8 A5 B5 A2 B9]
time 28406ms: Process B3 started using the CPU for 328ms burst [Q B1 B8 A9 A6 A3 B7 B6 A0 B0 B2 A1 A7 A8 A5 B5 A2 B9]
time 28415ms: Process B4 completed I/O; added to ready queue [Q B1 B8 A9 A6 A3 B7 B6 A0 B0 B2 A1 A7 A8 A5 B5 A2 B9 B4]
time 28734ms: Process B3 completed a CPU burst; 18 bursts to go [Q B1 B8 A9 A6 A3 B7 B6 A0 B0 B2 A1 A7 A8 A5 B5 A2 B9 B4]
time 28734ms: Process B3 switching out of CPU; blocking on I/O until time 28770ms [Q B1 B8 A9 A6 A3 B7 B6 A0 B0 B2 A1 A7 A8 A5 B5 A2 B9 B4]
time 28738ms: Process B1 started using the CPU for 268ms burst [Q B8 A9 A6 A3 B7 B6 A0 B0 B2 A1 A7 A8 A5 B5 A2 B9 B4]
time 28770ms: Process B3 completed I/O; added to ready queue [Q B8 A9 A6 A3 B7 B6 A0 B0 B2 A1 A7 A8 A5 B5 A2 B9 B4 B3]
time 29006ms: Process B1 completed a CPU burst; 12 bursts to go [Q B8 A9 A6 A3 B7 B6 A0 B0 B2 A1 A7 A8 A5 B5 A2 B9 B4 B3]
time 29006ms: Process B1 switching out of CPU; blocking on I/O until time 29011ms [Q B8 A9 A6 A3 B7 B6 A0 B0 B2 A1 A7 A8 A5 B5 A2 B9 B4 B3]
time 29010ms: Process B8 started using the CPU for 44ms burst [Q A9 A6 A3 B7 B6 A0 B0 B2 A1 A7 A8 A5 B5 A2 B9 B4 B3]
time 29011ms: Process B1 completed I/O; added to ready queue [Q A9 A6 A3 B7 B6 A0 B0 B2 A1 A7 A8 A5 B5 A2 B9 B4 B3 B1]
time 29054ms: Process B8 completed a CPU burst; 16 bursts to go [Q A9 A6 A3 B7 B6 A0 B0 B2 A1 A7 A8 A5 B5 A2 B9 B4 B3 B1]
time 29054ms: Process B8 switching out of CPU; blocking on I/O until time 31824ms [Q A9 A6 A3 B7 B6 A0 B0 B2 A1 A7 A8 A5 B5 A2 B9 B4 B3 B1]
time 29058ms: Process A9 started using the CPU for 644ms burst [Q A6 A3 B7 B6 A0 B0 B2 A1 A7 A8 A5 B5 A2 B9 B4 B3 B1]
time 29702ms: Process A9 completed a CPU burst; 27 bursts to go [Q A6 A3 B7 B6 A0 B0 B2 A1 A7 A8 A5 B5 A2 B9 B4 B3 B1]
time 29702ms: Process A9 switching out of CPU; blocking on I/O until time 29755ms [Q A6 A3 B7 B6 A0 B0 B2 A1 A7 A8 A5 B5 A2 B9 B4 B3 B1]
time 29706ms: Process A6 started using the CPU for 180ms burst [Q A3 B7 B6 A0 B0 B2 A1 A7 A8 A5 B5 A2 B9 B4 B3 B1]
time 29755ms: Process A9 completed I/O; added to ready queue [Q A3 B7 B6 A0 B0 B2 A1 A7 A8 A5 B5 A2 B9 B4 B3 B1 A9]
time 29886ms: Process A6 completed a CPU burst; 13 bursts to go [Q A3 B7 B6 A0 B0 B2 A1 A7 A8 A5 B5 A2 B9 B4 B3 B1 A9]
time 29886ms: Process A6 switching out of CPU; blocking on I/O until time 29943ms [Q A3 B7 B6 A0 B0 B2 A1 A7 A8 A5 B5 A2 B9 B4 B3 B1 A9]
time 29890ms: Process A3 started using the CPU for 28ms burst [Q B7 B6 A0 B0 B2 A1 A7 A8 A5 B5 A2 B9 B4 B3 B1 A9]
time 29918ms: Process A3 completed a CPU burst; 22 bursts to go [Q B7 B6 A0 B0 B2 A1 A7 A8 A5 B5 A2 B9 B4 B3 B1 A9]
time 29918ms: Process A3 switching out of CPU; blocking on I/O until time 30158ms [Q B7 B6 A0 B0 B2 A1 A7 A8 A5 B5 A2 B9 B4 B3 B1 A9]
time 29922ms: Process B7 started using the CPU for 74ms burst [Q B6 A0 B0 B2 A1 A7 A8 A5 B5 A2 B9 B4 B3 B1 A9]
time 29943ms: Process A6 completed I/O; added to ready queue [Q B6 A0 B0 B2 A1 A7 A8 A5 B5 A2 B9 B4 B3 B1 A9 A6]
time 29996ms: Process B7 completed a CPU burst; 22 bursts to go [Q B6 A0 B0 B2 A1 A7 A8 A5 B5 A2 B9 B4 B3 B1 A9 A6]
time 29996ms: Process B7 switching out of CPU; blocking on I/O until time 33710ms [Q B6 A0 B0 B2 A1 A7 A8 A5 B5 A2 B9 B4 B3 B1 A9 A6]
time 30000ms: Process B6 started using the CPU for 10ms burst [Q A0 B0 B2 A1 A7 A8 A5 B5 A2 B9 B4 B3 B1 A9 A6]
time 30010ms: Process B6 completed a CPU burst; 1 burst to go [Q A0 B0 B2 A1 A7 A8 A5 B5 A2 B9 B4 B3 B1 A9 A6]
time 30010ms: Process B6 switching out of CPU; blocking on I/O until time 30476ms [Q A0 B0 B2 A1 A7 A8 A5 B5 A2 B9 B4 B3 B1 A9 A6]
time 30014ms: Process A0 started using the CPU for 476ms burst [Q B0 B2 A1 A7 A8 A5 B5 A2 B9 B4 B3 B1 A9 A6]
time 30158ms: Process A3 completed I/O; added to ready queue [Q B0 B2 A1 A7 A8 A5 B5 A2 B9 B4 B3 B1 A9 A6 A3]
time 30476ms: Process B6 completed I/O; added to ready queue [Q B0 B2 A1 A7 A8 A5 B5 A2 B9 B4 B3 B1 A9 A6 A3 B6]
time 30490ms: Process A0 completed a CPU burst; 25 bursts to go [Q B0 B2 A1 A7 A8 A5 B5 A2 B9 B4 B3 B1 A9 A6 A3 B6]
time 30490ms: Process A0 switching out of CPU; blocking on I/O until time 30569ms [Q B0 B2 A1 A7 A8 A5 B5 A2 B9 B4 B3 B1 A9 A6 A3 B6]
time 30494ms: Process B0 started using the CPU for 604ms burst [Q B2 A1 A7 A8 A5 B5 A2 B9 B4 B3 B1 A9 A6 A3 B6]
time 30569ms: Process A0 completed I/O; added to ready queue [Q B2 A1 A7 A8 A5 B5 A2 B9 B4 B3 B1 A9 A6 A3 B6 A0]
time 31098ms: Process B0 completed a CPU burst; 14 bursts to go [Q B2 A1 A7 A8 A5 B5 A2 B9 B4 B3 B1 A9 A6 A3 B6 A0]
time 31098ms: Process B0 switching out of CPU; blocking on I/O until time 31137ms [Q B2 A1 A7 A8 A5 B5 A2 B9 B4 B3 B1 A9 A6 A3 B6 A0]
time 31102ms: Process B2 started using the CPU for 28ms burst [Q A1 A7 A8 A5 B5 A2 B9 B4 B3 B1 A9 A6 A3 B6 A0]
time 31130ms: Process B2 completed a CPU burst; 10 bursts to go [Q A1 A7 A8 A5 B5 A2 B9 B4 B3 B1 A9 A6 A3 B6 A0]
time 31130ms: Process B2 switching out of CPU; blocking on I/O until time 31138ms [Q A1 A7 A8 A5 B5 A2 B9 B4 B3 B1 A9 A6 A3 B6 A0]
time 31134ms: Process A1 started using the CPU for 100ms burst [Q A7 A8 A5 B5 A2 B9 B4 B3 B1 A9 A6 A3 B6 A0]
time 31137ms: Process B0 completed I/O; added to ready queue [Q A7 A8 A5 B5 A2 B9 B4 B3 B1 A9 A6 A3 B6 A0 B0]
time 31138ms: Process B2 completed I/O; added to ready queue [Q A7 A8 A5 B5 A2 B9 B4 B3 B1 A9 A6 A3 B6 A0 B0 B2]
time 31234ms: Process A1 completed a CPU burst; 7 bursts to go [Q A7 A8 A5 B5 A2 B9 B4 B3 B1 A9 A6 A3 B6 A0 B0 B2]
time 31234ms: Process A1 switching out of CPU; blocking on I/O until time 31302ms [Q A7 A8 A5 B5 A2 B9 B4 B3 B1 A9 A6 A3 B6 A0 B0 B2]
time 31238ms: Process A7 started using the CPU for 392ms burst [Q A8 A5 B5 A2 B9 B4 B3 B1 A9 A6 A3 B6 A0 B0 B2]
time 31302ms: Process A1 completed I/O; added to ready queue [Q A8 A5 B5 A2 B9 B4 B3 B1 A9 A6 A3 B6 A0 B0 B2 A1]
time 31630ms: Process A7 completed a CPU burst; 14 bursts to go [Q A8 A5 B5 A2 B9 B4 B3 B1 A9 A6 A3 B6 A0 B0 B2 A1]
time 31630ms: Process A7 switching out of CPU; blocking on I/O until time 31695ms [Q A8 A5 B5 A2 B9 B4 B3 B1 A9 A6 A3 B6 A0 B0 B2 A1]
time 31634ms: Process A8 started using the CPU for 184ms burst [Q A5 B5 A2 B9 B4 B3 B1 A9 A6 A3 B6 A0 B0 B2 A1]
time 31695ms: Process A7 completed I/O; added to ready queue [Q A5 B5 A2 B9 B4 B3 B1 A9 A6 A3 B6 A0 B0 B2 A1 A7]
time 31818ms: Process A8 completed a CPU burst; 3 bursts to go [Q A5 B5 A2 B9 B4 B3 B1 A9 A6 A3 B6 A0 B0 B2 A1 A7]
time 31818ms: Process A8 switching out of CPU; blocking on I/O until time 31868ms [Q A5 B5 A2 B9 B4 B3 B1 A9 A6 A3 B6 A0 B0 B2 A1 A7]
time 31822ms: Process A5 started using the CPU for 912ms burst [Q B5 A2 B9 B4 B3 B1 A9 A6 A3 B6 A0 B0 B2 A1 A7]
time 31824ms: Process B8 completed I/O; added to ready queue [Q B5 A2 B9 B4 B3 B1 A9 A6 A3 B6 A0 B0 B2 A1 A7 B8]
time 31868ms: Process A8 completed I/O; added to ready queue [Q B5 A2 B9 B4 B3 B1 A9 A6 A3 B6 A0 B0 B2 A1 A7 B8 A8]
time 32734ms: Process A5 terminated [Q B5 A2 B9 B4 B3 B1 A9 A6 A3 B6 A0 B0 B2 A1 A7 B8 A8]
time 32738ms: Process B5 started using the CPU for 84ms burst [Q A2 B9 B4 B3 B1 A9 A6 A3 B6 A0 B0 B2 A1 A7 B8 A8]
time 32822ms: Process B5 completed a CPU burst; 25 bursts to go [Q A2 B9 B4 B3 B1 A9 A6 A3 B6 A0 B0 B2 A1 A7 B8 A8]
time 32822ms: Process B5 switching out of CPU; blocking on I/O until time 32826ms [Q A2 B9 B4 B3 B1 A9 A6 A3 B6 A0 B0 B2 A1 A7 B8 A8]
time 32826ms: Process A2 started using the CPU for 136ms burst [Q B9 B4 B3 B1 A9 A6 A3 B6 A0 B0 B2 A1 A7 B8 A8]
time 32826ms: Process B5 completed I/O; added to ready queue [Q B9 B4 B3 B1 A9 A6 A3 B6 A0 B0 B2 A1 A7 B8 A8 B5]
time 32962ms: Process A2 completed a CPU burst; 25 bursts to go [Q B9 B4 B3 B1 A9 A6 A3 B6 A0 B0 B2 A1 A7 B8 A8 B5]
time 32962ms: Process A2 switching out of CPU; blocking on I/O until time 33135ms [Q B9 B4 B3 B1 A9 A6 A3 B6 A0 B0 B2 A1 A7 B8 A8 B5]
time 32966ms: Process B9 started using the CPU for 240ms burst [Q B4 B3 B1 A9 A6 A3 B6 A0 B0 B2 A1 A7 B8 A8 B5]
time 33135ms: Process A2 completed I/O; added to ready queue [Q B4 B3 B1 A9 A6 A3 B6 A0 B0 B2 A1 A7 B8 A8 B5 A2]
time 33206ms: Process B9 completed a CPU burst; 6 bursts to go [Q B4 B3 B1 A9 A6 A3 B6 A0 B0 B2 A1 A7 B8 A8 B5 A2]
time 33206ms: Process B9 switching out of CPU; blocking on I/O until time 33592ms [Q B4 B3 B1 A9 A6 A3 B6 A0 B0 B2 A1 A7 B8 A8 B5 A2]
time 33210ms: Process B4 started using the CPU for 820ms burst [Q B3 B1 A9 A6 A3 B6 A0 B0 B2 A1 A7 B8 A8 B5 A2]
time 33592ms: Process B9 completed I/O; added to ready queue [Q B3 B1 A9 A6 A3 B6 A0 B0 B2 A1 A7 B8 A8 B5 A2 B9]
time 33710ms: Process B7 completed I/O; added to ready queue [Q B3 B1 A9 A6 A3 B6 A0 B0 B2 A1 A7 B8 A8 B5 A2 B9 B7]
time 34030ms: Process B4 completed a CPU burst; 10 bursts to go [Q B3 B1 A9 A6 A3 B6 A0 B0 B2 A1 A7 B8 A8 B5 A2 B9 B7]
time 34030ms: Process B4 switching out of CPU; blocking on I/O until time 34105ms [Q B3 B1 A9 A6 A3 B6 A0 B0 B2 A1 A7 B8 A8 B5 A2 B9 B7]
time 34034ms: Process B3 started using the CPU for 500ms burst [Q B1 A9 A6 A3 B6 A0 B0 B2 A1 A7 B8 A8 B5 A2 B9 B7]
time 34105ms: Process B4 completed I/O; added to ready queue [Q B1 A9 A6 A3 B6 A0 B0 B2 A1 A7 B8 A8 B5 A2 B9 B7 B4]
time 34534ms: Process B3 completed a CPU burst; 17 bursts to go [Q B1 A9 A6 A3 B6 A0 B0 B2 A1 A7 B8 A8 B5 A2 B9 B7 B4]
time 34534ms: Process B3 switching out of CPU; blocking on I/O until time 34636ms [Q B1 A9 A6 A3 B6 A0 B0 B2 A1 A7 B8 A8 B5 A2 B9 B7 B4]
time 34538ms: Process B1 started using the CPU for 64ms burst [Q A9 A6 A3 B6 A0 B0 B2 A1 A7 B8 A8 B5 A2 B9 B7 B4]
time 34602ms: Process B1 completed a CPU burst; 11 bursts to go [Q A9 A6 A3 B6 A0 B0 B2 A1 A7 B8 A8 B5 A2 B9 B7 B4]
time 34602ms: Process B1 switching out of CPU; blocking on I/O until time 34813ms [Q A9 A6 A3 B6 A0 B0 B2 A1 A7 B8 A8 B5 A2 B9 B7 B4]
time 34606ms: Process A9 started using the CPU for 304ms burst [Q A6 A3 B6 A0 B0 B2 A1 A7 B8 A8 B5 A2 B9 B7 B4]
time 34636ms: Process B3 completed I/O; added to ready queue [Q A6 A3 B6 A0 B0 B2 A1 A7 B8 A8 B5 A2 B9 B7 B4 B3]
time 34813ms: Process B1 completed I/O; added to ready queue [Q A6 A3 B6 A0 B0 B2 A1 A7 B8 A8 B5 A2 B9 B7 B4 B3 B1]
time 34910ms: Process A9 completed a CPU burst; 26 bursts to go [Q A6 A3 B6 A0 B0 B2 A1 A7 B8 A8 B5 A2 B9 B7 B4 B3 B1]
time 34910ms: Process A9 switching out of CPU; blocking on I/O until time 35066ms [Q A6 A3 B6 A0 B0 B2 A1 A7 B8 A8 B5 A2 B9 B7 B4 B3 B1]
time 34914ms: Process A6 started using the CPU for 264ms burst [Q A3 B6 A0 B0 B2 A1 A7 B8 A8 B5 A2 B9 B7 B4 B3 B1]
time 35066ms: Process A9 completed I/O; added to ready queue [Q A3 B6 A0 B0 B2 A1 A7 B8 A8 B5 A2 B9 B7 B4 B3 B1 A9]
time 35178ms: Process A6 completed a CPU burst; 12 bursts to go [Q A3 B6 A0 B0 B2 A1 A7 B8 A8 B5 A2 B9 B7 B4 B3 B1 A9]
time 35178ms: Process A6 switching out of CPU; blocking on I/O until time 35281ms [Q A3 B6 A0 B0 B2 A1 A7 B8 A8 B5 A2 B9 B7 B4 B3 B1 A9]
time 35182ms: Process A3 started using the CPU for 88ms burst [Q B6 A0 B0 B2 A1 A7 B8 A8 B5 A2 B9 B7 B4 B3 B1 A9]
time 35270ms: Process A3 completed a CPU burst; 21 bursts to go [Q B6 A0 B0 B2 A1 A7 B8 A8 B5 A2 B9 B7 B4 B3 B1 A9]
time 35270ms: Process A3 switching out of CPU; blocking on I/O until time 35335ms [Q B6 A0 B0 B2 A1 A7 B8 A8 B5 A2 B9 B7 B4 B3 B1 A9]
time 35274ms: Process B6 started using the CPU for 46ms burst [Q A0 B0 B2 A1 A7 B8 A8 B5 A2 B9 B7 B4 B3 B1 A9]
time 35281ms: Process A6 completed I/O; added to ready queue [Q A0 B0 B2 A1 A7 B8 A8 B5 A2 B9 B7 B4 B3 B1 A9 A6]
time 35320ms: Process B6 terminated [Q A0 B0 B2 A1 A7 B8 A8 B5 A2 B9 B7 B4 B3 B1 A9 A6]
time 35324ms: Process A0 started using the CPU for 28ms burst [Q B0 B2 A1 A7 B8 A8 B5 A2 B9 B7 B4 B3 B1 A9 A6]
time 35335ms: Process A3 completed I/O; added to ready queue [Q B0 B2 A1 A7 B8 A8 B5 A2 B9 B7 B4 B3 B1 A9 A6 A3]
time 35352ms: Process A0 completed a CPU burst; 24 bursts to go [Q B0 B2 A1 A7 B8 A8 B5 A2 B9 B7 B4 B3 B1 A9 A6 A3]
time 35352ms: Process A0 switching out of CPU; blocking on I/O until time 35535ms [Q B0 B2 A1 A7 B8 A8 B5 A2 B9 B7 B4 B3 B1 A9 A6 A3]
time 35356ms: Process B0 started using the CPU for 48ms burst [Q B2 A1 A7 B8 A8 B5 A2 B9 B7 B4 B3 B1 A9 A6 A3]
time 35404ms: Process B0 completed a CPU burst; 13 bursts to go [Q B2 A1 A7 B8 A8 B5 A2 B9 B7 B4 B3 B1 A9 A6 A3]
time 35404ms: Process B0 switching out of CPU; blocking on I/O until time 35701ms [Q B2 A1 A7 B8 A8 B5 A2 B9 B7 B4 B3 B1 A9 A6 A3]
time 35408ms: Process B2 started using the CPU for 48ms burst [Q A1 A7 B8 A8 B5 A2 B9 B7 B4 B3 B1 A9 A6 A3]
time 35456ms: Process B2 completed a CPU burst; 9 bursts to go [Q A1 A7 B8 A8 B5 A2 B9 B7 B4 B3 B1 A9 A6 A3]
time 35456ms: Process B2 switching out of CPU; blocking on I/O until time 35502ms [Q A1 A7 B8 A8 B5 A2 B9 B7 B4 B3 B1 A9 A6 A3]
time 35460ms: Process A1 started using the CPU for 256ms burst [Q A7 B8 A8 B5 A2 B9 B7 B4 B3 B1 A9 A6 A3]
time 35502ms: Process B2 completed I/O; added to ready queue [Q A7 B8 A8 B5 A2 B9 B7 B4 B3 B1 A9 A6 A3 B2]
time 35535ms: Process A0 completed I/O; added to ready queue [Q A7 B8 A8 B5 A2 B9 B7 B4 B3 B1 A9 A6 A3 B2 A0]
time 35701ms: Process B0 completed I/O; added to ready queue [Q A7 B8 A8 B5 A2 B9 B7 B4 B3 B1 A9 A6 A3 B2 A0 B0]
time 35716ms: Process A1 completed a CPU burst; 6 bursts to go [Q A7 B8 A8 B5 A2 B9 B7 B4 B3 B1 A9 A6 A3 B2 A0 B0]
time 35716ms: Process A1 switching out of CPU; blocking on I/O until time 35833ms [Q A7 B8 A8 B5 A2 B9 B7 B4 B3 B1 A9 A6 A3 B2 A0 B0]
time 35720ms: Process A7 started using the CPU for 160ms burst [Q B8 A8 B5 A2 B9 B7 B4 B3 B1 A9 A6 A3 B2 A0 B0]
time 35833ms: Process A1 completed I/O; added to ready queue [Q B8 A8 B5 A2 B9 B7 B4 B3 B1 A9 A6 A3 B2 A0 B0 A1]
time 35880ms: Process A7 completed a CPU burst; 13 bursts to go [Q B8 A8 B5 A2 B9 B7 B4 B3 B1 A9 A6 A3 B2 A0 B0 A1]
time 35880ms: Process A7 switching out of CPU; blocking on I/O until time 35949ms [Q B8 A8 B5 A2 B9 B7 B4 B3 B1 A9 A6 A3 B2 A0 B0 A1]
time 35884ms: Process B8 started using the CPU for 56ms burst [Q A8 B5 A2 B9 B7 B4 B3 B1 A9 A6 A3 B2 A0 B0 A1]
time 35940ms: Process B8 completed a CPU burst; 15 bursts to go [Q A8 B5 A2 B9 B7 B4 B3 B1 A9 A6 A3 B2 A0 B0 A1]
time 35940ms: Process B8 switching out of CPU; blocking on I/O until time 37166ms [Q A8 B5 A2 B9 B7 B4 B3 B1 A9 A6 A3 B2 A0 B0 A1]
time 35944ms: Process A8 started using the CPU for 312ms burst [Q B5 A2 B9 B7 B4 B3 B1 A9 A6 A3 B2 A0 B0 A1]
time 35949ms: Process A7 completed I/O; added to ready queue [Q B5 A2 B9 B7 B4 B3 B1 A9 A6 A3 B2 A0 B0 A1 A7]
time 36256ms: Process A8 completed a CPU burst; 2 bursts to go [Q B5 A2 B9 B7 B4 B3 B1 A9 A6 A3 B2 A0 B0 A1 A7]
time 36256ms: Process A8 switching out of CPU; blocking on I/O until time 36453ms [Q B5 A2 B9 B7 B4 B3 B1 A9 A6 A3 B2 A0 B0 A1 A7]
time 36260ms: Process B5 started using the CPU for 96ms burst [Q A2 B9 B7 B4 B3 B1 A9 A6 A3 B2 A0 B0 A1 A7]
time 36356ms: Process B5 completed a CPU burst; 24 bursts to go [Q A2 B9 B7 B4 B3 B1 A9 A6 A3 B2 A0 B0 A1 A7]
time 36356ms: Process B5 switching out of CPU; blocking on I/O until time 36377ms [Q A2 B9 B7 B4 B3 B1 A9 A6 A3 B2 A0 B0 A1 A7]
time 36360ms: Process A2 started using the CPU for 236ms burst [Q B9 B7 B4 B3 B1 A9 A6 A3 B2 A0 B0 A1 A7]
time 36377ms: Process B5 completed I/O; added to ready queue [Q B9 B7 B4 B3 B1 A9 A6 A3 B2 A0 B0 A1 A7 B5]
time 36453ms: Process A8 completed I/O; added to ready queue [Q B9 B7 B4 B3 B1 A9 A6 A3 B2 A0 B0 A1 A7 B5 A8]
time 36596ms: Process A2 completed a CPU burst; 24 bursts to go [Q B9 B7 B4 B3 B1 A9 A6 A3 B2 A0 B0 A1 A7 B5 A8]
time 36596ms: Process A2 switching out of CPU; blocking on I/O until time 36682ms [Q B9 B7 B4 B3 B1 A9 A6 A3 B2 A0 B0 A1 A7 B5 A8]
time 36600ms: Process B9 started using the CPU for 23ms burst [Q B7 B4 B3 B1 A9 A6 A3 B2 A0 B0 A1 A7 B5 A8]
time 36623ms: Process B9 completed a CPU burst; 5 bursts to go [Q B7 B4 B3 B1 A9 A6 A3 B2 A0 B0 A1 A7 B5 A8]
time 36623ms: Process B9 switching out of CPU; blocking on I/O until time 36753ms [Q B7 B4 B3 B1 A9 A6 A3 B2 A0 B0 A1 A7 B5 A8]
time 36627ms: Process B7 started using the CPU for 133ms burst [Q B4 B3 B1 A9 A6 A3 B2 A0 B0 A1 A7 B5 A8]
time 36682ms: Process A2 completed I/O; added to ready queue [Q B4 B3 B1 A9 A6 A3 B2 A0 B0 A1 A7 B5 A8 A2]
time 36753ms: Process B9 completed I/O; added to ready queue [Q B4 B3 B1 A9 A6 A3 B2 A0 B0 A1 A7 B5 A8 A2 B9]
time 36760ms: Process B7 completed a CPU burst; 21 bursts to go [Q B4 B3 B1 A9 A6 A3 B2 A0 B0 A1 A7 B5 A8 A2 B9]
time 36760ms: Process B7 switching out of CPU; blocking on I/O until time 38034ms [Q B4 B3 B1 A9 A6 A3 B2 A0 B0 A1 A7 B5 A8 A2 B9]
time 36764ms: Process B4 started using the CPU for 188ms burst [Q B3 B1 A9 A6 A3 B2 A0 B0 A1 A7 B5 A8 A2 B9]
time 36952ms: Process B4 completed a CPU burst; 9 bursts to go [Q B3 B1 A9 A6 A3 B2 A0 B0 A1 A7 B5 A8 A2 B9]
time 36952ms: Process B4 switching out of CPU; blocking on I/O until time 37011ms [Q B3 B1 A9 A6 A3 B2 A0 B0 A1 A7 B5 A8 A2 B9]
time 36956ms: Process B3 started using the CPU for 124ms burst [Q B1 A9 A6 A3 B2 A0 B0 A1 A7 B5 A8 A2 B9]
time 37011ms: Process B4 completed I/O; added to ready queue [Q B1 A9 A6 A3 B2 A0 B0 A1 A7 B5 A8 A2 B9 B4]
time 37080ms: Process B3 completed a CPU burst; 16 bursts to go [Q B1 A9 A6 A3 B2 A0 B0 A1 A7 B5 A8 A2 B9 B4]
time 37080ms: Process B3 switching out of CPU; blocking on I/O until time 37476ms [Q B1 A9 A6 A3 B2 A0 B0 A1 A7 B5 A8 A2 B9 B4]
time 37084ms: Process B1 started using the CPU for 636ms burst [Q A9 A6 A3 B2 A0 B0 A1 A7 B5 A8 A2 B9 B4]
time 37166ms: Process B8 completed I/O; added to ready queue [Q A9 A6 A3 B2 A0 B0 A1 A7 B5 A8 A2 B9 B4 B8]
time 37476ms: Process B3 completed I/O; added to ready queue [Q A9 A6 A3 B2 A0 B0 A1 A7 B5 A8 A2 B9 B4 B8 B3]
time 37720ms: Process B1 completed a CPU burst; 10 bursts to go [Q A9 A6 A3 B2 A0 B0 A1 A7 B5 A8 A2 B9 B4 B8 B3]
time 37720ms: Process B1 switching out of CPU; blocking on I/O until time 37938ms [Q A9 A6 A3 B2 A0 B0 A1 A7 B5 A8 A2 B9 B4 B8 B3]
time 37724ms: Process A9 started using the CPU for 400ms burst [Q A6 A3 B2 A0 B0 A1 A7 B5 A8 A2 B9 B4 B8 B3]
time 37938ms: Process B1 completed I/O; added to ready queue [Q A6 A3 B2 A0 B0 A1 A7 B5 A8 A2 B9 B4 B8 B3 B1]
time 38034ms: Process B7 completed I/O; added to ready queue [Q A6 A3 B2 A0 B0 A1 A7 B5 A8 A2 B9 B4 B8 B3 B1 B7]
time 38124ms: Process A9 completed a CPU burst; 25 bursts to go [Q A6 A3 B2 A0 B0 A1 A7 B5 A8 A2 B9 B4 B8 B3 B1 B7]
time 38124ms: Process A9 switching out of CPU; blocking on I/O until time 38231ms [Q A6 A3 B2 A0 B0 A1 A7 B5 A8 A2 B9 B4 B8 B3 B1 B7]
time 38128ms: Process A6 started using the CPU for 588ms burst [Q A3 B2 A0 B0 A1 A7 B5 A8 A2 B9 B4 B8 B3 B1 B7]
time 38231ms: Process A9 completed I/O; added to ready queue [Q A3 B2 A0 B0 A1 A7 B5 A8 A2 B9 B4 B8 B3 B1 B7 A9]
time 38716ms: Process A6 completed a CPU burst; 11 bursts to go [Q A3 B2 A0 B0 A1 A7 B5 A8 A2 B9 B4 B8 B3 B1 B7 A9]
time 38716ms: Process A6 switching out of CPU; blocking on I/O until time 38765ms [Q A3 B2 A0 B0 A1 A7 B5 A8 A2 B9 B4 B8 B3 B1 B7 A9]
time 38720ms: Process A3 started using the CPU for 116ms burst [Q B2 A0 B0 A1 A7 B5 A8 A2 B9 B4 B8 B3 B1 B7 A9]
time 38765ms: Process A6 completed I/O; added to ready queue [Q B2 A0 B0 A1 A7 B5 A8 A2 B9 B4 B8 B3 B1 B7 A9 A6]
time 38836ms: Process A3 completed a CPU burst; 20 bursts to go [Q B2 A0 B0 A1 A7 B5 A8 A2 B9 B4 B8 B3 B1 B7 A9 A6]
time 38836ms: Process A3 switching out of CPU; blocking on I/O until time 38892ms [Q B2 A0 B0 A1 A7 B5 A8 A2 B9 B4 B8 B3 B1 B7 A9 A6]
time 38840ms: Process B2 started using the CPU for 568ms burst [Q A0 B0 A1 A7 B5 A8 A2 B9 B4 B8 B3 B1 B7 A9 A6]
time 38892ms: Process A3 completed I/O; added to ready queue [Q A0 B0 A1 A7 B5 A8 A2 B9 B4 B8 B3 B1 B7 A9 A6 A3]
time 39408ms: Process B2 completed a CPU burst; 8 bursts to go [Q A0 B0 A1 A7 B5 A8 A2 B9 B4 B8 B3 B1 B7 A9 A6 A3]
time 39408ms: Process B2 switching out of CPU; blocking on I/O until time 39414ms [Q A0 B0 A1 A7 B5 A8 A2 B9 B4 B8 B3 B1 B7 A9 A6 A3]
time 39412ms: Process A0 started using the CPU for 184ms burst [Q B0 A1 A7 B5 A8 A2 B9 B4 B8 B3 B1 B7 A9 A6 A3]
time 39414ms: Process B2 completed I/O; added to ready queue [Q B0 A1 A7 B5 A8 A2 B9 B4 B8 B3 B1 B7 A9 A6 A3 B2]
time 39596ms: Process A0 completed a CPU burst; 23 bursts to go [Q B0 A1 A7 B5 A8 A2 B9 B4 B8 B3 B1 B7 A9 A6 A3 B2]
time 39596ms: Process A0 switching out of CPU; blocking on I/O until time 40168ms [Q B0 A1 A7 B5 A8 A2 B9 B4 B8 B3 B1 B7 A9 A6 A3 B2]
time 39600ms: Process B0 started using the CPU for 224ms burst [Q A1 A7 B5 A8 A2 B9 B4 B8 B3 B1 B7 A9 A6 A3 B2]
time 39824ms: Process B0 completed a CPU burst; 12 bursts to go [Q A1 A7 B5 A8 A2 B9 B4 B8 B3 B1 B7 A9 A6 A3 B2]
time 39824ms: Process B0 switching out of CPU; blocking on I/O until time 39922ms [Q A1 A7 B5 A8 A2 B9 B4 B8 B3 B1 B7 A9 A6 A3 B2]
time 39828ms: Process A1 started using the CPU for 1684ms burst [Q A7 B5 A8 A2 B9 B4 B8 B3 B1 B7 A9 A6 A3 B2]
time 39922ms: Process B0 completed I/O; added to ready queue [Q A7 B5 A8 A2 B9 B4 B8 B3 B1 B7 A9 A6 A3 B2 B0]
time 40168ms: Process A0 completed I/O; added to ready queue [Q A7 B5 A8 A2 B9 B4 B8 B3 B1 B7 A9 A6 A3 B2 B0 A0]
time 41512ms: Process A1 completed a CPU burst; 5 bursts to go [Q A7 B5 A8 A2 B9 B4 B8 B3 B1 B7 A9 A6 A3 B2 B0 A0]
time 41512ms: Process A1 switching out of CPU; blocking on I/O until time 41576ms [Q A7 B5 A8 A2 B9 B4 B8 B3 B1 B7 A9 A6 A3 B2 B0 A0]
time 41516ms: Process A7 started using the CPU for 140ms burst [Q B5 A8 A2 B9 B4 B8 B3 B1 B7 A9 A6 A3 B2 B0 A0]
time 41576ms: Process A1 completed I/O; added to ready queue [Q B5 A8 A2 B9 B4 B8 B3 B1 B7 A9 A6 A3 B2 B0 A0 A1]
time 41656ms: Process A7 completed a CPU burst; 12 bursts to go [Q B5 A8 A2 B9 B4 B8 B3 B1 B7 A9 A6 A3 B2 B0 A0 A1]
time 41656ms: Process A7 switching out of CPU; blocking on I/O until time 41805ms [Q B5 A8 A2 B9 B4 B8 B3 B1 B7 A9 A6 A3 B2 B0 A0 A1]
time 41660ms: Process B5 started using the CPU for 480ms burst [Q A8 A2 B9 B4 B8 B3 B1 B7 A9 A6 A3 B2 B0 A0 A1]
time 41805ms: Process A7 completed I/O; added to ready queue [Q A8 A2 B9 B4 B8 B3 B1 B7 A9 A6 A3 B2 B0 A0 A1 A7]
time 42140ms: Process B5 completed a CPU burst; 23 bursts to go [Q A8 A2 B9 B4 B8 B3 B1 B7 A9 A6 A3 B2 B0 A0 A1 A7]
time 42140ms: Process B5 switching out of CPU; blocking on I/O until time 42222ms [Q A8 A2 B9 B4 B8 B3 B1 B7 A9 A6 A3 B2 B0 A0 A1 A7]
time 42144ms: Process A8 started using the CPU for 2620ms burst [Q A2 B9 B4 B8 B3 B1 B7 A9 A6 A3 B2 B0 A0 A1 A7]
time 42222ms: Process B5 completed I/O; added to ready queue [Q A2 B9 B4 B8 B3 B1 B7 A9 A6 A3 B2 B0 A0 A1 A7 B5]
time 44764ms: Process A8 completed a CPU burst; 1 burst to go [Q A2 B9 B4 B8 B3 B1 B7 A9 A6 A3 B2 B0 A0 A1 A7 B5]
time 44764ms: Process A8 switching out of CPU; blocking on I/O until time 44786ms [Q A2 B9 B4 B8 B3 B1 B7 A9 A6 A3 B2 B0 A0 A1 A7 B5]
time 44768ms: Process A2 started using the CPU for 112ms burst [Q B9 B4 B8 B3 B1 B7 A9 A6 A3 B2 B0 A0 A1 A7 B5]
time 44786ms: Process A8 completed I/O; added to ready queue [Q B9 B4 B8 B3 B1 B7 A9 A6 A3 B2 B0 A0 A1 A7 B5 A8]
time 44880ms: Process A2 completed a CPU burst; 23 bursts to go [Q B9 B4 B8 B3 B1 B7 A9 A6 A3 B2 B0 A0 A1 A7 B5 A8]
time 44880ms: Process A2 switching out of CPU; blocking on I/O until time 45004ms [Q B9 B4 B8 B3 B1 B7 A9 A6 A3 B2 B0 A0 A1 A7 B5 A8]
time 44884ms: Process B9 started using the CPU for 148ms burst [Q B4 B8 B3 B1 B7 A9 A6 A3 B2 B0 A0 A1 A7 B5 A8]
time 45004ms: Process A2 completed I/O; added to ready queue [Q B4 B8 B3 B1 B7 A9 A6 A3 B2 B0 A0 A1 A7 B5 A8 A2]
time 45032ms: Process B9 completed a CPU burst; 4 bursts to go [Q B4 B8 B3 B1 B7 A9 A6 A3 B2 B0 A0 A1 A7 B5 A8 A2]
time 45032ms: Process B9 switching out of CPU; blocking on I/O until time 45522ms [Q B4 B8 B3 B1 B7 A9 A6 A3 B2 B0 A0 A1 A7 B5 A8 A2]
time 45036ms: Process B4 started using the CPU for 264ms burst [Q B8 B3 B1 B7 A9 A6 A3 B2 B0 A0 A1 A7 B5 A8 A2]
time 45300ms: Process B4 completed a CPU burst; 8 bursts to go [Q B8 B3 B1 B7 A9 A6 A3 B2 B0 A0 A1 A7 B5 A8 A2]
time 45300ms: Process B4 switching out of CPU; blocking on I/O until time 45726ms [Q B8 B3 B1 B7 A9 A6 A3 B2 B0 A0 A1 A7 B5 A8 A2]
time 45304ms: Process B8 started using the CPU for 13ms burst [Q B3 B1 B7 A9 A6 A3 B2 B0 A0 A1 A7 B5 A8 A2]
time 45317ms: Process B8 completed a CPU burst; 14 bursts to go [Q B3 B1 B7 A9 A6 A3 B2 B0 A0 A1 A7 B5 A8 A2]
time 45317ms: Process B8 switching out of CPU; blocking on I/O until time 45759ms [Q B3 B1 B7 A9 A6 A3 B2 B0 A0 A1 A7 B5 A8 A2]
time 45321ms: Process B3 started using the CPU for 244ms burst [Q B1 B7 A9 A6 A3 B2 B0 A0 A1 A7 B5 A8 A2]
time 45522ms: Process B9 completed I/O; added to ready queue [Q B1 B7 A9 A6 A3 B2 B0 A0 A1 A7 B5 A8 A2 B9]
time 45565ms: Process B3 completed a CPU burst; 15 bursts to go [Q B1 B7 A9 A6 A3 B2 B0 A0 A1 A7 B5 A8 A2 B9]
time 45565ms: Process B3 switching out of CPU; blocking on I/O until time 45938ms [Q B1 B7 A9 A6 A3 B2 B0 A0 A1 A7 B5 A8 A2 B9]
time 45569ms: Process B1 started using the CPU for 620ms burst [Q B7 A9 A6 A3 B2 B0 A0 A1 A7 B5 A8 A2 B9]
time 45726ms: Process B4 completed I/O; added to ready queue [Q B7 A9 A6 A3 B2 B0 A0 A1 A7 B5 A8 A2 B9 B4]
time 45759ms: Process B8 completed I/O; added to ready queue [Q B7 A9 A6 A3 B2 B0 A0 A1 A7 B5 A8 A2 B9 B4 B8]
time 45938ms: Process B3 completed I/O; added to ready queue [Q B7 A9 A6 A3 B2 B0 A0 A1 A7 B5 A8 A2 B9 B4 B8 B3]
time 46189ms: Process B1 completed a CPU burst; 9 bursts to go [Q B7 A9 A6 A3 B2 B0 A0 A1 A7 B5 A8 A2 B9 B4 B8 B3]
time 46189ms: Process B1 switching out of CPU; blocking on I/O until time 46373ms [Q B7 A9 A6 A3 B2 B0 A0 A1 A7 B5 A8 A2 B9 B4 B8 B3]
time 46193ms: Process B7 started using the CPU for 24ms burst [Q A9 A6 A3 B2 B0 A0 A1 A7 B5 A8 A2 B9 B4 B8 B3]
time 46217ms: Process B7 completed a CPU burst; 20 bursts to go [Q A9 A6 A3 B2 B0 A0 A1 A7 B5 A8 A2 B9 B4 B8 B3]
time 46217ms: Process B7 switching out of CPU; blocking on I/O until time 48483ms [Q A9 A6 A3 B2 B0 A0 A1 A7 B5 A8 A2 B9 B4 B8 B3]
time 46221ms: Process A9 started using the CPU for 72ms burst [Q A6 A3 B2 B0 A0 A1 A7 B5 A8 A2 B9 B4 B8 B3]
time 46293ms: Process A9 completed a CPU burst; 24 bursts to go [Q A6 A3 B2 B0 A0 A1 A7 B5 A8 A2 B9 B4 B8 B3]
time 46293ms: Process A9 switching out of CPU; blocking on I/O until time 46334ms [Q A6 A3 B2 B0 A0 A1 A7 B5 A8 A2 B9 B4 B8 B3]
time 46297ms: Process A6 started using the CPU for 84ms burst [Q A3 B2 B0 A0 A1 A7 B5 A8 A2 B9 B4 B8 B3]
time 46334ms: Process A9 completed I/O; added to ready queue [Q A3 B2 B0 A0 A1 A7 B5 A8 A2 B9 B4 B8 B3 A9]
time 46373ms: Process B1 completed I/O; added to ready queue [Q A3 B2 B0 A0 A1 A7 B5 A8 A2 B9 B4 B8 B3 A9 B1]
time 46381ms: Process A6 completed a CPU burst; 10 bursts to go [Q A3 B2 B0 A0 A1 A7 B5 A8 A2 B9 B4 B8 B3 A9 B1]
time 46381ms: Process A6 switching out of CPU; blocking on I/O until time 46400ms [Q A3 B2 B0 A0 A1 A7 B5 A8 A2 B9 B4 B8 B3 A9 B1]
time 46385ms: Process A3 started using the CPU for 580ms burst [Q B2 B0 A0 A1 A7 B5 A8 A2 B9 B4 B8 B3 A9 B1]
time 46400ms: Process A6 completed I/O; added to ready queue [Q B2 B0 A0 A1 A7 B5 A8 A2 B9 B4 B8 B3 A9 B1 A6]
time 46965ms: Process A3 completed a CPU burst; 19 bursts to go [Q B2 B0 A0 A1 A7 B5 A8 A2 B9 B4 B8 B3 A9 B1 A6]
time 46965ms: Process A3 switching out of CPU; blocking on I/O until time 46972ms [Q B2 B0 A0 A1 A7 B5 A8 A2 B9 B4 B8 B3 A9 B1 A6]
time 46969ms: Process B2 started using the CPU for 324ms burst [Q B0 A0 A1 A7 B5 A8 A2 B9 B4 B8 B3 A9 B1 A6]
time 46972ms: Process A3 completed I/O; added to ready queue [Q B0 A0 A1 A7 B5 A8 A2 B9 B4 B8 B3 A9 B1 A6 A3]
time 47293ms: Process B2 completed a CPU burst; 7 bursts to go [Q B0 A0 A1 A7 B5 A8 A2 B9 B4 B8 B3 A9 B1 A6 A3]
time 47293ms: Process B2 switching out of CPU; blocking on I/O until time 47338ms [Q B0 A0 A1 A7 B5 A8 A2 B9 B4 B8 B3 A9 B1 A6 A3]
time 47297ms: Process B0 started using the CPU for 136ms burst [Q A0 A1 A7 B5 A8 A2 B9 B4 B8 B3 A9 B1 A6 A3]
time 47338ms: Process B2 completed I/O; added to ready queue [Q A0 A1 A7 B5 A8 A2 B9 B4 B8 B3 A9 B1 A6 A3 B2]
time 47433ms: Process B0 completed a CPU burst; 11 bursts to go [Q A0 A1 A7 B5 A8 A2 B9 B4 B8 B3 A9 B1 A6 A3 B2]
time 47433ms: Process B0 switching out of CPU; blocking on I/O until time 47441ms [Q A0 A1 A7 B5 A8 A2 B9 B4 B8 B3 A9 B1 A6 A3 B2]
time 47437ms: Process A0 started using the CPU for 268ms burst [Q A1 A7 B5 A8 A2 B9 B4 B8 B3 A9 B1 A6 A3 B2]
time 47441ms: Process B0 completed I/O; added to ready queue [Q A1 A7 B5 A8 A2 B9 B4 B8 B3 A9 B1 A6 A3 B2 B0]
time 47705ms: Process A0 completed a CPU burst; 22 bursts to go [Q A1 A7 B5 A8 A2 B9 B4 B8 B3 A9 B1 A6 A3 B2 B0]
time 47705ms: Process A0 switching out of CPU; blocking on I/O until time 47759ms [Q A1 A7 B5 A8 A2 B9 B4 B8 B3 A9 B1 A6 A3 B2 B0]
time 47709ms: Process A1 started using the CPU for 600ms burst [Q A7 B5 A8 A2 B9 B4 B8 B3 A9 B1 A6 A3 B2 B0]
time 47759ms: Process A0 completed I/O; added to ready queue [Q A7 B5 A8 A2 B9 B4 B8 B3 A9 B1 A6 A3 B2 B0 A0]
time 48309ms: Process A1 completed a CPU burst; 4 bursts to go [Q A7 B5 A8 A2 B9 B4 B8 B3 A9 B1 A6 A3 B2 B0 A0]
time 48309ms: Process A1 switching out of CPU; blocking on I/O until time 48412ms [Q A7 B5 A8 A2 B9 B4 B8 B3 A9 B1 A6 A3 B2 B0 A0]
time 48313ms: Process A7 started using the CPU for 524ms burst [Q B5 A8 A2 B9 B4 B8 B3 A9 B1 A6 A3 B2 B0 A0]
time 48412ms: Process A1 completed I/O; added to ready queue [Q B5 A8 A2 B9 B4 B8 B3 A9 B1 A6 A3 B2 B0 A0 A1]
time 48483ms: Process B7 completed I/O; added to ready queue [Q B5 A8 A2 B9 B4 B8 B3 A9 B1 A6 A3 B2 B0 A0 A1 B7]
time 48837ms: Process A7 completed a CPU burst; 11 bursts to go [Q B5 A8 A2 B9 B4 B8 B3 A9 B1 A6 A3 B2 B0 A0 A1 B7]
time 48837ms: Process A7 switching out of CPU; blocking on I/O until time 48911ms [Q B5 A8 A2 B9 B4 B8 B3 A9 B1 A6 A3 B2 B0 A0 A1 B7]
time 48841ms: Process B5 started using the CPU for 288ms burst [Q A8 A2 B9 B4 B8 B3 A9 B1 A6 A3 B2 B0 A0 A1 B7]
time 48911ms: Process A7 completed I/O; added to ready queue [Q A8 A2 B9 B4 B8 B3 A9 B1 A6 A3 B2 B0 A0 A1 B7 A7]
time 49129ms: Process B5 completed a CPU burst; 22 bursts to go [Q A8 A2 B9 B4 B8 B3 A9 B1 A6 A3 B2 B0 A0 A1 B7 A7]
time 49129ms: Process B5 switching out of CPU; blocking on I/O until time 49170ms [Q A8 A2 B9 B4 B8 B3 A9 B1 A6 A3 B2 B0 A0 A1 B7 A7]
time 49133ms: Process A8 started using the CPU for 112ms burst [Q A2 B9 B4 B8 B3 A9 B1 A6 A3 B2 B0 A0 A1 B7 A7]
time 49170ms: Process B5 completed I/O; added to ready queue [Q A2 B9 B4 B8 B3 A9 B1 A6 A3 B2 B0 A0 A1 B7 A7 B5]
time 49245ms: Process A8 terminated [Q A2 B9 B4 B8 B3 A9 B1 A6 A3 B2 B0 A0 A1 B7 A7 B5]
time 49249ms: Process A2 started using the CPU for 284ms burst [Q B9 B4 B8 B3 A9 B1 A6 A3 B2 B0 A0 A1 B7 A7 B5]
time 49533ms: Process A2 completed a CPU burst; 22 bursts to go [Q B9 B4 B8 B3 A9 B1 A6 A3 B2 B0 A0 A1 B7 A7 B5]
time 49533ms: Process A2 switching out of CPU; blocking on I/O until time 49560ms [Q B9 B4 B8 B3 A9 B1 A6 A3 B2 B0 A0 A1 B7 A7 B5]
time 49537ms: Process B9 started using the CPU for 159ms burst [Q B4 B8 B3 A9 B1 A6 A3 B2 B0 A0 A1 B7 A7 B5]
time 49560ms: Process A2 completed I/O; added to ready queue [Q B4 B8 B3 A9 B1 A6 A3 B2 B0 A0 A1 B7 A7 B5 A2]
time 49696ms: Process B9 completed a CPU burst; 3 bursts to go [Q B4 B8 B3 A9 B1 A6 A3 B2 B0 A0 A1 B7 A7 B5 A2]
time 49696ms: Process B9 switching out of CPU; blocking on I/O until time 50482ms [Q B4 B8 B3 A9 B1 A6 A3 B2 B0 A0 A1 B7 A7 B5 A2]
time 49700ms: Process B4 started using the CPU for 176ms burst [Q B8 B3 A9 B1 A6 A3 B2 B0 A0 A1 B7 A7 B5 A2]
time 49876ms: Process B4 completed a CPU burst; 7 bursts to go [Q B8 B3 A9 B1 A6 A3 B2 B0 A0 A1 B7 A7 B5 A2]
time 49876ms: Process B4 switching out of CPU; blocking on I/O until time 50046ms [Q B8 B3 A9 B1 A6 A3 B2 B0 A0 A1 B7 A7 B5 A2]
time 49880ms: Process B8 started using the CPU for 14ms burst [Q B3 A9 B1 A6 A3 B2 B0 A0 A1 B7 A7 B5 A2]
time 49894ms: Process B8 completed a CPU burst; 13 bursts to go [Q B3 A9 B1 A6 A3 B2 B0 A0 A1 B7 A7 B5 A2]
time 49894ms: Process B8 switching out of CPU; blocking on I/O until time 50088ms [Q B3 A9 B1 A6 A3 B2 B0 A0 A1 B7 A7 B5 A2]
time 49898ms: Process B3 started using the CPU for 40ms burst [Q A9 B1 A6 A3 B2 B0 A0 A1 B7 A7 B5 A2]
time 49938ms: Process B3 completed a CPU burst; 14 bursts to go [Q A9 B1 A6 A3 B2 B0 A0 A1 B7 A7 B5 A2]
time 49938ms: Process B3 switching out of CPU; blocking on I/O until time 50032ms [Q A9 B1 A6 A3 B2 B0 A0 A1 B7 A7 B5 A2]
time 49942ms: Process A9 started using the CPU for 316ms burst [Q B1 A6 A3 B2 B0 A0 A1 B7 A7 B5 A2]
time 50032ms: Process B3 completed I/O; added to ready queue [Q B1 A6 A3 B2 B0 A0 A1 B7 A7 B5 A2 B3]
time 50046ms: Process B4 completed I/O; added to ready queue [Q B1 A6 A3 B2 B0 A0 A1 B7 A7 B5 A2 B3 B4]
time 50088ms: Process B8 completed I/O; added to ready queue [Q B1 A6 A3 B2 B0 A0 A1 B7 A7 B5 A2 B3 B4 B8]
time 50258ms: Process A9 completed a CPU burst; 23 bursts to go [Q B1 A6 A3 B2 B0 A0 A1 B7 A7 B5 A2 B3 B4 B8]
time 50258ms: Process A9 switching out of CPU; blocking on I/O until time 50300ms [Q B1 A6 A3 B2 B0 A0 A1 B7 A7 B5 A2 B3 B4 B8]
time 50262ms: Process B1 started using the CPU for 2136ms burst [Q A6 A3 B2 B0 A0 A1 B7 A7 B5 A2 B3 B4 B8]
time 50300ms: Process A9 completed I/O; added to ready queue [Q A6 A3 B2 B0 A0 A1 B7 A7 B5 A2 B3 B4 B8 A9]
time 50482ms: Process B9 completed I/O; added to ready queue [Q A6 A3 B2 B0 A0 A1 B7 A7 B5 A2 B3 B4 B8 A9 B9]
time 52398ms: Process B1 completed a CPU burst; 8 bursts to go [Q A6 A3 B2 B0 A0 A1 B7 A7 B5 A2 B3 B4 B8 A9 B9]
time 52398ms: Process B1 switching out of CPU; blocking on I/O until time 52579ms [Q A6 A3 B2 B0 A0 A1 B7 A7 B5 A2 B3 B4 B8 A9 B9]
time 52402ms: Process A6 started using the CPU for 1312ms burst [Q A3 B2 B0 A0 A1 B7 A7 B5 A2 B3 B4 B8 A9 B9]
time 52579ms: Process B1 completed I/O; added to ready queue [Q A3 B2 B0 A0 A1 B7 A7 B5 A2 B3 B4 B8 A9 B9 B1]
time 53714ms: Process A6 completed a CPU burst; 9 bursts to go [Q A3 B2 B0 A0 A1 B7 A7 B5 A2 B3 B4 B8 A9 B9 B1]
time 53714ms: Process A6 switching out of CPU; blocking on I/O until time 53782ms [Q A3 B2 B0 A0 A1 B7 A7 B5 A2 B3 B4 B8 A9 B9 B1]
time 53718ms: Process A3 started using the CPU for 72ms burst [Q B2 B0 A0 A1 B7 A7 B5 A2 B3 B4 B8 A9 B9 B1]
time 53782ms: Process A6 completed I/O; added to ready queue [Q B2 B0 A0 A1 B7 A7 B5 A2 B3 B4 B8 A9 B9 B1 A6]
time 53790ms: Process A3 completed a CPU burst; 18 bursts to go [Q B2 B0 A0 A1 B7 A7 B5 A2 B3 B4 B8 A9 B9 B1 A6]
time 53790ms: Process A3 switching out of CPU; blocking on I/O until time 53869ms [Q B2 B0 A0 A1 B7 A7 B5 A2 B3 B4 B8 A9 B9 B1 A6]
time 53794ms: Process B2 started using the CPU for 112ms burst [Q B0 A0 A1 B7 A7 B5 A2 B3 B4 B8 A9 B9 B1 A6]
time 53869ms: Process A3 completed I/O; added to ready queue [Q B0 A0 A1 B7 A7 B5 A2 B3 B4 B8 A9 B9 B1 A6 A3]
time 53906ms: Process B2 completed a CPU burst; 6 bursts to go [Q B0 A0 A1 B7 A7 B5 A2 B3 B4 B8 A9 B9 B1 A6 A3]
time 53906ms: Process B2 switching out of CPU; blocking on I/O until time 53983ms [Q B0 A0 A1 B7 A7 B5 A2 B3 B4 B8 A9 B9 B1 A6 A3]
time 53910ms: Process B0 started using the CPU for 948ms burst [Q A0 A1 B7 A7 B5 A2 B3 B4 B8 A9 B9 B1 A6 A3]
time 53983ms: Process B2 completed I/O; added to ready queue [Q A0 A1 B7 A7 B5 A2 B3 B4 B8 A9 B9 B1 A6 A3 B2]
time 54858ms: Process B0 completed a CPU burst; 10 bursts to go [Q A0 A1 B7 A7 B5 A2 B3 B4 B8 A9 B9 B1 A6 A3 B2]
time 54858ms: Process B0 switching out of CPU; blocking on I/O until time 54862ms [Q A0 A1 B7 A7 B5 A2 B3 B4 B8 A9 B9 B1 A6 A3 B2]
time 54862ms: Process A0 started using the CPU for 412ms burst [Q A1 B7 A7 B5 A2 B3 B4 B8 A9 B9 B1 A6 A3 B2]
time 54862ms: Process B0 completed I/O; added to ready queue [Q A1 B7 A7 B5 A2 B3 B4 B8 A9 B9 B1 A6 A3 B2 B0]
time 55274ms: Process A0 completed a CPU burst; 21 bursts to go [Q A1 B7 A7 B5 A2 B3 B4 B8 A9 B9 B1 A6 A3 B2 B0]
time 55274ms: Process A0 switching out of CPU; blocking on I/O until time 55359ms [Q A1 B7 A7 B5 A2 B3 B4 B8 A9 B9 B1 A6 A3 B2 B0]
time 55278ms: Process A1 started using the CPU for 180ms burst [Q B7 A7 B5 A2 B3 B4 B8 A9 B9 B1 A6 A3 B2 B0]
time 55359ms: Process A0 completed I/O; added to ready queue [Q B7 A7 B5 A2 B3 B4 B8 A9 B9 B1 A6 A3 B2 B0 A0]
time 55458ms: Process A1 completed a CPU burst; 3 bursts to go [Q B7 A7 B5 A2 B3 B4 B8 A9 B9 B1 A6 A3 B2 B0 A0]
time 55458ms: Process A1 switching out of CPU; blocking on I/O until time 55527ms [Q B7 A7 B5 A2 B3 B4 B8 A9 B9 B1 A6 A3 B2 B0 A0]
time 55462ms: Process B7 started using the CPU for 11ms burst [Q A7 B5 A2 B3 B4 B8 A9 B9 B1 A6 A3 B2 B0 A0]
time 55473ms: Process B7 completed a CPU burst; 19 bursts to go [Q A7 B5 A2 B3 B4 B8 A9 B9 B1 A6 A3 B2 B0 A0]
time 55473ms: Process B7 switching out of CPU; blocking on I/O until time 55595ms [Q A7 B5 A2 B3 B4 B8 A9 B9 B1 A6 A3 B2 B0 A0]
time 55477ms: Process A7 started using the CPU for 484ms burst [Q B5 A2 B3 B4 B8 A9 B9 B1 A6 A3 B2 B0 A0]
time 55527ms: Process A1 completed I/O; added to ready queue [Q B5 A2 B3 B4 B8 A9 B9 B1 A6 A3 B2 B0 A0 A1]
time 55595ms: Process B7 completed I/O; added to ready queue [Q B5 A2 B3 B4 B8 A9 B9 B1 A6 A3 B2 B0 A0 A1 B7]
time 55961ms: Process A7 completed a CPU burst; 10 bursts to go [Q B5 A2 B3 B4 B8 A9 B9 B1 A6 A3 B2 B0 A0 A1 B7]
time 55961ms: Process A7 switching out of CPU; blocking on I/O until time 56000ms [Q B5 A2 B3 B4 B8 A9 B9 B1 A6 A3 B2 B0 A0 A1 B7]
time 55965ms: Process B5 started using the CPU for 776ms burst [Q A2 B3 B4 B8 A9 B9 B1 A6 A3 B2 B0 A0 A1 B7]
time 56000ms: Process A7 completed I/O; added to ready queue [Q A2 B3 B4 B8 A9 B9 B1 A6 A3 B2 B0 A0 A1 B7 A7]
time 56741ms: Process B5 completed a CPU burst; 21 bursts to go [Q A2 B3 B4 B8 A9 B9 B1 A6 A3 B2 B0 A0 A1 B7 A7]
time 56741ms: Process B5 switching out of CPU; blocking on I/O until time 56748ms [Q A2 B3 B4 B8 A9 B9 B1 A6 A3 B2 B0 A0 A1 B7 A7]
time 56745ms: Process A2 started using the CPU for 524ms burst [Q B3 B4 B8 A9 B9 B1 A6 A3 B2 B0 A0 A1 B7 A7]
time 56748ms: Process B5 completed I/O; added to ready queue [Q B3 B4 B8 A9 B9 B1 A6 A3 B2 B0 A0 A1 B7 A7 B5]
time 57269ms: Process A2 completed a CPU burst; 21 bursts to go [Q B3 B4 B8 A9 B9 B1 A6 A3 B2 B0 A0 A1 B7 A7 B5]
time 57269ms: Process A2 switching out of CPU; blocking on I/O until time 57457ms [Q B3 B4 B8 A9 B9 B1 A6 A3 B2 B0 A0 A1 B7 A7 B5]
time 57273ms: Process B3 started using the CPU for 356ms burst [Q B4 B8 A9 B9 B1 A6 A3 B2 B0 A0 A1 B7 A7 B5]
time 57457ms: Process A2 completed I/O; added to ready queue [Q B4 B8 A9 B9 B1 A6 A3 B2 B0 A0 A1 B7 A7 B5 A2]
time 57629ms: Process B3 completed a CPU burst; 13 bursts to go [Q B4 B8 A9 B9 B1 A6 A3 B2 B0 A0 A1 B7 A7 B5 A2]
time 57629ms: Process B3 switching out of CPU; blocking on I/O until time 57687ms [Q B4 B8 A9 B9 B1 A6 A3 B2 B0 A0 A1 B7 A7 B5 A2]
time 57633ms: Process B4 started using the CPU for 104ms burst [Q B8 A9 B9 B1 A6 A3 B2 B0 A0 A1 B7 A7 B5 A2]
time 57687ms: Process B3 completed I/O; added to ready queue [Q B8 A9 B9 B1 A6 A3 B2 B0 A0 A1 B7 A7 B5 A2 B3]
time 57737ms: Process B4 completed a CPU burst; 6 bursts to go [Q B8 A9 B9 B1 A6 A3 B2 B0 A0 A1 B7 A7 B5 A2 B3]
time 57737ms: Process B4 switching out of CPU; blocking on I/O until time 57746ms [Q B8 A9 B9 B1 A6 A3 B2 B0 A0 A1 B7 A7 B5 A2 B3]
time 57741ms: Process B8 started using the CPU for 32ms burst [Q A9 B9 B1 A6 A3 B2 B0 A0 A1 B7 A7 B5 A2 B3]
time 57746ms: Process B4 completed I/O; added to ready queue [Q A9 B9 B1 A6 A3 B2 B0 A0 A1 B7 A7 B5 A2 B3 B4]
time 57773ms: Process B8 completed a CPU burst; 12 bursts to go [Q A9 B9 B1 A6 A3 B2 B0 A0 A1 B7 A7 B5 A2 B3 B4]
time 57773ms: Process B8 switching out of CPU; blocking on I/O until time 58199ms [Q A9 B9 B1 A6 A3 B2 B0 A0 A1 B7 A7 B5 A2 B3 B4]
time 57777ms: Process A9 started using the CPU for 464ms burst [Q B9 B1 A6 A3 B2 B0 A0 A1 B7 A7 B5 A2 B3 B4]
time 58199ms: Process B8 completed I/O; added to ready queue [Q B9 B1 A6 A3 B2 B0 A0 A1 B7 A7 B5 A2 B3 B4 B8]
time 58241ms: Process A9 completed a CPU burst; 22 bursts to go [Q B9 B1 A6 A3 B2 B0 A0 A1 B7 A7 B5 A2 B3 B4 B8]
time 58241ms: Process A9 switching out of CPU; blocking on I/O until time 58247ms [Q B9 B1 A6 A3 B2 B0 A0 A1 B7 A7 B5 A2 B3 B4 B8]
time 58245ms: Process B9 started using the CPU for 77ms burst [Q B1 A6 A3 B2 B0 A0 A1 B7 A7 B5 A2 B3 B4 B8]
time 58247ms: Process A9 completed I/O; added to ready queue [Q B1 A6 A3 B2 B0 A0 A1 B7 A7 B5 A2 B3 B4 B8 A9]
time 58322ms: Process B9 completed a CPU burst; 2 bursts to go [Q B1 A6 A3 B2 B0 A0 A1 B7 A7 B5 A2 B3 B4 B8 A9]
time 58322ms: Process B9 switching out of CPU; blocking on I/O until time 59668ms [Q B1 A6 A3 B2 B0 A0 A1 B7 A7 B5 A2 B3 B4 B8 A9]
time 58326ms: Process B1 started using the CPU for 76ms burst [Q A6 A3 B2 B0 A0 A1 B7 A7 B5 A2 B3 B4 B8 A9]
time 58402ms: Process B1 completed a CPU burst; 7 bursts to go [Q A6 A3 B2 B0 A0 A1 B7 A7 B5 A2 B3 B4 B8 A9]
time 58402ms: Process B1 switching out of CPU; blocking on I/O until time 58442ms [Q A6 A3 B2 B0 A0 A1 B7 A7 B5 A2 B3 B4 B8 A9]
time 58406ms: Process A6 started using the CPU for 132ms burst [Q A3 B2 B0 A0 A1 B7 A7 B5 A2 B3 B4 B8 A9]
time 58442ms: Process B1 completed I/O; added to ready queue [Q A3 B2 B0 A0 A1 B7 A7 B5 A2 B3 B4 B8 A9 B1]
time 58538ms: Process A6 completed a CPU burst; 8 bursts to go [Q A3 B2 B0 A0 A1 B7 A7 B5 A2 B3 B4 B8 A9 B1]
time 58538ms: Process A6 switching out of CPU; blocking on I/O until time 58552ms [Q A3 B2 B0 A0 A1 B7 A7 B5 A2 B3 B4 B8 A9 B1]
time 58542ms: Process A3 started using the CPU for 440ms burst [Q B2 B0 A0 A1 B7 A7 B5 A2 B3 B4 B8 A9 B1]
time 58552ms: Process A6 completed I/O; added to ready queue [Q B2 B0 A0 A1 B7 A7 B5 A2 B3 B4 B8 A9 B1 A6]
time 58982ms: Process A3 completed a CPU burst; 17 bursts to go [Q B2 B0 A0 A1 B7 A7 B5 A2 B3 B4 B8 A9 B1 A6]
time 58982ms: Process A3 switching out of CPU; blocking on I/O until time 59043ms [Q B2 B0 A0 A1 B7 A7 B5 A2 B3 B4 B8 A9 B1 A6]
time 58986ms: Process B2 started using the CPU for 412ms burst [Q B0 A0 A1 B7 A7 B5 A2 B3 B4 B8 A9 B1 A6]
time 59043ms: Process A3 completed I/O; added to ready queue [Q B0 A0 A1 B7 A7 B5 A2 B3 B4 B8 A9 B1 A6 A3]
time 59398ms: Process B2 completed a CPU burst; 5 bursts to go [Q B0 A0 A1 B7 A7 B5 A2 B3 B4 B8 A9 B1 A6 A3]
time 59398ms: Process B2 switching out of CPU; blocking on I/O until time 59411ms [Q B0 A0 A1 B7 A7 B5 A2 B3 B4 B8 A9 B1 A6 A3]
time 59402ms: Process B0 started using the CPU for 336ms burst [Q A0 A1 B7 A7 B5 A2 B3 B4 B8 A9 B1 A6 A3]
time 59411ms: Process B2 completed I/O; added to ready queue [Q A0 A1 B7 A7 B5 A2 B3 B4 B8 A9 B1 A6 A3 B2]
time 59668ms: Process B9 completed I/O; added to ready queue [Q A0 A1 B7 A7 B5 A2 B3 B4 B8 A9 B1 A6 A3 B2 B9]
time 59738ms: Process B0 completed a CPU burst; 9 bursts to go [Q A0 A1 B7 A7 B5 A2 B3 B4 B8 A9 B1 A6 A3 B2 B9]
time 59738ms: Process B0 switching out of CPU; blocking on I/O until time 59801ms [Q A0 A1 B7 A7 B5 A2 B3 B4 B8 A9 B1 A6 A3 B2 B9]
time 59742ms: Process A0 started using the CPU for 124ms burst [Q A1 B7 A7 B5 A2 B3 B4 B8 A9 B1 A6 A3 B2 B9]
time 59801ms: Process B0 completed I/O; added to ready queue [Q A1 B7 A7 B5 A2 B3 B4 B8 A9 B1 A6 A3 B2 B9 B0]
time 59866ms: Process A0 completed a CPU burst; 20 bursts to go [Q A1 B7 A7 B5 A2 B3 B4 B8 A9 B1 A6 A3 B2 B9 B0]
time 59866ms: Process A0 switching out of CPU; blocking on I/O until time 60216ms [Q A1 B7 A7 B5 A2 B3 B4 B8 A9 B1 A6 A3 B2 B9 B0]
time 59870ms: Process A1 started using the CPU for 584ms burst [Q B7 A7 B5 A2 B3 B4 B8 A9 B1 A6 A3 B2 B9 B0]
time 60216ms: Process A0 completed I/O; added to ready queue [Q B7 A7 B5 A2 B3 B4 B8 A9 B1 A6 A3 B2 B9 B0 A0]
time 60454ms: Process A1 completed a CPU burst; 2 bursts to go [Q B7 A7 B5 A2 B3 B4 B8 A9 B1 A6 A3 B2 B9 B0 A0]
time 60454ms: Process A1 switching out of CPU; blocking on I/O until time 60687ms [Q B7 A7 B5 A2 B3 B4 B8 A9 B1 A6 A3 B2 B9 B0 A0]
time 60458ms: Process B7 started using the CPU for 140ms burst [Q A7 B5 A2 B3 B4 B8 A9 B1 A6 A3 B2 B9 B0 A0]
time 60598ms: Process B7 completed a CPU burst; 18 bursts to go [Q A7 B5 A2 B3 B4 B8 A9 B1 A6 A3 B2 B9 B0 A0]
time 60598ms: Process B7 switching out of CPU; blocking on I/O until time 61256ms [Q A7 B5 A2 B3 B4 B8 A9 B1 A6 A3 B2 B9 B0 A0]
time 60602ms: Process A7 started using the CPU for 24ms burst [Q B5 A2 B3 B4 B8 A9 B1 A6 A3 B2 B9 B0 A0]
time 60626ms: Process A7 completed a CPU burst; 9 bursts to go [Q B5 A2 B3 B4 B8 A9 B1 A6 A3 B2 B9 B0 A0]
time 60626ms: Process A7 switching out of CPU; blocking on I/O until time 60879ms [Q B5 A2 B3 B4 B8 A9 B1 A6 A3 B2 B9 B0 A0]
time 60630ms: Process B5 started using the CPU for 56ms burst [Q A2 B3 B4 B8 A9 B1 A6 A3 B2 B9 B0 A0]
time 60686ms: Process B5 completed a CPU burst; 20 bursts to go [Q A2 B3 B4 B8 A9 B1 A6 A3 B2 B9 B0 A0]
time 60686ms: Process B5 switching out of CPU; blocking on I/O until time 60753ms [Q A2 B3 B4 B8 A9 B1 A6 A3 B2 B9 B0 A0]
time 60687ms: Process A1 completed I/O; added to ready queue [Q A2 B3 B4 B8 A9 B1 A6 A3 B2 B9 B0 A0 A1]
time 60690ms: Process A2 started using the CPU for 460ms burst [Q B3 B4 B8 A9 B1 A6 A3 B2 B9 B0 A0 A1]
time 60753ms: Process B5 completed I/O; added to ready queue [Q B3 B4 B8 A9 B1 A6 A3 B2 B9 B0 A0 A1 B5]
time 60879ms: Process A7 completed I/O; added to ready queue [Q B3 B4 B8 A9 B1 A6 A3 B2 B9 B0 A0 A1 B5 A7]
time 61150ms: Process A2 completed a CPU burst; 20 bursts to go [Q B3 B4 B8 A9 B1 A6 A3 B2 B9 B0 A0 A1 B5 A7]
time 61150ms: Process A2 switching out of CPU; blocking on I/O until time 61408ms [Q B3 B4 B8 A9 B1 A6 A3 B2 B9 B0 A0 A1 B5 A7]
time 61154ms: Process B3 started using the CPU for 20ms burst [Q B4 B8 A9 B1 A6 A3 B2 B9 B0 A0 A1 B5 A7]
time 61174ms: Process B3 completed a CPU burst; 12 bursts to go [Q B4 B8 A9 B1 A6 A3 B2 B9 B0 A0 A1 B5 A7]
time 61174ms: Process B3 switching out of CPU; blocking on I/O until time 61394ms [Q B4 B8 A9 B1 A6 A3 B2 B9 B0 A0 A1 B5 A7]
time 61178ms: Process B4 started using the CPU for 32ms burst [Q B8 A9 B1 A6 A3 B2 B9 B0 A0 A1 B5 A7]
time 61210ms: Process B4 completed a CPU burst; 5 bursts to go [Q B8 A9 B1 A6 A3 B2 B9 B0 A0 A1 B5 A7]
time 61210ms: Process B4 switching out of CPU; blocking on I/O until time 61436ms [Q B8 A9 B1 A6 A3 B2 B9 B0 A0 A1 B5 A7]
time 61214ms: Process B8 started using the CPU for 33ms burst [Q A9 B1 A6 A3 B2 B9 B0 A0 A1 B5 A7]
time 61247ms: Process B8 completed a CPU burst; 11 bursts to go [Q A9 B1 A6 A3 B2 B9 B0 A0 A1 B5 A7]
time 61247ms: Process B8 switching out of CPU; blocking on I/O until time 61617ms [Q A9 B1 A6 A3 B2 B9 B0 A0 A1 B5 A7]
time 61251ms: Process A9 started using the CPU for 712ms burst [Q B1 A6 A3 B2 B9 B0 A0 A1 B5 A7]
time 61256ms: Process B7 completed I/O; added to ready queue [Q B1 A6 A3 B2 B9 B0 A0 A1 B5 A7 B7]
time 61394ms: Process B3 completed I/O; added to ready queue [Q B1 A6 A3 B2 B9 B0 A0 A1 B5 A7 B7 B3]
time 61408ms: Process A2 completed I/O; added to ready queue [Q B1 A6 A3 B2 B9 B0 A0 A1 B5 A7 B7 B3 A2]
time 61436ms: Process B4 completed I/O; added to ready queue [Q B1 A6 A3 B2 B9 B0 A0 A1 B5 A7 B7 B3 A2 B4]
time 61617ms: Process B8 completed I/O; added to ready queue [Q B1 A6 A3 B2 B9 B0 A0 A1 B5 A7 B7 B3 A2 B4 B8]
time 61963ms: Process A9 completed a CPU burst; 21 bursts to go [Q B1 A6 A3 B2 B9 B0 A0 A1 B5 A7 B7 B3 A2 B4 B8]
time 61963ms: Process A9 switching out of CPU; blocking on I/O until time 62014ms [Q B1 A6 A3 B2 B9 B0 A0 A1 B5 A7 B7 B3 A2 B4 B8]
time 61967ms: Process B1 started using the CPU for 112ms burst [Q A6 A3 B2 B9 B0 A0 A1 B5 A7 B7 B3 A2 B4 B8]
time 62014ms: Process A9 completed I/O; added to ready queue [Q A6 A3 B2 B9 B0 A0 A1 B5 A7 B7 B3 A2 B4 B8 A9]
time 62079ms: Process B1 completed a CPU burst; 6 bursts to go [Q A6 A3 B2 B9 B0 A0 A1 B5 A7 B7 B3 A2 B4 B8 A9]
time 62079ms: Process B1 switching out of CPU; blocking on I/O until time 62208ms [Q A6 A3 B2 B9 B0 A0 A1 B5 A7 B7 B3 A2 B4 B8 A9]
time 62083ms: Process A6 started using the CPU for 780ms burst [Q A3 B2 B9 B0 A0 A1 B5 A7 B7 B3 A2 B4 B8 A9]
time 62208ms: Process B1 completed I/O; added to ready queue [Q A3 B2 B9 B0 A0 A1 B5 A7 B7 B3 A2 B4 B8 A9 B1]
time 62863ms: Process A6 completed a CPU burst; 7 bursts to go [Q A3 B2 B9 B0 A0 A1 B5 A7 B7 B3 A2 B4 B8 A9 B1]
time 62863ms: Process A6 switching out of CPU; blocking on I/O until time 62885ms [Q A3 B2 B9 B0 A0 A1 B5 A7 B7 B3 A2 B4 B8 A9 B1]
time 62867ms: Process A3 started using the CPU for 252ms burst [Q B2 B9 B0 A0 A1 B5 A7 B7 B3 A2 B4 B8 A9 B1]
time 62885ms: Process A6 completed I/O; added to ready queue [Q B2 B9 B0 A0 A1 B5 A7 B7 B3 A2 B4 B8 A9 B1 A6]
time 63119ms: Process A3 completed a CPU burst; 16 bursts to go [Q B2 B9 B0 A0 A1 B5 A7 B7 B3 A2 B4 B8 A9 B1 A6]
time 63119ms: Process A3 switching out of CPU; blocking on I/O until time 63323ms [Q B2 B9 B0 A0 A1 B5 A7 B7 B3 A2 B4 B8 A9 B1 A6]
time 63123ms: Process B2 started using the CPU for 124ms burst [Q B9 B0 A0 A1 B5 A7 B7 B3 A2 B4 B8 A9 B1 A6]
time 63247ms: Process B2 completed a CPU burst; 4 bursts to go [Q B9 B0 A0 A1 B5 A7 B7 B3 A2 B4 B8 A9 B1 A6]
time 63247ms: Process B2 switching out of CPU; blocking on I/O until time 63361ms [Q B9 B0 A0 A1 B5 A7 B7 B3 A2 B4 B8 A9 B1 A6]
time 63251ms: Process B9 started using the CPU for 35ms burst [Q B0 A0 A1 B5 A7 B7 B3 A2 B4 B8 A9 B1 A6]
time 63286ms: Process B9 completed a CPU burst; 1 burst to go [Q B0 A0 A1 B5 A7 B7 B3 A2 B4 B8 A9 B1 A6]
time 63286ms: Process B9 switching out of CPU; blocking on I/O until time 64072ms [Q B0 A0 A1 B5 A7 B7 B3 A2 B4 B8 A9 B1 A6]
time 63290ms: Process B0 started using the CPU for 432ms burst [Q A0 A1 B5 A7 B7 B3 A2 B4 B8 A9 B1 A6]
time 63323ms: Process A3 completed I/O; added to ready queue [Q A0 A1 B5 A7 B7 B3 A2 B4 B8 A9 B1 A6 A3]
time 63361ms: Process B2 completed I/O; added to ready queue [Q A0 A1 B5 A7 B7 B3 A2 B4 B8 A9 B1 A6 A3 B2]
time 63722ms: Process B0 completed a CPU burst; 8 bursts to go [Q A0 A1 B5 A7 B7 B3 A2 B4 B8 A9 B1 A6 A3 B2]
time 63722ms: Process B0 switching out of CPU; blocking on I/O until time 63751ms [Q A0 A1 B5 A7 B7 B3 A2 B4 B8 A9 B1 A6 A3 B2]
time 63726ms: Process A0 started using the CPU for 208ms burst [Q A1 B5 A7 B7 B3 A2 B4 B8 A9 B1 A6 A3 B2]
time 63751ms: Process B0 completed I/O; added to ready queue [Q A1 B5 A7 B7 B3 A2 B4 B8 A9 B1 A6 A3 B2 B0]
time 63934ms: Process A0 completed a CPU burst; 19 bursts to go [Q A1 B5 A7 B7 B3 A2 B4 B8 A9 B1 A6 A3 B2 B0]
time 63934ms: Process A0 switching out of CPU; blocking on I/O until time 63963ms [Q A1 B5 A7 B7 B3 A2 B4 B8 A9 B1 A6 A3 B2 B0]
time 63938ms: Process A1 started using the CPU for 1032ms burst [Q B5 A7 B7 B3 A2 B4 B8 A9 B1 A6 A3 B2 B0]
time 63963ms: Process A0 completed I/O; added to ready queue [Q B5 A7 B7 B3 A2 B4 B8 A9 B1 A6 A3 B2 B0 A0]
time 64072ms: Process B9 completed I/O; added to ready queue [Q B5 A7 B7 B3 A2 B4 B8 A9 B1 A6 A3 B2 B0 A0 B9]
time 64970ms: Process A1 completed a CPU burst; 1 burst to go [Q B5 A7 B7 B3 A2 B4 B8 A9 B1 A6 A3 B2 B0 A0 B9]
time 64970ms: Process A1 switching out of CPU; blocking on I/O until time 65066ms [Q B5 A7 B7 B3 A2 B4 B8 A9 B1 A6 A3 B2 B0 A0 B9]
time 64974ms: Process B5 started using the CPU for 696ms burst [Q A7 B7 B3 A2 B4 B8 A9 B1 A6 A3 B2 B0 A0 B9]
time 65066ms: Process A1 completed I/O; added to ready queue [Q A7 B7 B3 A2 B4 B8 A9 B1 A6 A3 B2 B0 A0 B9 A1]
time 65670ms: Process B5 completed a CPU burst; 19 bursts to go [Q A7 B7 B3 A2 B4 B8 A9 B1 A6 A3 B2 B0 A0 B9 A1]
time 65670ms: Process B5 switching out of CPU; blocking on I/O until time 65799ms [Q A7 B7 B3 A2 B4 B8 A9 B1 A6 A3 B2 B0 A0 B9 A1]
time 65674ms: Process A7 started using the CPU for 376ms burst [Q B7 B3 A2 B4 B8 A9 B1 A6 A3 B2 B0 A0 B9 A1]
time 65799ms: Process B5 completed I/O; added to ready queue [Q B7 B3 A2 B4 B8 A9 B1 A6 A3 B2 B0 A0 B9 A1 B5]
time 66050ms: Process A7 completed a CPU burst; 8 bursts to go [Q B7 B3 A2 B4 B8 A9 B1 A6 A3 B2 B0 A0 B9 A1 B5]
time 66050ms: Process A7 switching out of CPU; blocking on I/O until time 66054ms [Q B7 B3 A2 B4 B8 A9 B1 A6 A3 B2 B0 A0 B9 A1 B5]
time 66054ms: Process B7 started using the CPU for 317ms burst [Q B3 A2 B4 B8 A9 B1 A6 A3 B2 B0 A0 B9 A1 B5]
time 66054ms: Process A7 completed I/O; added to ready queue [Q B3 A2 B4 B8 A9 B1 A6 A3 B2 B0 A0 B9 A1 B5 A7]
time 66371ms: Process B7 completed a CPU burst; 17 bursts to go [Q B3 A2 B4 B8 A9 B1 A6 A3 B2 B0 A0 B9 A1 B5 A7]
time 66371ms: Process B7 switching out of CPU; blocking on I/O until time 66421ms [Q B3 A2 B4 B8 A9 B1 A6 A3 B2 B0 A0 B9 A1 B5 A7]
time 66375ms: Process B3 started using the CPU for 764ms burst [Q A2 B4 B8 A9 B1 A6 A3 B2 B0 A0 B9 A1 B5 A7]
time 66421ms: Process B7 completed I/O; added to ready queue [Q A2 B4 B8 A9 B1 A6 A3 B2 B0 A0 B9 A1 B5 A7 B7]
time 67139ms: Process B3 completed a CPU burst; 11 bursts to go [Q A2 B4 B8 A9 B1 A6 A3 B2 B0 A0 B9 A1 B5 A7 B7]
time 67139ms: Process B3 switching out of CPU; blocking on I/O until time 67298ms [Q A2 B4 B8 A9 B1 A6 A3 B2 B0 A0 B9 A1 B5 A7 B7]
time 67143ms: Process A2 started using the CPU for 256ms burst [Q B4 B8 A9 B1 A6 A3 B2 B0 A0 B9 A1 B5 A7 B7]
time 67298ms: Process B3 completed I/O; added to ready queue [Q B4 B8 A9 B1 A6 A3 B2 B0 A0 B9 A1 B5 A7 B7 B3]
time 67399ms: Process A2 completed a CPU burst; 19 bursts to go [Q B4 B8 A9 B1 A6 A3 B2 B0 A0 B9 A1 B5 A7 B7 B3]
time 67399ms: Process A2 switching out of CPU; blocking on I/O until time 67425ms [Q B4 B8 A9 B1 A6 A3 B2 B0 A0 B9 A1 B5 A7 B7 B3]
time 67403ms: Process B4 started using the CPU for 28ms burst [Q B8 A9 B1 A6 A3 B2 B0 A0 B9 A1 B5 A7 B7 B3]
time 67425ms: Process A2 completed I/O; added to ready queue [Q B8 A9 B1 A6 A3 B2 B0 A0 B9 A1 B5 A7 B7 B3 A2]
time 67431ms: Process B4 completed a CPU burst; 4 bursts to go [Q B8 A9 B1 A6 A3 B2 B0 A0 B9 A1 B5 A7 B7 B3 A2]
time 67431ms: Process B4 switching out of CPU; blocking on I/O until time 67573ms [Q B8 A9 B1 A6 A3 B2 B0 A0 B9 A1 B5 A7 B7 B3 A2]
time 67435ms: Process B8 started using the CPU for 66ms burst [Q A9 B1 A6 A3 B2 B0 A0 B9 A1 B5 A7 B7 B3 A2]
time 67501ms: Process B8 completed a CPU burst; 10 bursts to go [Q A9 B1 A6 A3 B2 B0 A0 B9 A1 B5 A7 B7 B3 A2]
time 67501ms: Process B8 switching out of CPU; blocking on I/O until time 68775ms [Q A9 B1 A6 A3 B2 B0 A0 B9 A1 B5 A7 B7 B3 A2]
time 67505ms: Process A9 started using the CPU for 1680ms burst [Q B1 A6 A3 B2 B0 A0 B9 A1 B5 A7 B7 B3 A2]
time 67573ms: Process B4 completed I/O; added to ready queue [Q B1 A6 A3 B2 B0 A0 B9 A1 B5 A7 B7 B3 A2 B4]
time 68775ms: Process B8 completed I/O; added to ready queue [Q B1 A6 A3 B2 B0 A0 B9 A1 B5 A7 B7 B3 A2 B4 B8]
time 69185ms: Process A9 completed a CPU burst; 20 bursts to go [Q B1 A6 A3 B2 B0 A0 B9 A1 B5 A7 B7 B3 A2 B4 B8]
time 69185ms: Process A9 switching out of CPU; blocking on I/O until time 69219ms [Q B1 A6 A3 B2 B0 A0 B9 A1 B5 A7 B7 B3 A2 B4 B8]
time 69189ms: Process B1 started using the CPU for 392ms burst [Q A6 A3 B2 B0 A0 B9 A1 B5 A7 B7 B3 A2 B4 B8]
time 69219ms: Process A9 completed I/O; added to ready queue [Q A6 A3 B2 B0 A0 B9 A1 B5 A7 B7 B3 A2 B4 B8 A9]
time 69581ms: Process B1 completed a CPU burst; 5 bursts to go [Q A6 A3 B2 B0 A0 B9 A1 B5 A7 B7 B3 A2 B4 B8 A9]
time 69581ms: Process B1 switching out of CPU; blocking on I/O until time 69824ms [Q A6 A3 B2 B0 A0 B9 A1 B5 A7 B7 B3 A2 B4 B8 A9]
time 69585ms: Process A6 started using the CPU for 308ms burst [Q A3 B2 B0 A0 B9 A1 B5 A7 B7 B3 A2 B4 B8 A9]
time 69824ms: Process B1 completed I/O; added to ready queue [Q A3 B2 B0 A0 B9 A1 B5 A7 B7 B3 A2 B4 B8 A9 B1]
time 69893ms: Process A6 completed a CPU burst; 6 bursts to go [Q A3 B2 B0 A0 B9 A1 B5 A7 B7 B3 A2 B4 B8 A9 B1]
time 69893ms: Process A6 switching out of CPU; blocking on I/O until time 69939ms [Q A3 B2 B0 A0 B9 A1 B5 A7 B7 B3 A2 B4 B8 A9 B1]
time 69897ms: Process A3 started using the CPU for 300ms burst [Q B2 B0 A0 B9 A1 B5 A7 B7 B3 A2 B4 B8 A9 B1]
time 69939ms: Process A6 completed I/O; added to ready queue [Q B2 B0 A0 B9 A1 B5 A7 B7 B3 A2 B4 B8 A9 B1 A6]
time 70197ms: Process A3 completed a CPU burst; 15 bursts to go [Q B2 B0 A0 B9 A1 B5 A7 B7 B3 A2 B4 B8 A9 B1 A6]
time 70197ms: Process A3 switching out of CPU; blocking on I/O until time 70295ms [Q B2 B0 A0 B9 A1 B5 A7 B7 B3 A2 B4 B8 A9 B1 A6]
time 70201ms: Process B2 started using the CPU for 680ms burst [Q B0 A0 B9 A1 B5 A7 B7 B3 A2 B4 B8 A9 B1 A6]
time 70295ms: Process A3 completed I/O; added to ready queue [Q B0 A0 B9 A1 B5 A7 B7 B3 A2 B4 B8 A9 B1 A6 A3]
time 70881ms: Process B2 completed a CPU burst; 3 bursts to go [Q B0 A0 B9 A1 B5 A7 B7 B3 A2 B4 B8 A9 B1 A6 A3]
time 70881ms: Process B2 switching out of CPU; blocking on I/O until time 71040ms [Q B0 A0 B9 A1 B5 A7 B7 B3 A2 B4 B8 A9 B1 A6 A3]
time 70885ms: Process B0 started using the CPU for 180ms burst [Q A0 B9 A1 B5 A7 B7 B3 A2 B4 B8 A9 B1 A6 A3]
time 71040ms: Process B2 completed I/O; added to ready queue [Q A0 B9 A1 B5 A7 B7 B3 A2 B4 B8 A9 B1 A6 A3 B2]
time 71065ms: Process B0 completed a CPU burst; 7 bursts to go [Q A0 B9 A1 B5 A7 B7 B3 A2 B4 B8 A9 B1 A6 A3 B2]
time 71065ms: Process B0 switching out of CPU; blocking on I/O until time 71098ms [Q A0 B9 A1 B5 A7 B7 B3 A2 B4 B8 A9 B1 A6 A3 B2]
time 71069ms: Process A0 started using the CPU for 708ms burst [Q B9 A1 B5 A7 B7 B3 A2 B4 B8 A9 B1 A6 A3 B2]
time 71098ms: Process B0 completed I/O; added to ready queue [Q B9 A1 B5 A7 B7 B3 A2 B4 B8 A9 B1 A6 A3 B2 B0]
time 71777ms: Process A0 completed a CPU burst; 18 bursts to go [Q B9 A1 B5 A7 B7 B3 A2 B4 B8 A9 B1 A6 A3 B2 B0]
time 71777ms: Process A0 switching out of CPU; blocking on I/O until time 71807ms [Q B9 A1 B5 A7 B7 B3 A2 B4 B8 A9 B1 A6 A3 B2 B0]
time 71781ms: Process B9 started using the CPU for 19ms burst [Q A1 B5 A7 B7 B3 A2 B4 B8 A9 B1 A6 A3 B2 B0]
time 71800ms: Process B9 terminated [Q A1 B5 A7 B7 B3 A2 B4 B8 A9 B1 A6 A3 B2 B0]
time 71804ms: Process A1 started using the CPU for 188ms burst [Q B5 A7 B7 B3 A2 B4 B8 A9 B1 A6 A3 B2 B0]
time 71807ms: Process A0 completed I/O; added to ready queue [Q B5 A7 B7 B3 A2 B4 B8 A9 B1 A6 A3 B2 B0 A0]
time 71992ms: Process A1 terminated [Q B5 A7 B7 B3 A2 B4 B8 A9 B1 A6 A3 B2 B0 A0]
time 71996ms: Process B5 started using the CPU for 132ms burst [Q A7 B7 B3 A2 B4 B8 A9 B1 A6 A3 B2 B0 A0]
time 72128ms: Process B5 completed a CPU burst; 18 bursts to go [Q A7 B7 B3 A2 B4 B8 A9 B1 A6 A3 B2 B0 A0]
time 72128ms: Process B5 switching out of CPU; blocking on I/O until time 72357ms [Q A7 B7 B3 A2 B4 B8 A9 B1 A6 A3 B2 B0 A0]
time 72132ms: Process A7 started using the CPU for 8ms burst [Q B7 B3 A2 B4 B8 A9 B1 A6 A3 B2 B0 A0]
time 72140ms: Process A7 completed a CPU burst; 7 bursts to go [Q B7 B3 A2 B4 B8 A9 B1 A6 A3 B2 B0 A0]
time 72140ms: Process A7 switching out of CPU; blocking on I/O until time 72307ms [Q B7 B3 A2 B4 B8 A9 B1 A6 A3 B2 B0 A0]
time 72144ms: Process B7 started using the CPU for 104ms burst [Q B3 A2 B4 B8 A9 B1 A6 A3 B2 B0 A0]
time 72248ms: Process B7 completed a CPU burst; 16 bursts to go [Q B3 A2 B4 B8 A9 B1 A6 A3 B2 B0 A0]
time 72248ms: Process B7 switching out of CPU; blocking on I/O until time 73162ms [Q B3 A2 B4 B8 A9 B1 A6 A3 B2 B0 A0]
time 72252ms: Process B3 started using the CPU for 448ms burst [Q A2 B4 B8 A9 B1 A6 A3 B2 B0 A0]
time 72307ms: Process A7 completed I/O; added to ready queue [Q A2 B4 B8 A9 B1 A6 A3 B2 B0 A0 A7]
time 72357ms: Process B5 completed I/O; added to ready queue [Q A2 B4 B8 A9 B1 A6 A3 B2 B0 A0 A7 B5]
time 72700ms: Process B3 completed a CPU burst; 10 bursts to go [Q A2 B4 B8 A9 B1 A6 A3 B2 B0 A0 A7 B5]
time 72700ms: Process B3 switching out of CPU; blocking on I/O until time 72746ms [Q A2 B4 B8 A9 B1 A6 A3 B2 B0 A0 A7 B5]
time 72704ms: Process A2 started using the CPU for 280ms burst [Q B4 B8 A9 B1 A6 A3 B2 B0 A0 A7 B5]
time 72746ms: Process B3 completed I/O; added to ready queue [Q B4 B8 A9 B1 A6 A3 B2 B0 A0 A7 B5 B3]
time 72984ms: Process A2 completed a CPU burst; 18 bursts to go [Q B4 B8 A9 B1 A6 A3 B2 B0 A0 A7 B5 B3]
time 72984ms: Process A2 switching out of CPU; blocking on I/O until time 73158ms [Q B4 B8 A9 B1 A6 A3 B2 B0 A0 A7 B5 B3]
time 72988ms: Process B4 started using the CPU for 192ms burst [Q B8 A9 B1 A6 A3 B2 B0 A0 A7 B5 B3]
time 73158ms: Process A2 completed I/O; added to ready queue [Q B8 A9 B1 A6 A3 B2 B0 A0 A7 B5 B3 A2]
time 73162ms: Process B7 completed I/O; added to ready queue [Q B8 A9 B1 A6 A3 B2 B0 A0 A7 B5 B3 A2 B7]
time 73180ms: Process B4 completed a CPU burst; 3 bursts to go [Q B8 A9 B1 A6 A3 B2 B0 A0 A7 B5 B3 A2 B7]
time 73180ms: Process B4 switching out of CPU; blocking on I/O until time 73197ms [Q B8 A9 B1 A6 A3 B2 B0 A0 A7 B5 B3 A2 B7]
time 73184ms: Process B8 started using the CPU for 23ms burst [Q A9 B1 A6 A3 B2 B0 A0 A7 B5 B3 A2 B7]
time 73197ms: Process B4 completed I/O; added to ready queue [Q A9 B1 A6 A3 B2 B0 A0 A7 B5 B3 A2 B7 B4]
time 73207ms: Process B8 completed a CPU burst; 9 bursts to go [Q A9 B1 A6 A3 B2 B0 A0 A7 B5 B3 A2 B7 B4]
time 73207ms: Process B8 switching out of CPU; blocking on I/O until time 73257ms [Q A9 B1 A6 A3 B2 B0 A0 A7 B5 B3 A2 B7 B4]
time 73211ms: Process A9 started using the CPU for 140ms burst [Q B1 A6 A3 B2 B0 A0 A7 B5 B3 A2 B7 B4]
time 73257ms: Process B8 completed I/O; added to ready queue [Q B1 A6 A3 B2 B0 A0 A7 B5 B3 A2 B7 B4 B8]
time 73351ms: Process A9 completed a CPU burst; 19 bursts to go [Q B1 A6 A3 B2 B0 A0 A7 B5 B3 A2 B7 B4 B8]
time 73351ms: Process A9 switching out of CPU; blocking on I/O until time 73635ms [Q B1 A6 A3 B2 B0 A0 A7 B5 B3 A2 B7 B4 B8]
time 73355ms: Process B1 started using the CPU for 256ms burst [Q A6 A3 B2 B0 A0 A7 B5 B3 A2 B7 B4 B8]
