time 0ms: Simulator started for FCFS [Q empty]
time 54ms: Process A0 arrived; added to ready queue [Q A0]
time 56ms: Process A1 arrived; added to ready queue [Q A1]
time 57ms: Process A0 started using the CPU for 3764ms burst [Q A1]
time 115ms: Process A5 arrived; added to ready queue [Q A1 A5]
time 242ms: Process A6 arrived; added to ready queue [Q A1 A5 A6]
time 346ms: Process A4 arrived; added to ready queue [Q A1 A5 A6 A4]
time 357ms: Process A7 arrived; added to ready queue [Q A1 A5 A6 A4 A7]
time 456ms: Process A2 arrived; added to ready queue [Q A1 A5 A6 A4 A7 A2]
time 758ms: Process A3 arrived; added to ready queue [Q A1 A5 A6 A4 A7 A2 A3]
time 3821ms: Process A0 completed a CPU burst; 28 bursts to go [Q A1 A5 A6 A4 A7 A2 A3]
time 3821ms: Process A0 switching out of CPU; blocking on I/O until time 4510ms [Q A1 A5 A6 A4 A7 A2 A3]
time 3827ms: Process A1 started using the CPU for 2828ms burst [Q A5 A6 A4 A7 A2 A3]
time 4510ms: Process A0 completed I/O; added to ready queue [Q A5 A6 A4 A7 A2 A3 A0]
time 6655ms: Process A1 completed a CPU burst; 30 bursts to go [Q A5 A6 A4 A7 A2 A3 A0]
time 6655ms: Process A1 switching out of CPU; blocking on I/O until time 6980ms [Q A5 A6 A4 A7 A2 A3 A0]
time 6661ms: Process A5 started using the CPU for 564ms burst [Q A6 A4 A7 A2 A3 A0]
time 6980ms: Process A1 completed I/O; added to ready queue [Q A6 A4 A7 A2 A3 A0 A1]
time 7225ms: Process A5 terminated [Q A6 A4 A7 A2 A3 A0 A1]
time 7231ms: Process A6 started using the CPU for 761ms burst [Q A4 A7 A2 A3 A0 A1]
time 7992ms: Process A6 completed a CPU burst; 26 bursts to go [Q A4 A7 A2 A3 A0 A1]
time 7992ms: Process A6 switching out of CPU; blocking on I/O until time 10259ms [Q A4 A7 A2 A3 A0 A1]
time 7998ms: Process A4 started using the CPU for 2428ms burst [Q A7 A2 A3 A0 A1]
time 19820ms: Process A4 terminated [Q A2 A3 A0 A1 A7 A6]
time 71120ms: Process A2 terminated [Q A6 A3 A7 A0 A1]
time 122158ms: Process A3 terminated [Q A7 A1 A6 A0]
time 174453ms: Process A0 terminated [Q A7 A1]
time 178763ms: Process A7 terminated [Q empty]
time 182131ms: Process A1 terminated [Q empty]
time 207272ms: Process A6 terminated [Q empty]
time 207275ms: Simulator ended for FCFS [Q empty]
