time 0ms: Simulator started for SJF [Q empty]
time 93ms: Process A8 (tau 1000ms) arrived; added to ready queue [Q A8]
time 95ms: Process A8 (tau 1000ms) started using the CPU for 607ms burst [Q empty]
time 112ms: Process B1 (tau 1000ms) arrived; added to ready queue [Q B1]
time 322ms: Process A9 (tau 1000ms) arrived; added to ready queue [Q A9 B1]
time 385ms: Process A6 (tau 1000ms) arrived; added to ready queue [Q A6 A9 B1]
time 386ms: Process A3 (tau 1000ms) arrived; added to ready queue [Q A3 A6 A9 B1]
time 561ms: Process B4 (tau 1000ms) arrived; added to ready queue [Q A3 A6 A9 B1 B4]
time 591ms: Process B3 (tau 1000ms) arrived; added to ready queue [Q A3 A6 A9 B1 B3 B4]
time 702ms: Process A8 (tau 1000ms) completed a CPU burst; 13 bursts to go [Q A3 A6 A9 B1 B3 B4]
time 702ms: Recalculated tau for process A8: old tau 1000ms ==> new tau 824ms [Q A3 A6 A9 B1 B3 B4]
time 702ms: Process A8 switching out of CPU; blocking on I/O until time 3632ms [Q A3 A6 A9 B1 B3 B4]
time 706ms: Process A3 (tau 1000ms) started using the CPU for 544ms burst [Q A6 A9 B1 B3 B4]
time 749ms: Process A5 (tau 1000ms) arrived; added to ready queue [Q A5 A6 A9 B1 B3 B4]
time 877ms: Process B5 (tau 1000ms) arrived; added to ready queue [Q A5 A6 A9 B1 B3 B4 B5]
time 1197ms: Process B0 (tau 1000ms) arrived; added to ready queue [Q A5 A6 A9 B0 B1 B3 B4 B5]
time 1250ms: Process A3 (tau 1000ms) completed a CPU burst; 12 bursts to go [Q A5 A6 A9 B0 B1 B3 B4 B5]
time 1250ms: Recalculated tau for process A3: old tau 1000ms ==> new tau 795ms [Q A5 A6 A9 B0 B1 B3 B4 B5]
time 1250ms: Process A3 switching out of CPU; blocking on I/O until time 6748ms [Q A5 A6 A9 B0 B1 B3 B4 B5]
time 1254ms: Process A5 (tau 1000ms) started using the CPU for 638ms burst [Q A6 A9 B0 B1 B3 B4 B5]
time 1266ms: Process A1 (tau 1000ms) arrived; added to ready queue [Q A1 A6 A9 B0 B1 B3 B4 B5]
time 1572ms: Process B2 (tau 1000ms) arrived; added to ready queue [Q A1 A6 A9 B0 B1 B2 B3 B4 B5]
time 1585ms: Process A2 (tau 1000ms) arrived; added to ready queue [Q A1 A2 A6 A9 B0 B1 B2 B3 B4 B5]
time 1593ms: Process A7 (tau 1000ms) arrived; added to ready queue [Q A1 A2 A6 A7 A9 B0 B1 B2 B3 B4 B5]
time 1780ms: Process A4 (tau 1000ms) arrived; added to ready queue [Q A1 A2 A4 A6 A7 A9 B0 B1 B2 B3 B4 B5]
time 1892ms: Process A5 (tau 1000ms) completed a CPU burst; 31 bursts to go [Q A1 A2 A4 A6 A7 A9 B0 B1 B2 B3 B4 B5]
time 1892ms: Recalculated tau for process A5: old tau 1000ms ==> new tau 838ms [Q A1 A2 A4 A6 A7 A9 B0 B1 B2 B3 B4 B5]
time 1892ms: Process A5 switching out of CPU; blocking on I/O until time 6430ms [Q A1 A2 A4 A6 A7 A9 B0 B1 B2 B3 B4 B5]
time 1896ms: Process A1 (tau 1000ms) started using the CPU for 7140ms burst [Q A2 A4 A6 A7 A9 B0 B1 B2 B3 B4 B5]
time 1977ms: Process A0 (tau 1000ms) arrived; added to ready queue [Q A0 A2 A4 A6 A7 A9 B0 B1 B2 B3 B4 B5]
time 3632ms: Process A8 (tau 824ms) completed I/O; added to ready queue [Q A8 A0 A2 A4 A6 A7 A9 B0 B1 B2 B3 B4 B5]
time 6430ms: Process A5 (tau 838ms) completed I/O; added to ready queue [Q A8 A5 A0 A2 A4 A6 A7 A9 B0 B1 B2 B3 B4 B5]
time 6748ms: Process A3 (tau 795ms) completed I/O; added to ready queue [Q A3 A8 A5 A0 A2 A4 A6 A7 A9 B0 B1 B2 B3 B4 B5]
time 9036ms: Process A1 (tau 1000ms) completed a CPU burst; 24 bursts to go [Q A3 A8 A5 A0 A2 A4 A6 A7 A9 B0 B1 B2 B3 B4 B5]
time 9036ms: Recalculated tau for process A1: old tau 1000ms ==> new tau 3763ms [Q A3 A8 A5 A0 A2 A4 A6 A7 A9 B0 B1 B2 B3 B4 B5]
time 9036ms: Process A1 switching out of CPU; blocking on I/O until time 9591ms [Q A3 A8 A5 A0 A2 A4 A6 A7 A9 B0 B1 B2 B3 B4 B5]
time 9040ms: Process A3 (tau 795ms) started using the CPU for 1223ms burst [Q A8 A5 A0 A2 A4 A6 A7 A9 B0 B1 B2 B3 B4 B5]
time 9591ms: Process A1 (tau 3763ms) completed I/O; added to ready queue [Q A8 A5 A0 A2 A4 A6 A7 A9 B0 B1 B2 B3 B4 B5 A1]
time 10263ms: Process A3 (tau 795ms) completed a CPU burst; 11 bursts to go [Q A8 A5 A0 A2 A4 A6 A7 A9 B0 B1 B2 B3 B4 B5 A1]
time 10263ms: Recalculated tau for process A3: old tau 795ms ==> new tau 988ms [Q A8 A5 A0 A2 A4 A6 A7 A9 B0 B1 B2 B3 B4 B5 A1]
time 10263ms: Process A3 switching out of CPU; blocking on I/O until time 22473ms [Q A8 A5 A0 A2 A4 A6 A7 A9 B0 B1 B2 B3 B4 B5 A1]
time 10267ms: Process A8 (tau 824ms) started using the CPU for 7ms burst [Q A5 A0 A2 A4 A6 A7 A9 B0 B1 B2 B3 B4 B5 A1]
time 10274ms: Process A8 (tau 824ms) completed a CPU burst; 12 bursts to go [Q A5 A0 A2 A4 A6 A7 A9 B0 B1 B2 B3 B4 B5 A1]
time 10274ms: Recalculated tau for process A8: old tau 824ms ==> new tau 457ms [Q A5 A0 A2 A4 A6 A7 A9 B0 B1 B2 B3 B4 B5 A1]
time 10274ms: Process A8 switching out of CPU; blocking on I/O until time 13668ms [Q A5 A0 A2 A4 A6 A7 A9 B0 B1 B2 B3 B4 B5 A1]
time 10278ms: Process A5 (tau 838ms) started using the CPU for 926ms burst [Q A0 A2 A4 A6 A7 A9 B0 B1 B2 B3 B4 B5 A1]
time 11204ms: Process A5 (tau 838ms) completed a CPU burst; 30 bursts to go [Q A0 A2 A4 A6 A7 A9 B0 B1 B2 B3 B4 B5 A1]
time 11204ms: Recalculated tau for process A5: old tau 838ms ==> new tau 878ms [Q A0 A2 A4 A6 A7 A9 B0 B1 B2 B3 B4 B5 A1]
time 11204ms: Process A5 switching out of CPU; blocking on I/O until time 20686ms [Q A0 A2 A4 A6 A7 A9 B0 B1 B2 B3 B4 B5 A1]
time 11208ms: Process A0 (tau 1000ms) started using the CPU for 2372ms burst [Q A2 A4 A6 A7 A9 B0 B1 B2 B3 B4 B5 A1]
time 13580ms: Process A0 (tau 1000ms) completed a CPU burst; 1 burst to go [Q A2 A4 A6 A7 A9 B0 B1 B2 B3 B4 B5 A1]
time 13580ms: Recalculated tau for process A0: old tau 1000ms ==> new tau 1618ms [Q A2 A4 A6 A7 A9 B0 B1 B2 B3 B4 B5 A1]
time 13580ms: Process A0 switching out of CPU; blocking on I/O until time 14249ms [Q A2 A4 A6 A7 A9 B0 B1 B2 B3 B4 B5 A1]
time 13584ms: Process A2 (tau 1000ms) started using the CPU for 527ms burst [Q A4 A6 A7 A9 B0 B1 B2 B3 B4 B5 A1]
time 13668ms: Process A8 (tau 457ms) completed I/O; added to ready queue [Q A8 A4 A6 A7 A9 B0 B1 B2 B3 B4 B5 A1]
time 14111ms: Process A2 (tau 1000ms) completed a CPU burst; 4 bursts to go [Q A8 A4 A6 A7 A9 B0 B1 B2 B3 B4 B5 A1]
time 14111ms: Recalculated tau for process A2: old tau 1000ms ==> new tau 788ms [Q A8 A4 A6 A7 A9 B0 B1 B2 B3 B4 B5 A1]
time 14111ms: Process A2 switching out of CPU; blocking on I/O until time 18049ms [Q A8 A4 A6 A7 A9 B0 B1 B2 B3 B4 B5 A1]
time 14115ms: Process A8 (tau 457ms) started using the CPU for 506ms burst [Q A4 A6 A7 A9 B0 B1 B2 B3 B4 B5 A1]
time 14249ms: Process A0 (tau 1618ms) completed I/O; added to ready queue [Q A4 A6 A7 A9 B0 B1 B2 B3 B4 B5 A0 A1]
time 14621ms: Process A8 (tau 457ms) completed a CPU burst; 11 bursts to go [Q A4 A6 A7 A9 B0 B1 B2 B3 B4 B5 A0 A1]
time 14621ms: Recalculated tau for process A8: old tau 457ms ==> new tau 480ms [Q A4 A6 A7 A9 B0 B1 B2 B3 B4 B5 A0 A1]
time 14621ms: Process A8 switching out of CPU; blocking on I/O until time 28055ms [Q A4 A6 A7 A9 B0 B1 B2 B3 B4 B5 A0 A1]
time 14625ms: Process A4 (tau 1000ms) started using the CPU for 638ms burst [Q A6 A7 A9 B0 B1 B2 B3 B4 B5 A0 A1]
time 15263ms: Process A4 (tau 1000ms) completed a CPU burst; 25 bursts to go [Q A6 A7 A9 B0 B1 B2 B3 B4 B5 A0 A1]
time 15263ms: Recalculated tau for process A4: old tau 1000ms ==> new tau 838ms [Q A6 A7 A9 B0 B1 B2 B3 B4 B5 A0 A1]
time 15263ms: Process A4 switching out of CPU; blocking on I/O until time 16409ms [Q A6 A7 A9 B0 B1 B2 B3 B4 B5 A0 A1]
time 15267ms: Process A6 (tau 1000ms) started using the CPU for 696ms burst [Q A7 A9 B0 B1 B2 B3 B4 B5 A0 A1]
time 15963ms: Process A6 (tau 1000ms) completed a CPU burst; 15 bursts to go [Q A7 A9 B0 B1 B2 B3 B4 B5 A0 A1]
time 15963ms: Recalculated tau for process A6: old tau 1000ms ==> new tau 864ms [Q A7 A9 B0 B1 B2 B3 B4 B5 A0 A1]
time 15963ms: Process A6 switching out of CPU; blocking on I/O until time 20549ms [Q A7 A9 B0 B1 B2 B3 B4 B5 A0 A1]
time 15967ms: Process A7 (tau 1000ms) started using the CPU for 56ms burst [Q A9 B0 B1 B2 B3 B4 B5 A0 A1]
time 16023ms: Process A7 (tau 1000ms) completed a CPU burst; 6 bursts to go [Q A9 B0 B1 B2 B3 B4 B5 A0 A1]
time 16023ms: Recalculated tau for process A7: old tau 1000ms ==> new tau 576ms [Q A9 B0 B1 B2 B3 B4 B5 A0 A1]
time 16023ms: Process A7 switching out of CPU; blocking on I/O until time 21297ms [Q A9 B0 B1 B2 B3 B4 B5 A0 A1]
time 16027ms: Process A9 (tau 1000ms) started using the CPU for 932ms burst [Q B0 B1 B2 B3 B4 B5 A0 A1]
time 16409ms: Process A4 (tau 838ms) completed I/O; added to ready queue [Q A4 B0 B1 B2 B3 B4 B5 A0 A1]
time 16959ms: Process A9 (tau 1000ms) completed a CPU burst; 19 bursts to go [Q A4 B0 B1 B2 B3 B4 B5 A0 A1]
time 16959ms: Recalculated tau for process A9: old tau 1000ms ==> new tau 970ms [Q A4 B0 B1 B2 B3 B4 B5 A0 A1]
time 16959ms: Process A9 switching out of CPU; blocking on I/O until time 18153ms [Q A4 B0 B1 B2 B3 B4 B5 A0 A1]
time 16963ms: Process A4 (tau 838ms) started using the CPU for 1550ms burst [Q B0 B1 B2 B3 B4 B5 A0 A1]
time 18049ms: Process A2 (tau 788ms) completed I/O; added to ready queue [Q A2 B0 B1 B2 B3 B4 B5 A0 A1]
time 18153ms: Process A9 (tau 970ms) completed I/O; added to ready queue [Q A2 A9 B0 B1 B2 B3 B4 B5 A0 A1]
time 18513ms: Process A4 (tau 838ms) completed a CPU burst; 24 bursts to go [Q A2 A9 B0 B1 B2 B3 B4 B5 A0 A1]
time 18513ms: Recalculated tau for process A4: old tau 838ms ==> new tau 1159ms [Q A2 A9 B0 B1 B2 B3 B4 B5 A0 A1]
time 18513ms: Process A4 switching out of CPU; blocking on I/O until time 27467ms [Q A2 A9 B0 B1 B2 B3 B4 B5 A0 A1]
time 18517ms: Process A2 (tau 788ms) started using the CPU for 716ms burst [Q A9 B0 B1 B2 B3 B4 B5 A0 A1]
time 19233ms: Process A2 (tau 788ms) completed a CPU burst; 3 bursts to go [Q A9 B0 B1 B2 B3 B4 B5 A0 A1]
time 19233ms: Recalculated tau for process A2: old tau 788ms ==> new tau 756ms [Q A9 B0 B1 B2 B3 B4 B5 A0 A1]
time 19233ms: Process A2 switching out of CPU; blocking on I/O until time 21323ms [Q A9 B0 B1 B2 B3 B4 B5 A0 A1]
time 19237ms: Process A9 (tau 970ms) started using the CPU for 1190ms burst [Q B0 B1 B2 B3 B4 B5 A0 A1]
time 20427ms: Process A9 (tau 970ms) completed a CPU burst; 18 bursts to go [Q B0 B1 B2 B3 B4 B5 A0 A1]
time 20427ms: Recalculated tau for process A9: old tau 970ms ==> new tau 1069ms [Q B0 B1 B2 B3 B4 B5 A0 A1]
time 20427ms: Process A9 switching out of CPU; blocking on I/O until time 30933ms [Q B0 B1 B2 B3 B4 B5 A0 A1]
time 20431ms: Process B0 (tau 1000ms) started using the CPU for 288ms burst [Q B1 B2 B3 B4 B5 A0 A1]
time 20549ms: Process A6 (tau 864ms) completed I/O; added to ready queue [Q A6 B1 B2 B3 B4 B5 A0 A1]
time 20686ms: Process A5 (tau 878ms) completed I/O; added to ready queue [Q A6 A5 B1 B2 B3 B4 B5 A0 A1]
time 20719ms: Process B0 (tau 1000ms) completed a CPU burst; 29 bursts to go [Q A6 A5 B1 B2 B3 B4 B5 A0 A1]
time 20719ms: Recalculated tau for process B0: old tau 1000ms ==> new tau 680ms [Q A6 A5 B1 B2 B3 B4 B5 A0 A1]
time 20719ms: Process B0 switching out of CPU; blocking on I/O until time 29009ms [Q A6 A5 B1 B2 B3 B4 B5 A0 A1]
time 20723ms: Process A6 (tau 864ms) started using the CPU for 1015ms burst [Q A5 B1 B2 B3 B4 B5 A0 A1]
time 21297ms: Process A7 (tau 576ms) completed I/O; added to ready queue [Q A7 A5 B1 B2 B3 B4 B5 A0 A1]
time 21323ms: Process A2 (tau 756ms) completed I/O; added to ready queue [Q A7 A2 A5 B1 B2 B3 B4 B5 A0 A1]
time 21738ms: Process A6 (tau 864ms) completed a CPU burst; 14 bursts to go [Q A7 A2 A5 B1 B2 B3 B4 B5 A0 A1]
time 21738ms: Recalculated tau for process A6: old tau 864ms ==> new tau 932ms [Q A7 A2 A5 B1 B2 B3 B4 B5 A0 A1]
time 21738ms: Process A6 switching out of CPU; blocking on I/O until time 31500ms [Q A7 A2 A5 B1 B2 B3 B4 B5 A0 A1]
time 21742ms: Process A7 (tau 576ms) started using the CPU for 279ms burst [Q A2 A5 B1 B2 B3 B4 B5 A0 A1]
time 22021ms: Process A7 (tau 576ms) completed a CPU burst; 5 bursts to go [Q A2 A5 B1 B2 B3 B4 B5 A0 A1]
time 22021ms: Recalculated tau for process A7: old tau 576ms ==> new tau 443ms [Q A2 A5 B1 B2 B3 B4 B5 A0 A1]
time 22021ms: Process A7 switching out of CPU; blocking on I/O until time 28079ms [Q A2 A5 B1 B2 B3 B4 B5 A0 A1]
time 22025ms: Process A2 (tau 756ms) started using the CPU for 128ms burst [Q A5 B1 B2 B3 B4 B5 A0 A1]
time 22153ms: Process A2 (tau 756ms) completed a CPU burst; 2 bursts to go [Q A5 B1 B2 B3 B4 B5 A0 A1]
time 22153ms: Recalculated tau for process A2: old tau 756ms ==> new tau 474ms [Q A5 B1 B2 B3 B4 B5 A0 A1]
time 22153ms: Process A2 switching out of CPU; blocking on I/O until time 36235ms [Q A5 B1 B2 B3 B4 B5 A0 A1]
time 22157ms: Process A5 (tau 878ms) started using the CPU for 154ms burst [Q B1 B2 B3 B4 B5 A0 A1]
time 22311ms: Process A5 (tau 878ms) completed a CPU burst; 29 bursts to go [Q B1 B2 B3 B4 B5 A0 A1]
time 22311ms: Recalculated tau for process A5: old tau 878ms ==> new tau 553ms [Q B1 B2 B3 B4 B5 A0 A1]
time 22311ms: Process A5 switching out of CPU; blocking on I/O until time 27937ms [Q B1 B2 B3 B4 B5 A0 A1]
time 22315ms: Process B1 (tau 1000ms) started using the CPU for 1119ms burst [Q B2 B3 B4 B5 A0 A1]
time 22473ms: Process A3 (tau 988ms) completed I/O; added to ready queue [Q A3 B2 B3 B4 B5 A0 A1]
time 23434ms: Process B1 (tau 1000ms) completed a CPU burst; 27 bursts to go [Q A3 B2 B3 B4 B5 A0 A1]
time 23434ms: Recalculated tau for process B1: old tau 1000ms ==> new tau 1054ms [Q A3 B2 B3 B4 B5 A0 A1]
time 23434ms: Process B1 switching out of CPU; blocking on I/O until time 32836ms [Q A3 B2 B3 B4 B5 A0 A1]
time 23438ms: Process A3 (tau 988ms) started using the CPU for 918ms burst [Q B2 B3 B4 B5 A0 A1]
time 24356ms: Process A3 (tau 988ms) completed a CPU burst; 10 bursts to go [Q B2 B3 B4 B5 A0 A1]
time 24356ms: Recalculated tau for process A3: old tau 988ms ==> new tau 957ms [Q B2 B3 B4 B5 A0 A1]
time 24356ms: Process A3 switching out of CPU; blocking on I/O until time 30038ms [Q B2 B3 B4 B5 A0 A1]
time 24360ms: Process B2 (tau 1000ms) started using the CPU for 310ms burst [Q B3 B4 B5 A0 A1]
time 24670ms: Process B2 (tau 1000ms) completed a CPU burst; 12 bursts to go [Q B3 B4 B5 A0 A1]
time 24670ms: Recalculated tau for process B2: old tau 1000ms ==> new tau 690ms [Q B3 B4 B5 A0 A1]
time 24670ms: Process B2 switching out of CPU; blocking on I/O until time 27120ms [Q B3 B4 B5 A0 A1]
time 24674ms: Process B3 (tau 1000ms) started using the CPU for 944ms burst [Q B4 B5 A0 A1]
time 25618ms: Process B3 (tau 1000ms) completed a CPU burst; 4 bursts to go [Q B4 B5 A0 A1]
time 25618ms: Recalculated tau for process B3: old tau 1000ms ==> new tau 975ms [Q B4 B5 A0 A1]
time 25618ms: Process B3 switching out of CPU; blocking on I/O until time 39884ms [Q B4 B5 A0 A1]
time 25622ms: Process B4 (tau 1000ms) started using the CPU for 1575ms burst [Q B5 A0 A1]
time 27120ms: Process B2 (tau 690ms) completed I/O; added to ready queue [Q B2 B5 A0 A1]
time 27197ms: Process B4 (tau 1000ms) completed a CPU burst; 19 bursts to go [Q B2 B5 A0 A1]
time 27197ms: Recalculated tau for process B4: old tau 1000ms ==> new tau 1259ms [Q B2 B5 A0 A1]
time 27197ms: Process B4 switching out of CPU; blocking on I/O until time 27623ms [Q B2 B5 A0 A1]
time 27201ms: Process B2 (tau 690ms) started using the CPU for 1011ms burst [Q B5 A0 A1]
time 27467ms: Process A4 (tau 1159ms) completed I/O; added to ready queue [Q B5 A4 A0 A1]
time 27623ms: Process B4 (tau 1259ms) completed I/O; added to ready queue [Q B5 A4 B4 A0 A1]
time 27937ms: Process A5 (tau 553ms) completed I/O; added to ready queue [Q A5 B5 A4 B4 A0 A1]
time 28055ms: Process A8 (tau 480ms) completed I/O; added to ready queue [Q A8 A5 B5 A4 B4 A0 A1]
time 28079ms: Process A7 (tau 443ms) completed I/O; added to ready queue [Q A7 A8 A5 B5 A4 B4 A0 A1]
time 28212ms: Process B2 (tau 690ms) completed a CPU burst; 11 bursts to go [Q A7 A8 A5 B5 A4 B4 A0 A1]
time 28212ms: Recalculated tau for process B2: old tau 690ms ==> new tau 835ms [Q A7 A8 A5 B5 A4 B4 A0 A1]
time 28212ms: Process B2 switching out of CPU; blocking on I/O until time 38006ms [Q A7 A8 A5 B5 A4 B4 A0 A1]
time 28216ms: Process A7 (tau 443ms) started using the CPU for 453ms burst [Q A8 A5 B5 A4 B4 A0 A1]
time 28669ms: Process A7 (tau 443ms) completed a CPU burst; 4 bursts to go [Q A8 A5 B5 A4 B4 A0 A1]
time 28669ms: Recalculated tau for process A7: old tau 443ms ==> new tau 448ms [Q A8 A5 B5 A4 B4 A0 A1]
time 28669ms: Process A7 switching out of CPU; blocking on I/O until time 28959ms [Q A8 A5 B5 A4 B4 A0 A1]
time 28673ms: Process A8 (tau 480ms) started using the CPU for 1282ms burst [Q A5 B5 A4 B4 A0 A1]
time 28959ms: Process A7 (tau 448ms) completed I/O; added to ready queue [Q A7 A5 B5 A4 B4 A0 A1]
time 29009ms: Process B0 (tau 680ms) completed I/O; added to ready queue [Q A7 A5 B0 B5 A4 B4 A0 A1]
time 29955ms: Process A8 (tau 480ms) completed a CPU burst; 10 bursts to go [Q A7 A5 B0 B5 A4 B4 A0 A1]
time 29955ms: Recalculated tau for process A8: old tau 480ms ==> new tau 841ms [Q A7 A5 B0 B5 A4 B4 A0 A1]
time 29955ms: Process A8 switching out of CPU; blocking on I/O until time 35445ms [Q A7 A5 B0 B5 A4 B4 A0 A1]
time 29959ms: Process A7 (tau 448ms) started using the CPU for 199ms burst [Q A5 B0 B5 A4 B4 A0 A1]
time 30038ms: Process A3 (tau 957ms) completed I/O; added to ready queue [Q A5 B0 A3 B5 A4 B4 A0 A1]
time 30158ms: Process A7 (tau 448ms) completed a CPU burst; 3 bursts to go [Q A5 B0 A3 B5 A4 B4 A0 A1]
time 30158ms: Recalculated tau for process A7: old tau 448ms ==> new tau 336ms [Q A5 B0 A3 B5 A4 B4 A0 A1]
time 30158ms: Process A7 switching out of CPU; blocking on I/O until time 33224ms [Q A5 B0 A3 B5 A4 B4 A0 A1]
time 30162ms: Process A5 (tau 553ms) started using the CPU for 735ms burst [Q B0 A3 B5 A4 B4 A0 A1]
time 30897ms: Process A5 (tau 553ms) completed a CPU burst; 28 bursts to go [Q B0 A3 B5 A4 B4 A0 A1]
time 30897ms: Recalculated tau for process A5: old tau 553ms ==> new tau 635ms [Q B0 A3 B5 A4 B4 A0 A1]
time 30897ms: Process A5 switching out of CPU; blocking on I/O until time 37307ms [Q B0 A3 B5 A4 B4 A0 A1]
time 30901ms: Process B0 (tau 680ms) started using the CPU for 93ms burst [Q A3 B5 A4 B4 A0 A1]
time 30933ms: Process A9 (tau 1069ms) completed I/O; added to ready queue [Q A3 B5 A9 A4 B4 A0 A1]
time 30994ms: Process B0 (tau 680ms) completed a CPU burst; 28 bursts to go [Q A3 B5 A9 A4 B4 A0 A1]
time 30994ms: Recalculated tau for process B0: old tau 680ms ==> new tau 416ms [Q A3 B5 A9 A4 B4 A0 A1]
time 30994ms: Process B0 switching out of CPU; blocking on I/O until time 45740ms [Q A3 B5 A9 A4 B4 A0 A1]
time 30998ms: Process A3 (tau 957ms) started using the CPU for 165ms burst [Q B5 A9 A4 B4 A0 A1]
time 31163ms: Process A3 (tau 957ms) completed a CPU burst; 9 bursts to go [Q B5 A9 A4 B4 A0 A1]
time 31163ms: Recalculated tau for process A3: old tau 957ms ==> new tau 601ms [Q B5 A9 A4 B4 A0 A1]
time 31163ms: Process A3 switching out of CPU; blocking on I/O until time 34805ms [Q B5 A9 A4 B4 A0 A1]
time 31167ms: Process B5 (tau 1000ms) started using the CPU for 63ms burst [Q A9 A4 B4 A0 A1]
time 31230ms: Process B5 (tau 1000ms) completed a CPU burst; 24 bursts to go [Q A9 A4 B4 A0 A1]
time 31230ms: Recalculated tau for process B5: old tau 1000ms ==> new tau 579ms [Q A9 A4 B4 A0 A1]
time 31230ms: Process B5 switching out of CPU; blocking on I/O until time 35336ms [Q A9 A4 B4 A0 A1]
time 31234ms: Process A9 (tau 1069ms) started using the CPU for 1299ms burst [Q A4 B4 A0 A1]
time 31500ms: Process A6 (tau 932ms) completed I/O; added to ready queue [Q A6 A4 B4 A0 A1]
time 32533ms: Process A9 (tau 1069ms) completed a CPU burst; 17 bursts to go [Q A6 A4 B4 A0 A1]
time 32533ms: Recalculated tau for process A9: old tau 1069ms ==> new tau 1173ms [Q A6 A4 B4 A0 A1]
time 32533ms: Process A9 switching out of CPU; blocking on I/O until time 32735ms [Q A6 A4 B4 A0 A1]
time 32537ms: Process A6 (tau 932ms) started using the CPU for 16ms burst [Q A4 B4 A0 A1]
time 32553ms: Process A6 (tau 932ms) completed a CPU burst; 13 bursts to go [Q A4 B4 A0 A1]
time 32553ms: Recalculated tau for process A6: old tau 932ms ==> new tau 520ms [Q A4 B4 A0 A1]
time 32553ms: Process A6 switching out of CPU; blocking on I/O until time 33419ms [Q A4 B4 A0 A1]
time 32557ms: Process A4 (tau 1159ms) started using the CPU for 1306ms burst [Q B4 A0 A1]
time 32735ms: Process A9 (tau 1173ms) completed I/O; added to ready queue [Q A9 B4 A0 A1]
time 32836ms: Process B1 (tau 1054ms) completed I/O; added to ready queue [Q B1 A9 B4 A0 A1]
time 33224ms: Process A7 (tau 336ms) completed I/O; added to ready queue [Q A7 B1 A9 B4 A0 A1]
time 33419ms: Process A6 (tau 520ms) completed I/O; added to ready queue [Q A7 A6 B1 A9 B4 A0 A1]
time 33863ms: Process A4 (tau 1159ms) completed a CPU burst; 23 bursts to go [Q A7 A6 B1 A9 B4 A0 A1]
time 33863ms: Recalculated tau for process A4: old tau 1159ms ==> new tau 1226ms [Q A7 A6 B1 A9 B4 A0 A1]
time 33863ms: Process A4 switching out of CPU; blocking on I/O until time 41193ms [Q A7 A6 B1 A9 B4 A0 A1]
time 33867ms: Process A7 (tau 336ms) started using the CPU for 84ms burst [Q A6 B1 A9 B4 A0 A1]
time 33951ms: Process A7 (tau 336ms) completed a CPU burst; 2 bursts to go [Q A6 B1 A9 B4 A0 A1]
time 33951ms: Recalculated tau for process A7: old tau 336ms ==> new tau 223ms [Q A6 B1 A9 B4 A0 A1]
time 33951ms: Process A7 switching out of CPU; blocking on I/O until time 35329ms [Q A6 B1 A9 B4 A0 A1]
time 33955ms: Process A6 (tau 520ms) started using the CPU for 222ms burst [Q B1 A9 B4 A0 A1]
time 34177ms: Process A6 (tau 520ms) completed a CPU burst; 12 bursts to go [Q B1 A9 B4 A0 A1]
time 34177ms: Recalculated tau for process A6: old tau 520ms ==> new tau 386ms [Q B1 A9 B4 A0 A1]
time 34177ms: Process A6 switching out of CPU; blocking on I/O until time 39315ms [Q B1 A9 B4 A0 A1]
time 34181ms: Process B1 (tau 1054ms) started using the CPU for 501ms burst [Q A9 B4 A0 A1]
time 34682ms: Process B1 (tau 1054ms) completed a CPU burst; 26 bursts to go [Q A9 B4 A0 A1]
time 34682ms: Recalculated tau for process B1: old tau 1054ms ==> new tau 806ms [Q A9 B4 A0 A1]
time 34682ms: Process B1 switching out of CPU; blocking on I/O until time 38180ms [Q A9 B4 A0 A1]
time 34686ms: Process A9 (tau 1173ms) started using the CPU for 351ms burst [Q B4 A0 A1]
time 34805ms: Process A3 (tau 601ms) completed I/O; added to ready queue [Q A3 B4 A0 A1]
time 35037ms: Process A9 (tau 1173ms) completed a CPU burst; 16 bursts to go [Q A3 B4 A0 A1]
time 35037ms: Recalculated tau for process A9: old tau 1173ms ==> new tau 804ms [Q A3 B4 A0 A1]
time 35037ms: Process A9 switching out of CPU; blocking on I/O until time 36999ms [Q A3 B4 A0 A1]
time 35041ms: Process A3 (tau 601ms) started using the CPU for 1380ms burst [Q B4 A0 A1]
time 35329ms: Process A7 (tau 223ms) completed I/O; added to ready queue [Q A7 B4 A0 A1]
time 35336ms: Process B5 (tau 579ms) completed I/O; added to ready queue [Q A7 B5 B4 A0 A1]
time 35445ms: Process A8 (tau 841ms) completed I/O; added to ready queue [Q A7 B5 A8 B4 A0 A1]
time 36235ms: Process A2 (tau 474ms) completed I/O; added to ready queue [Q A7 A2 B5 A8 B4 A0 A1]
time 36421ms: Process A3 (tau 601ms) completed a CPU burst; 8 bursts to go [Q A7 A2 B5 A8 B4 A0 A1]
time 36421ms: Recalculated tau for process A3: old tau 601ms ==> new tau 952ms [Q A7 A2 B5 A8 B4 A0 A1]
time 36421ms: Process A3 switching out of CPU; blocking on I/O until time 40807ms [Q A7 A2 B5 A8 B4 A0 A1]
time 36425ms: Process A7 (tau 223ms) started using the CPU for 116ms burst [Q A2 B5 A8 B4 A0 A1]
time 36541ms: Process A7 (tau 223ms) completed a CPU burst; 1 burst to go [Q A2 B5 A8 B4 A0 A1]
time 36541ms: Recalculated tau for process A7: old tau 223ms ==> new tau 175ms [Q A2 B5 A8 B4 A0 A1]
time 36541ms: Process A7 switching out of CPU; blocking on I/O until time 36711ms [Q A2 B5 A8 B4 A0 A1]
time 36545ms: Process A2 (tau 474ms) started using the CPU for 226ms burst [Q B5 A8 B4 A0 A1]
time 36711ms: Process A7 (tau 175ms) completed I/O; added to ready queue [Q A7 B5 A8 B4 A0 A1]
time 36771ms: Process A2 (tau 474ms) completed a CPU burst; 1 burst to go [Q A7 B5 A8 B4 A0 A1]
time 36771ms: Recalculated tau for process A2: old tau 474ms ==> new tau 363ms [Q A7 B5 A8 B4 A0 A1]
time 36771ms: Process A2 switching out of CPU; blocking on I/O until time 40021ms [Q A7 B5 A8 B4 A0 A1]
time 36775ms: Process A7 (tau 175ms) started using the CPU for 618ms burst [Q B5 A8 B4 A0 A1]
time 36999ms: Process A9 (tau 804ms) completed I/O; added to ready queue [Q B5 A9 A8 B4 A0 A1]
time 37307ms: Process A5 (tau 635ms) completed I/O; added to ready queue [Q B5 A5 A9 A8 B4 A0 A1]
time 37393ms: Process A7 terminated [Q B5 A5 A9 A8 B4 A0 A1]
time 37397ms: Process B5 (tau 579ms) started using the CPU for 204ms burst [Q A5 A9 A8 B4 A0 A1]
time 37601ms: Process B5 (tau 579ms) completed a CPU burst; 23 bursts to go [Q A5 A9 A8 B4 A0 A1]
time 37601ms: Recalculated tau for process B5: old tau 579ms ==> new tau 411ms [Q A5 A9 A8 B4 A0 A1]
time 37601ms: Process B5 switching out of CPU; blocking on I/O until time 51363ms [Q A5 A9 A8 B4 A0 A1]
time 37605ms: Process A5 (tau 635ms) started using the CPU for 637ms burst [Q A9 A8 B4 A0 A1]
time 38006ms: Process B2 (tau 835ms) completed I/O; added to ready queue [Q A9 B2 A8 B4 A0 A1]
time 38180ms: Process B1 (tau 806ms) completed I/O; added to ready queue [Q A9 B1 B2 A8 B4 A0 A1]
time 38242ms: Process A5 (tau 635ms) completed a CPU burst; 27 bursts to go [Q A9 B1 B2 A8 B4 A0 A1]
time 38242ms: Recalculated tau for process A5: old tau 635ms ==> new tau 636ms [Q A9 B1 B2 A8 B4 A0 A1]
time 38242ms: Process A5 switching out of CPU; blocking on I/O until time 38804ms [Q A9 B1 B2 A8 B4 A0 A1]
time 38246ms: Process A9 (tau 804ms) started using the CPU for 14ms burst [Q B1 B2 A8 B4 A0 A1]
time 38260ms: Process A9 (tau 804ms) completed a CPU burst; 15 bursts to go [Q B1 B2 A8 B4 A0 A1]
time 38260ms: Recalculated tau for process A9: old tau 804ms ==> new tau 449ms [Q B1 B2 A8 B4 A0 A1]
time 38260ms: Process A9 switching out of CPU; blocking on I/O until time 38766ms [Q B1 B2 A8 B4 A0 A1]
time 38264ms: Process B1 (tau 806ms) started using the CPU for 1489ms burst [Q B2 A8 B4 A0 A1]
time 38766ms: Process A9 (tau 449ms) completed I/O; added to ready queue [Q A9 B2 A8 B4 A0 A1]
time 38804ms: Process A5 (tau 636ms) completed I/O; added to ready queue [Q A9 A5 B2 A8 B4 A0 A1]
time 39315ms: Process A6 (tau 386ms) completed I/O; added to ready queue [Q A6 A9 A5 B2 A8 B4 A0 A1]
time 39753ms: Process B1 (tau 806ms) completed a CPU burst; 25 bursts to go [Q A6 A9 A5 B2 A8 B4 A0 A1]
time 39753ms: Recalculated tau for process B1: old tau 806ms ==> new tau 1114ms [Q A6 A9 A5 B2 A8 B4 A0 A1]
time 39753ms: Process B1 switching out of CPU; blocking on I/O until time 45315ms [Q A6 A9 A5 B2 A8 B4 A0 A1]
time 39757ms: Process A6 (tau 386ms) started using the CPU for 657ms burst [Q A9 A5 B2 A8 B4 A0 A1]
time 39884ms: Process B3 (tau 975ms) completed I/O; added to ready queue [Q A9 A5 B2 A8 B3 B4 A0 A1]
time 40021ms: Process A2 (tau 363ms) completed I/O; added to ready queue [Q A2 A9 A5 B2 A8 B3 B4 A0 A1]
time 40414ms: Process A6 (tau 386ms) completed a CPU burst; 11 bursts to go [Q A2 A9 A5 B2 A8 B3 B4 A0 A1]
time 40414ms: Recalculated tau for process A6: old tau 386ms ==> new tau 508ms [Q A2 A9 A5 B2 A8 B3 B4 A0 A1]
time 40414ms: Process A6 switching out of CPU; blocking on I/O until time 47528ms [Q A2 A9 A5 B2 A8 B3 B4 A0 A1]
time 40418ms: Process A2 (tau 363ms) started using the CPU for 1125ms burst [Q A9 A5 B2 A8 B3 B4 A0 A1]
time 40807ms: Process A3 (tau 952ms) completed I/O; added to ready queue [Q A9 A5 B2 A8 A3 B3 B4 A0 A1]
time 41193ms: Process A4 (tau 1226ms) completed I/O; added to ready queue [Q A9 A5 B2 A8 A3 B3 A4 B4 A0 A1]
time 41543ms: Process A2 terminated [Q A9 A5 B2 A8 A3 B3 A4 B4 A0 A1]
time 41547ms: Process A9 (tau 449ms) started using the CPU for 382ms burst [Q A5 B2 A8 A3 B3 A4 B4 A0 A1]
time 41929ms: Process A9 (tau 449ms) completed a CPU burst; 14 bursts to go [Q A5 B2 A8 A3 B3 A4 B4 A0 A1]
time 41929ms: Recalculated tau for process A9: old tau 449ms ==> new tau 419ms [Q A5 B2 A8 A3 B3 A4 B4 A0 A1]
time 41929ms: Process A9 switching out of CPU; blocking on I/O until time 49379ms [Q A5 B2 A8 A3 B3 A4 B4 A0 A1]
time 41933ms: Process A5 (tau 636ms) started using the CPU for 1088ms burst [Q B2 A8 A3 B3 A4 B4 A0 A1]
time 43021ms: Process A5 (tau 636ms) completed a CPU burst; 26 bursts to go [Q B2 A8 A3 B3 A4 B4 A0 A1]
time 43021ms: Recalculated tau for process A5: old tau 636ms ==> new tau 840ms [Q B2 A8 A3 B3 A4 B4 A0 A1]
time 43021ms: Process A5 switching out of CPU; blocking on I/O until time 55511ms [Q B2 A8 A3 B3 A4 B4 A0 A1]
time 43025ms: Process B2 (tau 835ms) started using the CPU for 1671ms burst [Q A8 A3 B3 A4 B4 A0 A1]
time 44696ms: Process B2 (tau 835ms) completed a CPU burst; 10 bursts to go [Q A8 A3 B3 A4 B4 A0 A1]
time 44696ms: Recalculated tau for process B2: old tau 835ms ==> new tau 1212ms [Q A8 A3 B3 A4 B4 A0 A1]
time 44696ms: Process B2 switching out of CPU; blocking on I/O until time 60970ms [Q A8 A3 B3 A4 B4 A0 A1]
time 44700ms: Process A8 (tau 841ms) started using the CPU for 495ms burst [Q A3 B3 A4 B4 A0 A1]
time 45195ms: Process A8 (tau 841ms) completed a CPU burst; 9 bursts to go [Q A3 B3 A4 B4 A0 A1]
time 45195ms: Recalculated tau for process A8: old tau 841ms ==> new tau 686ms [Q A3 B3 A4 B4 A0 A1]
time 45195ms: Process A8 switching out of CPU; blocking on I/O until time 54141ms [Q A3 B3 A4 B4 A0 A1]
time 45199ms: Process A3 (tau 952ms) started using the CPU for 556ms burst [Q B3 A4 B4 A0 A1]
time 45315ms: Process B1 (tau 1114ms) completed I/O; added to ready queue [Q B3 B1 A4 B4 A0 A1]
time 45740ms: Process B0 (tau 416ms) completed I/O; added to ready queue [Q B0 B3 B1 A4 B4 A0 A1]
time 45755ms: Process A3 (tau 952ms) completed a CPU burst; 7 bursts to go [Q B0 B3 B1 A4 B4 A0 A1]
time 45755ms: Recalculated tau for process A3: old tau 952ms ==> new tau 774ms [Q B0 B3 B1 A4 B4 A0 A1]
time 45755ms: Process A3 switching out of CPU; blocking on I/O until time 59917ms [Q B0 B3 B1 A4 B4 A0 A1]
time 45759ms: Process B0 (tau 416ms) started using the CPU for 1931ms burst [Q B3 B1 A4 B4 A0 A1]
time 47528ms: Process A6 (tau 508ms) completed I/O; added to ready queue [Q A6 B3 B1 A4 B4 A0 A1]
time 47690ms: Process B0 (tau 416ms) completed a CPU burst; 27 bursts to go [Q A6 B3 B1 A4 B4 A0 A1]
time 47690ms: Recalculated tau for process B0: old tau 416ms ==> new tau 1098ms [Q A6 B3 B1 A4 B4 A0 A1]
time 47690ms: Process B0 switching out of CPU; blocking on I/O until time 59140ms [Q A6 B3 B1 A4 B4 A0 A1]
time 47694ms: Process A6 (tau 508ms) started using the CPU for 421ms burst [Q B3 B1 A4 B4 A0 A1]
time 48115ms: Process A6 (tau 508ms) completed a CPU burst; 10 bursts to go [Q B3 B1 A4 B4 A0 A1]
time 48115ms: Recalculated tau for process A6: old tau 508ms ==> new tau 469ms [Q B3 B1 A4 B4 A0 A1]
time 48115ms: Process A6 switching out of CPU; blocking on I/O until time 57485ms [Q B3 B1 A4 B4 A0 A1]
time 48119ms: Process B3 (tau 975ms) started using the CPU for 1090ms burst [Q B1 A4 B4 A0 A1]
time 49209ms: Process B3 (tau 975ms) completed a CPU burst; 3 bursts to go [Q B1 A4 B4 A0 A1]
time 49209ms: Recalculated tau for process B3: old tau 975ms ==> new tau 1027ms [Q B1 A4 B4 A0 A1]
time 49209ms: Process B3 switching out of CPU; blocking on I/O until time 51251ms [Q B1 A4 B4 A0 A1]
time 49213ms: Process B1 (tau 1114ms) started using the CPU for 210ms burst [Q A4 B4 A0 A1]
time 49379ms: Process A9 (tau 419ms) completed I/O; added to ready queue [Q A9 A4 B4 A0 A1]
time 49423ms: Process B1 (tau 1114ms) completed a CPU burst; 24 bursts to go [Q A9 A4 B4 A0 A1]
time 49423ms: Recalculated tau for process B1: old tau 1114ms ==> new tau 708ms [Q A9 A4 B4 A0 A1]
time 49423ms: Process B1 switching out of CPU; blocking on I/O until time 53593ms [Q A9 A4 B4 A0 A1]
time 49427ms: Process A9 (tau 419ms) started using the CPU for 1135ms burst [Q A4 B4 A0 A1]
time 50562ms: Process A9 (tau 419ms) completed a CPU burst; 13 bursts to go [Q A4 B4 A0 A1]
time 50562ms: Recalculated tau for process A9: old tau 419ms ==> new tau 742ms [Q A4 B4 A0 A1]
time 50562ms: Process A9 switching out of CPU; blocking on I/O until time 62900ms [Q A4 B4 A0 A1]
time 50566ms: Process A4 (tau 1226ms) started using the CPU for 1417ms burst [Q B4 A0 A1]
time 51251ms: Process B3 (tau 1027ms) completed I/O; added to ready queue [Q B3 B4 A0 A1]
time 51363ms: Process B5 (tau 411ms) completed I/O; added to ready queue [Q B5 B3 B4 A0 A1]
time 51983ms: Process A4 (tau 1226ms) completed a CPU burst; 22 bursts to go [Q B5 B3 B4 A0 A1]
time 51983ms: Recalculated tau for process A4: old tau 1226ms ==> new tau 1312ms [Q B5 B3 B4 A0 A1]
time 51983ms: Process A4 switching out of CPU; blocking on I/O until time 66369ms [Q B5 B3 B4 A0 A1]
time 51987ms: Process B5 (tau 411ms) started using the CPU for 858ms burst [Q B3 B4 A0 A1]
time 52845ms: Process B5 (tau 411ms) completed a CPU burst; 22 bursts to go [Q B3 B4 A0 A1]
time 52845ms: Recalculated tau for process B5: old tau 411ms ==> new tau 613ms [Q B3 B4 A0 A1]
time 52845ms: Process B5 switching out of CPU; blocking on I/O until time 55151ms [Q B3 B4 A0 A1]
time 52849ms: Process B3 (tau 1027ms) started using the CPU for 363ms burst [Q B4 A0 A1]
time 53212ms: Process B3 (tau 1027ms) completed a CPU burst; 2 bursts to go [Q B4 A0 A1]
time 53212ms: Recalculated tau for process B3: old tau 1027ms ==> new tau 729ms [Q B4 A0 A1]
time 53212ms: Process B3 switching out of CPU; blocking on I/O until time 53278ms [Q B4 A0 A1]
time 53216ms: Process B4 (tau 1259ms) started using the CPU for 1404ms burst [Q A0 A1]
time 53278ms: Process B3 (tau 729ms) completed I/O; added to ready queue [Q B3 A0 A1]
time 53593ms: Process B1 (tau 708ms) completed I/O; added to ready queue [Q B1 B3 A0 A1]
time 54141ms: Process A8 (tau 686ms) completed I/O; added to ready queue [Q A8 B1 B3 A0 A1]
time 54620ms: Process B4 (tau 1259ms) completed a CPU burst; 18 bursts to go [Q A8 B1 B3 A0 A1]
time 54620ms: Recalculated tau for process B4: old tau 1259ms ==> new tau 1325ms [Q A8 B1 B3 A0 A1]
time 54620ms: Process B4 switching out of CPU; blocking on I/O until time 68326ms [Q A8 B1 B3 A0 A1]
time 54624ms: Process A8 (tau 686ms) started using the CPU for 410ms burst [Q B1 B3 A0 A1]
time 55034ms: Process A8 (tau 686ms) completed a CPU burst; 8 bursts to go [Q B1 B3 A0 A1]
time 55034ms: Recalculated tau for process A8: old tau 686ms ==> new tau 562ms [Q B1 B3 A0 A1]
time 55034ms: Process A8 switching out of CPU; blocking on I/O until time 58636ms [Q B1 B3 A0 A1]
time 55038ms: Process B1 (tau 708ms) started using the CPU for 8ms burst [Q B3 A0 A1]
time 55046ms: Process B1 (tau 708ms) completed a CPU burst; 23 bursts to go [Q B3 A0 A1]
time 55046ms: Recalculated tau for process B1: old tau 708ms ==> new tau 394ms [Q B3 A0 A1]
time 55046ms: Process B1 switching out of CPU; blocking on I/O until time 68008ms [Q B3 A0 A1]
time 55050ms: Process B3 (tau 729ms) started using the CPU for 1100ms burst [Q A0 A1]
time 55151ms: Process B5 (tau 613ms) completed I/O; added to ready queue [Q B5 A0 A1]
time 55511ms: Process A5 (tau 840ms) completed I/O; added to ready queue [Q B5 A5 A0 A1]
time 56150ms: Process B3 (tau 729ms) completed a CPU burst; 1 burst to go [Q B5 A5 A0 A1]
time 56150ms: Recalculated tau for process B3: old tau 729ms ==> new tau 896ms [Q B5 A5 A0 A1]
time 56150ms: Process B3 switching out of CPU; blocking on I/O until time 59648ms [Q B5 A5 A0 A1]
time 56154ms: Process B5 (tau 613ms) started using the CPU for 264ms burst [Q A5 A0 A1]
time 56418ms: Process B5 (tau 613ms) completed a CPU burst; 21 bursts to go [Q A5 A0 A1]
time 56418ms: Recalculated tau for process B5: old tau 613ms ==> new tau 456ms [Q A5 A0 A1]
time 56418ms: Process B5 switching out of CPU; blocking on I/O until time 56548ms [Q A5 A0 A1]
time 56422ms: Process A5 (tau 840ms) started using the CPU for 2024ms burst [Q A0 A1]
time 56548ms: Process B5 (tau 456ms) completed I/O; added to ready queue [Q B5 A0 A1]
time 57485ms: Process A6 (tau 469ms) completed I/O; added to ready queue [Q B5 A6 A0 A1]
time 58446ms: Process A5 (tau 840ms) completed a CPU burst; 25 bursts to go [Q B5 A6 A0 A1]
time 58446ms: Recalculated tau for process A5: old tau 840ms ==> new tau 1373ms [Q B5 A6 A0 A1]
time 58446ms: Process A5 switching out of CPU; blocking on I/O until time 61344ms [Q B5 A6 A0 A1]
time 58450ms: Process B5 (tau 456ms) started using the CPU for 1666ms burst [Q A6 A0 A1]
time 58636ms: Process A8 (tau 562ms) completed I/O; added to ready queue [Q A6 A8 A0 A1]
time 59140ms: Process B0 (tau 1098ms) completed I/O; added to ready queue [Q A6 A8 B0 A0 A1]
time 59648ms: Process B3 (tau 896ms) completed I/O; added to ready queue [Q A6 A8 B3 B0 A0 A1]
time 59917ms: Process A3 (tau 774ms) completed I/O; added to ready queue [Q A6 A8 A3 B3 B0 A0 A1]
time 60116ms: Process B5 (tau 456ms) completed a CPU burst; 20 bursts to go [Q A6 A8 A3 B3 B0 A0 A1]
time 60116ms: Recalculated tau for process B5: old tau 456ms ==> new tau 1001ms [Q A6 A8 A3 B3 B0 A0 A1]
time 60116ms: Process B5 switching out of CPU; blocking on I/O until time 65582ms [Q A6 A8 A3 B3 B0 A0 A1]
time 60120ms: Process A6 (tau 469ms) started using the CPU for 1178ms burst [Q A8 A3 B3 B0 A0 A1]
time 60970ms: Process B2 (tau 1212ms) completed I/O; added to ready queue [Q A8 A3 B3 B0 B2 A0 A1]
time 61298ms: Process A6 (tau 469ms) completed a CPU burst; 9 bursts to go [Q A8 A3 B3 B0 B2 A0 A1]
time 61298ms: Recalculated tau for process A6: old tau 469ms ==> new tau 789ms [Q A8 A3 B3 B0 B2 A0 A1]
time 61298ms: Process A6 switching out of CPU; blocking on I/O until time 65900ms [Q A8 A3 B3 B0 B2 A0 A1]
time 61302ms: Process A8 (tau 562ms) started using the CPU for 561ms burst [Q A3 B3 B0 B2 A0 A1]
time 61344ms: Process A5 (tau 1373ms) completed I/O; added to ready queue [Q A3 B3 B0 B2 A5 A0 A1]
time 61863ms: Process A8 (tau 562ms) completed a CPU burst; 7 bursts to go [Q A3 B3 B0 B2 A5 A0 A1]
time 61863ms: Recalculated tau for process A8: old tau 562ms ==> new tau 562ms [Q A3 B3 B0 B2 A5 A0 A1]
time 61863ms: Process A8 switching out of CPU; blocking on I/O until time 72425ms [Q A3 B3 B0 B2 A5 A0 A1]
time 61867ms: Process A3 (tau 774ms) started using the CPU for 755ms burst [Q B3 B0 B2 A5 A0 A1]
time 62622ms: Process A3 (tau 774ms) completed a CPU burst; 6 bursts to go [Q B3 B0 B2 A5 A0 A1]
time 62622ms: Recalculated tau for process A3: old tau 774ms ==> new tau 766ms [Q B3 B0 B2 A5 A0 A1]
time 62622ms: Process A3 switching out of CPU; blocking on I/O until time 65624ms [Q B3 B0 B2 A5 A0 A1]
time 62626ms: Process B3 (tau 896ms) started using the CPU for 251ms burst [Q B0 B2 A5 A0 A1]
time 62877ms: Process B3 terminated [Q B0 B2 A5 A0 A1]
time 62881ms: Process B0 (tau 1098ms) started using the CPU for 924ms burst [Q B2 A5 A0 A1]
time 62900ms: Process A9 (tau 742ms) completed I/O; added to ready queue [Q A9 B2 A5 A0 A1]
time 63805ms: Process B0 (tau 1098ms) completed a CPU burst; 26 bursts to go [Q A9 B2 A5 A0 A1]
time 63805ms: Recalculated tau for process B0: old tau 1098ms ==> new tau 1020ms [Q A9 B2 A5 A0 A1]
time 63805ms: Process B0 switching out of CPU; blocking on I/O until time 78615ms [Q A9 B2 A5 A0 A1]
time 63809ms: Process A9 (tau 742ms) started using the CPU for 767ms burst [Q B2 A5 A0 A1]
time 64576ms: Process A9 (tau 742ms) completed a CPU burst; 12 bursts to go [Q B2 A5 A0 A1]
time 64576ms: Recalculated tau for process A9: old tau 742ms ==> new tau 754ms [Q B2 A5 A0 A1]
time 64576ms: Process A9 switching out of CPU; blocking on I/O until time 64634ms [Q B2 A5 A0 A1]
time 64580ms: Process B2 (tau 1212ms) started using the CPU for 216ms burst [Q A5 A0 A1]
time 64634ms: Process A9 (tau 754ms) completed I/O; added to ready queue [Q A9 A5 A0 A1]
time 64796ms: Process B2 (tau 1212ms) completed a CPU burst; 9 bursts to go [Q A9 A5 A0 A1]
time 64796ms: Recalculated tau for process B2: old tau 1212ms ==> new tau 764ms [Q A9 A5 A0 A1]
time 64796ms: Process B2 switching out of CPU; blocking on I/O until time 67606ms [Q A9 A5 A0 A1]
time 64800ms: Process A9 (tau 754ms) started using the CPU for 749ms burst [Q A5 A0 A1]
time 65549ms: Process A9 (tau 754ms) completed a CPU burst; 11 bursts to go [Q A5 A0 A1]
time 65549ms: Recalculated tau for process A9: old tau 754ms ==> new tau 752ms [Q A5 A0 A1]
time 65549ms: Process A9 switching out of CPU; blocking on I/O until time 74839ms [Q A5 A0 A1]
time 65553ms: Process A5 (tau 1373ms) started using the CPU for 359ms burst [Q A0 A1]
time 65582ms: Process B5 (tau 1001ms) completed I/O; added to ready queue [Q B5 A0 A1]
time 65624ms: Process A3 (tau 766ms) completed I/O; added to ready queue [Q A3 B5 A0 A1]
time 65900ms: Process A6 (tau 789ms) completed I/O; added to ready queue [Q A3 A6 B5 A0 A1]
time 65912ms: Process A5 (tau 1373ms) completed a CPU burst; 24 bursts to go [Q A3 A6 B5 A0 A1]
time 65912ms: Recalculated tau for process A5: old tau 1373ms ==> new tau 917ms [Q A3 A6 B5 A0 A1]
time 65912ms: Process A5 switching out of CPU; blocking on I/O until time 72050ms [Q A3 A6 B5 A0 A1]
time 65916ms: Process A3 (tau 766ms) started using the CPU for 1219ms burst [Q A6 B5 A0 A1]
time 66369ms: Process A4 (tau 1312ms) completed I/O; added to ready queue [Q A6 B5 A4 A0 A1]
time 67135ms: Process A3 (tau 766ms) completed a CPU burst; 5 bursts to go [Q A6 B5 A4 A0 A1]
time 67135ms: Recalculated tau for process A3: old tau 766ms ==> new tau 970ms [Q A6 B5 A4 A0 A1]
time 67135ms: Process A3 switching out of CPU; blocking on I/O until time 68753ms [Q A6 B5 A4 A0 A1]
time 67139ms: Process A6 (tau 789ms) started using the CPU for 540ms burst [Q B5 A4 A0 A1]
time 67606ms: Process B2 (tau 764ms) completed I/O; added to ready queue [Q B2 B5 A4 A0 A1]
time 67679ms: Process A6 (tau 789ms) completed a CPU burst; 8 bursts to go [Q B2 B5 A4 A0 A1]
time 67679ms: Recalculated tau for process A6: old tau 789ms ==> new tau 677ms [Q B2 B5 A4 A0 A1]
time 67679ms: Process A6 switching out of CPU; blocking on I/O until time 70657ms [Q B2 B5 A4 A0 A1]
time 67683ms: Process B2 (tau 764ms) started using the CPU for 155ms burst [Q B5 A4 A0 A1]
time 67838ms: Process B2 (tau 764ms) completed a CPU burst; 8 bursts to go [Q B5 A4 A0 A1]
time 67838ms: Recalculated tau for process B2: old tau 764ms ==> new tau 490ms [Q B5 A4 A0 A1]
time 67838ms: Process B2 switching out of CPU; blocking on I/O until time 77152ms [Q B5 A4 A0 A1]
time 67842ms: Process B5 (tau 1001ms) started using the CPU for 1108ms burst [Q A4 A0 A1]
time 68008ms: Process B1 (tau 394ms) completed I/O; added to ready queue [Q B1 A4 A0 A1]
time 68326ms: Process B4 (tau 1325ms) completed I/O; added to ready queue [Q B1 A4 B4 A0 A1]
time 68753ms: Process A3 (tau 970ms) completed I/O; added to ready queue [Q B1 A3 A4 B4 A0 A1]
time 68950ms: Process B5 (tau 1001ms) completed a CPU burst; 19 bursts to go [Q B1 A3 A4 B4 A0 A1]
time 68950ms: Recalculated tau for process B5: old tau 1001ms ==> new tau 1050ms [Q B1 A3 A4 B4 A0 A1]
time 68950ms: Process B5 switching out of CPU; blocking on I/O until time 80776ms [Q B1 A3 A4 B4 A0 A1]
time 68954ms: Process B1 (tau 394ms) started using the CPU for 229ms burst [Q A3 A4 B4 A0 A1]
time 69183ms: Process B1 (tau 394ms) completed a CPU burst; 22 bursts to go [Q A3 A4 B4 A0 A1]
time 69183ms: Recalculated tau for process B1: old tau 394ms ==> new tau 320ms [Q A3 A4 B4 A0 A1]
time 69183ms: Process B1 switching out of CPU; blocking on I/O until time 76681ms [Q A3 A4 B4 A0 A1]
time 69187ms: Process A3 (tau 970ms) started using the CPU for 752ms burst [Q A4 B4 A0 A1]
time 69939ms: Process A3 (tau 970ms) completed a CPU burst; 4 bursts to go [Q A4 B4 A0 A1]
time 69939ms: Recalculated tau for process A3: old tau 970ms ==> new tau 872ms [Q A4 B4 A0 A1]
time 69939ms: Process A3 switching out of CPU; blocking on I/O until time 72925ms [Q A4 B4 A0 A1]
time 69943ms: Process A4 (tau 1312ms) started using the CPU for 58ms burst [Q B4 A0 A1]
time 70001ms: Process A4 (tau 1312ms) completed a CPU burst; 21 bursts to go [Q B4 A0 A1]
time 70001ms: Recalculated tau for process A4: old tau 1312ms ==> new tau 748ms [Q B4 A0 A1]
time 70001ms: Process A4 switching out of CPU; blocking on I/O until time 72435ms [Q B4 A0 A1]
time 70005ms: Process B4 (tau 1325ms) started using the CPU for 693ms burst [Q A0 A1]
time 70657ms: Process A6 (tau 677ms) completed I/O; added to ready queue [Q A6 A0 A1]
time 70698ms: Process B4 (tau 1325ms) completed a CPU burst; 17 bursts to go [Q A6 A0 A1]
time 70698ms: Recalculated tau for process B4: old tau 1325ms ==> new tau 1041ms [Q A6 A0 A1]
time 70698ms: Process B4 switching out of CPU; blocking on I/O until time 73788ms [Q A6 A0 A1]
time 70702ms: Process A6 (tau 677ms) started using the CPU for 684ms burst [Q A0 A1]
time 71386ms: Process A6 (tau 677ms) completed a CPU burst; 7 bursts to go [Q A0 A1]
time 71386ms: Recalculated tau for process A6: old tau 677ms ==> new tau 681ms [Q A0 A1]
time 71386ms: Process A6 switching out of CPU; blocking on I/O until time 81124ms [Q A0 A1]
time 71390ms: Process A0 (tau 1618ms) started using the CPU for 2652ms burst [Q A1]
time 72050ms: Process A5 (tau 917ms) completed I/O; added to ready queue [Q A5 A1]
time 72425ms: Process A8 (tau 562ms) completed I/O; added to ready queue [Q A8 A5 A1]
time 72435ms: Process A4 (tau 748ms) completed I/O; added to ready queue [Q A8 A4 A5 A1]
time 72925ms: Process A3 (tau 872ms) completed I/O; added to ready queue [Q A8 A4 A3 A5 A1]
time 73788ms: Process B4 (tau 1041ms) completed I/O; added to ready queue [Q A8 A4 A3 A5 B4 A1]
time 74042ms: Process A0 terminated [Q A8 A4 A3 A5 B4 A1]
time 74046ms: Process A8 (tau 562ms) started using the CPU for 38ms burst [Q A4 A3 A5 B4 A1]
time 74084ms: Process A8 (tau 562ms) completed a CPU burst; 6 bursts to go [Q A4 A3 A5 B4 A1]
time 74084ms: Recalculated tau for process A8: old tau 562ms ==> new tau 327ms [Q A4 A3 A5 B4 A1]
time 74084ms: Process A8 switching out of CPU; blocking on I/O until time 79470ms [Q A4 A3 A5 B4 A1]
time 74088ms: Process A4 (tau 748ms) started using the CPU for 233ms burst [Q A3 A5 B4 A1]
time 74321ms: Process A4 (tau 748ms) completed a CPU burst; 20 bursts to go [Q A3 A5 B4 A1]
time 74321ms: Recalculated tau for process A4: old tau 748ms ==> new tau 517ms [Q A3 A5 B4 A1]
time 74321ms: Process A4 switching out of CPU; blocking on I/O until time 78963ms [Q A3 A5 B4 A1]
time 74325ms: Process A3 (tau 872ms) started using the CPU for 702ms burst [Q A5 B4 A1]
time 74839ms: Process A9 (tau 752ms) completed I/O; added to ready queue [Q A9 A5 B4 A1]
time 75027ms: Process A3 (tau 872ms) completed a CPU burst; 3 bursts to go [Q A9 A5 B4 A1]
time 75027ms: Recalculated tau for process A3: old tau 872ms ==> new tau 796ms [Q A9 A5 B4 A1]
time 75027ms: Process A3 switching out of CPU; blocking on I/O until time 76285ms [Q A9 A5 B4 A1]
time 75031ms: Process A9 (tau 752ms) started using the CPU for 2023ms burst [Q A5 B4 A1]
time 76285ms: Process A3 (tau 796ms) completed I/O; added to ready queue [Q A3 A5 B4 A1]
time 76681ms: Process B1 (tau 320ms) completed I/O; added to ready queue [Q B1 A3 A5 B4 A1]
time 77054ms: Process A9 (tau 752ms) completed a CPU burst; 10 bursts to go [Q B1 A3 A5 B4 A1]
time 77054ms: Recalculated tau for process A9: old tau 752ms ==> new tau 1324ms [Q B1 A3 A5 B4 A1]
time 77054ms: Process A9 switching out of CPU; blocking on I/O until time 78688ms [Q B1 A3 A5 B4 A1]
time 77058ms: Process B1 (tau 320ms) started using the CPU for 1357ms burst [Q A3 A5 B4 A1]
time 77152ms: Process B2 (tau 490ms) completed I/O; added to ready queue [Q B2 A3 A5 B4 A1]
time 78415ms: Process B1 (tau 320ms) completed a CPU burst; 21 bursts to go [Q B2 A3 A5 B4 A1]
time 78415ms: Recalculated tau for process B1: old tau 320ms ==> new tau 787ms [Q B2 A3 A5 B4 A1]
time 78415ms: Process B1 switching out of CPU; blocking on I/O until time 79865ms [Q B2 A3 A5 B4 A1]
time 78419ms: Process B2 (tau 490ms) started using the CPU for 139ms burst [Q A3 A5 B4 A1]
time 78558ms: Process B2 (tau 490ms) completed a CPU burst; 7 bursts to go [Q A3 A5 B4 A1]
time 78558ms: Recalculated tau for process B2: old tau 490ms ==> new tau 333ms [Q A3 A5 B4 A1]
time 78558ms: Process B2 switching out of CPU; blocking on I/O until time 82752ms [Q A3 A5 B4 A1]
time 78562ms: Process A3 (tau 796ms) started using the CPU for 54ms burst [Q A5 B4 A1]
time 78615ms: Process B0 (tau 1020ms) completed I/O; added to ready queue [Q A5 B0 B4 A1]
time 78616ms: Process A3 (tau 796ms) completed a CPU burst; 2 bursts to go [Q A5 B0 B4 A1]
time 78616ms: Recalculated tau for process A3: old tau 796ms ==> new tau 463ms [Q A5 B0 B4 A1]
time 78616ms: Process A3 switching out of CPU; blocking on I/O until time 79418ms [Q A5 B0 B4 A1]
time 78620ms: Process A5 (tau 917ms) started using the CPU for 1016ms burst [Q B0 B4 A1]
time 78688ms: Process A9 (tau 1324ms) completed I/O; added to ready queue [Q B0 B4 A9 A1]
time 78963ms: Process A4 (tau 517ms) completed I/O; added to ready queue [Q A4 B0 B4 A9 A1]
time 79418ms: Process A3 (tau 463ms) completed I/O; added to ready queue [Q A3 A4 B0 B4 A9 A1]
time 79470ms: Process A8 (tau 327ms) completed I/O; added to ready queue [Q A8 A3 A4 B0 B4 A9 A1]
time 79636ms: Process A5 (tau 917ms) completed a CPU burst; 23 bursts to go [Q A8 A3 A4 B0 B4 A9 A1]
time 79636ms: Recalculated tau for process A5: old tau 917ms ==> new tau 962ms [Q A8 A3 A4 B0 B4 A9 A1]
time 79636ms: Process A5 switching out of CPU; blocking on I/O until time 83990ms [Q A8 A3 A4 B0 B4 A9 A1]
time 79640ms: Process A8 (tau 327ms) started using the CPU for 1156ms burst [Q A3 A4 B0 B4 A9 A1]
time 79865ms: Process B1 (tau 787ms) completed I/O; added to ready queue [Q A3 A4 B1 B0 B4 A9 A1]
time 80776ms: Process B5 (tau 1050ms) completed I/O; added to ready queue [Q A3 A4 B1 B0 B4 B5 A9 A1]
time 80796ms: Process A8 (tau 327ms) completed a CPU burst; 5 bursts to go [Q A3 A4 B1 B0 B4 B5 A9 A1]
time 80796ms: Recalculated tau for process A8: old tau 327ms ==> new tau 701ms [Q A3 A4 B1 B0 B4 B5 A9 A1]
time 80796ms: Process A8 switching out of CPU; blocking on I/O until time 84502ms [Q A3 A4 B1 B0 B4 B5 A9 A1]
time 80800ms: Process A3 (tau 463ms) started using the CPU for 40ms burst [Q A4 B1 B0 B4 B5 A9 A1]
time 80840ms: Process A3 (tau 463ms) completed a CPU burst; 1 burst to go [Q A4 B1 B0 B4 B5 A9 A1]
time 80840ms: Recalculated tau for process A3: old tau 463ms ==> new tau 273ms [Q A4 B1 B0 B4 B5 A9 A1]
time 80840ms: Process A3 switching out of CPU; blocking on I/O until time 81594ms [Q A4 B1 B0 B4 B5 A9 A1]
time 80844ms: Process A4 (tau 517ms) started using the CPU for 380ms burst [Q B1 B0 B4 B5 A9 A1]
time 81124ms: Process A6 (tau 681ms) completed I/O; added to ready queue [Q A6 B1 B0 B4 B5 A9 A1]
time 81224ms: Process A4 (tau 517ms) completed a CPU burst; 19 bursts to go [Q A6 B1 B0 B4 B5 A9 A1]
time 81224ms: Recalculated tau for process A4: old tau 517ms ==> new tau 456ms [Q A6 B1 B0 B4 B5 A9 A1]
time 81224ms: Process A4 switching out of CPU; blocking on I/O until time 96682ms [Q A6 B1 B0 B4 B5 A9 A1]
time 81228ms: Process A6 (tau 681ms) started using the CPU for 1616ms burst [Q B1 B0 B4 B5 A9 A1]
time 81594ms: Process A3 (tau 273ms) completed I/O; added to ready queue [Q A3 B1 B0 B4 B5 A9 A1]
time 82752ms: Process B2 (tau 333ms) completed I/O; added to ready queue [Q A3 B2 B1 B0 B4 B5 A9 A1]
time 82844ms: Process A6 (tau 681ms) completed a CPU burst; 6 bursts to go [Q A3 B2 B1 B0 B4 B5 A9 A1]
time 82844ms: Recalculated tau for process A6: old tau 681ms ==> new tau 1102ms [Q A3 B2 B1 B0 B4 B5 A9 A1]
time 82844ms: Process A6 switching out of CPU; blocking on I/O until time 87838ms [Q A3 B2 B1 B0 B4 B5 A9 A1]
time 82848ms: Process A3 (tau 273ms) started using the CPU for 887ms burst [Q B2 B1 B0 B4 B5 A9 A1]
time 83735ms: Process A3 terminated [Q B2 B1 B0 B4 B5 A9 A1]
time 83739ms: Process B2 (tau 333ms) started using the CPU for 1896ms burst [Q B1 B0 B4 B5 A9 A1]
time 83990ms: Process A5 (tau 962ms) completed I/O; added to ready queue [Q B1 A5 B0 B4 B5 A9 A1]
time 84502ms: Process A8 (tau 701ms) completed I/O; added to ready queue [Q A8 B1 A5 B0 B4 B5 A9 A1]
time 85635ms: Process B2 (tau 333ms) completed a CPU burst; 6 bursts to go [Q A8 B1 A5 B0 B4 B5 A9 A1]
time 85635ms: Recalculated tau for process B2: old tau 333ms ==> new tau 1037ms [Q A8 B1 A5 B0 B4 B5 A9 A1]
time 85635ms: Process B2 switching out of CPU; blocking on I/O until time 87989ms [Q A8 B1 A5 B0 B4 B5 A9 A1]
time 85639ms: Process A8 (tau 701ms) started using the CPU for 158ms burst [Q B1 A5 B0 B4 B5 A9 A1]
time 85797ms: Process A8 (tau 701ms) completed a CPU burst; 4 bursts to go [Q B1 A5 B0 B4 B5 A9 A1]
time 85797ms: Recalculated tau for process A8: old tau 701ms ==> new tau 457ms [Q B1 A5 B0 B4 B5 A9 A1]
time 85797ms: Process A8 switching out of CPU; blocking on I/O until time 87847ms [Q B1 A5 B0 B4 B5 A9 A1]
time 85801ms: Process B1 (tau 787ms) started using the CPU for 963ms burst [Q A5 B0 B4 B5 A9 A1]
time 86764ms: Process B1 (tau 787ms) completed a CPU burst; 20 bursts to go [Q A5 B0 B4 B5 A9 A1]
time 86764ms: Recalculated tau for process B1: old tau 787ms ==> new tau 867ms [Q A5 B0 B4 B5 A9 A1]
time 86764ms: Process B1 switching out of CPU; blocking on I/O until time 97278ms [Q A5 B0 B4 B5 A9 A1]
time 86768ms: Process A5 (tau 962ms) started using the CPU for 36ms burst [Q B0 B4 B5 A9 A1]
time 86804ms: Process A5 (tau 962ms) completed a CPU burst; 22 bursts to go [Q B0 B4 B5 A9 A1]
time 86804ms: Recalculated tau for process A5: old tau 962ms ==> new tau 546ms [Q B0 B4 B5 A9 A1]
time 86804ms: Process A5 switching out of CPU; blocking on I/O until time 89646ms [Q B0 B4 B5 A9 A1]
time 86808ms: Process B0 (tau 1020ms) started using the CPU for 1459ms burst [Q B4 B5 A9 A1]
time 87838ms: Process A6 (tau 1102ms) completed I/O; added to ready queue [Q B4 B5 A6 A9 A1]
time 87847ms: Process A8 (tau 457ms) completed I/O; added to ready queue [Q A8 B4 B5 A6 A9 A1]
time 87989ms: Process B2 (tau 1037ms) completed I/O; added to ready queue [Q A8 B2 B4 B5 A6 A9 A1]
time 88267ms: Process B0 (tau 1020ms) completed a CPU burst; 25 bursts to go [Q A8 B2 B4 B5 A6 A9 A1]
time 88267ms: Recalculated tau for process B0: old tau 1020ms ==> new tau 1218ms [Q A8 B2 B4 B5 A6 A9 A1]
time 88267ms: Process B0 switching out of CPU; blocking on I/O until time 94781ms [Q A8 B2 B4 B5 A6 A9 A1]
time 88271ms: Process A8 (tau 457ms) started using the CPU for 114ms burst [Q B2 B4 B5 A6 A9 A1]
time 88385ms: Process A8 (tau 457ms) completed a CPU burst; 3 bursts to go [Q B2 B4 B5 A6 A9 A1]
time 88385ms: Recalculated tau for process A8: old tau 457ms ==> new tau 303ms [Q B2 B4 B5 A6 A9 A1]
time 88385ms: Process A8 switching out of CPU; blocking on I/O until time 89163ms [Q B2 B4 B5 A6 A9 A1]
time 88389ms: Process B2 (tau 1037ms) started using the CPU for 322ms burst [Q B4 B5 A6 A9 A1]
time 88711ms: Process B2 (tau 1037ms) completed a CPU burst; 5 bursts to go [Q B4 B5 A6 A9 A1]
time 88711ms: Recalculated tau for process B2: old tau 1037ms ==> new tau 716ms [Q B4 B5 A6 A9 A1]
time 88711ms: Process B2 switching out of CPU; blocking on I/O until time 91433ms [Q B4 B5 A6 A9 A1]
time 88715ms: Process B4 (tau 1041ms) started using the CPU for 279ms burst [Q B5 A6 A9 A1]
time 88994ms: Process B4 (tau 1041ms) completed a CPU burst; 16 bursts to go [Q B5 A6 A9 A1]
time 88994ms: Recalculated tau for process B4: old tau 1041ms ==> new tau 699ms [Q B5 A6 A9 A1]
time 88994ms: Process B4 switching out of CPU; blocking on I/O until time 91188ms [Q B5 A6 A9 A1]
time 88998ms: Process B5 (tau 1050ms) started using the CPU for 110ms burst [Q A6 A9 A1]
time 89108ms: Process B5 (tau 1050ms) completed a CPU burst; 18 bursts to go [Q A6 A9 A1]
time 89108ms: Recalculated tau for process B5: old tau 1050ms ==> new tau 627ms [Q A6 A9 A1]
time 89108ms: Process B5 switching out of CPU; blocking on I/O until time 95686ms [Q A6 A9 A1]
time 89112ms: Process A6 (tau 1102ms) started using the CPU for 102ms burst [Q A9 A1]
time 89163ms: Process A8 (tau 303ms) completed I/O; added to ready queue [Q A8 A9 A1]
time 89214ms: Process A6 (tau 1102ms) completed a CPU burst; 5 bursts to go [Q A8 A9 A1]
time 89214ms: Recalculated tau for process A6: old tau 1102ms ==> new tau 652ms [Q A8 A9 A1]
time 89214ms: Process A6 switching out of CPU; blocking on I/O until time 104808ms [Q A8 A9 A1]
time 89218ms: Process A8 (tau 303ms) started using the CPU for 186ms burst [Q A9 A1]
time 89404ms: Process A8 (tau 303ms) completed a CPU burst; 2 bursts to go [Q A9 A1]
time 89404ms: Recalculated tau for process A8: old tau 303ms ==> new tau 251ms [Q A9 A1]
time 89404ms: Process A8 switching out of CPU; blocking on I/O until time 90126ms [Q A9 A1]
time 89408ms: Process A9 (tau 1324ms) started using the CPU for 870ms burst [Q A1]
time 89646ms: Process A5 (tau 546ms) completed I/O; added to ready queue [Q A5 A1]
time 90126ms: Process A8 (tau 251ms) completed I/O; added to ready queue [Q A8 A5 A1]
time 90278ms: Process A9 (tau 1324ms) completed a CPU burst; 9 bursts to go [Q A8 A5 A1]
time 90278ms: Recalculated tau for process A9: old tau 1324ms ==> new tau 1120ms [Q A8 A5 A1]
time 90278ms: Process A9 switching out of CPU; blocking on I/O until time 98536ms [Q A8 A5 A1]
time 90282ms: Process A8 (tau 251ms) started using the CPU for 44ms burst [Q A5 A1]
time 90326ms: Process A8 (tau 251ms) completed a CPU burst; 1 burst to go [Q A5 A1]
time 90326ms: Recalculated tau for process A8: old tau 251ms ==> new tau 158ms [Q A5 A1]
time 90326ms: Process A8 switching out of CPU; blocking on I/O until time 104336ms [Q A5 A1]
time 90330ms: Process A5 (tau 546ms) started using the CPU for 133ms burst [Q A1]
time 90463ms: Process A5 (tau 546ms) completed a CPU burst; 21 bursts to go [Q A1]
time 90463ms: Recalculated tau for process A5: old tau 546ms ==> new tau 361ms [Q A1]
time 90463ms: Process A5 switching out of CPU; blocking on I/O until time 92553ms [Q A1]
time 90467ms: Process A1 (tau 3763ms) started using the CPU for 7828ms burst [Q empty]
time 91188ms: Process B4 (tau 699ms) completed I/O; added to ready queue [Q B4]
time 91433ms: Process B2 (tau 716ms) completed I/O; added to ready queue [Q B4 B2]
time 92553ms: Process A5 (tau 361ms) completed I/O; added to ready queue [Q A5 B4 B2]
time 94781ms: Process B0 (tau 1218ms) completed I/O; added to ready queue [Q A5 B4 B2 B0]
time 95686ms: Process B5 (tau 627ms) completed I/O; added to ready queue [Q A5 B5 B4 B2 B0]
time 96682ms: Process A4 (tau 456ms) completed I/O; added to ready queue [Q A5 A4 B5 B4 B2 B0]
time 97278ms: Process B1 (tau 867ms) completed I/O; added to ready queue [Q A5 A4 B5 B4 B2 B1 B0]
time 98295ms: Process A1 (tau 3763ms) completed a CPU burst; 23 bursts to go [Q A5 A4 B5 B4 B2 B1 B0]
time 98295ms: Recalculated tau for process A1: old tau 3763ms ==> new tau 5593ms [Q A5 A4 B5 B4 B2 B1 B0]
time 98295ms: Process A1 switching out of CPU; blocking on I/O until time 98433ms [Q A5 A4 B5 B4 B2 B1 B0]
time 98299ms: Process A5 (tau 361ms) started using the CPU for 1105ms burst [Q A4 B5 B4 B2 B1 B0]
time 98433ms: Process A1 (tau 5593ms) completed I/O; added to ready queue [Q A4 B5 B4 B2 B1 B0 A1]
time 98536ms: Process A9 (tau 1120ms) completed I/O; added to ready queue [Q A4 B5 B4 B2 B1 A9 B0 A1]
time 99404ms: Process A5 (tau 361ms) completed a CPU burst; 20 bursts to go [Q A4 B5 B4 B2 B1 A9 B0 A1]
time 99404ms: Recalculated tau for process A5: old tau 361ms ==> new tau 696ms [Q A4 B5 B4 B2 B1 A9 B0 A1]
time 99404ms: Process A5 switching out of CPU; blocking on I/O until time 112878ms [Q A4 B5 B4 B2 B1 A9 B0 A1]
time 99408ms: Process A4 (tau 456ms) started using the CPU for 1081ms burst [Q B5 B4 B2 B1 A9 B0 A1]
time 100489ms: Process A4 (tau 456ms) completed a CPU burst; 18 bursts to go [Q B5 B4 B2 B1 A9 B0 A1]
time 100489ms: Recalculated tau for process A4: old tau 456ms ==> new tau 738ms [Q B5 B4 B2 B1 A9 B0 A1]
time 100489ms: Process A4 switching out of CPU; blocking on I/O until time 114523ms [Q B5 B4 B2 B1 A9 B0 A1]
time 100493ms: Process B5 (tau 627ms) started using the CPU for 780ms burst [Q B4 B2 B1 A9 B0 A1]
time 101273ms: Process B5 (tau 627ms) completed a CPU burst; 17 bursts to go [Q B4 B2 B1 A9 B0 A1]
time 101273ms: Recalculated tau for process B5: old tau 627ms ==> new tau 696ms [Q B4 B2 B1 A9 B0 A1]
time 101273ms: Process B5 switching out of CPU; blocking on I/O until time 104515ms [Q B4 B2 B1 A9 B0 A1]
time 101277ms: Process B4 (tau 699ms) started using the CPU for 1160ms burst [Q B2 B1 A9 B0 A1]
time 102437ms: Process B4 (tau 699ms) completed a CPU burst; 15 bursts to go [Q B2 B1 A9 B0 A1]
time 102437ms: Recalculated tau for process B4: old tau 699ms ==> new tau 907ms [Q B2 B1 A9 B0 A1]
time 102437ms: Process B4 switching out of CPU; blocking on I/O until time 106703ms [Q B2 B1 A9 B0 A1]
time 102441ms: Process B2 (tau 716ms) started using the CPU for 819ms burst [Q B1 A9 B0 A1]
time 103260ms: Process B2 (tau 716ms) completed a CPU burst; 4 bursts to go [Q B1 A9 B0 A1]
time 103260ms: Recalculated tau for process B2: old tau 716ms ==> new tau 763ms [Q B1 A9 B0 A1]
time 103260ms: Process B2 switching out of CPU; blocking on I/O until time 114878ms [Q B1 A9 B0 A1]
time 103264ms: Process B1 (tau 867ms) started using the CPU for 542ms burst [Q A9 B0 A1]
time 103806ms: Process B1 (tau 867ms) completed a CPU burst; 19 bursts to go [Q A9 B0 A1]
time 103806ms: Recalculated tau for process B1: old tau 867ms ==> new tau 721ms [Q A9 B0 A1]
time 103806ms: Process B1 switching out of CPU; blocking on I/O until time 104376ms [Q A9 B0 A1]
time 103810ms: Process A9 (tau 1120ms) started using the CPU for 1290ms burst [Q B0 A1]
time 104336ms: Process A8 (tau 158ms) completed I/O; added to ready queue [Q A8 B0 A1]
time 104376ms: Process B1 (tau 721ms) completed I/O; added to ready queue [Q A8 B1 B0 A1]
time 104515ms: Process B5 (tau 696ms) completed I/O; added to ready queue [Q A8 B5 B1 B0 A1]
time 104808ms: Process A6 (tau 652ms) completed I/O; added to ready queue [Q A8 A6 B5 B1 B0 A1]
time 105100ms: Process A9 (tau 1120ms) completed a CPU burst; 8 bursts to go [Q A8 A6 B5 B1 B0 A1]
time 105100ms: Recalculated tau for process A9: old tau 1120ms ==> new tau 1197ms [Q A8 A6 B5 B1 B0 A1]
time 105100ms: Process A9 switching out of CPU; blocking on I/O until time 118118ms [Q A8 A6 B5 B1 B0 A1]
time 105104ms: Process A8 (tau 158ms) started using the CPU for 625ms burst [Q A6 B5 B1 B0 A1]
time 105729ms: Process A8 terminated [Q A6 B5 B1 B0 A1]
time 105733ms: Process A6 (tau 652ms) started using the CPU for 1321ms burst [Q B5 B1 B0 A1]
time 106703ms: Process B4 (tau 907ms) completed I/O; added to ready queue [Q B5 B1 B4 B0 A1]
time 107054ms: Process A6 (tau 652ms) completed a CPU burst; 4 bursts to go [Q B5 B1 B4 B0 A1]
time 107054ms: Recalculated tau for process A6: old tau 652ms ==> new tau 954ms [Q B5 B1 B4 B0 A1]
time 107054ms: Process A6 switching out of CPU; blocking on I/O until time 113048ms [Q B5 B1 B4 B0 A1]
time 107058ms: Process B5 (tau 696ms) started using the CPU for 437ms burst [Q B1 B4 B0 A1]
time 107495ms: Process B5 (tau 696ms) completed a CPU burst; 16 bursts to go [Q B1 B4 B0 A1]
time 107495ms: Recalculated tau for process B5: old tau 696ms ==> new tau 580ms [Q B1 B4 B0 A1]
time 107495ms: Process B5 switching out of CPU; blocking on I/O until time 116881ms [Q B1 B4 B0 A1]
time 107499ms: Process B1 (tau 721ms) started using the CPU for 416ms burst [Q B4 B0 A1]
time 107915ms: Process B1 (tau 721ms) completed a CPU burst; 18 bursts to go [Q B4 B0 A1]
time 107915ms: Recalculated tau for process B1: old tau 721ms ==> new tau 584ms [Q B4 B0 A1]
time 107915ms: Process B1 switching out of CPU; blocking on I/O until time 110757ms [Q B4 B0 A1]
time 107919ms: Process B4 (tau 907ms) started using the CPU for 593ms burst [Q B0 A1]
time 108512ms: Process B4 (tau 907ms) completed a CPU burst; 14 bursts to go [Q B0 A1]
time 108512ms: Recalculated tau for process B4: old tau 907ms ==> new tau 766ms [Q B0 A1]
time 108512ms: Process B4 switching out of CPU; blocking on I/O until time 109578ms [Q B0 A1]
time 108516ms: Process B0 (tau 1218ms) started using the CPU for 1587ms burst [Q A1]
time 109578ms: Process B4 (tau 766ms) completed I/O; added to ready queue [Q B4 A1]
time 110103ms: Process B0 (tau 1218ms) completed a CPU burst; 24 bursts to go [Q B4 A1]
time 110103ms: Recalculated tau for process B0: old tau 1218ms ==> new tau 1385ms [Q B4 A1]
time 110103ms: Process B0 switching out of CPU; blocking on I/O until time 112993ms [Q B4 A1]
time 110107ms: Process B4 (tau 766ms) started using the CPU for 761ms burst [Q A1]
time 110757ms: Process B1 (tau 584ms) completed I/O; added to ready queue [Q B1 A1]
time 110868ms: Process B4 (tau 766ms) completed a CPU burst; 13 bursts to go [Q B1 A1]
time 110868ms: Recalculated tau for process B4: old tau 766ms ==> new tau 764ms [Q B1 A1]
time 110868ms: Process B4 switching out of CPU; blocking on I/O until time 117150ms [Q B1 A1]
time 110872ms: Process B1 (tau 584ms) started using the CPU for 211ms burst [Q A1]
time 111083ms: Process B1 (tau 584ms) completed a CPU burst; 17 bursts to go [Q A1]
time 111083ms: Recalculated tau for process B1: old tau 584ms ==> new tau 417ms [Q A1]
time 111083ms: Process B1 switching out of CPU; blocking on I/O until time 116941ms [Q A1]
time 111087ms: Process A1 (tau 5593ms) started using the CPU for 5880ms burst [Q empty]
time 112878ms: Process A5 (tau 696ms) completed I/O; added to ready queue [Q A5]
time 112993ms: Process B0 (tau 1385ms) completed I/O; added to ready queue [Q A5 B0]
time 113048ms: Process A6 (tau 954ms) completed I/O; added to ready queue [Q A5 A6 B0]
time 114523ms: Process A4 (tau 738ms) completed I/O; added to ready queue [Q A5 A4 A6 B0]
time 114878ms: Process B2 (tau 763ms) completed I/O; added to ready queue [Q A5 A4 B2 A6 B0]
time 116881ms: Process B5 (tau 580ms) completed I/O; added to ready queue [Q B5 A5 A4 B2 A6 B0]
time 116941ms: Process B1 (tau 417ms) completed I/O; added to ready queue [Q B1 B5 A5 A4 B2 A6 B0]
time 116967ms: Process A1 (tau 5593ms) completed a CPU burst; 22 bursts to go [Q B1 B5 A5 A4 B2 A6 B0]
time 116967ms: Recalculated tau for process A1: old tau 5593ms ==> new tau 5723ms [Q B1 B5 A5 A4 B2 A6 B0]
time 116967ms: Process A1 switching out of CPU; blocking on I/O until time 118650ms [Q B1 B5 A5 A4 B2 A6 B0]
time 116971ms: Process B1 (tau 417ms) started using the CPU for 255ms burst [Q B5 A5 A4 B2 A6 B0]
time 117150ms: Process B4 (tau 764ms) completed I/O; added to ready queue [Q B5 A5 A4 B2 B4 A6 B0]
time 117226ms: Process B1 (tau 417ms) completed a CPU burst; 16 bursts to go [Q B5 A5 A4 B2 B4 A6 B0]
time 117226ms: Recalculated tau for process B1: old tau 417ms ==> new tau 345ms [Q B5 A5 A4 B2 B4 A6 B0]
time 117226ms: Process B1 switching out of CPU; blocking on I/O until time 125836ms [Q B5 A5 A4 B2 B4 A6 B0]
time 117230ms: Process B5 (tau 580ms) started using the CPU for 303ms burst [Q A5 A4 B2 B4 A6 B0]
time 117533ms: Process B5 (tau 580ms) completed a CPU burst; 15 bursts to go [Q A5 A4 B2 B4 A6 B0]
time 117533ms: Recalculated tau for process B5: old tau 580ms ==> new tau 456ms [Q A5 A4 B2 B4 A6 B0]
time 117533ms: Process B5 switching out of CPU; blocking on I/O until time 133519ms [Q A5 A4 B2 B4 A6 B0]
time 117537ms: Process A5 (tau 696ms) started using the CPU for 1862ms burst [Q A4 B2 B4 A6 B0]
time 118118ms: Process A9 (tau 1197ms) completed I/O; added to ready queue [Q A4 B2 B4 A6 A9 B0]
time 118650ms: Process A1 (tau 5723ms) completed I/O; added to ready queue [Q A4 B2 B4 A6 A9 B0 A1]
time 119399ms: Process A5 (tau 696ms) completed a CPU burst; 19 bursts to go [Q A4 B2 B4 A6 A9 B0 A1]
time 119399ms: Recalculated tau for process A5: old tau 696ms ==> new tau 1221ms [Q A4 B2 B4 A6 A9 B0 A1]
time 119399ms: Process A5 switching out of CPU; blocking on I/O until time 123033ms [Q A4 B2 B4 A6 A9 B0 A1]
time 119403ms: Process A4 (tau 738ms) started using the CPU for 517ms burst [Q B2 B4 A6 A9 B0 A1]
time 119920ms: Process A4 (tau 738ms) completed a CPU burst; 17 bursts to go [Q B2 B4 A6 A9 B0 A1]
time 119920ms: Recalculated tau for process A4: old tau 738ms ==> new tau 639ms [Q B2 B4 A6 A9 B0 A1]
time 119920ms: Process A4 switching out of CPU; blocking on I/O until time 125978ms [Q B2 B4 A6 A9 B0 A1]
time 119924ms: Process B2 (tau 763ms) started using the CPU for 481ms burst [Q B4 A6 A9 B0 A1]
time 120405ms: Process B2 (tau 763ms) completed a CPU burst; 3 bursts to go [Q B4 A6 A9 B0 A1]
time 120405ms: Recalculated tau for process B2: old tau 763ms ==> new tau 637ms [Q B4 A6 A9 B0 A1]
time 120405ms: Process B2 switching out of CPU; blocking on I/O until time 122535ms [Q B4 A6 A9 B0 A1]
time 120409ms: Process B4 (tau 764ms) started using the CPU for 869ms burst [Q A6 A9 B0 A1]
time 121278ms: Process B4 (tau 764ms) completed a CPU burst; 12 bursts to go [Q A6 A9 B0 A1]
time 121278ms: Recalculated tau for process B4: old tau 764ms ==> new tau 812ms [Q A6 A9 B0 A1]
time 121278ms: Process B4 switching out of CPU; blocking on I/O until time 134104ms [Q A6 A9 B0 A1]
time 121282ms: Process A6 (tau 954ms) started using the CPU for 1468ms burst [Q A9 B0 A1]
time 122535ms: Process B2 (tau 637ms) completed I/O; added to ready queue [Q B2 A9 B0 A1]
time 122750ms: Process A6 (tau 954ms) completed a CPU burst; 3 bursts to go [Q B2 A9 B0 A1]
time 122750ms: Recalculated tau for process A6: old tau 954ms ==> new tau 1186ms [Q B2 A9 B0 A1]
time 122750ms: Process A6 switching out of CPU; blocking on I/O until time 123824ms [Q B2 A9 B0 A1]
time 122754ms: Process B2 (tau 637ms) started using the CPU for 451ms burst [Q A9 B0 A1]
time 123033ms: Process A5 (tau 1221ms) completed I/O; added to ready queue [Q A9 A5 B0 A1]
time 123205ms: Process B2 (tau 637ms) completed a CPU burst; 2 bursts to go [Q A9 A5 B0 A1]
time 123205ms: Recalculated tau for process B2: old tau 637ms ==> new tau 554ms [Q A9 A5 B0 A1]
time 123205ms: Process B2 switching out of CPU; blocking on I/O until time 125847ms [Q A9 A5 B0 A1]
time 123209ms: Process A9 (tau 1197ms) started using the CPU for 487ms burst [Q A5 B0 A1]
time 123696ms: Process A9 (tau 1197ms) completed a CPU burst; 7 bursts to go [Q A5 B0 A1]
time 123696ms: Recalculated tau for process A9: old tau 1197ms ==> new tau 878ms [Q A5 B0 A1]
time 123696ms: Process A9 switching out of CPU; blocking on I/O until time 139410ms [Q A5 B0 A1]
time 123700ms: Process A5 (tau 1221ms) started using the CPU for 582ms burst [Q B0 A1]
time 123824ms: Process A6 (tau 1186ms) completed I/O; added to ready queue [Q A6 B0 A1]
time 124282ms: Process A5 (tau 1221ms) completed a CPU burst; 18 bursts to go [Q A6 B0 A1]
time 124282ms: Recalculated tau for process A5: old tau 1221ms ==> new tau 934ms [Q A6 B0 A1]
time 124282ms: Process A5 switching out of CPU; blocking on I/O until time 137044ms [Q A6 B0 A1]
time 124286ms: Process A6 (tau 1186ms) started using the CPU for 333ms burst [Q B0 A1]
time 124619ms: Process A6 (tau 1186ms) completed a CPU burst; 2 bursts to go [Q B0 A1]
time 124619ms: Recalculated tau for process A6: old tau 1186ms ==> new tau 803ms [Q B0 A1]
time 124619ms: Process A6 switching out of CPU; blocking on I/O until time 125781ms [Q B0 A1]
time 124623ms: Process B0 (tau 1385ms) started using the CPU for 229ms burst [Q A1]
time 124852ms: Process B0 (tau 1385ms) completed a CPU burst; 23 bursts to go [Q A1]
time 124852ms: Recalculated tau for process B0: old tau 1385ms ==> new tau 865ms [Q A1]
time 124852ms: Process B0 switching out of CPU; blocking on I/O until time 129062ms [Q A1]
time 124856ms: Process A1 (tau 5723ms) started using the CPU for 1912ms burst [Q empty]
time 125781ms: Process A6 (tau 803ms) completed I/O; added to ready queue [Q A6]
time 125836ms: Process B1 (tau 345ms) completed I/O; added to ready queue [Q B1 A6]
time 125847ms: Process B2 (tau 554ms) completed I/O; added to ready queue [Q B1 B2 A6]
time 125978ms: Process A4 (tau 639ms) completed I/O; added to ready queue [Q B1 B2 A4 A6]
time 126768ms: Process A1 (tau 5723ms) completed a CPU burst; 21 bursts to go [Q B1 B2 A4 A6]
time 126768ms: Recalculated tau for process A1: old tau 5723ms ==> new tau 4009ms [Q B1 B2 A4 A6]
time 126768ms: Process A1 switching out of CPU; blocking on I/O until time 127000ms [Q B1 B2 A4 A6]
time 126772ms: Process B1 (tau 345ms) started using the CPU for 1565ms burst [Q B2 A4 A6]
time 127000ms: Process A1 (tau 4009ms) completed I/O; added to ready queue [Q B2 A4 A6 A1]
time 128337ms: Process B1 (tau 345ms) completed a CPU burst; 15 bursts to go [Q B2 A4 A6 A1]
time 128337ms: Recalculated tau for process B1: old tau 345ms ==> new tau 894ms [Q B2 A4 A6 A1]
time 128337ms: Process B1 switching out of CPU; blocking on I/O until time 133387ms [Q B2 A4 A6 A1]
time 128341ms: Process B2 (tau 554ms) started using the CPU for 1625ms burst [Q A4 A6 A1]
time 129062ms: Process B0 (tau 865ms) completed I/O; added to ready queue [Q A4 A6 B0 A1]
time 129966ms: Process B2 (tau 554ms) completed a CPU burst; 1 burst to go [Q A4 A6 B0 A1]
time 129966ms: Recalculated tau for process B2: old tau 554ms ==> new tau 1036ms [Q A4 A6 B0 A1]
time 129966ms: Process B2 switching out of CPU; blocking on I/O until time 145616ms [Q A4 A6 B0 A1]
time 129970ms: Process A4 (tau 639ms) started using the CPU for 922ms burst [Q A6 B0 A1]
time 130892ms: Process A4 (tau 639ms) completed a CPU burst; 16 bursts to go [Q A6 B0 A1]
time 130892ms: Recalculated tau for process A4: old tau 639ms ==> new tau 767ms [Q A6 B0 A1]
time 130892ms: Process A4 switching out of CPU; blocking on I/O until time 132006ms [Q A6 B0 A1]
time 130896ms: Process A6 (tau 803ms) started using the CPU for 417ms burst [Q B0 A1]
time 131313ms: Process A6 (tau 803ms) completed a CPU burst; 1 burst to go [Q B0 A1]
time 131313ms: Recalculated tau for process A6: old tau 803ms ==> new tau 630ms [Q B0 A1]
time 131313ms: Process A6 switching out of CPU; blocking on I/O until time 136163ms [Q B0 A1]
time 131317ms: Process B0 (tau 865ms) started using the CPU for 1386ms burst [Q A1]
time 132006ms: Process A4 (tau 767ms) completed I/O; added to ready queue [Q A4 A1]
time 132703ms: Process B0 (tau 865ms) completed a CPU burst; 22 bursts to go [Q A4 A1]
time 132703ms: Recalculated tau for process B0: old tau 865ms ==> new tau 1100ms [Q A4 A1]
time 132703ms: Process B0 switching out of CPU; blocking on I/O until time 142297ms [Q A4 A1]
time 132707ms: Process A4 (tau 767ms) started using the CPU for 721ms burst [Q A1]
time 133387ms: Process B1 (tau 894ms) completed I/O; added to ready queue [Q B1 A1]
time 133428ms: Process A4 (tau 767ms) completed a CPU burst; 15 bursts to go [Q B1 A1]
time 133428ms: Recalculated tau for process A4: old tau 767ms ==> new tau 747ms [Q B1 A1]
time 133428ms: Process A4 switching out of CPU; blocking on I/O until time 134606ms [Q B1 A1]
time 133432ms: Process B1 (tau 894ms) started using the CPU for 1245ms burst [Q A1]
time 133519ms: Process B5 (tau 456ms) completed I/O; added to ready queue [Q B5 A1]
time 134104ms: Process B4 (tau 812ms) completed I/O; added to ready queue [Q B5 B4 A1]
time 134606ms: Process A4 (tau 747ms) completed I/O; added to ready queue [Q B5 A4 B4 A1]
time 134677ms: Process B1 (tau 894ms) completed a CPU burst; 14 bursts to go [Q B5 A4 B4 A1]
time 134677ms: Recalculated tau for process B1: old tau 894ms ==> new tau 1052ms [Q B5 A4 B4 A1]
time 134677ms: Process B1 switching out of CPU; blocking on I/O until time 137151ms [Q B5 A4 B4 A1]
time 134681ms: Process B5 (tau 456ms) started using the CPU for 197ms burst [Q A4 B4 A1]
time 134878ms: Process B5 (tau 456ms) completed a CPU burst; 14 bursts to go [Q A4 B4 A1]
time 134878ms: Recalculated tau for process B5: old tau 456ms ==> new tau 340ms [Q A4 B4 A1]
time 134878ms: Process B5 switching out of CPU; blocking on I/O until time 137768ms [Q A4 B4 A1]
time 134882ms: Process A4 (tau 747ms) started using the CPU for 1208ms burst [Q B4 A1]
time 136090ms: Process A4 (tau 747ms) completed a CPU burst; 14 bursts to go [Q B4 A1]
time 136090ms: Recalculated tau for process A4: old tau 747ms ==> new tau 955ms [Q B4 A1]
time 136090ms: Process A4 switching out of CPU; blocking on I/O until time 136372ms [Q B4 A1]
time 136094ms: Process B4 (tau 812ms) started using the CPU for 233ms burst [Q A1]
time 136163ms: Process A6 (tau 630ms) completed I/O; added to ready queue [Q A6 A1]
time 136327ms: Process B4 (tau 812ms) completed a CPU burst; 11 bursts to go [Q A6 A1]
time 136327ms: Recalculated tau for process B4: old tau 812ms ==> new tau 552ms [Q A6 A1]
time 136327ms: Process B4 switching out of CPU; blocking on I/O until time 140385ms [Q A6 A1]
time 136331ms: Process A6 (tau 630ms) started using the CPU for 951ms burst [Q A1]
time 136372ms: Process A4 (tau 955ms) completed I/O; added to ready queue [Q A4 A1]
time 137044ms: Process A5 (tau 934ms) completed I/O; added to ready queue [Q A5 A4 A1]
time 137151ms: Process B1 (tau 1052ms) completed I/O; added to ready queue [Q A5 A4 B1 A1]
time 137282ms: Process A6 terminated [Q A5 A4 B1 A1]
time 137286ms: Process A5 (tau 934ms) started using the CPU for 512ms burst [Q A4 B1 A1]
time 137768ms: Process B5 (tau 340ms) completed I/O; added to ready queue [Q B5 A4 B1 A1]
time 137798ms: Process A5 (tau 934ms) completed a CPU burst; 17 bursts to go [Q B5 A4 B1 A1]
time 137798ms: Recalculated tau for process A5: old tau 934ms ==> new tau 745ms [Q B5 A4 B1 A1]
time 137798ms: Process A5 switching out of CPU; blocking on I/O until time 142208ms [Q B5 A4 B1 A1]
time 137802ms: Process B5 (tau 340ms) started using the CPU for 54ms burst [Q A4 B1 A1]
time 137856ms: Process B5 (tau 340ms) completed a CPU burst; 13 bursts to go [Q A4 B1 A1]
time 137856ms: Recalculated tau for process B5: old tau 340ms ==> new tau 212ms [Q A4 B1 A1]
time 137856ms: Process B5 switching out of CPU; blocking on I/O until time 145954ms [Q A4 B1 A1]
time 137860ms: Process A4 (tau 955ms) started using the CPU for 1559ms burst [Q B1 A1]
time 139410ms: Process A9 (tau 878ms) completed I/O; added to ready queue [Q A9 B1 A1]
time 139419ms: Process A4 (tau 955ms) completed a CPU burst; 13 bursts to go [Q A9 B1 A1]
time 139419ms: Recalculated tau for process A4: old tau 955ms ==> new tau 1227ms [Q A9 B1 A1]
time 139419ms: Process A4 switching out of CPU; blocking on I/O until time 141269ms [Q A9 B1 A1]
time 139423ms: Process A9 (tau 878ms) started using the CPU for 173ms burst [Q B1 A1]
time 139596ms: Process A9 (tau 878ms) completed a CPU burst; 6 bursts to go [Q B1 A1]
time 139596ms: Recalculated tau for process A9: old tau 878ms ==> new tau 561ms [Q B1 A1]
time 139596ms: Process A9 switching out of CPU; blocking on I/O until time 147214ms [Q B1 A1]
time 139600ms: Process B1 (tau 1052ms) started using the CPU for 1071ms burst [Q A1]
time 140385ms: Process B4 (tau 552ms) completed I/O; added to ready queue [Q B4 A1]
time 140671ms: Process B1 (tau 1052ms) completed a CPU burst; 13 bursts to go [Q B4 A1]
time 140671ms: Recalculated tau for process B1: old tau 1052ms ==> new tau 1061ms [Q B4 A1]
time 140671ms: Process B1 switching out of CPU; blocking on I/O until time 140825ms [Q B4 A1]
time 140675ms: Process B4 (tau 552ms) started using the CPU for 383ms burst [Q A1]
time 140825ms: Process B1 (tau 1061ms) completed I/O; added to ready queue [Q B1 A1]
time 141058ms: Process B4 (tau 552ms) completed a CPU burst; 10 bursts to go [Q B1 A1]
time 141058ms: Recalculated tau for process B4: old tau 552ms ==> new tau 476ms [Q B1 A1]
time 141058ms: Process B4 switching out of CPU; blocking on I/O until time 145860ms [Q B1 A1]
time 141062ms: Process B1 (tau 1061ms) started using the CPU for 1182ms burst [Q A1]
time 141269ms: Process A4 (tau 1227ms) completed I/O; added to ready queue [Q A4 A1]
time 142208ms: Process A5 (tau 745ms) completed I/O; added to ready queue [Q A5 A4 A1]
time 142244ms: Process B1 (tau 1061ms) completed a CPU burst; 12 bursts to go [Q A5 A4 A1]
time 142244ms: Recalculated tau for process B1: old tau 1061ms ==> new tau 1116ms [Q A5 A4 A1]
time 142244ms: Process B1 switching out of CPU; blocking on I/O until time 153494ms [Q A5 A4 A1]
time 142248ms: Process A5 (tau 745ms) started using the CPU for 403ms burst [Q A4 A1]
time 142297ms: Process B0 (tau 1100ms) completed I/O; added to ready queue [Q B0 A4 A1]
time 142651ms: Process A5 (tau 745ms) completed a CPU burst; 16 bursts to go [Q B0 A4 A1]
time 142651ms: Recalculated tau for process A5: old tau 745ms ==> new tau 592ms [Q B0 A4 A1]
time 142651ms: Process A5 switching out of CPU; blocking on I/O until time 148893ms [Q B0 A4 A1]
time 142655ms: Process B0 (tau 1100ms) started using the CPU for 39ms burst [Q A4 A1]
time 142694ms: Process B0 (tau 1100ms) completed a CPU burst; 21 bursts to go [Q A4 A1]
time 142694ms: Recalculated tau for process B0: old tau 1100ms ==> new tau 623ms [Q A4 A1]
time 142694ms: Process B0 switching out of CPU; blocking on I/O until time 148456ms [Q A4 A1]
time 142698ms: Process A4 (tau 1227ms) started using the CPU for 573ms burst [Q A1]
time 143271ms: Process A4 (tau 1227ms) completed a CPU burst; 12 bursts to go [Q A1]
time 143271ms: Recalculated tau for process A4: old tau 1227ms ==> new tau 933ms [Q A1]
time 143271ms: Process A4 switching out of CPU; blocking on I/O until time 156617ms [Q A1]
time 143275ms: Process A1 (tau 4009ms) started using the CPU for 200ms burst [Q empty]
time 143475ms: Process A1 (tau 4009ms) completed a CPU burst; 20 bursts to go [Q empty]
time 143475ms: Recalculated tau for process A1: old tau 4009ms ==> new tau 2295ms [Q empty]
time 143475ms: Process A1 switching out of CPU; blocking on I/O until time 143907ms [Q empty]
time 143907ms: Process A1 (tau 2295ms) completed I/O; added to ready queue [Q A1]
time 143909ms: Process A1 (tau 2295ms) started using the CPU for 7884ms burst [Q empty]
time 145616ms: Process B2 (tau 1036ms) completed I/O; added to ready queue [Q B2]
time 145860ms: Process B4 (tau 476ms) completed I/O; added to ready queue [Q B4 B2]
time 145954ms: Process B5 (tau 212ms) completed I/O; added to ready queue [Q B5 B4 B2]
time 147214ms: Process A9 (tau 561ms) completed I/O; added to ready queue [Q B5 B4 A9 B2]
time 148456ms: Process B0 (tau 623ms) completed I/O; added to ready queue [Q B5 B4 A9 B0 B2]
time 148893ms: Process A5 (tau 592ms) completed I/O; added to ready queue [Q B5 B4 A9 A5 B0 B2]
time 151793ms: Process A1 (tau 2295ms) completed a CPU burst; 19 bursts to go [Q B5 B4 A9 A5 B0 B2]
time 151793ms: Recalculated tau for process A1: old tau 2295ms ==> new tau 4811ms [Q B5 B4 A9 A5 B0 B2]
time 151793ms: Process A1 switching out of CPU; blocking on I/O until time 152053ms [Q B5 B4 A9 A5 B0 B2]
time 151797ms: Process B5 (tau 212ms) started using the CPU for 296ms burst [Q B4 A9 A5 B0 B2]
time 152053ms: Process A1 (tau 4811ms) completed I/O; added to ready queue [Q B4 A9 A5 B0 B2 A1]
time 152093ms: Process B5 (tau 212ms) completed a CPU burst; 12 bursts to go [Q B4 A9 A5 B0 B2 A1]
time 152093ms: Recalculated tau for process B5: old tau 212ms ==> new tau 250ms [Q B4 A9 A5 B0 B2 A1]
time 152093ms: Process B5 switching out of CPU; blocking on I/O until time 158391ms [Q B4 A9 A5 B0 B2 A1]
time 152097ms: Process B4 (tau 476ms) started using the CPU for 634ms burst [Q A9 A5 B0 B2 A1]
time 152731ms: Process B4 (tau 476ms) completed a CPU burst; 9 bursts to go [Q A9 A5 B0 B2 A1]
time 152731ms: Recalculated tau for process B4: old tau 476ms ==> new tau 548ms [Q A9 A5 B0 B2 A1]
time 152731ms: Process B4 switching out of CPU; blocking on I/O until time 163989ms [Q A9 A5 B0 B2 A1]
time 152735ms: Process A9 (tau 561ms) started using the CPU for 780ms burst [Q A5 B0 B2 A1]
time 153494ms: Process B1 (tau 1116ms) completed I/O; added to ready queue [Q A5 B0 B2 B1 A1]
time 153515ms: Process A9 (tau 561ms) completed a CPU burst; 5 bursts to go [Q A5 B0 B2 B1 A1]
time 153515ms: Recalculated tau for process A9: old tau 561ms ==> new tau 660ms [Q A5 B0 B2 B1 A1]
time 153515ms: Process A9 switching out of CPU; blocking on I/O until time 156589ms [Q A5 B0 B2 B1 A1]
time 153519ms: Process A5 (tau 592ms) started using the CPU for 505ms burst [Q B0 B2 B1 A1]
time 154024ms: Process A5 (tau 592ms) completed a CPU burst; 15 bursts to go [Q B0 B2 B1 A1]
time 154024ms: Recalculated tau for process A5: old tau 592ms ==> new tau 553ms [Q B0 B2 B1 A1]
time 154024ms: Process A5 switching out of CPU; blocking on I/O until time 154826ms [Q B0 B2 B1 A1]
time 154028ms: Process B0 (tau 623ms) started using the CPU for 848ms burst [Q B2 B1 A1]
time 154826ms: Process A5 (tau 553ms) completed I/O; added to ready queue [Q A5 B2 B1 A1]
time 154876ms: Process B0 (tau 623ms) completed a CPU burst; 20 bursts to go [Q A5 B2 B1 A1]
time 154876ms: Recalculated tau for process B0: old tau 623ms ==> new tau 725ms [Q A5 B2 B1 A1]
time 154876ms: Process B0 switching out of CPU; blocking on I/O until time 156198ms [Q A5 B2 B1 A1]
time 154880ms: Process A5 (tau 553ms) started using the CPU for 139ms burst [Q B2 B1 A1]
time 155019ms: Process A5 (tau 553ms) completed a CPU burst; 14 bursts to go [Q B2 B1 A1]
time 155019ms: Recalculated tau for process A5: old tau 553ms ==> new tau 367ms [Q B2 B1 A1]
time 155019ms: Process A5 switching out of CPU; blocking on I/O until time 160069ms [Q B2 B1 A1]
time 155023ms: Process B2 (tau 1036ms) started using the CPU for 724ms burst [Q B1 A1]
time 155747ms: Process B2 terminated [Q B1 A1]
time 155751ms: Process B1 (tau 1116ms) started using the CPU for 20ms burst [Q A1]
time 155771ms: Process B1 (tau 1116ms) completed a CPU burst; 11 bursts to go [Q A1]
time 155771ms: Recalculated tau for process B1: old tau 1116ms ==> new tau 623ms [Q A1]
time 155771ms: Process B1 switching out of CPU; blocking on I/O until time 162013ms [Q A1]
time 155775ms: Process A1 (tau 4811ms) started using the CPU for 2308ms burst [Q empty]
time 156198ms: Process B0 (tau 725ms) completed I/O; added to ready queue [Q B0]
time 156589ms: Process A9 (tau 660ms) completed I/O; added to ready queue [Q A9 B0]
time 156617ms: Process A4 (tau 933ms) completed I/O; added to ready queue [Q A9 B0 A4]
time 158083ms: Process A1 (tau 4811ms) completed a CPU burst; 18 bursts to go [Q A9 B0 A4]
time 158083ms: Recalculated tau for process A1: old tau 4811ms ==> new tau 3685ms [Q A9 B0 A4]
time 158083ms: Process A1 switching out of CPU; blocking on I/O until time 158250ms [Q A9 B0 A4]
time 158087ms: Process A9 (tau 660ms) started using the CPU for 13ms burst [Q B0 A4]
time 158100ms: Process A9 (tau 660ms) completed a CPU burst; 4 bursts to go [Q B0 A4]
time 158100ms: Recalculated tau for process A9: old tau 660ms ==> new tau 369ms [Q B0 A4]
time 158100ms: Process A9 switching out of CPU; blocking on I/O until time 161006ms [Q B0 A4]
time 158104ms: Process B0 (tau 725ms) started using the CPU for 325ms burst [Q A4]
time 158250ms: Process A1 (tau 3685ms) completed I/O; added to ready queue [Q A4 A1]
time 158391ms: Process B5 (tau 250ms) completed I/O; added to ready queue [Q B5 A4 A1]
time 158429ms: Process B0 (tau 725ms) completed a CPU burst; 19 bursts to go [Q B5 A4 A1]
time 158429ms: Recalculated tau for process B0: old tau 725ms ==> new tau 545ms [Q B5 A4 A1]
time 158429ms: Process B0 switching out of CPU; blocking on I/O until time 165799ms [Q B5 A4 A1]
time 158433ms: Process B5 (tau 250ms) started using the CPU for 268ms burst [Q A4 A1]
time 158701ms: Process B5 (tau 250ms) completed a CPU burst; 11 bursts to go [Q A4 A1]
time 158701ms: Recalculated tau for process B5: old tau 250ms ==> new tau 259ms [Q A4 A1]
time 158701ms: Process B5 switching out of CPU; blocking on I/O until time 167935ms [Q A4 A1]
time 158705ms: Process A4 (tau 933ms) started using the CPU for 595ms burst [Q A1]
time 159300ms: Process A4 (tau 933ms) completed a CPU burst; 11 bursts to go [Q A1]
time 159300ms: Recalculated tau for process A4: old tau 933ms ==> new tau 781ms [Q A1]
time 159300ms: Process A4 switching out of CPU; blocking on I/O until time 159598ms [Q A1]
time 159304ms: Process A1 (tau 3685ms) started using the CPU for 3492ms burst [Q empty]
time 159598ms: Process A4 (tau 781ms) completed I/O; added to ready queue [Q A4]
time 160069ms: Process A5 (tau 367ms) completed I/O; added to ready queue [Q A5 A4]
time 161006ms: Process A9 (tau 369ms) completed I/O; added to ready queue [Q A5 A9 A4]
time 162013ms: Process B1 (tau 623ms) completed I/O; added to ready queue [Q A5 A9 B1 A4]
time 162796ms: Process A1 (tau 3685ms) completed a CPU burst; 17 bursts to go [Q A5 A9 B1 A4]
time 162796ms: Recalculated tau for process A1: old tau 3685ms ==> new tau 3599ms [Q A5 A9 B1 A4]
time 162796ms: Process A1 switching out of CPU; blocking on I/O until time 163917ms [Q A5 A9 B1 A4]
time 162800ms: Process A5 (tau 367ms) started using the CPU for 914ms burst [Q A9 B1 A4]
time 163714ms: Process A5 (tau 367ms) completed a CPU burst; 13 bursts to go [Q A9 B1 A4]
time 163714ms: Recalculated tau for process A5: old tau 367ms ==> new tau 614ms [Q A9 B1 A4]
time 163714ms: Process A5 switching out of CPU; blocking on I/O until time 167332ms [Q A9 B1 A4]
time 163718ms: Process A9 (tau 369ms) started using the CPU for 157ms burst [Q B1 A4]
time 163875ms: Process A9 (tau 369ms) completed a CPU burst; 3 bursts to go [Q B1 A4]
time 163875ms: Recalculated tau for process A9: old tau 369ms ==> new tau 274ms [Q B1 A4]
time 163875ms: Process A9 switching out of CPU; blocking on I/O until time 174501ms [Q B1 A4]
time 163879ms: Process B1 (tau 623ms) started using the CPU for 427ms burst [Q A4]
time 163917ms: Process A1 (tau 3599ms) completed I/O; added to ready queue [Q A4 A1]
time 163989ms: Process B4 (tau 548ms) completed I/O; added to ready queue [Q B4 A4 A1]
time 164306ms: Process B1 (tau 623ms) completed a CPU burst; 10 bursts to go [Q B4 A4 A1]
time 164306ms: Recalculated tau for process B1: old tau 623ms ==> new tau 535ms [Q B4 A4 A1]
time 164306ms: Process B1 switching out of CPU; blocking on I/O until time 165852ms [Q B4 A4 A1]
time 164310ms: Process B4 (tau 548ms) started using the CPU for 3ms burst [Q A4 A1]
time 164313ms: Process B4 (tau 548ms) completed a CPU burst; 8 bursts to go [Q A4 A1]
time 164313ms: Recalculated tau for process B4: old tau 548ms ==> new tau 303ms [Q A4 A1]
time 164313ms: Process B4 switching out of CPU; blocking on I/O until time 170323ms [Q A4 A1]
time 164317ms: Process A4 (tau 781ms) started using the CPU for 1138ms burst [Q A1]
time 165455ms: Process A4 (tau 781ms) completed a CPU burst; 10 bursts to go [Q A1]
time 165455ms: Recalculated tau for process A4: old tau 781ms ==> new tau 942ms [Q A1]
time 165455ms: Process A4 switching out of CPU; blocking on I/O until time 173161ms [Q A1]
time 165459ms: Process A1 (tau 3599ms) started using the CPU for 724ms burst [Q empty]
time 165799ms: Process B0 (tau 545ms) completed I/O; added to ready queue [Q B0]
time 165852ms: Process B1 (tau 535ms) completed I/O; added to ready queue [Q B1 B0]
time 166183ms: Process A1 (tau 3599ms) completed a CPU burst; 16 bursts to go [Q B1 B0]
time 166183ms: Recalculated tau for process A1: old tau 3599ms ==> new tau 2306ms [Q B1 B0]
time 166183ms: Process A1 switching out of CPU; blocking on I/O until time 167479ms [Q B1 B0]
time 166187ms: Process B1 (tau 535ms) started using the CPU for 350ms burst [Q B0]
time 166537ms: Process B1 (tau 535ms) completed a CPU burst; 9 bursts to go [Q B0]
time 166537ms: Recalculated tau for process B1: old tau 535ms ==> new tau 452ms [Q B0]
time 166537ms: Process B1 switching out of CPU; blocking on I/O until time 167731ms [Q B0]
time 166541ms: Process B0 (tau 545ms) started using the CPU for 857ms burst [Q empty]
time 167332ms: Process A5 (tau 614ms) completed I/O; added to ready queue [Q A5]
time 167398ms: Process B0 (tau 545ms) completed a CPU burst; 18 bursts to go [Q A5]
time 167398ms: Recalculated tau for process B0: old tau 545ms ==> new tau 686ms [Q A5]
time 167398ms: Process B0 switching out of CPU; blocking on I/O until time 179816ms [Q A5]
time 167402ms: Process A5 (tau 614ms) started using the CPU for 16ms burst [Q empty]
time 167418ms: Process A5 (tau 614ms) completed a CPU burst; 12 bursts to go [Q empty]
time 167418ms: Recalculated tau for process A5: old tau 614ms ==> new tau 345ms [Q empty]
time 167418ms: Process A5 switching out of CPU; blocking on I/O until time 171812ms [Q empty]
time 167479ms: Process A1 (tau 2306ms) completed I/O; added to ready queue [Q A1]
time 167481ms: Process A1 (tau 2306ms) started using the CPU for 4068ms burst [Q empty]
time 167731ms: Process B1 (tau 452ms) completed I/O; added to ready queue [Q B1]
time 167935ms: Process B5 (tau 259ms) completed I/O; added to ready queue [Q B5 B1]
time 170323ms: Process B4 (tau 303ms) completed I/O; added to ready queue [Q B5 B4 B1]
time 171549ms: Process A1 (tau 2306ms) completed a CPU burst; 15 bursts to go [Q B5 B4 B1]
time 171549ms: Recalculated tau for process A1: old tau 2306ms ==> new tau 3099ms [Q B5 B4 B1]
time 171549ms: Process A1 switching out of CPU; blocking on I/O until time 172161ms [Q B5 B4 B1]
time 171553ms: Process B5 (tau 259ms) started using the CPU for 43ms burst [Q B4 B1]
time 171596ms: Process B5 (tau 259ms) completed a CPU burst; 10 bursts to go [Q B4 B1]
time 171596ms: Recalculated tau for process B5: old tau 259ms ==> new tau 162ms [Q B4 B1]
time 171596ms: Process B5 switching out of CPU; blocking on I/O until time 172598ms [Q B4 B1]
time 171600ms: Process B4 (tau 303ms) started using the CPU for 1072ms burst [Q B1]
time 171812ms: Process A5 (tau 345ms) completed I/O; added to ready queue [Q A5 B1]
time 172161ms: Process A1 (tau 3099ms) completed I/O; added to ready queue [Q A5 B1 A1]
time 172598ms: Process B5 (tau 162ms) completed I/O; added to ready queue [Q B5 A5 B1 A1]
time 172672ms: Process B4 (tau 303ms) completed a CPU burst; 7 bursts to go [Q B5 A5 B1 A1]
time 172672ms: Recalculated tau for process B4: old tau 303ms ==> new tau 650ms [Q B5 A5 B1 A1]
time 172672ms: Process B4 switching out of CPU; blocking on I/O until time 178626ms [Q B5 A5 B1 A1]
time 172676ms: Process B5 (tau 162ms) started using the CPU for 1821ms burst [Q A5 B1 A1]
time 173161ms: Process A4 (tau 942ms) completed I/O; added to ready queue [Q A5 B1 A4 A1]
time 174497ms: Process B5 (tau 162ms) completed a CPU burst; 9 bursts to go [Q A5 B1 A4 A1]
time 174497ms: Recalculated tau for process B5: old tau 162ms ==> new tau 909ms [Q A5 B1 A4 A1]
time 174497ms: Process B5 switching out of CPU; blocking on I/O until time 185147ms [Q A5 B1 A4 A1]
time 174501ms: Process A5 (tau 345ms) started using the CPU for 620ms burst [Q B1 A4 A1]
time 174501ms: Process A9 (tau 274ms) completed I/O; added to ready queue [Q A9 B1 A4 A1]
time 175121ms: Process A5 (tau 345ms) completed a CPU burst; 11 bursts to go [Q A9 B1 A4 A1]
time 175121ms: Recalculated tau for process A5: old tau 345ms ==> new tau 469ms [Q A9 B1 A4 A1]
time 175121ms: Process A5 switching out of CPU; blocking on I/O until time 179875ms [Q A9 B1 A4 A1]
time 175125ms: Process A9 (tau 274ms) started using the CPU for 952ms burst [Q B1 A4 A1]
time 176077ms: Process A9 (tau 274ms) completed a CPU burst; 2 bursts to go [Q B1 A4 A1]
time 176077ms: Recalculated tau for process A9: old tau 274ms ==> new tau 580ms [Q B1 A4 A1]
time 176077ms: Process A9 switching out of CPU; blocking on I/O until time 176319ms [Q B1 A4 A1]
time 176081ms: Process B1 (tau 452ms) started using the CPU for 319ms burst [Q A4 A1]
time 176319ms: Process A9 (tau 580ms) completed I/O; added to ready queue [Q A9 A4 A1]
time 176400ms: Process B1 (tau 452ms) completed a CPU burst; 8 bursts to go [Q A9 A4 A1]
time 176400ms: Recalculated tau for process B1: old tau 452ms ==> new tau 393ms [Q A9 A4 A1]
time 176400ms: Process B1 switching out of CPU; blocking on I/O until time 178058ms [Q A9 A4 A1]
time 176404ms: Process A9 (tau 580ms) started using the CPU for 840ms burst [Q A4 A1]
time 177244ms: Process A9 (tau 580ms) completed a CPU burst; 1 burst to go [Q A4 A1]
time 177244ms: Recalculated tau for process A9: old tau 580ms ==> new tau 697ms [Q A4 A1]
time 177244ms: Process A9 switching out of CPU; blocking on I/O until time 179438ms [Q A4 A1]
time 177248ms: Process A4 (tau 942ms) started using the CPU for 119ms burst [Q A1]
time 177367ms: Process A4 (tau 942ms) completed a CPU burst; 9 bursts to go [Q A1]
time 177367ms: Recalculated tau for process A4: old tau 942ms ==> new tau 572ms [Q A1]
time 177367ms: Process A4 switching out of CPU; blocking on I/O until time 181553ms [Q A1]
time 177371ms: Process A1 (tau 3099ms) started using the CPU for 3264ms burst [Q empty]
time 178058ms: Process B1 (tau 393ms) completed I/O; added to ready queue [Q B1]
time 178626ms: Process B4 (tau 650ms) completed I/O; added to ready queue [Q B1 B4]
time 179438ms: Process A9 (tau 697ms) completed I/O; added to ready queue [Q B1 B4 A9]
time 179816ms: Process B0 (tau 686ms) completed I/O; added to ready queue [Q B1 B4 B0 A9]
time 179875ms: Process A5 (tau 469ms) completed I/O; added to ready queue [Q B1 A5 B4 B0 A9]
time 180635ms: Process A1 (tau 3099ms) completed a CPU burst; 14 bursts to go [Q B1 A5 B4 B0 A9]
time 180635ms: Recalculated tau for process A1: old tau 3099ms ==> new tau 3174ms [Q B1 A5 B4 B0 A9]
time 180635ms: Process A1 switching out of CPU; blocking on I/O until time 181403ms [Q B1 A5 B4 B0 A9]
time 180639ms: Process B1 (tau 393ms) started using the CPU for 81ms burst [Q A5 B4 B0 A9]
time 180720ms: Process B1 (tau 393ms) completed a CPU burst; 7 bursts to go [Q A5 B4 B0 A9]
time 180720ms: Recalculated tau for process B1: old tau 393ms ==> new tau 253ms [Q A5 B4 B0 A9]
time 180720ms: Process B1 switching out of CPU; blocking on I/O until time 194074ms [Q A5 B4 B0 A9]
time 180724ms: Process A5 (tau 469ms) started using the CPU for 757ms burst [Q B4 B0 A9]
time 181403ms: Process A1 (tau 3174ms) completed I/O; added to ready queue [Q B4 B0 A9 A1]
time 181481ms: Process A5 (tau 469ms) completed a CPU burst; 10 bursts to go [Q B4 B0 A9 A1]
time 181481ms: Recalculated tau for process A5: old tau 469ms ==> new tau 599ms [Q B4 B0 A9 A1]
time 181481ms: Process A5 switching out of CPU; blocking on I/O until time 184787ms [Q B4 B0 A9 A1]
time 181485ms: Process B4 (tau 650ms) started using the CPU for 795ms burst [Q B0 A9 A1]
time 181553ms: Process A4 (tau 572ms) completed I/O; added to ready queue [Q A4 B0 A9 A1]
time 182280ms: Process B4 (tau 650ms) completed a CPU burst; 6 bursts to go [Q A4 B0 A9 A1]
time 182280ms: Recalculated tau for process B4: old tau 650ms ==> new tau 716ms [Q A4 B0 A9 A1]
time 182280ms: Process B4 switching out of CPU; blocking on I/O until time 184898ms [Q A4 B0 A9 A1]
time 182284ms: Process A4 (tau 572ms) started using the CPU for 914ms burst [Q B0 A9 A1]
time 183198ms: Process A4 (tau 572ms) completed a CPU burst; 8 bursts to go [Q B0 A9 A1]
time 183198ms: Recalculated tau for process A4: old tau 572ms ==> new tau 726ms [Q B0 A9 A1]
time 183198ms: Process A4 switching out of CPU; blocking on I/O until time 193592ms [Q B0 A9 A1]
time 183202ms: Process B0 (tau 686ms) started using the CPU for 1107ms burst [Q A9 A1]
time 184309ms: Process B0 (tau 686ms) completed a CPU burst; 17 bursts to go [Q A9 A1]
time 184309ms: Recalculated tau for process B0: old tau 686ms ==> new tau 876ms [Q A9 A1]
time 184309ms: Process B0 switching out of CPU; blocking on I/O until time 190407ms [Q A9 A1]
time 184313ms: Process A9 (tau 697ms) started using the CPU for 129ms burst [Q A1]
time 184442ms: Process A9 terminated [Q A1]
time 184446ms: Process A1 (tau 3174ms) started using the CPU for 4000ms burst [Q empty]
time 184787ms: Process A5 (tau 599ms) completed I/O; added to ready queue [Q A5]
time 184898ms: Process B4 (tau 716ms) completed I/O; added to ready queue [Q A5 B4]
time 185147ms: Process B5 (tau 909ms) completed I/O; added to ready queue [Q A5 B4 B5]
time 188446ms: Process A1 (tau 3174ms) completed a CPU burst; 13 bursts to go [Q A5 B4 B5]
time 188446ms: Recalculated tau for process A1: old tau 3174ms ==> new tau 3546ms [Q A5 B4 B5]
time 188446ms: Process A1 switching out of CPU; blocking on I/O until time 188540ms [Q A5 B4 B5]
time 188450ms: Process A5 (tau 599ms) started using the CPU for 1782ms burst [Q B4 B5]
time 188540ms: Process A1 (tau 3546ms) completed I/O; added to ready queue [Q B4 B5 A1]
time 190232ms: Process A5 (tau 599ms) completed a CPU burst; 9 bursts to go [Q B4 B5 A1]
time 190232ms: Recalculated tau for process A5: old tau 599ms ==> new tau 1132ms [Q B4 B5 A1]
