time 0ms: Simulator started for SJF [Q empty]
time 2ms: Process B4 (tau 100ms) arrived; added to ready queue [Q B4]
time 4ms: Process B4 (tau 100ms) started using the CPU for 32ms burst [Q empty]
time 9ms: Process B1 (tau 100ms) arrived; added to ready queue [Q B1]
time 29ms: Process A6 (tau 100ms) arrived; added to ready queue [Q A6 B1]
time 30ms: Process B7 (tau 100ms) arrived; added to ready queue [Q A6 B1 B7]
time 36ms: Process B4 (tau 100ms) completed a CPU burst; 15 bursts to go [Q A6 B1 B7]
time 36ms: Recalculated tau for process B4: old tau 100ms ==> new tau 33ms [Q A6 B1 B7]
time 36ms: Process B4 switching out of CPU; blocking on I/O until time 159ms [Q A6 B1 B7]
time 40ms: Process A6 (tau 100ms) started using the CPU for 280ms burst [Q B1 B7]
time 41ms: Process A9 (tau 100ms) arrived; added to ready queue [Q A9 B1 B7]
time 45ms: Process A0 (tau 100ms) arrived; added to ready queue [Q A0 A9 B1 B7]
time 45ms: Process B0 (tau 100ms) arrived; added to ready queue [Q A0 A9 B0 B1 B7]
time 46ms: Process B2 (tau 100ms) arrived; added to ready queue [Q A0 A9 B0 B1 B2 B7]
time 47ms: Process A1 (tau 100ms) arrived; added to ready queue [Q A0 A1 A9 B0 B1 B2 B7]
time 54ms: Process A7 (tau 100ms) arrived; added to ready queue [Q A0 A1 A7 A9 B0 B1 B2 B7]
time 62ms: Process A8 (tau 100ms) arrived; added to ready queue [Q A0 A1 A7 A8 A9 B0 B1 B2 B7]
time 92ms: Process A2 (tau 100ms) arrived; added to ready queue [Q A0 A1 A2 A7 A8 A9 B0 B1 B2 B7]
time 95ms: Process B9 (tau 100ms) arrived; added to ready queue [Q A0 A1 A2 A7 A8 A9 B0 B1 B2 B7 B9]
time 102ms: Process B6 (tau 100ms) arrived; added to ready queue [Q A0 A1 A2 A7 A8 A9 B0 B1 B2 B6 B7 B9]
time 130ms: Process A5 (tau 100ms) arrived; added to ready queue [Q A0 A1 A2 A5 A7 A8 A9 B0 B1 B2 B6 B7 B9]
time 140ms: Process B5 (tau 100ms) arrived; added to ready queue [Q A0 A1 A2 A5 A7 A8 A9 B0 B1 B2 B5 B6 B7 B9]
time 157ms: Process A4 (tau 100ms) arrived; added to ready queue [Q A0 A1 A2 A4 A5 A7 A8 A9 B0 B1 B2 B5 B6 B7 B9]
time 159ms: Process B4 (tau 33ms) completed I/O; added to ready queue [Q B4 A0 A1 A2 A4 A5 A7 A8 A9 B0 B1 B2 B5 B6 B7 B9]
time 225ms: Process B8 (tau 100ms) arrived; added to ready queue [Q B4 A0 A1 A2 A4 A5 A7 A8 A9 B0 B1 B2 B5 B6 B7 B8 B9]
time 271ms: Process B3 (tau 100ms) arrived; added to ready queue [Q B4 A0 A1 A2 A4 A5 A7 A8 A9 B0 B1 B2 B3 B5 B6 B7 B8 B9]
time 320ms: Process A6 (tau 100ms) completed a CPU burst; 17 bursts to go [Q B4 A0 A1 A2 A4 A5 A7 A8 A9 B0 B1 B2 B3 B5 B6 B7 B8 B9]
time 320ms: Recalculated tau for process A6: old tau 100ms ==> new tau 279ms [Q B4 A0 A1 A2 A4 A5 A7 A8 A9 B0 B1 B2 B3 B5 B6 B7 B8 B9]
time 320ms: Process A6 switching out of CPU; blocking on I/O until time 394ms [Q B4 A0 A1 A2 A4 A5 A7 A8 A9 B0 B1 B2 B3 B5 B6 B7 B8 B9]
time 324ms: Process B4 (tau 33ms) started using the CPU for 12ms burst [Q A0 A1 A2 A4 A5 A7 A8 A9 B0 B1 B2 B3 B5 B6 B7 B8 B9]
time 324ms: Process A3 (tau 100ms) arrived; added to ready queue [Q A0 A1 A2 A3 A4 A5 A7 A8 A9 B0 B1 B2 B3 B5 B6 B7 B8 B9]
time 336ms: Process B4 (tau 33ms) completed a CPU burst; 14 bursts to go [Q A0 A1 A2 A3 A4 A5 A7 A8 A9 B0 B1 B2 B3 B5 B6 B7 B8 B9]
time 336ms: Recalculated tau for process B4: old tau 33ms ==> new tau 13ms [Q A0 A1 A2 A3 A4 A5 A7 A8 A9 B0 B1 B2 B3 B5 B6 B7 B8 B9]
time 336ms: Process B4 switching out of CPU; blocking on I/O until time 475ms [Q A0 A1 A2 A3 A4 A5 A7 A8 A9 B0 B1 B2 B3 B5 B6 B7 B8 B9]
time 340ms: Process A0 (tau 100ms) started using the CPU for 196ms burst [Q A1 A2 A3 A4 A5 A7 A8 A9 B0 B1 B2 B3 B5 B6 B7 B8 B9]
time 394ms: Process A6 (tau 279ms) completed I/O; added to ready queue [Q A1 A2 A3 A4 A5 A7 A8 A9 B0 B1 B2 B3 B5 B6 B7 B8 B9 A6]
time 475ms: Process B4 (tau 13ms) completed I/O; added to ready queue [Q B4 A1 A2 A3 A4 A5 A7 A8 A9 B0 B1 B2 B3 B5 B6 B7 B8 B9 A6]
time 536ms: Process A0 (tau 100ms) completed a CPU burst; 29 bursts to go [Q B4 A1 A2 A3 A4 A5 A7 A8 A9 B0 B1 B2 B3 B5 B6 B7 B8 B9 A6]
time 536ms: Recalculated tau for process A0: old tau 100ms ==> new tau 196ms [Q B4 A1 A2 A3 A4 A5 A7 A8 A9 B0 B1 B2 B3 B5 B6 B7 B8 B9 A6]
time 536ms: Process A0 switching out of CPU; blocking on I/O until time 617ms [Q B4 A1 A2 A3 A4 A5 A7 A8 A9 B0 B1 B2 B3 B5 B6 B7 B8 B9 A6]
time 540ms: Process B4 (tau 13ms) started using the CPU for 1140ms burst [Q A1 A2 A3 A4 A5 A7 A8 A9 B0 B1 B2 B3 B5 B6 B7 B8 B9 A6]
time 617ms: Process A0 (tau 196ms) completed I/O; added to ready queue [Q A1 A2 A3 A4 A5 A7 A8 A9 B0 B1 B2 B3 B5 B6 B7 B8 B9 A0 A6]
time 1680ms: Process B4 (tau 13ms) completed a CPU burst; 13 bursts to go [Q A1 A2 A3 A4 A5 A7 A8 A9 B0 B1 B2 B3 B5 B6 B7 B8 B9 A0 A6]
time 1680ms: Recalculated tau for process B4: old tau 13ms ==> new tau 1129ms [Q A1 A2 A3 A4 A5 A7 A8 A9 B0 B1 B2 B3 B5 B6 B7 B8 B9 A0 A6]
time 1680ms: Process B4 switching out of CPU; blocking on I/O until time 1710ms [Q A1 A2 A3 A4 A5 A7 A8 A9 B0 B1 B2 B3 B5 B6 B7 B8 B9 A0 A6]
time 1684ms: Process A1 (tau 100ms) started using the CPU for 632ms burst [Q A2 A3 A4 A5 A7 A8 A9 B0 B1 B2 B3 B5 B6 B7 B8 B9 A0 A6]
time 1710ms: Process B4 (tau 1129ms) completed I/O; added to ready queue [Q A2 A3 A4 A5 A7 A8 A9 B0 B1 B2 B3 B5 B6 B7 B8 B9 A0 A6 B4]
time 2316ms: Process A1 (tau 100ms) completed a CPU burst; 11 bursts to go [Q A2 A3 A4 A5 A7 A8 A9 B0 B1 B2 B3 B5 B6 B7 B8 B9 A0 A6 B4]
time 2316ms: Recalculated tau for process A1: old tau 100ms ==> new tau 627ms [Q A2 A3 A4 A5 A7 A8 A9 B0 B1 B2 B3 B5 B6 B7 B8 B9 A0 A6 B4]
time 2316ms: Process A1 switching out of CPU; blocking on I/O until time 2356ms [Q A2 A3 A4 A5 A7 A8 A9 B0 B1 B2 B3 B5 B6 B7 B8 B9 A0 A6 B4]
time 2320ms: Process A2 (tau 100ms) started using the CPU for 28ms burst [Q A3 A4 A5 A7 A8 A9 B0 B1 B2 B3 B5 B6 B7 B8 B9 A0 A6 B4]
time 2348ms: Process A2 (tau 100ms) completed a CPU burst; 29 bursts to go [Q A3 A4 A5 A7 A8 A9 B0 B1 B2 B3 B5 B6 B7 B8 B9 A0 A6 B4]
time 2348ms: Recalculated tau for process A2: old tau 100ms ==> new tau 29ms [Q A3 A4 A5 A7 A8 A9 B0 B1 B2 B3 B5 B6 B7 B8 B9 A0 A6 B4]
time 2348ms: Process A2 switching out of CPU; blocking on I/O until time 2363ms [Q A3 A4 A5 A7 A8 A9 B0 B1 B2 B3 B5 B6 B7 B8 B9 A0 A6 B4]
time 2352ms: Process A3 (tau 100ms) started using the CPU for 96ms burst [Q A4 A5 A7 A8 A9 B0 B1 B2 B3 B5 B6 B7 B8 B9 A0 A6 B4]
time 2356ms: Process A1 (tau 627ms) completed I/O; added to ready queue [Q A4 A5 A7 A8 A9 B0 B1 B2 B3 B5 B6 B7 B8 B9 A0 A6 A1 B4]
time 2363ms: Process A2 (tau 29ms) completed I/O; added to ready queue [Q A2 A4 A5 A7 A8 A9 B0 B1 B2 B3 B5 B6 B7 B8 B9 A0 A6 A1 B4]
time 2448ms: Process A3 (tau 100ms) completed a CPU burst; 25 bursts to go [Q A2 A4 A5 A7 A8 A9 B0 B1 B2 B3 B5 B6 B7 B8 B9 A0 A6 A1 B4]
time 2448ms: Recalculated tau for process A3: old tau 100ms ==> new tau 97ms [Q A2 A4 A5 A7 A8 A9 B0 B1 B2 B3 B5 B6 B7 B8 B9 A0 A6 A1 B4]
time 2448ms: Process A3 switching out of CPU; blocking on I/O until time 2820ms [Q A2 A4 A5 A7 A8 A9 B0 B1 B2 B3 B5 B6 B7 B8 B9 A0 A6 A1 B4]
time 2452ms: Process A2 (tau 29ms) started using the CPU for 444ms burst [Q A4 A5 A7 A8 A9 B0 B1 B2 B3 B5 B6 B7 B8 B9 A0 A6 A1 B4]
time 2820ms: Process A3 (tau 97ms) completed I/O; added to ready queue [Q A3 A4 A5 A7 A8 A9 B0 B1 B2 B3 B5 B6 B7 B8 B9 A0 A6 A1 B4]
time 2896ms: Process A2 (tau 29ms) completed a CPU burst; 28 bursts to go [Q A3 A4 A5 A7 A8 A9 B0 B1 B2 B3 B5 B6 B7 B8 B9 A0 A6 A1 B4]
time 2896ms: Recalculated tau for process A2: old tau 29ms ==> new tau 440ms [Q A3 A4 A5 A7 A8 A9 B0 B1 B2 B3 B5 B6 B7 B8 B9 A0 A6 A1 B4]
time 2896ms: Process A2 switching out of CPU; blocking on I/O until time 3357ms [Q A3 A4 A5 A7 A8 A9 B0 B1 B2 B3 B5 B6 B7 B8 B9 A0 A6 A1 B4]
time 2900ms: Process A3 (tau 97ms) started using the CPU for 308ms burst [Q A4 A5 A7 A8 A9 B0 B1 B2 B3 B5 B6 B7 B8 B9 A0 A6 A1 B4]
time 3208ms: Process A3 (tau 97ms) completed a CPU burst; 24 bursts to go [Q A4 A5 A7 A8 A9 B0 B1 B2 B3 B5 B6 B7 B8 B9 A0 A6 A1 B4]
time 3208ms: Recalculated tau for process A3: old tau 97ms ==> new tau 306ms [Q A4 A5 A7 A8 A9 B0 B1 B2 B3 B5 B6 B7 B8 B9 A0 A6 A1 B4]
time 3208ms: Process A3 switching out of CPU; blocking on I/O until time 3298ms [Q A4 A5 A7 A8 A9 B0 B1 B2 B3 B5 B6 B7 B8 B9 A0 A6 A1 B4]
time 3212ms: Process A4 (tau 100ms) started using the CPU for 300ms burst [Q A5 A7 A8 A9 B0 B1 B2 B3 B5 B6 B7 B8 B9 A0 A6 A1 B4]
time 3298ms: Process A3 (tau 306ms) completed I/O; added to ready queue [Q A5 A7 A8 A9 B0 B1 B2 B3 B5 B6 B7 B8 B9 A0 A6 A3 A1 B4]
time 3357ms: Process A2 (tau 440ms) completed I/O; added to ready queue [Q A5 A7 A8 A9 B0 B1 B2 B3 B5 B6 B7 B8 B9 A0 A6 A3 A2 A1 B4]
time 3512ms: Process A4 (tau 100ms) completed a CPU burst; 3 bursts to go [Q A5 A7 A8 A9 B0 B1 B2 B3 B5 B6 B7 B8 B9 A0 A6 A3 A2 A1 B4]
time 3512ms: Recalculated tau for process A4: old tau 100ms ==> new tau 298ms [Q A5 A7 A8 A9 B0 B1 B2 B3 B5 B6 B7 B8 B9 A0 A6 A3 A2 A1 B4]
time 3512ms: Process A4 switching out of CPU; blocking on I/O until time 3603ms [Q A5 A7 A8 A9 B0 B1 B2 B3 B5 B6 B7 B8 B9 A0 A6 A3 A2 A1 B4]
time 3516ms: Process A5 (tau 100ms) started using the CPU for 196ms burst [Q A7 A8 A9 B0 B1 B2 B3 B5 B6 B7 B8 B9 A0 A6 A3 A2 A1 B4]
time 3603ms: Process A4 (tau 298ms) completed I/O; added to ready queue [Q A7 A8 A9 B0 B1 B2 B3 B5 B6 B7 B8 B9 A0 A6 A4 A3 A2 A1 B4]
time 3712ms: Process A5 (tau 100ms) completed a CPU burst; 4 bursts to go [Q A7 A8 A9 B0 B1 B2 B3 B5 B6 B7 B8 B9 A0 A6 A4 A3 A2 A1 B4]
time 3712ms: Recalculated tau for process A5: old tau 100ms ==> new tau 196ms [Q A7 A8 A9 B0 B1 B2 B3 B5 B6 B7 B8 B9 A0 A6 A4 A3 A2 A1 B4]
time 3712ms: Process A5 switching out of CPU; blocking on I/O until time 3731ms [Q A7 A8 A9 B0 B1 B2 B3 B5 B6 B7 B8 B9 A0 A6 A4 A3 A2 A1 B4]
time 3716ms: Process A7 (tau 100ms) started using the CPU for 84ms burst [Q A8 A9 B0 B1 B2 B3 B5 B6 B7 B8 B9 A0 A6 A4 A3 A2 A1 B4]
time 3731ms: Process A5 (tau 196ms) completed I/O; added to ready queue [Q A8 A9 B0 B1 B2 B3 B5 B6 B7 B8 B9 A0 A5 A6 A4 A3 A2 A1 B4]
time 3800ms: Process A7 (tau 100ms) completed a CPU burst; 18 bursts to go [Q A8 A9 B0 B1 B2 B3 B5 B6 B7 B8 B9 A0 A5 A6 A4 A3 A2 A1 B4]
time 3800ms: Recalculated tau for process A7: old tau 100ms ==> new tau 85ms [Q A8 A9 B0 B1 B2 B3 B5 B6 B7 B8 B9 A0 A5 A6 A4 A3 A2 A1 B4]
time 3800ms: Process A7 switching out of CPU; blocking on I/O until time 3851ms [Q A8 A9 B0 B1 B2 B3 B5 B6 B7 B8 B9 A0 A5 A6 A4 A3 A2 A1 B4]
time 3804ms: Process A8 (tau 100ms) started using the CPU for 420ms burst [Q A9 B0 B1 B2 B3 B5 B6 B7 B8 B9 A0 A5 A6 A4 A3 A2 A1 B4]
time 3851ms: Process A7 (tau 85ms) completed I/O; added to ready queue [Q A7 A9 B0 B1 B2 B3 B5 B6 B7 B8 B9 A0 A5 A6 A4 A3 A2 A1 B4]
time 4224ms: Process A8 (tau 100ms) completed a CPU burst; 7 bursts to go [Q A7 A9 B0 B1 B2 B3 B5 B6 B7 B8 B9 A0 A5 A6 A4 A3 A2 A1 B4]
time 4224ms: Recalculated tau for process A8: old tau 100ms ==> new tau 417ms [Q A7 A9 B0 B1 B2 B3 B5 B6 B7 B8 B9 A0 A5 A6 A4 A3 A2 A1 B4]
time 4224ms: Process A8 switching out of CPU; blocking on I/O until time 4280ms [Q A7 A9 B0 B1 B2 B3 B5 B6 B7 B8 B9 A0 A5 A6 A4 A3 A2 A1 B4]
time 4228ms: Process A7 (tau 85ms) started using the CPU for 768ms burst [Q A9 B0 B1 B2 B3 B5 B6 B7 B8 B9 A0 A5 A6 A4 A3 A2 A1 B4]
time 4280ms: Process A8 (tau 417ms) completed I/O; added to ready queue [Q A9 B0 B1 B2 B3 B5 B6 B7 B8 B9 A0 A5 A6 A4 A3 A8 A2 A1 B4]
time 4996ms: Process A7 (tau 85ms) completed a CPU burst; 17 bursts to go [Q A9 B0 B1 B2 B3 B5 B6 B7 B8 B9 A0 A5 A6 A4 A3 A8 A2 A1 B4]
time 4996ms: Recalculated tau for process A7: old tau 85ms ==> new tau 762ms [Q A9 B0 B1 B2 B3 B5 B6 B7 B8 B9 A0 A5 A6 A4 A3 A8 A2 A1 B4]
time 4996ms: Process A7 switching out of CPU; blocking on I/O until time 5119ms [Q A9 B0 B1 B2 B3 B5 B6 B7 B8 B9 A0 A5 A6 A4 A3 A8 A2 A1 B4]
time 5000ms: Process A9 (tau 100ms) started using the CPU for 360ms burst [Q B0 B1 B2 B3 B5 B6 B7 B8 B9 A0 A5 A6 A4 A3 A8 A2 A1 B4]
time 5119ms: Process A7 (tau 762ms) completed I/O; added to ready queue [Q B0 B1 B2 B3 B5 B6 B7 B8 B9 A0 A5 A6 A4 A3 A8 A2 A1 A7 B4]
time 5360ms: Process A9 (tau 100ms) completed a CPU burst; 31 bursts to go [Q B0 B1 B2 B3 B5 B6 B7 B8 B9 A0 A5 A6 A4 A3 A8 A2 A1 A7 B4]
time 5360ms: Recalculated tau for process A9: old tau 100ms ==> new tau 358ms [Q B0 B1 B2 B3 B5 B6 B7 B8 B9 A0 A5 A6 A4 A3 A8 A2 A1 A7 B4]
time 5360ms: Process A9 switching out of CPU; blocking on I/O until time 5402ms [Q B0 B1 B2 B3 B5 B6 B7 B8 B9 A0 A5 A6 A4 A3 A8 A2 A1 A7 B4]
time 5364ms: Process B0 (tau 100ms) started using the CPU for 216ms burst [Q B1 B2 B3 B5 B6 B7 B8 B9 A0 A5 A6 A4 A3 A8 A2 A1 A7 B4]
time 5402ms: Process A9 (tau 358ms) completed I/O; added to ready queue [Q B1 B2 B3 B5 B6 B7 B8 B9 A0 A5 A6 A4 A3 A9 A8 A2 A1 A7 B4]
time 5580ms: Process B0 (tau 100ms) completed a CPU burst; 18 bursts to go [Q B1 B2 B3 B5 B6 B7 B8 B9 A0 A5 A6 A4 A3 A9 A8 A2 A1 A7 B4]
time 5580ms: Recalculated tau for process B0: old tau 100ms ==> new tau 215ms [Q B1 B2 B3 B5 B6 B7 B8 B9 A0 A5 A6 A4 A3 A9 A8 A2 A1 A7 B4]
time 5580ms: Process B0 switching out of CPU; blocking on I/O until time 5731ms [Q B1 B2 B3 B5 B6 B7 B8 B9 A0 A5 A6 A4 A3 A9 A8 A2 A1 A7 B4]
time 5584ms: Process B1 (tau 100ms) started using the CPU for 28ms burst [Q B2 B3 B5 B6 B7 B8 B9 A0 A5 A6 A4 A3 A9 A8 A2 A1 A7 B4]
time 5612ms: Process B1 (tau 100ms) completed a CPU burst; 16 bursts to go [Q B2 B3 B5 B6 B7 B8 B9 A0 A5 A6 A4 A3 A9 A8 A2 A1 A7 B4]
time 5612ms: Recalculated tau for process B1: old tau 100ms ==> new tau 29ms [Q B2 B3 B5 B6 B7 B8 B9 A0 A5 A6 A4 A3 A9 A8 A2 A1 A7 B4]
time 5612ms: Process B1 switching out of CPU; blocking on I/O until time 5832ms [Q B2 B3 B5 B6 B7 B8 B9 A0 A5 A6 A4 A3 A9 A8 A2 A1 A7 B4]
time 5616ms: Process B2 (tau 100ms) started using the CPU for 488ms burst [Q B3 B5 B6 B7 B8 B9 A0 A5 A6 A4 A3 A9 A8 A2 A1 A7 B4]
time 5731ms: Process B0 (tau 215ms) completed I/O; added to ready queue [Q B3 B5 B6 B7 B8 B9 A0 A5 B0 A6 A4 A3 A9 A8 A2 A1 A7 B4]
time 5832ms: Process B1 (tau 29ms) completed I/O; added to ready queue [Q B1 B3 B5 B6 B7 B8 B9 A0 A5 B0 A6 A4 A3 A9 A8 A2 A1 A7 B4]
time 6104ms: Process B2 (tau 100ms) completed a CPU burst; 14 bursts to go [Q B1 B3 B5 B6 B7 B8 B9 A0 A5 B0 A6 A4 A3 A9 A8 A2 A1 A7 B4]
time 6104ms: Recalculated tau for process B2: old tau 100ms ==> new tau 485ms [Q B1 B3 B5 B6 B7 B8 B9 A0 A5 B0 A6 A4 A3 A9 A8 A2 A1 A7 B4]
time 6104ms: Process B2 switching out of CPU; blocking on I/O until time 6171ms [Q B1 B3 B5 B6 B7 B8 B9 A0 A5 B0 A6 A4 A3 A9 A8 A2 A1 A7 B4]
time 6108ms: Process B1 (tau 29ms) started using the CPU for 3004ms burst [Q B3 B5 B6 B7 B8 B9 A0 A5 B0 A6 A4 A3 A9 A8 A2 A1 A7 B4]
time 6171ms: Process B2 (tau 485ms) completed I/O; added to ready queue [Q B3 B5 B6 B7 B8 B9 A0 A5 B0 A6 A4 A3 A9 A8 A2 B2 A1 A7 B4]
time 9112ms: Process B1 (tau 29ms) completed a CPU burst; 15 bursts to go [Q B3 B5 B6 B7 B8 B9 A0 A5 B0 A6 A4 A3 A9 A8 A2 B2 A1 A7 B4]
time 9112ms: Recalculated tau for process B1: old tau 29ms ==> new tau 2975ms [Q B3 B5 B6 B7 B8 B9 A0 A5 B0 A6 A4 A3 A9 A8 A2 B2 A1 A7 B4]
time 9112ms: Process B1 switching out of CPU; blocking on I/O until time 9253ms [Q B3 B5 B6 B7 B8 B9 A0 A5 B0 A6 A4 A3 A9 A8 A2 B2 A1 A7 B4]
time 9116ms: Process B3 (tau 100ms) started using the CPU for 204ms burst [Q B5 B6 B7 B8 B9 A0 A5 B0 A6 A4 A3 A9 A8 A2 B2 A1 A7 B4]
time 9253ms: Process B1 (tau 2975ms) completed I/O; added to ready queue [Q B5 B6 B7 B8 B9 A0 A5 B0 A6 A4 A3 A9 A8 A2 B2 A1 A7 B4 B1]
time 9320ms: Process B3 (tau 100ms) completed a CPU burst; 21 bursts to go [Q B5 B6 B7 B8 B9 A0 A5 B0 A6 A4 A3 A9 A8 A2 B2 A1 A7 B4 B1]
time 9320ms: Recalculated tau for process B3: old tau 100ms ==> new tau 203ms [Q B5 B6 B7 B8 B9 A0 A5 B0 A6 A4 A3 A9 A8 A2 B2 A1 A7 B4 B1]
time 9320ms: Process B3 switching out of CPU; blocking on I/O until time 9614ms [Q B5 B6 B7 B8 B9 A0 A5 B0 A6 A4 A3 A9 A8 A2 B2 A1 A7 B4 B1]
time 9324ms: Process B5 (tau 100ms) started using the CPU for 80ms burst [Q B6 B7 B8 B9 A0 A5 B0 A6 A4 A3 A9 A8 A2 B2 A1 A7 B4 B1]
time 9404ms: Process B5 (tau 100ms) completed a CPU burst; 29 bursts to go [Q B6 B7 B8 B9 A0 A5 B0 A6 A4 A3 A9 A8 A2 B2 A1 A7 B4 B1]
time 9404ms: Recalculated tau for process B5: old tau 100ms ==> new tau 81ms [Q B6 B7 B8 B9 A0 A5 B0 A6 A4 A3 A9 A8 A2 B2 A1 A7 B4 B1]
time 9404ms: Process B5 switching out of CPU; blocking on I/O until time 9437ms [Q B6 B7 B8 B9 A0 A5 B0 A6 A4 A3 A9 A8 A2 B2 A1 A7 B4 B1]
time 9408ms: Process B6 (tau 100ms) started using the CPU for 113ms burst [Q B7 B8 B9 A0 A5 B0 A6 A4 A3 A9 A8 A2 B2 A1 A7 B4 B1]
time 9437ms: Process B5 (tau 81ms) completed I/O; added to ready queue [Q B5 B7 B8 B9 A0 A5 B0 A6 A4 A3 A9 A8 A2 B2 A1 A7 B4 B1]
time 9521ms: Process B6 (tau 100ms) completed a CPU burst; 4 bursts to go [Q B5 B7 B8 B9 A0 A5 B0 A6 A4 A3 A9 A8 A2 B2 A1 A7 B4 B1]
time 9521ms: Recalculated tau for process B6: old tau 100ms ==> new tau 113ms [Q B5 B7 B8 B9 A0 A5 B0 A6 A4 A3 A9 A8 A2 B2 A1 A7 B4 B1]
time 9521ms: Process B6 switching out of CPU; blocking on I/O until time 12747ms [Q B5 B7 B8 B9 A0 A5 B0 A6 A4 A3 A9 A8 A2 B2 A1 A7 B4 B1]
time 9525ms: Process B5 (tau 81ms) started using the CPU for 340ms burst [Q B7 B8 B9 A0 A5 B0 A6 A4 A3 A9 A8 A2 B2 A1 A7 B4 B1]
time 9614ms: Process B3 (tau 203ms) completed I/O; added to ready queue [Q B7 B8 B9 A0 A5 B3 B0 A6 A4 A3 A9 A8 A2 B2 A1 A7 B4 B1]
time 9865ms: Process B5 (tau 81ms) completed a CPU burst; 28 bursts to go [Q B7 B8 B9 A0 A5 B3 B0 A6 A4 A3 A9 A8 A2 B2 A1 A7 B4 B1]
time 9865ms: Recalculated tau for process B5: old tau 81ms ==> new tau 338ms [Q B7 B8 B9 A0 A5 B3 B0 A6 A4 A3 A9 A8 A2 B2 A1 A7 B4 B1]
time 9865ms: Process B5 switching out of CPU; blocking on I/O until time 9897ms [Q B7 B8 B9 A0 A5 B3 B0 A6 A4 A3 A9 A8 A2 B2 A1 A7 B4 B1]
time 9869ms: Process B7 (tau 100ms) started using the CPU for 71ms burst [Q B8 B9 A0 A5 B3 B0 A6 A4 A3 A9 A8 A2 B2 A1 A7 B4 B1]
time 9897ms: Process B5 (tau 338ms) completed I/O; added to ready queue [Q B8 B9 A0 A5 B3 B0 A6 A4 A3 B5 A9 A8 A2 B2 A1 A7 B4 B1]
time 9940ms: Process B7 (tau 100ms) completed a CPU burst; 25 bursts to go [Q B8 B9 A0 A5 B3 B0 A6 A4 A3 B5 A9 A8 A2 B2 A1 A7 B4 B1]
time 9940ms: Recalculated tau for process B7: old tau 100ms ==> new tau 72ms [Q B8 B9 A0 A5 B3 B0 A6 A4 A3 B5 A9 A8 A2 B2 A1 A7 B4 B1]
time 9940ms: Process B7 switching out of CPU; blocking on I/O until time 12990ms [Q B8 B9 A0 A5 B3 B0 A6 A4 A3 B5 A9 A8 A2 B2 A1 A7 B4 B1]
time 9944ms: Process B8 (tau 100ms) started using the CPU for 308ms burst [Q B9 A0 A5 B3 B0 A6 A4 A3 B5 A9 A8 A2 B2 A1 A7 B4 B1]
time 10252ms: Process B8 (tau 100ms) completed a CPU burst; 19 bursts to go [Q B9 A0 A5 B3 B0 A6 A4 A3 B5 A9 A8 A2 B2 A1 A7 B4 B1]
time 10252ms: Recalculated tau for process B8: old tau 100ms ==> new tau 306ms [Q B9 A0 A5 B3 B0 A6 A4 A3 B5 A9 A8 A2 B2 A1 A7 B4 B1]
time 10252ms: Process B8 switching out of CPU; blocking on I/O until time 12534ms [Q B9 A0 A5 B3 B0 A6 A4 A3 B5 A9 A8 A2 B2 A1 A7 B4 B1]
time 10256ms: Process B9 (tau 100ms) started using the CPU for 22ms burst [Q A0 A5 B3 B0 A6 A4 A3 B5 A9 A8 A2 B2 A1 A7 B4 B1]
time 10278ms: Process B9 (tau 100ms) completed a CPU burst; 10 bursts to go [Q A0 A5 B3 B0 A6 A4 A3 B5 A9 A8 A2 B2 A1 A7 B4 B1]
time 10278ms: Recalculated tau for process B9: old tau 100ms ==> new tau 23ms [Q A0 A5 B3 B0 A6 A4 A3 B5 A9 A8 A2 B2 A1 A7 B4 B1]
time 10278ms: Process B9 switching out of CPU; blocking on I/O until time 10888ms [Q A0 A5 B3 B0 A6 A4 A3 B5 A9 A8 A2 B2 A1 A7 B4 B1]
time 10282ms: Process A0 (tau 196ms) started using the CPU for 1096ms burst [Q A5 B3 B0 A6 A4 A3 B5 A9 A8 A2 B2 A1 A7 B4 B1]
time 10888ms: Process B9 (tau 23ms) completed I/O; added to ready queue [Q B9 A5 B3 B0 A6 A4 A3 B5 A9 A8 A2 B2 A1 A7 B4 B1]
time 11378ms: Process A0 (tau 196ms) completed a CPU burst; 28 bursts to go [Q B9 A5 B3 B0 A6 A4 A3 B5 A9 A8 A2 B2 A1 A7 B4 B1]
time 11378ms: Recalculated tau for process A0: old tau 196ms ==> new tau 1087ms [Q B9 A5 B3 B0 A6 A4 A3 B5 A9 A8 A2 B2 A1 A7 B4 B1]
time 11378ms: Process A0 switching out of CPU; blocking on I/O until time 11465ms [Q B9 A5 B3 B0 A6 A4 A3 B5 A9 A8 A2 B2 A1 A7 B4 B1]
time 11382ms: Process B9 (tau 23ms) started using the CPU for 142ms burst [Q A5 B3 B0 A6 A4 A3 B5 A9 A8 A2 B2 A1 A7 B4 B1]
time 11465ms: Process A0 (tau 1087ms) completed I/O; added to ready queue [Q A5 B3 B0 A6 A4 A3 B5 A9 A8 A2 B2 A1 A7 A0 B4 B1]
time 11524ms: Process B9 (tau 23ms) completed a CPU burst; 9 bursts to go [Q A5 B3 B0 A6 A4 A3 B5 A9 A8 A2 B2 A1 A7 A0 B4 B1]
time 11524ms: Recalculated tau for process B9: old tau 23ms ==> new tau 141ms [Q A5 B3 B0 A6 A4 A3 B5 A9 A8 A2 B2 A1 A7 A0 B4 B1]
time 11524ms: Process B9 switching out of CPU; blocking on I/O until time 11598ms [Q A5 B3 B0 A6 A4 A3 B5 A9 A8 A2 B2 A1 A7 A0 B4 B1]
time 11528ms: Process A5 (tau 196ms) started using the CPU for 140ms burst [Q B3 B0 A6 A4 A3 B5 A9 A8 A2 B2 A1 A7 A0 B4 B1]
time 11598ms: Process B9 (tau 141ms) completed I/O; added to ready queue [Q B9 B3 B0 A6 A4 A3 B5 A9 A8 A2 B2 A1 A7 A0 B4 B1]
time 11668ms: Process A5 (tau 196ms) completed a CPU burst; 3 bursts to go [Q B9 B3 B0 A6 A4 A3 B5 A9 A8 A2 B2 A1 A7 A0 B4 B1]
time 11668ms: Recalculated tau for process A5: old tau 196ms ==> new tau 141ms [Q B9 B3 B0 A6 A4 A3 B5 A9 A8 A2 B2 A1 A7 A0 B4 B1]
time 11668ms: Process A5 switching out of CPU; blocking on I/O until time 11782ms [Q B9 B3 B0 A6 A4 A3 B5 A9 A8 A2 B2 A1 A7 A0 B4 B1]
time 11672ms: Process B9 (tau 141ms) started using the CPU for 64ms burst [Q B3 B0 A6 A4 A3 B5 A9 A8 A2 B2 A1 A7 A0 B4 B1]
time 11736ms: Process B9 (tau 141ms) completed a CPU burst; 8 bursts to go [Q B3 B0 A6 A4 A3 B5 A9 A8 A2 B2 A1 A7 A0 B4 B1]
time 11736ms: Recalculated tau for process B9: old tau 141ms ==> new tau 65ms [Q B3 B0 A6 A4 A3 B5 A9 A8 A2 B2 A1 A7 A0 B4 B1]
time 11736ms: Process B9 switching out of CPU; blocking on I/O until time 12578ms [Q B3 B0 A6 A4 A3 B5 A9 A8 A2 B2 A1 A7 A0 B4 B1]
time 11740ms: Process B3 (tau 203ms) started using the CPU for 516ms burst [Q B0 A6 A4 A3 B5 A9 A8 A2 B2 A1 A7 A0 B4 B1]
time 11782ms: Process A5 (tau 141ms) completed I/O; added to ready queue [Q A5 B0 A6 A4 A3 B5 A9 A8 A2 B2 A1 A7 A0 B4 B1]
time 12256ms: Process B3 (tau 203ms) completed a CPU burst; 20 bursts to go [Q A5 B0 A6 A4 A3 B5 A9 A8 A2 B2 A1 A7 A0 B4 B1]
time 12256ms: Recalculated tau for process B3: old tau 203ms ==> new tau 513ms [Q A5 B0 A6 A4 A3 B5 A9 A8 A2 B2 A1 A7 A0 B4 B1]
time 12256ms: Process B3 switching out of CPU; blocking on I/O until time 12428ms [Q A5 B0 A6 A4 A3 B5 A9 A8 A2 B2 A1 A7 A0 B4 B1]
time 12260ms: Process A5 (tau 141ms) started using the CPU for 200ms burst [Q B0 A6 A4 A3 B5 A9 A8 A2 B2 A1 A7 A0 B4 B1]
time 12428ms: Process B3 (tau 513ms) completed I/O; added to ready queue [Q B0 A6 A4 A3 B5 A9 A8 A2 B2 B3 A1 A7 A0 B4 B1]
time 12460ms: Process A5 (tau 141ms) completed a CPU burst; 2 bursts to go [Q B0 A6 A4 A3 B5 A9 A8 A2 B2 B3 A1 A7 A0 B4 B1]
time 12460ms: Recalculated tau for process A5: old tau 141ms ==> new tau 200ms [Q B0 A6 A4 A3 B5 A9 A8 A2 B2 B3 A1 A7 A0 B4 B1]
time 12460ms: Process A5 switching out of CPU; blocking on I/O until time 12528ms [Q B0 A6 A4 A3 B5 A9 A8 A2 B2 B3 A1 A7 A0 B4 B1]
time 12464ms: Process B0 (tau 215ms) started using the CPU for 1264ms burst [Q A6 A4 A3 B5 A9 A8 A2 B2 B3 A1 A7 A0 B4 B1]
time 12528ms: Process A5 (tau 200ms) completed I/O; added to ready queue [Q A5 A6 A4 A3 B5 A9 A8 A2 B2 B3 A1 A7 A0 B4 B1]
time 12534ms: Process B8 (tau 306ms) completed I/O; added to ready queue [Q A5 A6 A4 A3 B8 B5 A9 A8 A2 B2 B3 A1 A7 A0 B4 B1]
time 12578ms: Process B9 (tau 65ms) completed I/O; added to ready queue [Q B9 A5 A6 A4 A3 B8 B5 A9 A8 A2 B2 B3 A1 A7 A0 B4 B1]
time 12747ms: Process B6 (tau 113ms) completed I/O; added to ready queue [Q B9 B6 A5 A6 A4 A3 B8 B5 A9 A8 A2 B2 B3 A1 A7 A0 B4 B1]
time 12990ms: Process B7 (tau 72ms) completed I/O; added to ready queue [Q B9 B7 B6 A5 A6 A4 A3 B8 B5 A9 A8 A2 B2 B3 A1 A7 A0 B4 B1]
time 13728ms: Process B0 (tau 215ms) completed a CPU burst; 17 bursts to go [Q B9 B7 B6 A5 A6 A4 A3 B8 B5 A9 A8 A2 B2 B3 A1 A7 A0 B4 B1]
time 13728ms: Recalculated tau for process B0: old tau 215ms ==> new tau 1254ms [Q B9 B7 B6 A5 A6 A4 A3 B8 B5 A9 A8 A2 B2 B3 A1 A7 A0 B4 B1]
time 13728ms: Process B0 switching out of CPU; blocking on I/O until time 13739ms [Q B9 B7 B6 A5 A6 A4 A3 B8 B5 A9 A8 A2 B2 B3 A1 A7 A0 B4 B1]
time 13732ms: Process B9 (tau 65ms) started using the CPU for 181ms burst [Q B7 B6 A5 A6 A4 A3 B8 B5 A9 A8 A2 B2 B3 A1 A7 A0 B4 B1]
time 13739ms: Process B0 (tau 1254ms) completed I/O; added to ready queue [Q B7 B6 A5 A6 A4 A3 B8 B5 A9 A8 A2 B2 B3 A1 A7 A0 B4 B0 B1]
time 13913ms: Process B9 (tau 65ms) completed a CPU burst; 7 bursts to go [Q B7 B6 A5 A6 A4 A3 B8 B5 A9 A8 A2 B2 B3 A1 A7 A0 B4 B0 B1]
time 13913ms: Recalculated tau for process B9: old tau 65ms ==> new tau 180ms [Q B7 B6 A5 A6 A4 A3 B8 B5 A9 A8 A2 B2 B3 A1 A7 A0 B4 B0 B1]
time 13913ms: Process B9 switching out of CPU; blocking on I/O until time 14107ms [Q B7 B6 A5 A6 A4 A3 B8 B5 A9 A8 A2 B2 B3 A1 A7 A0 B4 B0 B1]
time 13917ms: Process B7 (tau 72ms) started using the CPU for 20ms burst [Q B6 A5 A6 A4 A3 B8 B5 A9 A8 A2 B2 B3 A1 A7 A0 B4 B0 B1]
time 13937ms: Process B7 (tau 72ms) completed a CPU burst; 24 bursts to go [Q B6 A5 A6 A4 A3 B8 B5 A9 A8 A2 B2 B3 A1 A7 A0 B4 B0 B1]
time 13937ms: Recalculated tau for process B7: old tau 72ms ==> new tau 21ms [Q B6 A5 A6 A4 A3 B8 B5 A9 A8 A2 B2 B3 A1 A7 A0 B4 B0 B1]
time 13937ms: Process B7 switching out of CPU; blocking on I/O until time 13979ms [Q B6 A5 A6 A4 A3 B8 B5 A9 A8 A2 B2 B3 A1 A7 A0 B4 B0 B1]
time 13941ms: Process B6 (tau 113ms) started using the CPU for 142ms burst [Q A5 A6 A4 A3 B8 B5 A9 A8 A2 B2 B3 A1 A7 A0 B4 B0 B1]
time 13979ms: Process B7 (tau 21ms) completed I/O; added to ready queue [Q B7 A5 A6 A4 A3 B8 B5 A9 A8 A2 B2 B3 A1 A7 A0 B4 B0 B1]
time 14083ms: Process B6 (tau 113ms) completed a CPU burst; 3 bursts to go [Q B7 A5 A6 A4 A3 B8 B5 A9 A8 A2 B2 B3 A1 A7 A0 B4 B0 B1]
time 14083ms: Recalculated tau for process B6: old tau 113ms ==> new tau 142ms [Q B7 A5 A6 A4 A3 B8 B5 A9 A8 A2 B2 B3 A1 A7 A0 B4 B0 B1]
time 14083ms: Process B6 switching out of CPU; blocking on I/O until time 14957ms [Q B7 A5 A6 A4 A3 B8 B5 A9 A8 A2 B2 B3 A1 A7 A0 B4 B0 B1]
time 14087ms: Process B7 (tau 21ms) started using the CPU for 3ms burst [Q A5 A6 A4 A3 B8 B5 A9 A8 A2 B2 B3 A1 A7 A0 B4 B0 B1]
time 14090ms: Process B7 (tau 21ms) completed a CPU burst; 23 bursts to go [Q A5 A6 A4 A3 B8 B5 A9 A8 A2 B2 B3 A1 A7 A0 B4 B0 B1]
time 14090ms: Recalculated tau for process B7: old tau 21ms ==> new tau 4ms [Q A5 A6 A4 A3 B8 B5 A9 A8 A2 B2 B3 A1 A7 A0 B4 B0 B1]
time 14090ms: Process B7 switching out of CPU; blocking on I/O until time 17052ms [Q A5 A6 A4 A3 B8 B5 A9 A8 A2 B2 B3 A1 A7 A0 B4 B0 B1]
time 14094ms: Process A5 (tau 200ms) started using the CPU for 60ms burst [Q A6 A4 A3 B8 B5 A9 A8 A2 B2 B3 A1 A7 A0 B4 B0 B1]
time 14107ms: Process B9 (tau 180ms) completed I/O; added to ready queue [Q B9 A6 A4 A3 B8 B5 A9 A8 A2 B2 B3 A1 A7 A0 B4 B0 B1]
time 14154ms: Process A5 (tau 200ms) completed a CPU burst; 1 burst to go [Q B9 A6 A4 A3 B8 B5 A9 A8 A2 B2 B3 A1 A7 A0 B4 B0 B1]
time 14154ms: Recalculated tau for process A5: old tau 200ms ==> new tau 62ms [Q B9 A6 A4 A3 B8 B5 A9 A8 A2 B2 B3 A1 A7 A0 B4 B0 B1]
time 14154ms: Process A5 switching out of CPU; blocking on I/O until time 14262ms [Q B9 A6 A4 A3 B8 B5 A9 A8 A2 B2 B3 A1 A7 A0 B4 B0 B1]
time 14158ms: Process B9 (tau 180ms) started using the CPU for 240ms burst [Q A6 A4 A3 B8 B5 A9 A8 A2 B2 B3 A1 A7 A0 B4 B0 B1]
time 14262ms: Process A5 (tau 62ms) completed I/O; added to ready queue [Q A5 A6 A4 A3 B8 B5 A9 A8 A2 B2 B3 A1 A7 A0 B4 B0 B1]
time 14398ms: Process B9 (tau 180ms) completed a CPU burst; 6 bursts to go [Q A5 A6 A4 A3 B8 B5 A9 A8 A2 B2 B3 A1 A7 A0 B4 B0 B1]
time 14398ms: Recalculated tau for process B9: old tau 180ms ==> new tau 240ms [Q A5 A6 A4 A3 B8 B5 A9 A8 A2 B2 B3 A1 A7 A0 B4 B0 B1]
time 14398ms: Process B9 switching out of CPU; blocking on I/O until time 14784ms [Q A5 A6 A4 A3 B8 B5 A9 A8 A2 B2 B3 A1 A7 A0 B4 B0 B1]
time 14402ms: Process A5 (tau 62ms) started using the CPU for 912ms burst [Q A6 A4 A3 B8 B5 A9 A8 A2 B2 B3 A1 A7 A0 B4 B0 B1]
time 14784ms: Process B9 (tau 240ms) completed I/O; added to ready queue [Q B9 A6 A4 A3 B8 B5 A9 A8 A2 B2 B3 A1 A7 A0 B4 B0 B1]
time 14957ms: Process B6 (tau 142ms) completed I/O; added to ready queue [Q B6 B9 A6 A4 A3 B8 B5 A9 A8 A2 B2 B3 A1 A7 A0 B4 B0 B1]
time 15314ms: Process A5 terminated [Q B6 B9 A6 A4 A3 B8 B5 A9 A8 A2 B2 B3 A1 A7 A0 B4 B0 B1]
time 15318ms: Process B6 (tau 142ms) started using the CPU for 235ms burst [Q B9 A6 A4 A3 B8 B5 A9 A8 A2 B2 B3 A1 A7 A0 B4 B0 B1]
time 15553ms: Process B6 (tau 142ms) completed a CPU burst; 2 bursts to go [Q B9 A6 A4 A3 B8 B5 A9 A8 A2 B2 B3 A1 A7 A0 B4 B0 B1]
time 15553ms: Recalculated tau for process B6: old tau 142ms ==> new tau 235ms [Q B9 A6 A4 A3 B8 B5 A9 A8 A2 B2 B3 A1 A7 A0 B4 B0 B1]
time 15553ms: Process B6 switching out of CPU; blocking on I/O until time 16515ms [Q B9 A6 A4 A3 B8 B5 A9 A8 A2 B2 B3 A1 A7 A0 B4 B0 B1]
time 15557ms: Process B9 (tau 240ms) started using the CPU for 23ms burst [Q A6 A4 A3 B8 B5 A9 A8 A2 B2 B3 A1 A7 A0 B4 B0 B1]
time 15580ms: Process B9 (tau 240ms) completed a CPU burst; 5 bursts to go [Q A6 A4 A3 B8 B5 A9 A8 A2 B2 B3 A1 A7 A0 B4 B0 B1]
time 15580ms: Recalculated tau for process B9: old tau 240ms ==> new tau 26ms [Q A6 A4 A3 B8 B5 A9 A8 A2 B2 B3 A1 A7 A0 B4 B0 B1]
time 15580ms: Process B9 switching out of CPU; blocking on I/O until time 15710ms [Q A6 A4 A3 B8 B5 A9 A8 A2 B2 B3 A1 A7 A0 B4 B0 B1]
time 15584ms: Process A6 (tau 279ms) started using the CPU for 100ms burst [Q A4 A3 B8 B5 A9 A8 A2 B2 B3 A1 A7 A0 B4 B0 B1]
time 15684ms: Process A6 (tau 279ms) completed a CPU burst; 16 bursts to go [Q A4 A3 B8 B5 A9 A8 A2 B2 B3 A1 A7 A0 B4 B0 B1]
time 15684ms: Recalculated tau for process A6: old tau 279ms ==> new tau 102ms [Q A4 A3 B8 B5 A9 A8 A2 B2 B3 A1 A7 A0 B4 B0 B1]
time 15684ms: Process A6 switching out of CPU; blocking on I/O until time 15701ms [Q A4 A3 B8 B5 A9 A8 A2 B2 B3 A1 A7 A0 B4 B0 B1]
time 15688ms: Process A4 (tau 298ms) started using the CPU for 20ms burst [Q A3 B8 B5 A9 A8 A2 B2 B3 A1 A7 A0 B4 B0 B1]
time 15701ms: Process A6 (tau 102ms) completed I/O; added to ready queue [Q A6 A3 B8 B5 A9 A8 A2 B2 B3 A1 A7 A0 B4 B0 B1]
time 15708ms: Process A4 (tau 298ms) completed a CPU burst; 2 bursts to go [Q A6 A3 B8 B5 A9 A8 A2 B2 B3 A1 A7 A0 B4 B0 B1]
time 15708ms: Recalculated tau for process A4: old tau 298ms ==> new tau 23ms [Q A6 A3 B8 B5 A9 A8 A2 B2 B3 A1 A7 A0 B4 B0 B1]
time 15708ms: Process A4 switching out of CPU; blocking on I/O until time 15870ms [Q A6 A3 B8 B5 A9 A8 A2 B2 B3 A1 A7 A0 B4 B0 B1]
time 15710ms: Process B9 (tau 26ms) completed I/O; added to ready queue [Q B9 A6 A3 B8 B5 A9 A8 A2 B2 B3 A1 A7 A0 B4 B0 B1]
time 15712ms: Process B9 (tau 26ms) started using the CPU for 148ms burst [Q A6 A3 B8 B5 A9 A8 A2 B2 B3 A1 A7 A0 B4 B0 B1]
time 15860ms: Process B9 (tau 26ms) completed a CPU burst; 4 bursts to go [Q A6 A3 B8 B5 A9 A8 A2 B2 B3 A1 A7 A0 B4 B0 B1]
time 15860ms: Recalculated tau for process B9: old tau 26ms ==> new tau 147ms [Q A6 A3 B8 B5 A9 A8 A2 B2 B3 A1 A7 A0 B4 B0 B1]
time 15860ms: Process B9 switching out of CPU; blocking on I/O until time 16350ms [Q A6 A3 B8 B5 A9 A8 A2 B2 B3 A1 A7 A0 B4 B0 B1]
time 15864ms: Process A6 (tau 102ms) started using the CPU for 344ms burst [Q A3 B8 B5 A9 A8 A2 B2 B3 A1 A7 A0 B4 B0 B1]
time 15870ms: Process A4 (tau 23ms) completed I/O; added to ready queue [Q A4 A3 B8 B5 A9 A8 A2 B2 B3 A1 A7 A0 B4 B0 B1]
time 16208ms: Process A6 (tau 102ms) completed a CPU burst; 15 bursts to go [Q A4 A3 B8 B5 A9 A8 A2 B2 B3 A1 A7 A0 B4 B0 B1]
time 16208ms: Recalculated tau for process A6: old tau 102ms ==> new tau 342ms [Q A4 A3 B8 B5 A9 A8 A2 B2 B3 A1 A7 A0 B4 B0 B1]
time 16208ms: Process A6 switching out of CPU; blocking on I/O until time 16251ms [Q A4 A3 B8 B5 A9 A8 A2 B2 B3 A1 A7 A0 B4 B0 B1]
time 16212ms: Process A4 (tau 23ms) started using the CPU for 1248ms burst [Q A3 B8 B5 A9 A8 A2 B2 B3 A1 A7 A0 B4 B0 B1]
time 16251ms: Process A6 (tau 342ms) completed I/O; added to ready queue [Q A3 B8 B5 A6 A9 A8 A2 B2 B3 A1 A7 A0 B4 B0 B1]
time 16350ms: Process B9 (tau 147ms) completed I/O; added to ready queue [Q B9 A3 B8 B5 A6 A9 A8 A2 B2 B3 A1 A7 A0 B4 B0 B1]
time 16515ms: Process B6 (tau 235ms) completed I/O; added to ready queue [Q B9 B6 A3 B8 B5 A6 A9 A8 A2 B2 B3 A1 A7 A0 B4 B0 B1]
time 17052ms: Process B7 (tau 4ms) completed I/O; added to ready queue [Q B7 B9 B6 A3 B8 B5 A6 A9 A8 A2 B2 B3 A1 A7 A0 B4 B0 B1]
time 17460ms: Process A4 (tau 23ms) completed a CPU burst; 1 burst to go [Q B7 B9 B6 A3 B8 B5 A6 A9 A8 A2 B2 B3 A1 A7 A0 B4 B0 B1]
time 17460ms: Recalculated tau for process A4: old tau 23ms ==> new tau 1236ms [Q B7 B9 B6 A3 B8 B5 A6 A9 A8 A2 B2 B3 A1 A7 A0 B4 B0 B1]
time 17460ms: Process A4 switching out of CPU; blocking on I/O until time 17486ms [Q B7 B9 B6 A3 B8 B5 A6 A9 A8 A2 B2 B3 A1 A7 A0 B4 B0 B1]
time 17464ms: Process B7 (tau 4ms) started using the CPU for 74ms burst [Q B9 B6 A3 B8 B5 A6 A9 A8 A2 B2 B3 A1 A7 A0 B4 B0 B1]
time 17486ms: Process A4 (tau 1236ms) completed I/O; added to ready queue [Q B9 B6 A3 B8 B5 A6 A9 A8 A2 B2 B3 A1 A7 A0 B4 A4 B0 B1]
time 17538ms: Process B7 (tau 4ms) completed a CPU burst; 22 bursts to go [Q B9 B6 A3 B8 B5 A6 A9 A8 A2 B2 B3 A1 A7 A0 B4 A4 B0 B1]
time 17538ms: Recalculated tau for process B7: old tau 4ms ==> new tau 74ms [Q B9 B6 A3 B8 B5 A6 A9 A8 A2 B2 B3 A1 A7 A0 B4 A4 B0 B1]
time 17538ms: Process B7 switching out of CPU; blocking on I/O until time 21252ms [Q B9 B6 A3 B8 B5 A6 A9 A8 A2 B2 B3 A1 A7 A0 B4 A4 B0 B1]
time 17542ms: Process B9 (tau 147ms) started using the CPU for 159ms burst [Q B6 A3 B8 B5 A6 A9 A8 A2 B2 B3 A1 A7 A0 B4 A4 B0 B1]
time 17701ms: Process B9 (tau 147ms) completed a CPU burst; 3 bursts to go [Q B6 A3 B8 B5 A6 A9 A8 A2 B2 B3 A1 A7 A0 B4 A4 B0 B1]
time 17701ms: Recalculated tau for process B9: old tau 147ms ==> new tau 159ms [Q B6 A3 B8 B5 A6 A9 A8 A2 B2 B3 A1 A7 A0 B4 A4 B0 B1]
time 17701ms: Process B9 switching out of CPU; blocking on I/O until time 18487ms [Q B6 A3 B8 B5 A6 A9 A8 A2 B2 B3 A1 A7 A0 B4 A4 B0 B1]
time 17705ms: Process B6 (tau 235ms) started using the CPU for 10ms burst [Q A3 B8 B5 A6 A9 A8 A2 B2 B3 A1 A7 A0 B4 A4 B0 B1]
time 17715ms: Process B6 (tau 235ms) completed a CPU burst; 1 burst to go [Q A3 B8 B5 A6 A9 A8 A2 B2 B3 A1 A7 A0 B4 A4 B0 B1]
time 17715ms: Recalculated tau for process B6: old tau 235ms ==> new tau 13ms [Q A3 B8 B5 A6 A9 A8 A2 B2 B3 A1 A7 A0 B4 A4 B0 B1]
time 17715ms: Process B6 switching out of CPU; blocking on I/O until time 18181ms [Q A3 B8 B5 A6 A9 A8 A2 B2 B3 A1 A7 A0 B4 A4 B0 B1]
time 17719ms: Process A3 (tau 306ms) started using the CPU for 12ms burst [Q B8 B5 A6 A9 A8 A2 B2 B3 A1 A7 A0 B4 A4 B0 B1]
time 17731ms: Process A3 (tau 306ms) completed a CPU burst; 23 bursts to go [Q B8 B5 A6 A9 A8 A2 B2 B3 A1 A7 A0 B4 A4 B0 B1]
time 17731ms: Recalculated tau for process A3: old tau 306ms ==> new tau 15ms [Q B8 B5 A6 A9 A8 A2 B2 B3 A1 A7 A0 B4 A4 B0 B1]
time 17731ms: Process A3 switching out of CPU; blocking on I/O until time 17796ms [Q B8 B5 A6 A9 A8 A2 B2 B3 A1 A7 A0 B4 A4 B0 B1]
time 17735ms: Process B8 (tau 306ms) started using the CPU for 18ms burst [Q B5 A6 A9 A8 A2 B2 B3 A1 A7 A0 B4 A4 B0 B1]
time 17753ms: Process B8 (tau 306ms) completed a CPU burst; 18 bursts to go [Q B5 A6 A9 A8 A2 B2 B3 A1 A7 A0 B4 A4 B0 B1]
time 17753ms: Recalculated tau for process B8: old tau 306ms ==> new tau 21ms [Q B5 A6 A9 A8 A2 B2 B3 A1 A7 A0 B4 A4 B0 B1]
time 17753ms: Process B8 switching out of CPU; blocking on I/O until time 17883ms [Q B5 A6 A9 A8 A2 B2 B3 A1 A7 A0 B4 A4 B0 B1]
time 17757ms: Process B5 (tau 338ms) started using the CPU for 80ms burst [Q A6 A9 A8 A2 B2 B3 A1 A7 A0 B4 A4 B0 B1]
time 17796ms: Process A3 (tau 15ms) completed I/O; added to ready queue [Q A3 A6 A9 A8 A2 B2 B3 A1 A7 A0 B4 A4 B0 B1]
time 17837ms: Process B5 (tau 338ms) completed a CPU burst; 27 bursts to go [Q A3 A6 A9 A8 A2 B2 B3 A1 A7 A0 B4 A4 B0 B1]
time 17837ms: Recalculated tau for process B5: old tau 338ms ==> new tau 83ms [Q A3 A6 A9 A8 A2 B2 B3 A1 A7 A0 B4 A4 B0 B1]
time 17837ms: Process B5 switching out of CPU; blocking on I/O until time 17892ms [Q A3 A6 A9 A8 A2 B2 B3 A1 A7 A0 B4 A4 B0 B1]
time 17841ms: Process A3 (tau 15ms) started using the CPU for 28ms burst [Q A6 A9 A8 A2 B2 B3 A1 A7 A0 B4 A4 B0 B1]
time 17869ms: Process A3 (tau 15ms) completed a CPU burst; 22 bursts to go [Q A6 A9 A8 A2 B2 B3 A1 A7 A0 B4 A4 B0 B1]
time 17869ms: Recalculated tau for process A3: old tau 15ms ==> new tau 28ms [Q A6 A9 A8 A2 B2 B3 A1 A7 A0 B4 A4 B0 B1]
time 17869ms: Process A3 switching out of CPU; blocking on I/O until time 18109ms [Q A6 A9 A8 A2 B2 B3 A1 A7 A0 B4 A4 B0 B1]
time 17873ms: Process A6 (tau 342ms) started using the CPU for 756ms burst [Q A9 A8 A2 B2 B3 A1 A7 A0 B4 A4 B0 B1]
time 17883ms: Process B8 (tau 21ms) completed I/O; added to ready queue [Q B8 A9 A8 A2 B2 B3 A1 A7 A0 B4 A4 B0 B1]
time 17892ms: Process B5 (tau 83ms) completed I/O; added to ready queue [Q B8 B5 A9 A8 A2 B2 B3 A1 A7 A0 B4 A4 B0 B1]
time 18109ms: Process A3 (tau 28ms) completed I/O; added to ready queue [Q B8 A3 B5 A9 A8 A2 B2 B3 A1 A7 A0 B4 A4 B0 B1]
time 18181ms: Process B6 (tau 13ms) completed I/O; added to ready queue [Q B6 B8 A3 B5 A9 A8 A2 B2 B3 A1 A7 A0 B4 A4 B0 B1]
time 18487ms: Process B9 (tau 159ms) completed I/O; added to ready queue [Q B6 B8 A3 B5 B9 A9 A8 A2 B2 B3 A1 A7 A0 B4 A4 B0 B1]
time 18629ms: Process A6 (tau 342ms) completed a CPU burst; 14 bursts to go [Q B6 B8 A3 B5 B9 A9 A8 A2 B2 B3 A1 A7 A0 B4 A4 B0 B1]
time 18629ms: Recalculated tau for process A6: old tau 342ms ==> new tau 752ms [Q B6 B8 A3 B5 B9 A9 A8 A2 B2 B3 A1 A7 A0 B4 A4 B0 B1]
time 18629ms: Process A6 switching out of CPU; blocking on I/O until time 18749ms [Q B6 B8 A3 B5 B9 A9 A8 A2 B2 B3 A1 A7 A0 B4 A4 B0 B1]
time 18633ms: Process B6 (tau 13ms) started using the CPU for 46ms burst [Q B8 A3 B5 B9 A9 A8 A2 B2 B3 A1 A7 A0 B4 A4 B0 B1]
time 18679ms: Process B6 terminated [Q B8 A3 B5 B9 A9 A8 A2 B2 B3 A1 A7 A0 B4 A4 B0 B1]
time 18683ms: Process B8 (tau 21ms) started using the CPU for 75ms burst [Q A3 B5 B9 A9 A8 A2 B2 B3 A1 A7 A0 B4 A4 B0 B1]
time 18749ms: Process A6 (tau 752ms) completed I/O; added to ready queue [Q A3 B5 B9 A9 A8 A2 B2 B3 A1 A6 A7 A0 B4 A4 B0 B1]
time 18758ms: Process B8 (tau 21ms) completed a CPU burst; 17 bursts to go [Q A3 B5 B9 A9 A8 A2 B2 B3 A1 A6 A7 A0 B4 A4 B0 B1]
time 18758ms: Recalculated tau for process B8: old tau 21ms ==> new tau 75ms [Q A3 B5 B9 A9 A8 A2 B2 B3 A1 A6 A7 A0 B4 A4 B0 B1]
time 18758ms: Process B8 switching out of CPU; blocking on I/O until time 19024ms [Q A3 B5 B9 A9 A8 A2 B2 B3 A1 A6 A7 A0 B4 A4 B0 B1]
time 18762ms: Process A3 (tau 28ms) started using the CPU for 88ms burst [Q B5 B9 A9 A8 A2 B2 B3 A1 A6 A7 A0 B4 A4 B0 B1]
time 18850ms: Process A3 (tau 28ms) completed a CPU burst; 21 bursts to go [Q B5 B9 A9 A8 A2 B2 B3 A1 A6 A7 A0 B4 A4 B0 B1]
time 18850ms: Recalculated tau for process A3: old tau 28ms ==> new tau 88ms [Q B5 B9 A9 A8 A2 B2 B3 A1 A6 A7 A0 B4 A4 B0 B1]
time 18850ms: Process A3 switching out of CPU; blocking on I/O until time 18915ms [Q B5 B9 A9 A8 A2 B2 B3 A1 A6 A7 A0 B4 A4 B0 B1]
time 18854ms: Process B5 (tau 83ms) started using the CPU for 56ms burst [Q B9 A9 A8 A2 B2 B3 A1 A6 A7 A0 B4 A4 B0 B1]
time 18910ms: Process B5 (tau 83ms) completed a CPU burst; 26 bursts to go [Q B9 A9 A8 A2 B2 B3 A1 A6 A7 A0 B4 A4 B0 B1]
time 18910ms: Recalculated tau for process B5: old tau 83ms ==> new tau 57ms [Q B9 A9 A8 A2 B2 B3 A1 A6 A7 A0 B4 A4 B0 B1]
time 18910ms: Process B5 switching out of CPU; blocking on I/O until time 19052ms [Q B9 A9 A8 A2 B2 B3 A1 A6 A7 A0 B4 A4 B0 B1]
time 18914ms: Process B9 (tau 159ms) started using the CPU for 77ms burst [Q A9 A8 A2 B2 B3 A1 A6 A7 A0 B4 A4 B0 B1]
time 18915ms: Process A3 (tau 88ms) completed I/O; added to ready queue [Q A3 A9 A8 A2 B2 B3 A1 A6 A7 A0 B4 A4 B0 B1]
time 18991ms: Process B9 (tau 159ms) completed a CPU burst; 2 bursts to go [Q A3 A9 A8 A2 B2 B3 A1 A6 A7 A0 B4 A4 B0 B1]
time 18991ms: Recalculated tau for process B9: old tau 159ms ==> new tau 78ms [Q A3 A9 A8 A2 B2 B3 A1 A6 A7 A0 B4 A4 B0 B1]
time 18991ms: Process B9 switching out of CPU; blocking on I/O until time 20337ms [Q A3 A9 A8 A2 B2 B3 A1 A6 A7 A0 B4 A4 B0 B1]
time 18995ms: Process A3 (tau 88ms) started using the CPU for 116ms burst [Q A9 A8 A2 B2 B3 A1 A6 A7 A0 B4 A4 B0 B1]
time 19024ms: Process B8 (tau 75ms) completed I/O; added to ready queue [Q B8 A9 A8 A2 B2 B3 A1 A6 A7 A0 B4 A4 B0 B1]
time 19052ms: Process B5 (tau 57ms) completed I/O; added to ready queue [Q B5 B8 A9 A8 A2 B2 B3 A1 A6 A7 A0 B4 A4 B0 B1]
time 19111ms: Process A3 (tau 88ms) completed a CPU burst; 20 bursts to go [Q B5 B8 A9 A8 A2 B2 B3 A1 A6 A7 A0 B4 A4 B0 B1]
time 19111ms: Recalculated tau for process A3: old tau 88ms ==> new tau 116ms [Q B5 B8 A9 A8 A2 B2 B3 A1 A6 A7 A0 B4 A4 B0 B1]
time 19111ms: Process A3 switching out of CPU; blocking on I/O until time 19167ms [Q B5 B8 A9 A8 A2 B2 B3 A1 A6 A7 A0 B4 A4 B0 B1]
time 19115ms: Process B5 (tau 57ms) started using the CPU for 84ms burst [Q B8 A9 A8 A2 B2 B3 A1 A6 A7 A0 B4 A4 B0 B1]
time 19167ms: Process A3 (tau 116ms) completed I/O; added to ready queue [Q B8 A3 A9 A8 A2 B2 B3 A1 A6 A7 A0 B4 A4 B0 B1]
time 19199ms: Process B5 (tau 57ms) completed a CPU burst; 25 bursts to go [Q B8 A3 A9 A8 A2 B2 B3 A1 A6 A7 A0 B4 A4 B0 B1]
time 19199ms: Recalculated tau for process B5: old tau 57ms ==> new tau 84ms [Q B8 A3 A9 A8 A2 B2 B3 A1 A6 A7 A0 B4 A4 B0 B1]
time 19199ms: Process B5 switching out of CPU; blocking on I/O until time 19203ms [Q B8 A3 A9 A8 A2 B2 B3 A1 A6 A7 A0 B4 A4 B0 B1]
time 19203ms: Process B8 (tau 75ms) started using the CPU for 44ms burst [Q A3 A9 A8 A2 B2 B3 A1 A6 A7 A0 B4 A4 B0 B1]
time 19203ms: Process B5 (tau 84ms) completed I/O; added to ready queue [Q B5 A3 A9 A8 A2 B2 B3 A1 A6 A7 A0 B4 A4 B0 B1]
time 19247ms: Process B8 (tau 75ms) completed a CPU burst; 16 bursts to go [Q B5 A3 A9 A8 A2 B2 B3 A1 A6 A7 A0 B4 A4 B0 B1]
time 19247ms: Recalculated tau for process B8: old tau 75ms ==> new tau 45ms [Q B5 A3 A9 A8 A2 B2 B3 A1 A6 A7 A0 B4 A4 B0 B1]
time 19247ms: Process B8 switching out of CPU; blocking on I/O until time 22017ms [Q B5 A3 A9 A8 A2 B2 B3 A1 A6 A7 A0 B4 A4 B0 B1]
time 19251ms: Process B5 (tau 84ms) started using the CPU for 96ms burst [Q A3 A9 A8 A2 B2 B3 A1 A6 A7 A0 B4 A4 B0 B1]
time 19347ms: Process B5 (tau 84ms) completed a CPU burst; 24 bursts to go [Q A3 A9 A8 A2 B2 B3 A1 A6 A7 A0 B4 A4 B0 B1]
time 19347ms: Recalculated tau for process B5: old tau 84ms ==> new tau 96ms [Q A3 A9 A8 A2 B2 B3 A1 A6 A7 A0 B4 A4 B0 B1]
time 19347ms: Process B5 switching out of CPU; blocking on I/O until time 19368ms [Q A3 A9 A8 A2 B2 B3 A1 A6 A7 A0 B4 A4 B0 B1]
time 19351ms: Process A3 (tau 116ms) started using the CPU for 580ms burst [Q A9 A8 A2 B2 B3 A1 A6 A7 A0 B4 A4 B0 B1]
time 19368ms: Process B5 (tau 96ms) completed I/O; added to ready queue [Q B5 A9 A8 A2 B2 B3 A1 A6 A7 A0 B4 A4 B0 B1]
time 19931ms: Process A3 (tau 116ms) completed a CPU burst; 19 bursts to go [Q B5 A9 A8 A2 B2 B3 A1 A6 A7 A0 B4 A4 B0 B1]
time 19931ms: Recalculated tau for process A3: old tau 116ms ==> new tau 576ms [Q B5 A9 A8 A2 B2 B3 A1 A6 A7 A0 B4 A4 B0 B1]
time 19931ms: Process A3 switching out of CPU; blocking on I/O until time 19938ms [Q B5 A9 A8 A2 B2 B3 A1 A6 A7 A0 B4 A4 B0 B1]
time 19935ms: Process B5 (tau 96ms) started using the CPU for 480ms burst [Q A9 A8 A2 B2 B3 A1 A6 A7 A0 B4 A4 B0 B1]
time 19938ms: Process A3 (tau 576ms) completed I/O; added to ready queue [Q A9 A8 A2 B2 B3 A3 A1 A6 A7 A0 B4 A4 B0 B1]
time 20337ms: Process B9 (tau 78ms) completed I/O; added to ready queue [Q B9 A9 A8 A2 B2 B3 A3 A1 A6 A7 A0 B4 A4 B0 B1]
time 20415ms: Process B5 (tau 96ms) completed a CPU burst; 23 bursts to go [Q B9 A9 A8 A2 B2 B3 A3 A1 A6 A7 A0 B4 A4 B0 B1]
time 20415ms: Recalculated tau for process B5: old tau 96ms ==> new tau 477ms [Q B9 A9 A8 A2 B2 B3 A3 A1 A6 A7 A0 B4 A4 B0 B1]
time 20415ms: Process B5 switching out of CPU; blocking on I/O until time 20497ms [Q B9 A9 A8 A2 B2 B3 A3 A1 A6 A7 A0 B4 A4 B0 B1]
time 20419ms: Process B9 (tau 78ms) started using the CPU for 35ms burst [Q A9 A8 A2 B2 B3 A3 A1 A6 A7 A0 B4 A4 B0 B1]
time 20454ms: Process B9 (tau 78ms) completed a CPU burst; 1 burst to go [Q A9 A8 A2 B2 B3 A3 A1 A6 A7 A0 B4 A4 B0 B1]
time 20454ms: Recalculated tau for process B9: old tau 78ms ==> new tau 36ms [Q A9 A8 A2 B2 B3 A3 A1 A6 A7 A0 B4 A4 B0 B1]
time 20454ms: Process B9 switching out of CPU; blocking on I/O until time 21240ms [Q A9 A8 A2 B2 B3 A3 A1 A6 A7 A0 B4 A4 B0 B1]
time 20458ms: Process A9 (tau 358ms) started using the CPU for 28ms burst [Q A8 A2 B2 B3 A3 A1 A6 A7 A0 B4 A4 B0 B1]
time 20486ms: Process A9 (tau 358ms) completed a CPU burst; 30 bursts to go [Q A8 A2 B2 B3 A3 A1 A6 A7 A0 B4 A4 B0 B1]
time 20486ms: Recalculated tau for process A9: old tau 358ms ==> new tau 32ms [Q A8 A2 B2 B3 A3 A1 A6 A7 A0 B4 A4 B0 B1]
time 20486ms: Process A9 switching out of CPU; blocking on I/O until time 20516ms [Q A8 A2 B2 B3 A3 A1 A6 A7 A0 B4 A4 B0 B1]
time 20490ms: Process A8 (tau 417ms) started using the CPU for 176ms burst [Q A2 B2 B3 A3 A1 A6 A7 A0 B4 A4 B0 B1]
time 20497ms: Process B5 (tau 477ms) completed I/O; added to ready queue [Q A2 B5 B2 B3 A3 A1 A6 A7 A0 B4 A4 B0 B1]
time 20516ms: Process A9 (tau 32ms) completed I/O; added to ready queue [Q A9 A2 B5 B2 B3 A3 A1 A6 A7 A0 B4 A4 B0 B1]
time 20666ms: Process A8 (tau 417ms) completed a CPU burst; 6 bursts to go [Q A9 A2 B5 B2 B3 A3 A1 A6 A7 A0 B4 A4 B0 B1]
time 20666ms: Recalculated tau for process A8: old tau 417ms ==> new tau 179ms [Q A9 A2 B5 B2 B3 A3 A1 A6 A7 A0 B4 A4 B0 B1]
time 20666ms: Process A8 switching out of CPU; blocking on I/O until time 20706ms [Q A9 A2 B5 B2 B3 A3 A1 A6 A7 A0 B4 A4 B0 B1]
time 20670ms: Process A9 (tau 32ms) started using the CPU for 308ms burst [Q A2 B5 B2 B3 A3 A1 A6 A7 A0 B4 A4 B0 B1]
time 20706ms: Process A8 (tau 179ms) completed I/O; added to ready queue [Q A8 A2 B5 B2 B3 A3 A1 A6 A7 A0 B4 A4 B0 B1]
time 20978ms: Process A9 (tau 32ms) completed a CPU burst; 29 bursts to go [Q A8 A2 B5 B2 B3 A3 A1 A6 A7 A0 B4 A4 B0 B1]
time 20978ms: Recalculated tau for process A9: old tau 32ms ==> new tau 306ms [Q A8 A2 B5 B2 B3 A3 A1 A6 A7 A0 B4 A4 B0 B1]
time 20978ms: Process A9 switching out of CPU; blocking on I/O until time 21013ms [Q A8 A2 B5 B2 B3 A3 A1 A6 A7 A0 B4 A4 B0 B1]
time 20982ms: Process A8 (tau 179ms) started using the CPU for 340ms burst [Q A2 B5 B2 B3 A3 A1 A6 A7 A0 B4 A4 B0 B1]
time 21013ms: Process A9 (tau 306ms) completed I/O; added to ready queue [Q A9 A2 B5 B2 B3 A3 A1 A6 A7 A0 B4 A4 B0 B1]
time 21240ms: Process B9 (tau 36ms) completed I/O; added to ready queue [Q B9 A9 A2 B5 B2 B3 A3 A1 A6 A7 A0 B4 A4 B0 B1]
time 21252ms: Process B7 (tau 74ms) completed I/O; added to ready queue [Q B9 B7 A9 A2 B5 B2 B3 A3 A1 A6 A7 A0 B4 A4 B0 B1]
time 21322ms: Process A8 (tau 179ms) completed a CPU burst; 5 bursts to go [Q B9 B7 A9 A2 B5 B2 B3 A3 A1 A6 A7 A0 B4 A4 B0 B1]
time 21322ms: Recalculated tau for process A8: old tau 179ms ==> new tau 339ms [Q B9 B7 A9 A2 B5 B2 B3 A3 A1 A6 A7 A0 B4 A4 B0 B1]
time 21322ms: Process A8 switching out of CPU; blocking on I/O until time 21389ms [Q B9 B7 A9 A2 B5 B2 B3 A3 A1 A6 A7 A0 B4 A4 B0 B1]
time 21326ms: Process B9 (tau 36ms) started using the CPU for 19ms burst [Q B7 A9 A2 B5 B2 B3 A3 A1 A6 A7 A0 B4 A4 B0 B1]
time 21345ms: Process B9 terminated [Q B7 A9 A2 B5 B2 B3 A3 A1 A6 A7 A0 B4 A4 B0 B1]
time 21349ms: Process B7 (tau 74ms) started using the CPU for 133ms burst [Q A9 A2 B5 B2 B3 A3 A1 A6 A7 A0 B4 A4 B0 B1]
time 21389ms: Process A8 (tau 339ms) completed I/O; added to ready queue [Q A9 A8 A2 B5 B2 B3 A3 A1 A6 A7 A0 B4 A4 B0 B1]
time 21482ms: Process B7 (tau 74ms) completed a CPU burst; 21 bursts to go [Q A9 A8 A2 B5 B2 B3 A3 A1 A6 A7 A0 B4 A4 B0 B1]
time 21482ms: Recalculated tau for process B7: old tau 74ms ==> new tau 133ms [Q A9 A8 A2 B5 B2 B3 A3 A1 A6 A7 A0 B4 A4 B0 B1]
time 21482ms: Process B7 switching out of CPU; blocking on I/O until time 22756ms [Q A9 A8 A2 B5 B2 B3 A3 A1 A6 A7 A0 B4 A4 B0 B1]
time 21486ms: Process A9 (tau 306ms) started using the CPU for 16ms burst [Q A8 A2 B5 B2 B3 A3 A1 A6 A7 A0 B4 A4 B0 B1]
time 21502ms: Process A9 (tau 306ms) completed a CPU burst; 28 bursts to go [Q A8 A2 B5 B2 B3 A3 A1 A6 A7 A0 B4 A4 B0 B1]
time 21502ms: Recalculated tau for process A9: old tau 306ms ==> new tau 19ms [Q A8 A2 B5 B2 B3 A3 A1 A6 A7 A0 B4 A4 B0 B1]
time 21502ms: Process A9 switching out of CPU; blocking on I/O until time 21518ms [Q A8 A2 B5 B2 B3 A3 A1 A6 A7 A0 B4 A4 B0 B1]
time 21506ms: Process A8 (tau 339ms) started using the CPU for 820ms burst [Q A2 B5 B2 B3 A3 A1 A6 A7 A0 B4 A4 B0 B1]
time 21518ms: Process A9 (tau 19ms) completed I/O; added to ready queue [Q A9 A2 B5 B2 B3 A3 A1 A6 A7 A0 B4 A4 B0 B1]
time 22017ms: Process B8 (tau 45ms) completed I/O; added to ready queue [Q A9 B8 A2 B5 B2 B3 A3 A1 A6 A7 A0 B4 A4 B0 B1]
time 22326ms: Process A8 (tau 339ms) completed a CPU burst; 4 bursts to go [Q A9 B8 A2 B5 B2 B3 A3 A1 A6 A7 A0 B4 A4 B0 B1]
time 22326ms: Recalculated tau for process A8: old tau 339ms ==> new tau 816ms [Q A9 B8 A2 B5 B2 B3 A3 A1 A6 A7 A0 B4 A4 B0 B1]
time 22326ms: Process A8 switching out of CPU; blocking on I/O until time 22401ms [Q A9 B8 A2 B5 B2 B3 A3 A1 A6 A7 A0 B4 A4 B0 B1]
time 22330ms: Process A9 (tau 19ms) started using the CPU for 644ms burst [Q B8 A2 B5 B2 B3 A3 A1 A6 A7 A0 B4 A4 B0 B1]
time 22401ms: Process A8 (tau 816ms) completed I/O; added to ready queue [Q B8 A2 B5 B2 B3 A3 A1 A6 A7 A8 A0 B4 A4 B0 B1]
time 22756ms: Process B7 (tau 133ms) completed I/O; added to ready queue [Q B8 B7 A2 B5 B2 B3 A3 A1 A6 A7 A8 A0 B4 A4 B0 B1]
time 22974ms: Process A9 (tau 19ms) completed a CPU burst; 27 bursts to go [Q B8 B7 A2 B5 B2 B3 A3 A1 A6 A7 A8 A0 B4 A4 B0 B1]
time 22974ms: Recalculated tau for process A9: old tau 19ms ==> new tau 638ms [Q B8 B7 A2 B5 B2 B3 A3 A1 A6 A7 A8 A0 B4 A4 B0 B1]
time 22974ms: Process A9 switching out of CPU; blocking on I/O until time 23027ms [Q B8 B7 A2 B5 B2 B3 A3 A1 A6 A7 A8 A0 B4 A4 B0 B1]
time 22978ms: Process B8 (tau 45ms) started using the CPU for 56ms burst [Q B7 A2 B5 B2 B3 A3 A1 A6 A7 A8 A0 B4 A4 B0 B1]
time 23027ms: Process A9 (tau 638ms) completed I/O; added to ready queue [Q B7 A2 B5 B2 B3 A3 A1 A9 A6 A7 A8 A0 B4 A4 B0 B1]
time 23034ms: Process B8 (tau 45ms) completed a CPU burst; 15 bursts to go [Q B7 A2 B5 B2 B3 A3 A1 A9 A6 A7 A8 A0 B4 A4 B0 B1]
time 23034ms: Recalculated tau for process B8: old tau 45ms ==> new tau 56ms [Q B7 A2 B5 B2 B3 A3 A1 A9 A6 A7 A8 A0 B4 A4 B0 B1]
time 23034ms: Process B8 switching out of CPU; blocking on I/O until time 24260ms [Q B7 A2 B5 B2 B3 A3 A1 A9 A6 A7 A8 A0 B4 A4 B0 B1]
time 23038ms: Process B7 (tau 133ms) started using the CPU for 24ms burst [Q A2 B5 B2 B3 A3 A1 A9 A6 A7 A8 A0 B4 A4 B0 B1]
time 23062ms: Process B7 (tau 133ms) completed a CPU burst; 20 bursts to go [Q A2 B5 B2 B3 A3 A1 A9 A6 A7 A8 A0 B4 A4 B0 B1]
time 23062ms: Recalculated tau for process B7: old tau 133ms ==> new tau 26ms [Q A2 B5 B2 B3 A3 A1 A9 A6 A7 A8 A0 B4 A4 B0 B1]
time 23062ms: Process B7 switching out of CPU; blocking on I/O until time 25328ms [Q A2 B5 B2 B3 A3 A1 A9 A6 A7 A8 A0 B4 A4 B0 B1]
time 23066ms: Process A2 (tau 440ms) started using the CPU for 760ms burst [Q B5 B2 B3 A3 A1 A9 A6 A7 A8 A0 B4 A4 B0 B1]
time 23826ms: Process A2 (tau 440ms) completed a CPU burst; 27 bursts to go [Q B5 B2 B3 A3 A1 A9 A6 A7 A8 A0 B4 A4 B0 B1]
time 23826ms: Recalculated tau for process A2: old tau 440ms ==> new tau 757ms [Q B5 B2 B3 A3 A1 A9 A6 A7 A8 A0 B4 A4 B0 B1]
time 23826ms: Process A2 switching out of CPU; blocking on I/O until time 24078ms [Q B5 B2 B3 A3 A1 A9 A6 A7 A8 A0 B4 A4 B0 B1]
time 23830ms: Process B5 (tau 477ms) started using the CPU for 288ms burst [Q B2 B3 A3 A1 A9 A6 A7 A8 A0 B4 A4 B0 B1]
time 24078ms: Process A2 (tau 757ms) completed I/O; added to ready queue [Q B2 B3 A3 A1 A9 A6 A2 A7 A8 A0 B4 A4 B0 B1]
time 24118ms: Process B5 (tau 477ms) completed a CPU burst; 22 bursts to go [Q B2 B3 A3 A1 A9 A6 A2 A7 A8 A0 B4 A4 B0 B1]
time 24118ms: Recalculated tau for process B5: old tau 477ms ==> new tau 290ms [Q B2 B3 A3 A1 A9 A6 A2 A7 A8 A0 B4 A4 B0 B1]
time 24118ms: Process B5 switching out of CPU; blocking on I/O until time 24159ms [Q B2 B3 A3 A1 A9 A6 A2 A7 A8 A0 B4 A4 B0 B1]
time 24122ms: Process B2 (tau 485ms) started using the CPU for 732ms burst [Q B3 A3 A1 A9 A6 A2 A7 A8 A0 B4 A4 B0 B1]
time 24159ms: Process B5 (tau 290ms) completed I/O; added to ready queue [Q B5 B3 A3 A1 A9 A6 A2 A7 A8 A0 B4 A4 B0 B1]
time 24260ms: Process B8 (tau 56ms) completed I/O; added to ready queue [Q B8 B5 B3 A3 A1 A9 A6 A2 A7 A8 A0 B4 A4 B0 B1]
time 24854ms: Process B2 (tau 485ms) completed a CPU burst; 13 bursts to go [Q B8 B5 B3 A3 A1 A9 A6 A2 A7 A8 A0 B4 A4 B0 B1]
time 24854ms: Recalculated tau for process B2: old tau 485ms ==> new tau 730ms [Q B8 B5 B3 A3 A1 A9 A6 A2 A7 A8 A0 B4 A4 B0 B1]
time 24854ms: Process B2 switching out of CPU; blocking on I/O until time 24895ms [Q B8 B5 B3 A3 A1 A9 A6 A2 A7 A8 A0 B4 A4 B0 B1]
time 24858ms: Process B8 (tau 56ms) started using the CPU for 13ms burst [Q B5 B3 A3 A1 A9 A6 A2 A7 A8 A0 B4 A4 B0 B1]
time 24871ms: Process B8 (tau 56ms) completed a CPU burst; 14 bursts to go [Q B5 B3 A3 A1 A9 A6 A2 A7 A8 A0 B4 A4 B0 B1]
time 24871ms: Recalculated tau for process B8: old tau 56ms ==> new tau 14ms [Q B5 B3 A3 A1 A9 A6 A2 A7 A8 A0 B4 A4 B0 B1]
time 24871ms: Process B8 switching out of CPU; blocking on I/O until time 25313ms [Q B5 B3 A3 A1 A9 A6 A2 A7 A8 A0 B4 A4 B0 B1]
time 24875ms: Process B5 (tau 290ms) started using the CPU for 776ms burst [Q B3 A3 A1 A9 A6 A2 A7 A8 A0 B4 A4 B0 B1]
time 24895ms: Process B2 (tau 730ms) completed I/O; added to ready queue [Q B3 A3 A1 A9 B2 A6 A2 A7 A8 A0 B4 A4 B0 B1]
time 25313ms: Process B8 (tau 14ms) completed I/O; added to ready queue [Q B8 B3 A3 A1 A9 B2 A6 A2 A7 A8 A0 B4 A4 B0 B1]
time 25328ms: Process B7 (tau 26ms) completed I/O; added to ready queue [Q B8 B7 B3 A3 A1 A9 B2 A6 A2 A7 A8 A0 B4 A4 B0 B1]
time 25651ms: Process B5 (tau 290ms) completed a CPU burst; 21 bursts to go [Q B8 B7 B3 A3 A1 A9 B2 A6 A2 A7 A8 A0 B4 A4 B0 B1]
time 25651ms: Recalculated tau for process B5: old tau 290ms ==> new tau 772ms [Q B8 B7 B3 A3 A1 A9 B2 A6 A2 A7 A8 A0 B4 A4 B0 B1]
time 25651ms: Process B5 switching out of CPU; blocking on I/O until time 25658ms [Q B8 B7 B3 A3 A1 A9 B2 A6 A2 A7 A8 A0 B4 A4 B0 B1]
time 25655ms: Process B8 (tau 14ms) started using the CPU for 14ms burst [Q B7 B3 A3 A1 A9 B2 A6 A2 A7 A8 A0 B4 A4 B0 B1]
time 25658ms: Process B5 (tau 772ms) completed I/O; added to ready queue [Q B7 B3 A3 A1 A9 B2 A6 A2 A7 B5 A8 A0 B4 A4 B0 B1]
time 25669ms: Process B8 (tau 14ms) completed a CPU burst; 13 bursts to go [Q B7 B3 A3 A1 A9 B2 A6 A2 A7 B5 A8 A0 B4 A4 B0 B1]
time 25669ms: Recalculated tau for process B8: old tau 14ms ==> new tau 14ms [Q B7 B3 A3 A1 A9 B2 A6 A2 A7 B5 A8 A0 B4 A4 B0 B1]
time 25669ms: Process B8 switching out of CPU; blocking on I/O until time 25863ms [Q B7 B3 A3 A1 A9 B2 A6 A2 A7 B5 A8 A0 B4 A4 B0 B1]
time 25673ms: Process B7 (tau 26ms) started using the CPU for 11ms burst [Q B3 A3 A1 A9 B2 A6 A2 A7 B5 A8 A0 B4 A4 B0 B1]
time 25684ms: Process B7 (tau 26ms) completed a CPU burst; 19 bursts to go [Q B3 A3 A1 A9 B2 A6 A2 A7 B5 A8 A0 B4 A4 B0 B1]
time 25684ms: Recalculated tau for process B7: old tau 26ms ==> new tau 12ms [Q B3 A3 A1 A9 B2 A6 A2 A7 B5 A8 A0 B4 A4 B0 B1]
time 25684ms: Process B7 switching out of CPU; blocking on I/O until time 25806ms [Q B3 A3 A1 A9 B2 A6 A2 A7 B5 A8 A0 B4 A4 B0 B1]
time 25688ms: Process B3 (tau 513ms) started using the CPU for 16ms burst [Q A3 A1 A9 B2 A6 A2 A7 B5 A8 A0 B4 A4 B0 B1]
time 25704ms: Process B3 (tau 513ms) completed a CPU burst; 19 bursts to go [Q A3 A1 A9 B2 A6 A2 A7 B5 A8 A0 B4 A4 B0 B1]
time 25704ms: Recalculated tau for process B3: old tau 513ms ==> new tau 21ms [Q A3 A1 A9 B2 A6 A2 A7 B5 A8 A0 B4 A4 B0 B1]
time 25704ms: Process B3 switching out of CPU; blocking on I/O until time 25725ms [Q A3 A1 A9 B2 A6 A2 A7 B5 A8 A0 B4 A4 B0 B1]
time 25708ms: Process A3 (tau 576ms) started using the CPU for 72ms burst [Q A1 A9 B2 A6 A2 A7 B5 A8 A0 B4 A4 B0 B1]
time 25725ms: Process B3 (tau 21ms) completed I/O; added to ready queue [Q B3 A1 A9 B2 A6 A2 A7 B5 A8 A0 B4 A4 B0 B1]
time 25780ms: Process A3 (tau 576ms) completed a CPU burst; 18 bursts to go [Q B3 A1 A9 B2 A6 A2 A7 B5 A8 A0 B4 A4 B0 B1]
time 25780ms: Recalculated tau for process A3: old tau 576ms ==> new tau 78ms [Q B3 A1 A9 B2 A6 A2 A7 B5 A8 A0 B4 A4 B0 B1]
time 25780ms: Process A3 switching out of CPU; blocking on I/O until time 25859ms [Q B3 A1 A9 B2 A6 A2 A7 B5 A8 A0 B4 A4 B0 B1]
time 25784ms: Process B3 (tau 21ms) started using the CPU for 328ms burst [Q A1 A9 B2 A6 A2 A7 B5 A8 A0 B4 A4 B0 B1]
time 25806ms: Process B7 (tau 12ms) completed I/O; added to ready queue [Q B7 A1 A9 B2 A6 A2 A7 B5 A8 A0 B4 A4 B0 B1]
time 25859ms: Process A3 (tau 78ms) completed I/O; added to ready queue [Q B7 A3 A1 A9 B2 A6 A2 A7 B5 A8 A0 B4 A4 B0 B1]
time 25863ms: Process B8 (tau 14ms) completed I/O; added to ready queue [Q B7 B8 A3 A1 A9 B2 A6 A2 A7 B5 A8 A0 B4 A4 B0 B1]
time 26112ms: Process B3 (tau 21ms) completed a CPU burst; 18 bursts to go [Q B7 B8 A3 A1 A9 B2 A6 A2 A7 B5 A8 A0 B4 A4 B0 B1]
time 26112ms: Recalculated tau for process B3: old tau 21ms ==> new tau 325ms [Q B7 B8 A3 A1 A9 B2 A6 A2 A7 B5 A8 A0 B4 A4 B0 B1]
time 26112ms: Process B3 switching out of CPU; blocking on I/O until time 26148ms [Q B7 B8 A3 A1 A9 B2 A6 A2 A7 B5 A8 A0 B4 A4 B0 B1]
time 26116ms: Process B7 (tau 12ms) started using the CPU for 140ms burst [Q B8 A3 A1 A9 B2 A6 A2 A7 B5 A8 A0 B4 A4 B0 B1]
time 26148ms: Process B3 (tau 325ms) completed I/O; added to ready queue [Q B8 A3 B3 A1 A9 B2 A6 A2 A7 B5 A8 A0 B4 A4 B0 B1]
time 26256ms: Process B7 (tau 12ms) completed a CPU burst; 18 bursts to go [Q B8 A3 B3 A1 A9 B2 A6 A2 A7 B5 A8 A0 B4 A4 B0 B1]
time 26256ms: Recalculated tau for process B7: old tau 12ms ==> new tau 139ms [Q B8 A3 B3 A1 A9 B2 A6 A2 A7 B5 A8 A0 B4 A4 B0 B1]
time 26256ms: Process B7 switching out of CPU; blocking on I/O until time 26914ms [Q B8 A3 B3 A1 A9 B2 A6 A2 A7 B5 A8 A0 B4 A4 B0 B1]
time 26260ms: Process B8 (tau 14ms) started using the CPU for 32ms burst [Q A3 B3 A1 A9 B2 A6 A2 A7 B5 A8 A0 B4 A4 B0 B1]
time 26292ms: Process B8 (tau 14ms) completed a CPU burst; 12 bursts to go [Q A3 B3 A1 A9 B2 A6 A2 A7 B5 A8 A0 B4 A4 B0 B1]
time 26292ms: Recalculated tau for process B8: old tau 14ms ==> new tau 32ms [Q A3 B3 A1 A9 B2 A6 A2 A7 B5 A8 A0 B4 A4 B0 B1]
time 26292ms: Process B8 switching out of CPU; blocking on I/O until time 26718ms [Q A3 B3 A1 A9 B2 A6 A2 A7 B5 A8 A0 B4 A4 B0 B1]
time 26296ms: Process A3 (tau 78ms) started using the CPU for 440ms burst [Q B3 A1 A9 B2 A6 A2 A7 B5 A8 A0 B4 A4 B0 B1]
time 26718ms: Process B8 (tau 32ms) completed I/O; added to ready queue [Q B8 B3 A1 A9 B2 A6 A2 A7 B5 A8 A0 B4 A4 B0 B1]
time 26736ms: Process A3 (tau 78ms) completed a CPU burst; 17 bursts to go [Q B8 B3 A1 A9 B2 A6 A2 A7 B5 A8 A0 B4 A4 B0 B1]
time 26736ms: Recalculated tau for process A3: old tau 78ms ==> new tau 437ms [Q B8 B3 A1 A9 B2 A6 A2 A7 B5 A8 A0 B4 A4 B0 B1]
time 26736ms: Process A3 switching out of CPU; blocking on I/O until time 26797ms [Q B8 B3 A1 A9 B2 A6 A2 A7 B5 A8 A0 B4 A4 B0 B1]
time 26740ms: Process B8 (tau 32ms) started using the CPU for 33ms burst [Q B3 A1 A9 B2 A6 A2 A7 B5 A8 A0 B4 A4 B0 B1]
time 26773ms: Process B8 (tau 32ms) completed a CPU burst; 11 bursts to go [Q B3 A1 A9 B2 A6 A2 A7 B5 A8 A0 B4 A4 B0 B1]
time 26773ms: Recalculated tau for process B8: old tau 32ms ==> new tau 33ms [Q B3 A1 A9 B2 A6 A2 A7 B5 A8 A0 B4 A4 B0 B1]
time 26773ms: Process B8 switching out of CPU; blocking on I/O until time 27143ms [Q B3 A1 A9 B2 A6 A2 A7 B5 A8 A0 B4 A4 B0 B1]
time 26777ms: Process B3 (tau 325ms) started using the CPU for 500ms burst [Q A1 A9 B2 A6 A2 A7 B5 A8 A0 B4 A4 B0 B1]
time 26797ms: Process A3 (tau 437ms) completed I/O; added to ready queue [Q A3 A1 A9 B2 A6 A2 A7 B5 A8 A0 B4 A4 B0 B1]
time 26914ms: Process B7 (tau 139ms) completed I/O; added to ready queue [Q B7 A3 A1 A9 B2 A6 A2 A7 B5 A8 A0 B4 A4 B0 B1]
time 27143ms: Process B8 (tau 33ms) completed I/O; added to ready queue [Q B8 B7 A3 A1 A9 B2 A6 A2 A7 B5 A8 A0 B4 A4 B0 B1]
time 27277ms: Process B3 (tau 325ms) completed a CPU burst; 17 bursts to go [Q B8 B7 A3 A1 A9 B2 A6 A2 A7 B5 A8 A0 B4 A4 B0 B1]
time 27277ms: Recalculated tau for process B3: old tau 325ms ==> new tau 499ms [Q B8 B7 A3 A1 A9 B2 A6 A2 A7 B5 A8 A0 B4 A4 B0 B1]
time 27277ms: Process B3 switching out of CPU; blocking on I/O until time 27379ms [Q B8 B7 A3 A1 A9 B2 A6 A2 A7 B5 A8 A0 B4 A4 B0 B1]
time 27281ms: Process B8 (tau 33ms) started using the CPU for 66ms burst [Q B7 A3 A1 A9 B2 A6 A2 A7 B5 A8 A0 B4 A4 B0 B1]
time 27347ms: Process B8 (tau 33ms) completed a CPU burst; 10 bursts to go [Q B7 A3 A1 A9 B2 A6 A2 A7 B5 A8 A0 B4 A4 B0 B1]
time 27347ms: Recalculated tau for process B8: old tau 33ms ==> new tau 66ms [Q B7 A3 A1 A9 B2 A6 A2 A7 B5 A8 A0 B4 A4 B0 B1]
time 27347ms: Process B8 switching out of CPU; blocking on I/O until time 28621ms [Q B7 A3 A1 A9 B2 A6 A2 A7 B5 A8 A0 B4 A4 B0 B1]
time 27351ms: Process B7 (tau 139ms) started using the CPU for 317ms burst [Q A3 A1 A9 B2 A6 A2 A7 B5 A8 A0 B4 A4 B0 B1]
time 27379ms: Process B3 (tau 499ms) completed I/O; added to ready queue [Q A3 B3 A1 A9 B2 A6 A2 A7 B5 A8 A0 B4 A4 B0 B1]
time 27668ms: Process B7 (tau 139ms) completed a CPU burst; 17 bursts to go [Q A3 B3 A1 A9 B2 A6 A2 A7 B5 A8 A0 B4 A4 B0 B1]
time 27668ms: Recalculated tau for process B7: old tau 139ms ==> new tau 316ms [Q A3 B3 A1 A9 B2 A6 A2 A7 B5 A8 A0 B4 A4 B0 B1]
time 27668ms: Process B7 switching out of CPU; blocking on I/O until time 27718ms [Q A3 B3 A1 A9 B2 A6 A2 A7 B5 A8 A0 B4 A4 B0 B1]
time 27672ms: Process A3 (tau 437ms) started using the CPU for 252ms burst [Q B3 A1 A9 B2 A6 A2 A7 B5 A8 A0 B4 A4 B0 B1]
time 27718ms: Process B7 (tau 316ms) completed I/O; added to ready queue [Q B7 B3 A1 A9 B2 A6 A2 A7 B5 A8 A0 B4 A4 B0 B1]
time 27924ms: Process A3 (tau 437ms) completed a CPU burst; 16 bursts to go [Q B7 B3 A1 A9 B2 A6 A2 A7 B5 A8 A0 B4 A4 B0 B1]
time 27924ms: Recalculated tau for process A3: old tau 437ms ==> new tau 254ms [Q B7 B3 A1 A9 B2 A6 A2 A7 B5 A8 A0 B4 A4 B0 B1]
time 27924ms: Process A3 switching out of CPU; blocking on I/O until time 28128ms [Q B7 B3 A1 A9 B2 A6 A2 A7 B5 A8 A0 B4 A4 B0 B1]
time 27928ms: Process B7 (tau 316ms) started using the CPU for 104ms burst [Q B3 A1 A9 B2 A6 A2 A7 B5 A8 A0 B4 A4 B0 B1]
time 28032ms: Process B7 (tau 316ms) completed a CPU burst; 16 bursts to go [Q B3 A1 A9 B2 A6 A2 A7 B5 A8 A0 B4 A4 B0 B1]
time 28032ms: Recalculated tau for process B7: old tau 316ms ==> new tau 107ms [Q B3 A1 A9 B2 A6 A2 A7 B5 A8 A0 B4 A4 B0 B1]
time 28032ms: Process B7 switching out of CPU; blocking on I/O until time 28946ms [Q B3 A1 A9 B2 A6 A2 A7 B5 A8 A0 B4 A4 B0 B1]
time 28036ms: Process B3 (tau 499ms) started using the CPU for 124ms burst [Q A1 A9 B2 A6 A2 A7 B5 A8 A0 B4 A4 B0 B1]
time 28128ms: Process A3 (tau 254ms) completed I/O; added to ready queue [Q A3 A1 A9 B2 A6 A2 A7 B5 A8 A0 B4 A4 B0 B1]
time 28160ms: Process B3 (tau 499ms) completed a CPU burst; 16 bursts to go [Q A3 A1 A9 B2 A6 A2 A7 B5 A8 A0 B4 A4 B0 B1]
time 28160ms: Recalculated tau for process B3: old tau 499ms ==> new tau 128ms [Q A3 A1 A9 B2 A6 A2 A7 B5 A8 A0 B4 A4 B0 B1]
time 28160ms: Process B3 switching out of CPU; blocking on I/O until time 28556ms [Q A3 A1 A9 B2 A6 A2 A7 B5 A8 A0 B4 A4 B0 B1]
time 28164ms: Process A3 (tau 254ms) started using the CPU for 300ms burst [Q A1 A9 B2 A6 A2 A7 B5 A8 A0 B4 A4 B0 B1]
time 28464ms: Process A3 (tau 254ms) completed a CPU burst; 15 bursts to go [Q A1 A9 B2 A6 A2 A7 B5 A8 A0 B4 A4 B0 B1]
time 28464ms: Recalculated tau for process A3: old tau 254ms ==> new tau 300ms [Q A1 A9 B2 A6 A2 A7 B5 A8 A0 B4 A4 B0 B1]
time 28464ms: Process A3 switching out of CPU; blocking on I/O until time 28562ms [Q A1 A9 B2 A6 A2 A7 B5 A8 A0 B4 A4 B0 B1]
time 28468ms: Process A1 (tau 627ms) started using the CPU for 200ms burst [Q A9 B2 A6 A2 A7 B5 A8 A0 B4 A4 B0 B1]
time 28556ms: Process B3 (tau 128ms) completed I/O; added to ready queue [Q B3 A9 B2 A6 A2 A7 B5 A8 A0 B4 A4 B0 B1]
time 28562ms: Process A3 (tau 300ms) completed I/O; added to ready queue [Q B3 A3 A9 B2 A6 A2 A7 B5 A8 A0 B4 A4 B0 B1]
time 28621ms: Process B8 (tau 66ms) completed I/O; added to ready queue [Q B8 B3 A3 A9 B2 A6 A2 A7 B5 A8 A0 B4 A4 B0 B1]
time 28668ms: Process A1 (tau 627ms) completed a CPU burst; 10 bursts to go [Q B8 B3 A3 A9 B2 A6 A2 A7 B5 A8 A0 B4 A4 B0 B1]
time 28668ms: Recalculated tau for process A1: old tau 627ms ==> new tau 205ms [Q B8 B3 A3 A9 B2 A6 A2 A7 B5 A8 A0 B4 A4 B0 B1]
time 28668ms: Process A1 switching out of CPU; blocking on I/O until time 28702ms [Q B8 B3 A3 A9 B2 A6 A2 A7 B5 A8 A0 B4 A4 B0 B1]
time 28672ms: Process B8 (tau 66ms) started using the CPU for 23ms burst [Q B3 A3 A9 B2 A6 A2 A7 B5 A8 A0 B4 A4 B0 B1]
time 28695ms: Process B8 (tau 66ms) completed a CPU burst; 9 bursts to go [Q B3 A3 A9 B2 A6 A2 A7 B5 A8 A0 B4 A4 B0 B1]
time 28695ms: Recalculated tau for process B8: old tau 66ms ==> new tau 24ms [Q B3 A3 A9 B2 A6 A2 A7 B5 A8 A0 B4 A4 B0 B1]
time 28695ms: Process B8 switching out of CPU; blocking on I/O until time 28745ms [Q B3 A3 A9 B2 A6 A2 A7 B5 A8 A0 B4 A4 B0 B1]
time 28699ms: Process B3 (tau 128ms) started using the CPU for 244ms burst [Q A3 A9 B2 A6 A2 A7 B5 A8 A0 B4 A4 B0 B1]
time 28702ms: Process A1 (tau 205ms) completed I/O; added to ready queue [Q A1 A3 A9 B2 A6 A2 A7 B5 A8 A0 B4 A4 B0 B1]
time 28745ms: Process B8 (tau 24ms) completed I/O; added to ready queue [Q B8 A1 A3 A9 B2 A6 A2 A7 B5 A8 A0 B4 A4 B0 B1]
time 28943ms: Process B3 (tau 128ms) completed a CPU burst; 15 bursts to go [Q B8 A1 A3 A9 B2 A6 A2 A7 B5 A8 A0 B4 A4 B0 B1]
time 28943ms: Recalculated tau for process B3: old tau 128ms ==> new tau 243ms [Q B8 A1 A3 A9 B2 A6 A2 A7 B5 A8 A0 B4 A4 B0 B1]
time 28943ms: Process B3 switching out of CPU; blocking on I/O until time 29316ms [Q B8 A1 A3 A9 B2 A6 A2 A7 B5 A8 A0 B4 A4 B0 B1]
time 28946ms: Process B7 (tau 107ms) completed I/O; added to ready queue [Q B7 A1 A3 A9 B2 A6 A2 A7 B5 A8 A0 B4 A4 B0 B1]
time 28947ms: Process B8 (tau 24ms) started using the CPU for 125ms burst [Q B7 A1 A3 A9 B2 A6 A2 A7 B5 A8 A0 B4 A4 B0 B1]
time 29072ms: Process B8 (tau 24ms) completed a CPU burst; 8 bursts to go [Q B7 A1 A3 A9 B2 A6 A2 A7 B5 A8 A0 B4 A4 B0 B1]
time 29072ms: Recalculated tau for process B8: old tau 24ms ==> new tau 124ms [Q B7 A1 A3 A9 B2 A6 A2 A7 B5 A8 A0 B4 A4 B0 B1]
time 29072ms: Process B8 switching out of CPU; blocking on I/O until time 29674ms [Q B7 A1 A3 A9 B2 A6 A2 A7 B5 A8 A0 B4 A4 B0 B1]
time 29076ms: Process B7 (tau 107ms) started using the CPU for 126ms burst [Q A1 A3 A9 B2 A6 A2 A7 B5 A8 A0 B4 A4 B0 B1]
time 29202ms: Process B7 (tau 107ms) completed a CPU burst; 15 bursts to go [Q A1 A3 A9 B2 A6 A2 A7 B5 A8 A0 B4 A4 B0 B1]
time 29202ms: Recalculated tau for process B7: old tau 107ms ==> new tau 126ms [Q A1 A3 A9 B2 A6 A2 A7 B5 A8 A0 B4 A4 B0 B1]
time 29202ms: Process B7 switching out of CPU; blocking on I/O until time 30292ms [Q A1 A3 A9 B2 A6 A2 A7 B5 A8 A0 B4 A4 B0 B1]
time 29206ms: Process A1 (tau 205ms) started using the CPU for 608ms burst [Q A3 A9 B2 A6 A2 A7 B5 A8 A0 B4 A4 B0 B1]
time 29316ms: Process B3 (tau 243ms) completed I/O; added to ready queue [Q B3 A3 A9 B2 A6 A2 A7 B5 A8 A0 B4 A4 B0 B1]
time 29674ms: Process B8 (tau 124ms) completed I/O; added to ready queue [Q B8 B3 A3 A9 B2 A6 A2 A7 B5 A8 A0 B4 A4 B0 B1]
time 29814ms: Process A1 (tau 205ms) completed a CPU burst; 9 bursts to go [Q B8 B3 A3 A9 B2 A6 A2 A7 B5 A8 A0 B4 A4 B0 B1]
time 29814ms: Recalculated tau for process A1: old tau 205ms ==> new tau 604ms [Q B8 B3 A3 A9 B2 A6 A2 A7 B5 A8 A0 B4 A4 B0 B1]
time 29814ms: Process A1 switching out of CPU; blocking on I/O until time 29841ms [Q B8 B3 A3 A9 B2 A6 A2 A7 B5 A8 A0 B4 A4 B0 B1]
time 29818ms: Process B8 (tau 124ms) started using the CPU for 34ms burst [Q B3 A3 A9 B2 A6 A2 A7 B5 A8 A0 B4 A4 B0 B1]
time 29841ms: Process A1 (tau 604ms) completed I/O; added to ready queue [Q B3 A3 A1 A9 B2 A6 A2 A7 B5 A8 A0 B4 A4 B0 B1]
time 29852ms: Process B8 (tau 124ms) completed a CPU burst; 7 bursts to go [Q B3 A3 A1 A9 B2 A6 A2 A7 B5 A8 A0 B4 A4 B0 B1]
time 29852ms: Recalculated tau for process B8: old tau 124ms ==> new tau 35ms [Q B3 A3 A1 A9 B2 A6 A2 A7 B5 A8 A0 B4 A4 B0 B1]
time 29852ms: Process B8 switching out of CPU; blocking on I/O until time 29862ms [Q B3 A3 A1 A9 B2 A6 A2 A7 B5 A8 A0 B4 A4 B0 B1]
time 29856ms: Process B3 (tau 243ms) started using the CPU for 40ms burst [Q A3 A1 A9 B2 A6 A2 A7 B5 A8 A0 B4 A4 B0 B1]
time 29862ms: Process B8 (tau 35ms) completed I/O; added to ready queue [Q B8 A3 A1 A9 B2 A6 A2 A7 B5 A8 A0 B4 A4 B0 B1]
time 29896ms: Process B3 (tau 243ms) completed a CPU burst; 14 bursts to go [Q B8 A3 A1 A9 B2 A6 A2 A7 B5 A8 A0 B4 A4 B0 B1]
time 29896ms: Recalculated tau for process B3: old tau 243ms ==> new tau 43ms [Q B8 A3 A1 A9 B2 A6 A2 A7 B5 A8 A0 B4 A4 B0 B1]
time 29896ms: Process B3 switching out of CPU; blocking on I/O until time 29990ms [Q B8 A3 A1 A9 B2 A6 A2 A7 B5 A8 A0 B4 A4 B0 B1]
time 29900ms: Process B8 (tau 35ms) started using the CPU for 112ms burst [Q A3 A1 A9 B2 A6 A2 A7 B5 A8 A0 B4 A4 B0 B1]
time 29990ms: Process B3 (tau 43ms) completed I/O; added to ready queue [Q B3 A3 A1 A9 B2 A6 A2 A7 B5 A8 A0 B4 A4 B0 B1]
time 30012ms: Process B8 (tau 35ms) completed a CPU burst; 6 bursts to go [Q B3 A3 A1 A9 B2 A6 A2 A7 B5 A8 A0 B4 A4 B0 B1]
time 30012ms: Recalculated tau for process B8: old tau 35ms ==> new tau 112ms [Q B3 A3 A1 A9 B2 A6 A2 A7 B5 A8 A0 B4 A4 B0 B1]
time 30012ms: Process B8 switching out of CPU; blocking on I/O until time 30094ms [Q B3 A3 A1 A9 B2 A6 A2 A7 B5 A8 A0 B4 A4 B0 B1]
time 30016ms: Process B3 (tau 43ms) started using the CPU for 356ms burst [Q A3 A1 A9 B2 A6 A2 A7 B5 A8 A0 B4 A4 B0 B1]
time 30094ms: Process B8 (tau 112ms) completed I/O; added to ready queue [Q B8 A3 A1 A9 B2 A6 A2 A7 B5 A8 A0 B4 A4 B0 B1]
time 30292ms: Process B7 (tau 126ms) completed I/O; added to ready queue [Q B8 B7 A3 A1 A9 B2 A6 A2 A7 B5 A8 A0 B4 A4 B0 B1]
time 30372ms: Process B3 (tau 43ms) completed a CPU burst; 13 bursts to go [Q B8 B7 A3 A1 A9 B2 A6 A2 A7 B5 A8 A0 B4 A4 B0 B1]
time 30372ms: Recalculated tau for process B3: old tau 43ms ==> new tau 353ms [Q B8 B7 A3 A1 A9 B2 A6 A2 A7 B5 A8 A0 B4 A4 B0 B1]
time 30372ms: Process B3 switching out of CPU; blocking on I/O until time 30430ms [Q B8 B7 A3 A1 A9 B2 A6 A2 A7 B5 A8 A0 B4 A4 B0 B1]
time 30376ms: Process B8 (tau 112ms) started using the CPU for 14ms burst [Q B7 A3 A1 A9 B2 A6 A2 A7 B5 A8 A0 B4 A4 B0 B1]
time 30390ms: Process B8 (tau 112ms) completed a CPU burst; 5 bursts to go [Q B7 A3 A1 A9 B2 A6 A2 A7 B5 A8 A0 B4 A4 B0 B1]
time 30390ms: Recalculated tau for process B8: old tau 112ms ==> new tau 15ms [Q B7 A3 A1 A9 B2 A6 A2 A7 B5 A8 A0 B4 A4 B0 B1]
time 30390ms: Process B8 switching out of CPU; blocking on I/O until time 30912ms [Q B7 A3 A1 A9 B2 A6 A2 A7 B5 A8 A0 B4 A4 B0 B1]
time 30394ms: Process B7 (tau 126ms) started using the CPU for 6ms burst [Q A3 A1 A9 B2 A6 A2 A7 B5 A8 A0 B4 A4 B0 B1]
time 30400ms: Process B7 (tau 126ms) completed a CPU burst; 14 bursts to go [Q A3 A1 A9 B2 A6 A2 A7 B5 A8 A0 B4 A4 B0 B1]
time 30400ms: Recalculated tau for process B7: old tau 126ms ==> new tau 8ms [Q A3 A1 A9 B2 A6 A2 A7 B5 A8 A0 B4 A4 B0 B1]
time 30400ms: Process B7 switching out of CPU; blocking on I/O until time 31066ms [Q A3 A1 A9 B2 A6 A2 A7 B5 A8 A0 B4 A4 B0 B1]
time 30404ms: Process A3 (tau 300ms) started using the CPU for 268ms burst [Q A1 A9 B2 A6 A2 A7 B5 A8 A0 B4 A4 B0 B1]
time 30430ms: Process B3 (tau 353ms) completed I/O; added to ready queue [Q B3 A1 A9 B2 A6 A2 A7 B5 A8 A0 B4 A4 B0 B1]
time 30672ms: Process A3 (tau 300ms) completed a CPU burst; 14 bursts to go [Q B3 A1 A9 B2 A6 A2 A7 B5 A8 A0 B4 A4 B0 B1]
time 30672ms: Recalculated tau for process A3: old tau 300ms ==> new tau 269ms [Q B3 A1 A9 B2 A6 A2 A7 B5 A8 A0 B4 A4 B0 B1]
time 30672ms: Process A3 switching out of CPU; blocking on I/O until time 30943ms [Q B3 A1 A9 B2 A6 A2 A7 B5 A8 A0 B4 A4 B0 B1]
time 30676ms: Process B3 (tau 353ms) started using the CPU for 20ms burst [Q A1 A9 B2 A6 A2 A7 B5 A8 A0 B4 A4 B0 B1]
time 30696ms: Process B3 (tau 353ms) completed a CPU burst; 12 bursts to go [Q A1 A9 B2 A6 A2 A7 B5 A8 A0 B4 A4 B0 B1]
time 30696ms: Recalculated tau for process B3: old tau 353ms ==> new tau 24ms [Q A1 A9 B2 A6 A2 A7 B5 A8 A0 B4 A4 B0 B1]
time 30696ms: Process B3 switching out of CPU; blocking on I/O until time 30916ms [Q A1 A9 B2 A6 A2 A7 B5 A8 A0 B4 A4 B0 B1]
time 30700ms: Process A1 (tau 604ms) started using the CPU for 532ms burst [Q A9 B2 A6 A2 A7 B5 A8 A0 B4 A4 B0 B1]
time 30912ms: Process B8 (tau 15ms) completed I/O; added to ready queue [Q B8 A9 B2 A6 A2 A7 B5 A8 A0 B4 A4 B0 B1]
time 30916ms: Process B3 (tau 24ms) completed I/O; added to ready queue [Q B8 B3 A9 B2 A6 A2 A7 B5 A8 A0 B4 A4 B0 B1]
time 30943ms: Process A3 (tau 269ms) completed I/O; added to ready queue [Q B8 B3 A3 A9 B2 A6 A2 A7 B5 A8 A0 B4 A4 B0 B1]
time 31066ms: Process B7 (tau 8ms) completed I/O; added to ready queue [Q B7 B8 B3 A3 A9 B2 A6 A2 A7 B5 A8 A0 B4 A4 B0 B1]
time 31232ms: Process A1 (tau 604ms) completed a CPU burst; 8 bursts to go [Q B7 B8 B3 A3 A9 B2 A6 A2 A7 B5 A8 A0 B4 A4 B0 B1]
time 31232ms: Recalculated tau for process A1: old tau 604ms ==> new tau 533ms [Q B7 B8 B3 A3 A9 B2 A6 A2 A7 B5 A8 A0 B4 A4 B0 B1]
time 31232ms: Process A1 switching out of CPU; blocking on I/O until time 31251ms [Q B7 B8 B3 A3 A9 B2 A6 A2 A7 B5 A8 A0 B4 A4 B0 B1]
time 31236ms: Process B7 (tau 8ms) started using the CPU for 103ms burst [Q B8 B3 A3 A9 B2 A6 A2 A7 B5 A8 A0 B4 A4 B0 B1]
time 31251ms: Process A1 (tau 533ms) completed I/O; added to ready queue [Q B8 B3 A3 A1 A9 B2 A6 A2 A7 B5 A8 A0 B4 A4 B0 B1]
time 31339ms: Process B7 (tau 8ms) completed a CPU burst; 13 bursts to go [Q B8 B3 A3 A1 A9 B2 A6 A2 A7 B5 A8 A0 B4 A4 B0 B1]
time 31339ms: Recalculated tau for process B7: old tau 8ms ==> new tau 103ms [Q B8 B3 A3 A1 A9 B2 A6 A2 A7 B5 A8 A0 B4 A4 B0 B1]
time 31339ms: Process B7 switching out of CPU; blocking on I/O until time 31797ms [Q B8 B3 A3 A1 A9 B2 A6 A2 A7 B5 A8 A0 B4 A4 B0 B1]
time 31343ms: Process B8 (tau 15ms) started using the CPU for 18ms burst [Q B3 A3 A1 A9 B2 A6 A2 A7 B5 A8 A0 B4 A4 B0 B1]
time 31361ms: Process B8 (tau 15ms) completed a CPU burst; 4 bursts to go [Q B3 A3 A1 A9 B2 A6 A2 A7 B5 A8 A0 B4 A4 B0 B1]
time 31361ms: Recalculated tau for process B8: old tau 15ms ==> new tau 18ms [Q B3 A3 A1 A9 B2 A6 A2 A7 B5 A8 A0 B4 A4 B0 B1]
time 31361ms: Process B8 switching out of CPU; blocking on I/O until time 31443ms [Q B3 A3 A1 A9 B2 A6 A2 A7 B5 A8 A0 B4 A4 B0 B1]
time 31365ms: Process B3 (tau 24ms) started using the CPU for 764ms burst [Q A3 A1 A9 B2 A6 A2 A7 B5 A8 A0 B4 A4 B0 B1]
time 31443ms: Process B8 (tau 18ms) completed I/O; added to ready queue [Q B8 A3 A1 A9 B2 A6 A2 A7 B5 A8 A0 B4 A4 B0 B1]
time 31797ms: Process B7 (tau 103ms) completed I/O; added to ready queue [Q B8 B7 A3 A1 A9 B2 A6 A2 A7 B5 A8 A0 B4 A4 B0 B1]
time 32129ms: Process B3 (tau 24ms) completed a CPU burst; 11 bursts to go [Q B8 B7 A3 A1 A9 B2 A6 A2 A7 B5 A8 A0 B4 A4 B0 B1]
time 32129ms: Recalculated tau for process B3: old tau 24ms ==> new tau 757ms [Q B8 B7 A3 A1 A9 B2 A6 A2 A7 B5 A8 A0 B4 A4 B0 B1]
time 32129ms: Process B3 switching out of CPU; blocking on I/O until time 32288ms [Q B8 B7 A3 A1 A9 B2 A6 A2 A7 B5 A8 A0 B4 A4 B0 B1]
time 32133ms: Process B8 (tau 18ms) started using the CPU for 68ms burst [Q B7 A3 A1 A9 B2 A6 A2 A7 B5 A8 A0 B4 A4 B0 B1]
time 32201ms: Process B8 (tau 18ms) completed a CPU burst; 3 bursts to go [Q B7 A3 A1 A9 B2 A6 A2 A7 B5 A8 A0 B4 A4 B0 B1]
time 32201ms: Recalculated tau for process B8: old tau 18ms ==> new tau 68ms [Q B7 A3 A1 A9 B2 A6 A2 A7 B5 A8 A0 B4 A4 B0 B1]
time 32201ms: Process B8 switching out of CPU; blocking on I/O until time 33811ms [Q B7 A3 A1 A9 B2 A6 A2 A7 B5 A8 A0 B4 A4 B0 B1]
time 32205ms: Process B7 (tau 103ms) started using the CPU for 81ms burst [Q A3 A1 A9 B2 A6 A2 A7 B5 A8 A0 B4 A4 B0 B1]
time 32286ms: Process B7 (tau 103ms) completed a CPU burst; 12 bursts to go [Q A3 A1 A9 B2 A6 A2 A7 B5 A8 A0 B4 A4 B0 B1]
time 32286ms: Recalculated tau for process B7: old tau 103ms ==> new tau 82ms [Q A3 A1 A9 B2 A6 A2 A7 B5 A8 A0 B4 A4 B0 B1]
time 32286ms: Process B7 switching out of CPU; blocking on I/O until time 32584ms [Q A3 A1 A9 B2 A6 A2 A7 B5 A8 A0 B4 A4 B0 B1]
time 32288ms: Process B3 (tau 757ms) completed I/O; added to ready queue [Q A3 A1 A9 B2 A6 A2 B3 A7 B5 A8 A0 B4 A4 B0 B1]
time 32290ms: Process A3 (tau 269ms) started using the CPU for 36ms burst [Q A1 A9 B2 A6 A2 B3 A7 B5 A8 A0 B4 A4 B0 B1]
time 32326ms: Process A3 (tau 269ms) completed a CPU burst; 13 bursts to go [Q A1 A9 B2 A6 A2 B3 A7 B5 A8 A0 B4 A4 B0 B1]
time 32326ms: Recalculated tau for process A3: old tau 269ms ==> new tau 39ms [Q A1 A9 B2 A6 A2 B3 A7 B5 A8 A0 B4 A4 B0 B1]
time 32326ms: Process A3 switching out of CPU; blocking on I/O until time 32505ms [Q A1 A9 B2 A6 A2 B3 A7 B5 A8 A0 B4 A4 B0 B1]
time 32330ms: Process A1 (tau 533ms) started using the CPU for 100ms burst [Q A9 B2 A6 A2 B3 A7 B5 A8 A0 B4 A4 B0 B1]
time 32430ms: Process A1 (tau 533ms) completed a CPU burst; 7 bursts to go [Q A9 B2 A6 A2 B3 A7 B5 A8 A0 B4 A4 B0 B1]
time 32430ms: Recalculated tau for process A1: old tau 533ms ==> new tau 105ms [Q A9 B2 A6 A2 B3 A7 B5 A8 A0 B4 A4 B0 B1]
time 32430ms: Process A1 switching out of CPU; blocking on I/O until time 32498ms [Q A9 B2 A6 A2 B3 A7 B5 A8 A0 B4 A4 B0 B1]
time 32434ms: Process A9 (tau 638ms) started using the CPU for 304ms burst [Q B2 A6 A2 B3 A7 B5 A8 A0 B4 A4 B0 B1]
time 32498ms: Process A1 (tau 105ms) completed I/O; added to ready queue [Q A1 B2 A6 A2 B3 A7 B5 A8 A0 B4 A4 B0 B1]
time 32505ms: Process A3 (tau 39ms) completed I/O; added to ready queue [Q A3 A1 B2 A6 A2 B3 A7 B5 A8 A0 B4 A4 B0 B1]
time 32584ms: Process B7 (tau 82ms) completed I/O; added to ready queue [Q A3 B7 A1 B2 A6 A2 B3 A7 B5 A8 A0 B4 A4 B0 B1]
time 32738ms: Process A9 (tau 638ms) completed a CPU burst; 26 bursts to go [Q A3 B7 A1 B2 A6 A2 B3 A7 B5 A8 A0 B4 A4 B0 B1]
time 32738ms: Recalculated tau for process A9: old tau 638ms ==> new tau 308ms [Q A3 B7 A1 B2 A6 A2 B3 A7 B5 A8 A0 B4 A4 B0 B1]
time 32738ms: Process A9 switching out of CPU; blocking on I/O until time 32894ms [Q A3 B7 A1 B2 A6 A2 B3 A7 B5 A8 A0 B4 A4 B0 B1]
time 32742ms: Process A3 (tau 39ms) started using the CPU for 944ms burst [Q B7 A1 B2 A6 A2 B3 A7 B5 A8 A0 B4 A4 B0 B1]
time 32894ms: Process A9 (tau 308ms) completed I/O; added to ready queue [Q B7 A1 A9 B2 A6 A2 B3 A7 B5 A8 A0 B4 A4 B0 B1]
time 33686ms: Process A3 (tau 39ms) completed a CPU burst; 12 bursts to go [Q B7 A1 A9 B2 A6 A2 B3 A7 B5 A8 A0 B4 A4 B0 B1]
time 33686ms: Recalculated tau for process A3: old tau 39ms ==> new tau 935ms [Q B7 A1 A9 B2 A6 A2 B3 A7 B5 A8 A0 B4 A4 B0 B1]
time 33686ms: Process A3 switching out of CPU; blocking on I/O until time 33692ms [Q B7 A1 A9 B2 A6 A2 B3 A7 B5 A8 A0 B4 A4 B0 B1]
time 33690ms: Process B7 (tau 82ms) started using the CPU for 141ms burst [Q A1 A9 B2 A6 A2 B3 A7 B5 A8 A0 B4 A4 B0 B1]
time 33692ms: Process A3 (tau 935ms) completed I/O; added to ready queue [Q A1 A9 B2 A6 A2 B3 A7 B5 A8 A3 A0 B4 A4 B0 B1]
time 33811ms: Process B8 (tau 68ms) completed I/O; added to ready queue [Q B8 A1 A9 B2 A6 A2 B3 A7 B5 A8 A3 A0 B4 A4 B0 B1]
time 33831ms: Process B7 (tau 82ms) completed a CPU burst; 11 bursts to go [Q B8 A1 A9 B2 A6 A2 B3 A7 B5 A8 A3 A0 B4 A4 B0 B1]
time 33831ms: Recalculated tau for process B7: old tau 82ms ==> new tau 141ms [Q B8 A1 A9 B2 A6 A2 B3 A7 B5 A8 A3 A0 B4 A4 B0 B1]
time 33831ms: Process B7 switching out of CPU; blocking on I/O until time 35657ms [Q B8 A1 A9 B2 A6 A2 B3 A7 B5 A8 A3 A0 B4 A4 B0 B1]
time 33835ms: Process B8 (tau 68ms) started using the CPU for 62ms burst [Q A1 A9 B2 A6 A2 B3 A7 B5 A8 A3 A0 B4 A4 B0 B1]
time 33897ms: Process B8 (tau 68ms) completed a CPU burst; 2 bursts to go [Q A1 A9 B2 A6 A2 B3 A7 B5 A8 A3 A0 B4 A4 B0 B1]
time 33897ms: Recalculated tau for process B8: old tau 68ms ==> new tau 63ms [Q A1 A9 B2 A6 A2 B3 A7 B5 A8 A3 A0 B4 A4 B0 B1]
time 33897ms: Process B8 switching out of CPU; blocking on I/O until time 36707ms [Q A1 A9 B2 A6 A2 B3 A7 B5 A8 A3 A0 B4 A4 B0 B1]
time 33901ms: Process A1 (tau 105ms) started using the CPU for 256ms burst [Q A9 B2 A6 A2 B3 A7 B5 A8 A3 A0 B4 A4 B0 B1]
time 34157ms: Process A1 (tau 105ms) completed a CPU burst; 6 bursts to go [Q A9 B2 A6 A2 B3 A7 B5 A8 A3 A0 B4 A4 B0 B1]
time 34157ms: Recalculated tau for process A1: old tau 105ms ==> new tau 255ms [Q A9 B2 A6 A2 B3 A7 B5 A8 A3 A0 B4 A4 B0 B1]
time 34157ms: Process A1 switching out of CPU; blocking on I/O until time 34274ms [Q A9 B2 A6 A2 B3 A7 B5 A8 A3 A0 B4 A4 B0 B1]
time 34161ms: Process A9 (tau 308ms) started using the CPU for 400ms burst [Q B2 A6 A2 B3 A7 B5 A8 A3 A0 B4 A4 B0 B1]
time 34274ms: Process A1 (tau 255ms) completed I/O; added to ready queue [Q A1 B2 A6 A2 B3 A7 B5 A8 A3 A0 B4 A4 B0 B1]
time 34561ms: Process A9 (tau 308ms) completed a CPU burst; 25 bursts to go [Q A1 B2 A6 A2 B3 A7 B5 A8 A3 A0 B4 A4 B0 B1]
time 34561ms: Recalculated tau for process A9: old tau 308ms ==> new tau 400ms [Q A1 B2 A6 A2 B3 A7 B5 A8 A3 A0 B4 A4 B0 B1]
time 34561ms: Process A9 switching out of CPU; blocking on I/O until time 34668ms [Q A1 B2 A6 A2 B3 A7 B5 A8 A3 A0 B4 A4 B0 B1]
time 34565ms: Process A1 (tau 255ms) started using the CPU for 1684ms burst [Q B2 A6 A2 B3 A7 B5 A8 A3 A0 B4 A4 B0 B1]
time 34668ms: Process A9 (tau 400ms) completed I/O; added to ready queue [Q A9 B2 A6 A2 B3 A7 B5 A8 A3 A0 B4 A4 B0 B1]
time 35657ms: Process B7 (tau 141ms) completed I/O; added to ready queue [Q B7 A9 B2 A6 A2 B3 A7 B5 A8 A3 A0 B4 A4 B0 B1]
time 36249ms: Process A1 (tau 255ms) completed a CPU burst; 5 bursts to go [Q B7 A9 B2 A6 A2 B3 A7 B5 A8 A3 A0 B4 A4 B0 B1]
time 36249ms: Recalculated tau for process A1: old tau 255ms ==> new tau 1670ms [Q B7 A9 B2 A6 A2 B3 A7 B5 A8 A3 A0 B4 A4 B0 B1]
time 36249ms: Process A1 switching out of CPU; blocking on I/O until time 36313ms [Q B7 A9 B2 A6 A2 B3 A7 B5 A8 A3 A0 B4 A4 B0 B1]
time 36253ms: Process B7 (tau 141ms) started using the CPU for 705ms burst [Q A9 B2 A6 A2 B3 A7 B5 A8 A3 A0 B4 A4 B0 B1]
time 36313ms: Process A1 (tau 1670ms) completed I/O; added to ready queue [Q A9 B2 A6 A2 B3 A7 B5 A8 A3 A0 B4 A4 B0 A1 B1]
time 36707ms: Process B8 (tau 63ms) completed I/O; added to ready queue [Q B8 A9 B2 A6 A2 B3 A7 B5 A8 A3 A0 B4 A4 B0 A1 B1]
time 36958ms: Process B7 (tau 141ms) completed a CPU burst; 10 bursts to go [Q B8 A9 B2 A6 A2 B3 A7 B5 A8 A3 A0 B4 A4 B0 A1 B1]
time 36958ms: Recalculated tau for process B7: old tau 141ms ==> new tau 700ms [Q B8 A9 B2 A6 A2 B3 A7 B5 A8 A3 A0 B4 A4 B0 A1 B1]
time 36958ms: Process B7 switching out of CPU; blocking on I/O until time 37896ms [Q B8 A9 B2 A6 A2 B3 A7 B5 A8 A3 A0 B4 A4 B0 A1 B1]
time 36962ms: Process B8 (tau 63ms) started using the CPU for 67ms burst [Q A9 B2 A6 A2 B3 A7 B5 A8 A3 A0 B4 A4 B0 A1 B1]
time 37029ms: Process B8 (tau 63ms) completed a CPU burst; 1 burst to go [Q A9 B2 A6 A2 B3 A7 B5 A8 A3 A0 B4 A4 B0 A1 B1]
time 37029ms: Recalculated tau for process B8: old tau 63ms ==> new tau 67ms [Q A9 B2 A6 A2 B3 A7 B5 A8 A3 A0 B4 A4 B0 A1 B1]
time 37029ms: Process B8 switching out of CPU; blocking on I/O until time 39927ms [Q A9 B2 A6 A2 B3 A7 B5 A8 A3 A0 B4 A4 B0 A1 B1]
time 37033ms: Process A9 (tau 400ms) started using the CPU for 72ms burst [Q B2 A6 A2 B3 A7 B5 A8 A3 A0 B4 A4 B0 A1 B1]
time 37105ms: Process A9 (tau 400ms) completed a CPU burst; 24 bursts to go [Q B2 A6 A2 B3 A7 B5 A8 A3 A0 B4 A4 B0 A1 B1]
time 37105ms: Recalculated tau for process A9: old tau 400ms ==> new tau 76ms [Q B2 A6 A2 B3 A7 B5 A8 A3 A0 B4 A4 B0 A1 B1]
time 37105ms: Process A9 switching out of CPU; blocking on I/O until time 37146ms [Q B2 A6 A2 B3 A7 B5 A8 A3 A0 B4 A4 B0 A1 B1]
time 37109ms: Process B2 (tau 730ms) started using the CPU for 876ms burst [Q A6 A2 B3 A7 B5 A8 A3 A0 B4 A4 B0 A1 B1]
time 37146ms: Process A9 (tau 76ms) completed I/O; added to ready queue [Q A9 A6 A2 B3 A7 B5 A8 A3 A0 B4 A4 B0 A1 B1]
time 37896ms: Process B7 (tau 700ms) completed I/O; added to ready queue [Q A9 B7 A6 A2 B3 A7 B5 A8 A3 A0 B4 A4 B0 A1 B1]
time 37985ms: Process B2 (tau 730ms) completed a CPU burst; 12 bursts to go [Q A9 B7 A6 A2 B3 A7 B5 A8 A3 A0 B4 A4 B0 A1 B1]
time 37985ms: Recalculated tau for process B2: old tau 730ms ==> new tau 875ms [Q A9 B7 A6 A2 B3 A7 B5 A8 A3 A0 B4 A4 B0 A1 B1]
time 37985ms: Process B2 switching out of CPU; blocking on I/O until time 38021ms [Q A9 B7 A6 A2 B3 A7 B5 A8 A3 A0 B4 A4 B0 A1 B1]
time 37989ms: Process A9 (tau 76ms) started using the CPU for 316ms burst [Q B7 A6 A2 B3 A7 B5 A8 A3 A0 B4 A4 B0 A1 B1]
time 38021ms: Process B2 (tau 875ms) completed I/O; added to ready queue [Q B7 A6 A2 B3 A7 B5 A8 B2 A3 A0 B4 A4 B0 A1 B1]
time 38305ms: Process A9 (tau 76ms) completed a CPU burst; 23 bursts to go [Q B7 A6 A2 B3 A7 B5 A8 B2 A3 A0 B4 A4 B0 A1 B1]
time 38305ms: Recalculated tau for process A9: old tau 76ms ==> new tau 314ms [Q B7 A6 A2 B3 A7 B5 A8 B2 A3 A0 B4 A4 B0 A1 B1]
time 38305ms: Process A9 switching out of CPU; blocking on I/O until time 38347ms [Q B7 A6 A2 B3 A7 B5 A8 B2 A3 A0 B4 A4 B0 A1 B1]
time 38309ms: Process B7 (tau 700ms) started using the CPU for 3ms burst [Q A6 A2 B3 A7 B5 A8 B2 A3 A0 B4 A4 B0 A1 B1]
time 38312ms: Process B7 (tau 700ms) completed a CPU burst; 9 bursts to go [Q A6 A2 B3 A7 B5 A8 B2 A3 A0 B4 A4 B0 A1 B1]
time 38312ms: Recalculated tau for process B7: old tau 700ms ==> new tau 10ms [Q A6 A2 B3 A7 B5 A8 B2 A3 A0 B4 A4 B0 A1 B1]
time 38312ms: Process B7 switching out of CPU; blocking on I/O until time 38514ms [Q A6 A2 B3 A7 B5 A8 B2 A3 A0 B4 A4 B0 A1 B1]
time 38316ms: Process A6 (tau 752ms) started using the CPU for 180ms burst [Q A2 B3 A7 B5 A8 B2 A3 A0 B4 A4 B0 A1 B1]
time 38347ms: Process A9 (tau 314ms) completed I/O; added to ready queue [Q A9 A2 B3 A7 B5 A8 B2 A3 A0 B4 A4 B0 A1 B1]
time 38496ms: Process A6 (tau 752ms) completed a CPU burst; 13 bursts to go [Q A9 A2 B3 A7 B5 A8 B2 A3 A0 B4 A4 B0 A1 B1]
time 38496ms: Recalculated tau for process A6: old tau 752ms ==> new tau 186ms [Q A9 A2 B3 A7 B5 A8 B2 A3 A0 B4 A4 B0 A1 B1]
time 38496ms: Process A6 switching out of CPU; blocking on I/O until time 38553ms [Q A9 A2 B3 A7 B5 A8 B2 A3 A0 B4 A4 B0 A1 B1]
time 38500ms: Process A9 (tau 314ms) started using the CPU for 464ms burst [Q A2 B3 A7 B5 A8 B2 A3 A0 B4 A4 B0 A1 B1]
time 38514ms: Process B7 (tau 10ms) completed I/O; added to ready queue [Q B7 A2 B3 A7 B5 A8 B2 A3 A0 B4 A4 B0 A1 B1]
time 38553ms: Process A6 (tau 186ms) completed I/O; added to ready queue [Q B7 A6 A2 B3 A7 B5 A8 B2 A3 A0 B4 A4 B0 A1 B1]
time 38964ms: Process A9 (tau 314ms) completed a CPU burst; 22 bursts to go [Q B7 A6 A2 B3 A7 B5 A8 B2 A3 A0 B4 A4 B0 A1 B1]
time 38964ms: Recalculated tau for process A9: old tau 314ms ==> new tau 463ms [Q B7 A6 A2 B3 A7 B5 A8 B2 A3 A0 B4 A4 B0 A1 B1]
time 38964ms: Process A9 switching out of CPU; blocking on I/O until time 38970ms [Q B7 A6 A2 B3 A7 B5 A8 B2 A3 A0 B4 A4 B0 A1 B1]
time 38968ms: Process B7 (tau 10ms) started using the CPU for 186ms burst [Q A6 A2 B3 A7 B5 A8 B2 A3 A0 B4 A4 B0 A1 B1]
time 38970ms: Process A9 (tau 463ms) completed I/O; added to ready queue [Q A6 A9 A2 B3 A7 B5 A8 B2 A3 A0 B4 A4 B0 A1 B1]
time 39154ms: Process B7 (tau 10ms) completed a CPU burst; 8 bursts to go [Q A6 A9 A2 B3 A7 B5 A8 B2 A3 A0 B4 A4 B0 A1 B1]
time 39154ms: Recalculated tau for process B7: old tau 10ms ==> new tau 185ms [Q A6 A9 A2 B3 A7 B5 A8 B2 A3 A0 B4 A4 B0 A1 B1]
time 39154ms: Process B7 switching out of CPU; blocking on I/O until time 41108ms [Q A6 A9 A2 B3 A7 B5 A8 B2 A3 A0 B4 A4 B0 A1 B1]
time 39158ms: Process A6 (tau 186ms) started using the CPU for 264ms burst [Q A9 A2 B3 A7 B5 A8 B2 A3 A0 B4 A4 B0 A1 B1]
time 39422ms: Process A6 (tau 186ms) completed a CPU burst; 12 bursts to go [Q A9 A2 B3 A7 B5 A8 B2 A3 A0 B4 A4 B0 A1 B1]
time 39422ms: Recalculated tau for process A6: old tau 186ms ==> new tau 264ms [Q A9 A2 B3 A7 B5 A8 B2 A3 A0 B4 A4 B0 A1 B1]
time 39422ms: Process A6 switching out of CPU; blocking on I/O until time 39525ms [Q A9 A2 B3 A7 B5 A8 B2 A3 A0 B4 A4 B0 A1 B1]
time 39426ms: Process A9 (tau 463ms) started using the CPU for 712ms burst [Q A2 B3 A7 B5 A8 B2 A3 A0 B4 A4 B0 A1 B1]
time 39525ms: Process A6 (tau 264ms) completed I/O; added to ready queue [Q A6 A2 B3 A7 B5 A8 B2 A3 A0 B4 A4 B0 A1 B1]
time 39927ms: Process B8 (tau 67ms) completed I/O; added to ready queue [Q B8 A6 A2 B3 A7 B5 A8 B2 A3 A0 B4 A4 B0 A1 B1]
time 40138ms: Process A9 (tau 463ms) completed a CPU burst; 21 bursts to go [Q B8 A6 A2 B3 A7 B5 A8 B2 A3 A0 B4 A4 B0 A1 B1]
time 40138ms: Recalculated tau for process A9: old tau 463ms ==> new tau 710ms [Q B8 A6 A2 B3 A7 B5 A8 B2 A3 A0 B4 A4 B0 A1 B1]
time 40138ms: Process A9 switching out of CPU; blocking on I/O until time 40189ms [Q B8 A6 A2 B3 A7 B5 A8 B2 A3 A0 B4 A4 B0 A1 B1]
time 40142ms: Process B8 (tau 67ms) started using the CPU for 64ms burst [Q A6 A2 B3 A7 B5 A8 B2 A3 A0 B4 A4 B0 A1 B1]
time 40189ms: Process A9 (tau 710ms) completed I/O; added to ready queue [Q A6 A9 A2 B3 A7 B5 A8 B2 A3 A0 B4 A4 B0 A1 B1]
time 40206ms: Process B8 terminated [Q A6 A9 A2 B3 A7 B5 A8 B2 A3 A0 B4 A4 B0 A1 B1]
time 40210ms: Process A6 (tau 264ms) started using the CPU for 588ms burst [Q A9 A2 B3 A7 B5 A8 B2 A3 A0 B4 A4 B0 A1 B1]
time 40798ms: Process A6 (tau 264ms) completed a CPU burst; 11 bursts to go [Q A9 A2 B3 A7 B5 A8 B2 A3 A0 B4 A4 B0 A1 B1]
time 40798ms: Recalculated tau for process A6: old tau 264ms ==> new tau 585ms [Q A9 A2 B3 A7 B5 A8 B2 A3 A0 B4 A4 B0 A1 B1]
time 40798ms: Process A6 switching out of CPU; blocking on I/O until time 40847ms [Q A9 A2 B3 A7 B5 A8 B2 A3 A0 B4 A4 B0 A1 B1]
time 40802ms: Process A9 (tau 710ms) started using the CPU for 1680ms burst [Q A2 B3 A7 B5 A8 B2 A3 A0 B4 A4 B0 A1 B1]
time 40847ms: Process A6 (tau 585ms) completed I/O; added to ready queue [Q A6 A2 B3 A7 B5 A8 B2 A3 A0 B4 A4 B0 A1 B1]
time 41108ms: Process B7 (tau 185ms) completed I/O; added to ready queue [Q B7 A6 A2 B3 A7 B5 A8 B2 A3 A0 B4 A4 B0 A1 B1]
time 42482ms: Process A9 (tau 710ms) completed a CPU burst; 20 bursts to go [Q B7 A6 A2 B3 A7 B5 A8 B2 A3 A0 B4 A4 B0 A1 B1]
time 42482ms: Recalculated tau for process A9: old tau 710ms ==> new tau 1671ms [Q B7 A6 A2 B3 A7 B5 A8 B2 A3 A0 B4 A4 B0 A1 B1]
time 42482ms: Process A9 switching out of CPU; blocking on I/O until time 42516ms [Q B7 A6 A2 B3 A7 B5 A8 B2 A3 A0 B4 A4 B0 A1 B1]
time 42486ms: Process B7 (tau 185ms) started using the CPU for 257ms burst [Q A6 A2 B3 A7 B5 A8 B2 A3 A0 B4 A4 B0 A1 B1]
time 42516ms: Process A9 (tau 1671ms) completed I/O; added to ready queue [Q A6 A2 B3 A7 B5 A8 B2 A3 A0 B4 A4 B0 A1 A9 B1]
time 42743ms: Process B7 (tau 185ms) completed a CPU burst; 7 bursts to go [Q A6 A2 B3 A7 B5 A8 B2 A3 A0 B4 A4 B0 A1 A9 B1]
time 42743ms: Recalculated tau for process B7: old tau 185ms ==> new tau 257ms [Q A6 A2 B3 A7 B5 A8 B2 A3 A0 B4 A4 B0 A1 A9 B1]
time 42743ms: Process B7 switching out of CPU; blocking on I/O until time 42753ms [Q A6 A2 B3 A7 B5 A8 B2 A3 A0 B4 A4 B0 A1 A9 B1]
time 42747ms: Process A6 (tau 585ms) started using the CPU for 84ms burst [Q A2 B3 A7 B5 A8 B2 A3 A0 B4 A4 B0 A1 A9 B1]
time 42753ms: Process B7 (tau 257ms) completed I/O; added to ready queue [Q B7 A2 B3 A7 B5 A8 B2 A3 A0 B4 A4 B0 A1 A9 B1]
time 42831ms: Process A6 (tau 585ms) completed a CPU burst; 10 bursts to go [Q B7 A2 B3 A7 B5 A8 B2 A3 A0 B4 A4 B0 A1 A9 B1]
time 42831ms: Recalculated tau for process A6: old tau 585ms ==> new tau 90ms [Q B7 A2 B3 A7 B5 A8 B2 A3 A0 B4 A4 B0 A1 A9 B1]
time 42831ms: Process A6 switching out of CPU; blocking on I/O until time 42850ms [Q B7 A2 B3 A7 B5 A8 B2 A3 A0 B4 A4 B0 A1 A9 B1]
time 42835ms: Process B7 (tau 257ms) started using the CPU for 42ms burst [Q A2 B3 A7 B5 A8 B2 A3 A0 B4 A4 B0 A1 A9 B1]
time 42850ms: Process A6 (tau 90ms) completed I/O; added to ready queue [Q A6 A2 B3 A7 B5 A8 B2 A3 A0 B4 A4 B0 A1 A9 B1]
time 42877ms: Process B7 (tau 257ms) completed a CPU burst; 6 bursts to go [Q A6 A2 B3 A7 B5 A8 B2 A3 A0 B4 A4 B0 A1 A9 B1]
time 42877ms: Recalculated tau for process B7: old tau 257ms ==> new tau 45ms [Q A6 A2 B3 A7 B5 A8 B2 A3 A0 B4 A4 B0 A1 A9 B1]
time 42877ms: Process B7 switching out of CPU; blocking on I/O until time 43879ms [Q A6 A2 B3 A7 B5 A8 B2 A3 A0 B4 A4 B0 A1 A9 B1]
time 42881ms: Process A6 (tau 90ms) started using the CPU for 1312ms burst [Q A2 B3 A7 B5 A8 B2 A3 A0 B4 A4 B0 A1 A9 B1]
time 43879ms: Process B7 (tau 45ms) completed I/O; added to ready queue [Q B7 A2 B3 A7 B5 A8 B2 A3 A0 B4 A4 B0 A1 A9 B1]
time 44193ms: Process A6 (tau 90ms) completed a CPU burst; 9 bursts to go [Q B7 A2 B3 A7 B5 A8 B2 A3 A0 B4 A4 B0 A1 A9 B1]
time 44193ms: Recalculated tau for process A6: old tau 90ms ==> new tau 1300ms [Q B7 A2 B3 A7 B5 A8 B2 A3 A0 B4 A4 B0 A1 A9 B1]
time 44193ms: Process A6 switching out of CPU; blocking on I/O until time 44261ms [Q B7 A2 B3 A7 B5 A8 B2 A3 A0 B4 A4 B0 A1 A9 B1]
time 44197ms: Process B7 (tau 45ms) started using the CPU for 54ms burst [Q A2 B3 A7 B5 A8 B2 A3 A0 B4 A4 B0 A1 A9 B1]
time 44251ms: Process B7 (tau 45ms) completed a CPU burst; 5 bursts to go [Q A2 B3 A7 B5 A8 B2 A3 A0 B4 A4 B0 A1 A9 B1]
time 44251ms: Recalculated tau for process B7: old tau 45ms ==> new tau 54ms [Q A2 B3 A7 B5 A8 B2 A3 A0 B4 A4 B0 A1 A9 B1]
time 44251ms: Process B7 switching out of CPU; blocking on I/O until time 44309ms [Q A2 B3 A7 B5 A8 B2 A3 A0 B4 A4 B0 A1 A9 B1]
time 44255ms: Process A2 (tau 757ms) started using the CPU for 92ms burst [Q B3 A7 B5 A8 B2 A3 A0 B4 A4 B0 A1 A9 B1]
time 44261ms: Process A6 (tau 1300ms) completed I/O; added to ready queue [Q B3 A7 B5 A8 B2 A3 A0 B4 A4 B0 A6 A1 A9 B1]
time 44309ms: Process B7 (tau 54ms) completed I/O; added to ready queue [Q B7 B3 A7 B5 A8 B2 A3 A0 B4 A4 B0 A6 A1 A9 B1]
time 44347ms: Process A2 (tau 757ms) completed a CPU burst; 26 bursts to go [Q B7 B3 A7 B5 A8 B2 A3 A0 B4 A4 B0 A6 A1 A9 B1]
time 44347ms: Recalculated tau for process A2: old tau 757ms ==> new tau 99ms [Q B7 B3 A7 B5 A8 B2 A3 A0 B4 A4 B0 A6 A1 A9 B1]
time 44347ms: Process A2 switching out of CPU; blocking on I/O until time 44408ms [Q B7 B3 A7 B5 A8 B2 A3 A0 B4 A4 B0 A6 A1 A9 B1]
time 44351ms: Process B7 (tau 54ms) started using the CPU for 6ms burst [Q B3 A7 B5 A8 B2 A3 A0 B4 A4 B0 A6 A1 A9 B1]
time 44357ms: Process B7 (tau 54ms) completed a CPU burst; 4 bursts to go [Q B3 A7 B5 A8 B2 A3 A0 B4 A4 B0 A6 A1 A9 B1]
time 44357ms: Recalculated tau for process B7: old tau 54ms ==> new tau 7ms [Q B3 A7 B5 A8 B2 A3 A0 B4 A4 B0 A6 A1 A9 B1]
time 44357ms: Process B7 switching out of CPU; blocking on I/O until time 44503ms [Q B3 A7 B5 A8 B2 A3 A0 B4 A4 B0 A6 A1 A9 B1]
time 44361ms: Process B3 (tau 757ms) started using the CPU for 448ms burst [Q A7 B5 A8 B2 A3 A0 B4 A4 B0 A6 A1 A9 B1]
time 44408ms: Process A2 (tau 99ms) completed I/O; added to ready queue [Q A2 A7 B5 A8 B2 A3 A0 B4 A4 B0 A6 A1 A9 B1]
time 44503ms: Process B7 (tau 7ms) completed I/O; added to ready queue [Q B7 A2 A7 B5 A8 B2 A3 A0 B4 A4 B0 A6 A1 A9 B1]
time 44809ms: Process B3 (tau 757ms) completed a CPU burst; 10 bursts to go [Q B7 A2 A7 B5 A8 B2 A3 A0 B4 A4 B0 A6 A1 A9 B1]
time 44809ms: Recalculated tau for process B3: old tau 757ms ==> new tau 452ms [Q B7 A2 A7 B5 A8 B2 A3 A0 B4 A4 B0 A6 A1 A9 B1]
time 44809ms: Process B3 switching out of CPU; blocking on I/O until time 44855ms [Q B7 A2 A7 B5 A8 B2 A3 A0 B4 A4 B0 A6 A1 A9 B1]
time 44813ms: Process B7 (tau 7ms) started using the CPU for 44ms burst [Q A2 A7 B5 A8 B2 A3 A0 B4 A4 B0 A6 A1 A9 B1]
time 44855ms: Process B3 (tau 452ms) completed I/O; added to ready queue [Q A2 B3 A7 B5 A8 B2 A3 A0 B4 A4 B0 A6 A1 A9 B1]
time 44857ms: Process B7 (tau 7ms) completed a CPU burst; 3 bursts to go [Q A2 B3 A7 B5 A8 B2 A3 A0 B4 A4 B0 A6 A1 A9 B1]
time 44857ms: Recalculated tau for process B7: old tau 7ms ==> new tau 44ms [Q A2 B3 A7 B5 A8 B2 A3 A0 B4 A4 B0 A6 A1 A9 B1]
time 44857ms: Process B7 switching out of CPU; blocking on I/O until time 45483ms [Q A2 B3 A7 B5 A8 B2 A3 A0 B4 A4 B0 A6 A1 A9 B1]
time 44861ms: Process A2 (tau 99ms) started using the CPU for 136ms burst [Q B3 A7 B5 A8 B2 A3 A0 B4 A4 B0 A6 A1 A9 B1]
time 44997ms: Process A2 (tau 99ms) completed a CPU burst; 25 bursts to go [Q B3 A7 B5 A8 B2 A3 A0 B4 A4 B0 A6 A1 A9 B1]
time 44997ms: Recalculated tau for process A2: old tau 99ms ==> new tau 136ms [Q B3 A7 B5 A8 B2 A3 A0 B4 A4 B0 A6 A1 A9 B1]
time 44997ms: Process A2 switching out of CPU; blocking on I/O until time 45170ms [Q B3 A7 B5 A8 B2 A3 A0 B4 A4 B0 A6 A1 A9 B1]
time 45001ms: Process B3 (tau 452ms) started using the CPU for 552ms burst [Q A7 B5 A8 B2 A3 A0 B4 A4 B0 A6 A1 A9 B1]
time 45170ms: Process A2 (tau 136ms) completed I/O; added to ready queue [Q A2 A7 B5 A8 B2 A3 A0 B4 A4 B0 A6 A1 A9 B1]
time 45483ms: Process B7 (tau 44ms) completed I/O; added to ready queue [Q B7 A2 A7 B5 A8 B2 A3 A0 B4 A4 B0 A6 A1 A9 B1]
time 45553ms: Process B3 (tau 452ms) completed a CPU burst; 9 bursts to go [Q B7 A2 A7 B5 A8 B2 A3 A0 B4 A4 B0 A6 A1 A9 B1]
time 45553ms: Recalculated tau for process B3: old tau 452ms ==> new tau 551ms [Q B7 A2 A7 B5 A8 B2 A3 A0 B4 A4 B0 A6 A1 A9 B1]
time 45553ms: Process B3 switching out of CPU; blocking on I/O until time 45661ms [Q B7 A2 A7 B5 A8 B2 A3 A0 B4 A4 B0 A6 A1 A9 B1]
time 45557ms: Process B7 (tau 44ms) started using the CPU for 19ms burst [Q A2 A7 B5 A8 B2 A3 A0 B4 A4 B0 A6 A1 A9 B1]
time 45576ms: Process B7 (tau 44ms) completed a CPU burst; 2 bursts to go [Q A2 A7 B5 A8 B2 A3 A0 B4 A4 B0 A6 A1 A9 B1]
time 45576ms: Recalculated tau for process B7: old tau 44ms ==> new tau 20ms [Q A2 A7 B5 A8 B2 A3 A0 B4 A4 B0 A6 A1 A9 B1]
time 45576ms: Process B7 switching out of CPU; blocking on I/O until time 45850ms [Q A2 A7 B5 A8 B2 A3 A0 B4 A4 B0 A6 A1 A9 B1]
time 45580ms: Process A2 (tau 136ms) started using the CPU for 236ms burst [Q A7 B5 A8 B2 A3 A0 B4 A4 B0 A6 A1 A9 B1]
time 45661ms: Process B3 (tau 551ms) completed I/O; added to ready queue [Q B3 A7 B5 A8 B2 A3 A0 B4 A4 B0 A6 A1 A9 B1]
time 45816ms: Process A2 (tau 136ms) completed a CPU burst; 24 bursts to go [Q B3 A7 B5 A8 B2 A3 A0 B4 A4 B0 A6 A1 A9 B1]
time 45816ms: Recalculated tau for process A2: old tau 136ms ==> new tau 235ms [Q B3 A7 B5 A8 B2 A3 A0 B4 A4 B0 A6 A1 A9 B1]
time 45816ms: Process A2 switching out of CPU; blocking on I/O until time 45902ms [Q B3 A7 B5 A8 B2 A3 A0 B4 A4 B0 A6 A1 A9 B1]
time 45820ms: Process B3 (tau 551ms) started using the CPU for 92ms burst [Q A7 B5 A8 B2 A3 A0 B4 A4 B0 A6 A1 A9 B1]
time 45850ms: Process B7 (tau 20ms) completed I/O; added to ready queue [Q B7 A7 B5 A8 B2 A3 A0 B4 A4 B0 A6 A1 A9 B1]
time 45902ms: Process A2 (tau 235ms) completed I/O; added to ready queue [Q B7 A2 A7 B5 A8 B2 A3 A0 B4 A4 B0 A6 A1 A9 B1]
time 45912ms: Process B3 (tau 551ms) completed a CPU burst; 8 bursts to go [Q B7 A2 A7 B5 A8 B2 A3 A0 B4 A4 B0 A6 A1 A9 B1]
time 45912ms: Recalculated tau for process B3: old tau 551ms ==> new tau 97ms [Q B7 A2 A7 B5 A8 B2 A3 A0 B4 A4 B0 A6 A1 A9 B1]
time 45912ms: Process B3 switching out of CPU; blocking on I/O until time 46001ms [Q B7 A2 A7 B5 A8 B2 A3 A0 B4 A4 B0 A6 A1 A9 B1]
time 45916ms: Process B7 (tau 20ms) started using the CPU for 17ms burst [Q A2 A7 B5 A8 B2 A3 A0 B4 A4 B0 A6 A1 A9 B1]
time 45933ms: Process B7 (tau 20ms) completed a CPU burst; 1 burst to go [Q A2 A7 B5 A8 B2 A3 A0 B4 A4 B0 A6 A1 A9 B1]
time 45933ms: Recalculated tau for process B7: old tau 20ms ==> new tau 18ms [Q A2 A7 B5 A8 B2 A3 A0 B4 A4 B0 A6 A1 A9 B1]
time 45933ms: Process B7 switching out of CPU; blocking on I/O until time 46359ms [Q A2 A7 B5 A8 B2 A3 A0 B4 A4 B0 A6 A1 A9 B1]
time 45937ms: Process A2 (tau 235ms) started using the CPU for 112ms burst [Q A7 B5 A8 B2 A3 A0 B4 A4 B0 A6 A1 A9 B1]
time 46001ms: Process B3 (tau 97ms) completed I/O; added to ready queue [Q B3 A7 B5 A8 B2 A3 A0 B4 A4 B0 A6 A1 A9 B1]
